Workbook
Name SyncBankC: Sync!$C$6:$C$15
Name SyncBankD: Sync!$D$6:$D$15
Name AcctTblA: Sync!$F$6:$I$565
Name PkPartyA: Sync!$T$6:$T$565
Name NPartyA: Sync!$S$565
Name PkExpA: Sync!$X$6:$X$105
Name NExpA: Sync!$W$105
Name CalcDebit: Calc!$I$6:$I$2005
Name CalcCredit: Calc!$J$6:$J$2005
Name CalcAmt: Calc!$H$6:$H$2005
Name CalcDep: Calc!$F$6:$F$2005
Name CalcWit: Calc!$G$6:$G$2005
Name CalcGroup: Calc!$D$6:$D$2005
Name CalcDebit2: Calc!$O$6:$O$505
Name CalcCredit2: Calc!$P$6:$P$505
Name CalcAmt2: Calc!$M$6:$M$505
Name CalcAmt3: Calc!$X$6:$X$1005
Name CalcDebit3: Calc!$Z$6:$Z$1005
Name CalcCredit3: Calc!$AA$6:$AA$1005
Name AcctCodesA: Sync!$F$6:$F$565
Name IssueNosA: Sync!$AG$6:$AG$505
Name PkFixedA: Sync!$AO$6:$AO$565
Name NFixedA: Sync!$AN$565
Name PkLoanA: Sync!$AR$6:$AR$565
Name NLoanA: Sync!$AQ$565
Name PkCapA: Sync!$AU$6:$AU$565
Name NCapA: Sync!$AT$565
Name CalcProb1: Calc!$K$6:$K$2005
Name CalcRank1: Calc!$W$6:$W$2005
Name CalcProb2: Calc!$R$6:$R$505
Name CalcRank2: Calc!$T$6:$T$505
Name TrialType: Trial!$D$10:$D$2365
Name TrialDr: Trial!$E$10:$E$2365
Name TrialCr: Trial!$F$10:$F$2365
Name TrialBal: Trial!$G$10:$G$2365

Sheet Trial
A1: =IF(Sync!$P$6="","مازندشت",Sync!$P$6)&" — "&IF(Sync!$P$9="","سورتینگ و بسته‌بندی مرکبات",Sync!$P$9)
A2: =IF(Sync!$P$7="","باغدشت، بخش مرکزی، شهرستان قائم‌شهر، استان مازندران، ایران",Sync!$P$7)&" | MAZANDASHT · CITRUS SORTING & PACKING"
A3: تراز آزمایشی — تشخیص خودکار بدهکار/بستانکار از تراکنش‌ها و چک‌ها
A4: هر تراکنش دوطرفه است: واریز ← بدهکار بانک / بستانکار طرف · برداشت هزینه ← بدهکار «هزینه: زیرگروه» / بستانکار بانک · برداشت خرید ← بدهکار طرف / بستانکار بانک · «پاس چک» ← بدهکار اسناد چک / بستانکار بانک · صدور چک ← بدهکار ذی‌نفع / بستانکار اسناد چک. طرف حساب با ماهیت «دارایی ثابت» در دارایی‌ها، «وام و تسهیلات» در بدهی‌ها و «سرمایه و آورده صاحبان» در حقوق ترازنامه می‌نشیند. کد طرفِ تعریف‌نشده یا بدون گروه، به «متفرقه» می‌رود و در شیت Control فهرست می‌شود. «شخصی قاسم» طبق تعریف شما خارج از حساب‌های شرکت است و فقط برای توازن نمایش داده می‌شود. خرید سبد (دفتر Baskets): بدهکار «سبد و ظروف» / بستانکار فروشنده سبد — پس مانده هر فروشنده سبد دقیقاً مطابق کارتکس فایل Baskets می‌شود.
A5: جمع کل بدهکار (ریال) | C5: جمع کل بستانکار (ریال) | E5: کنترل توازن | G5: تعداد حساب‌های دارای گردش
A6: =E2366 | C6: =F2366 | E6: =IF(ROUND(E2366-F2366,0)=0,"√ تراز است","▲ مغایرت") | G6: =COUNTIF($G$10:$G$2365,"<>0")
A7: ردیف | B7: حساب | C7: کد / کلید | D7: نوع | E7: جمع بدهکار (ریال) | F7: جمع بستانکار (ریال) | G7: مانده (ریال) | H7: وضعیت
A8: No. | B8: Account | C8: Code / Key | D8: Type | E8: Total Debit | F8: Total Credit | G8: Balance | H8: State
A10: =IF($B10="","",1) | B10: =IF(Sync!$A6="","",Sync!$A6&" — "&Sync!$B6) | C10: =IF($B10="","",Sync!$A6) | D10: =IF($B10="","","b") | E10: =IF($B10="","",SUMIF(CalcDebit,Sync!$A6,CalcAmt)+IF(Sync!$D6="بله",IF(Sync!$C6="",0,Sync!$C6),0)) | F10: =IF($B10="","",SUMIF(CalcCredit,Sync!$A6,CalcAmt)) | G10: =IF($B10="","",ROUND($E10-$F10,0)) | H10: =IF($B10="","",IF(ROUND($G10,0)>0,"بدهکار",IF(ROUND($G10,0)<0,"بستانکار","تسویه")))
A11: =IF($B11="","",2) | B11: =IF(Sync!$A7="","",Sync!$A7&" — "&Sync!$B7) | C11: =IF($B11="","",Sync!$A7) | D11: =IF($B11="","","b") | E11: =IF($B11="","",SUMIF(CalcDebit,Sync!$A7,CalcAmt)+IF(Sync!$D7="بله",IF(Sync!$C7="",0,Sync!$C7),0)) | F11: =IF($B11="","",SUMIF(CalcCredit,Sync!$A7,CalcAmt)) | G11: =IF($B11="","",ROUND($E11-$F11,0)) | H11: =IF($B11="","",IF(ROUND($G11,0)>0,"بدهکار",IF(ROUND($G11,0)<0,"بستانکار","تسویه")))
A12: =IF($B12="","",3) | B12: =IF(Sync!$A8="","",Sync!$A8&" — "&Sync!$B8) | C12: =IF($B12="","",Sync!$A8) | D12: =IF($B12="","","b") | E12: =IF($B12="","",SUMIF(CalcDebit,Sync!$A8,CalcAmt)+IF(Sync!$D8="بله",IF(Sync!$C8="",0,Sync!$C8),0)) | F12: =IF($B12="","",SUMIF(CalcCredit,Sync!$A8,CalcAmt)) | G12: =IF($B12="","",ROUND($E12-$F12,0)) | H12: =IF($B12="","",IF(ROUND($G12,0)>0,"بدهکار",IF(ROUND($G12,0)<0,"بستانکار","تسویه")))
A13: =IF($B13="","",4) | B13: =IF(Sync!$A9="","",Sync!$A9&" — "&Sync!$B9) | C13: =IF($B13="","",Sync!$A9) | D13: =IF($B13="","","b") | E13: =IF($B13="","",SUMIF(CalcDebit,Sync!$A9,CalcAmt)+IF(Sync!$D9="بله",IF(Sync!$C9="",0,Sync!$C9),0)) | F13: =IF($B13="","",SUMIF(CalcCredit,Sync!$A9,CalcAmt)) | G13: =IF($B13="","",ROUND($E13-$F13,0)) | H13: =IF($B13="","",IF(ROUND($G13,0)>0,"بدهکار",IF(ROUND($G13,0)<0,"بستانکار","تسویه")))
A14: =IF($B14="","",5) | B14: =IF(Sync!$A10="","",Sync!$A10&" — "&Sync!$B10) | C14: =IF($B14="","",Sync!$A10) | D14: =IF($B14="","","b") | E14: =IF($B14="","",SUMIF(CalcDebit,Sync!$A10,CalcAmt)+IF(Sync!$D10="بله",IF(Sync!$C10="",0,Sync!$C10),0)) | F14: =IF($B14="","",SUMIF(CalcCredit,Sync!$A10,CalcAmt)) | G14: =IF($B14="","",ROUND($E14-$F14,0)) | H14: =IF($B14="","",IF(ROUND($G14,0)>0,"بدهکار",IF(ROUND($G14,0)<0,"بستانکار","تسویه")))
A15: =IF($B15="","",6) | B15: =IF(Sync!$A11="","",Sync!$A11&" — "&Sync!$B11) | C15: =IF($B15="","",Sync!$A11) | D15: =IF($B15="","","b") | E15: =IF($B15="","",SUMIF(CalcDebit,Sync!$A11,CalcAmt)+IF(Sync!$D11="بله",IF(Sync!$C11="",0,Sync!$C11),0)) | F15: =IF($B15="","",SUMIF(CalcCredit,Sync!$A11,CalcAmt)) | G15: =IF($B15="","",ROUND($E15-$F15,0)) | H15: =IF($B15="","",IF(ROUND($G15,0)>0,"بدهکار",IF(ROUND($G15,0)<0,"بستانکار","تسویه")))
A16: =IF($B16="","",7) | B16: =IF(Sync!$A12="","",Sync!$A12&" — "&Sync!$B12) | C16: =IF($B16="","",Sync!$A12) | D16: =IF($B16="","","b") | E16: =IF($B16="","",SUMIF(CalcDebit,Sync!$A12,CalcAmt)+IF(Sync!$D12="بله",IF(Sync!$C12="",0,Sync!$C12),0)) | F16: =IF($B16="","",SUMIF(CalcCredit,Sync!$A12,CalcAmt)) | G16: =IF($B16="","",ROUND($E16-$F16,0)) | H16: =IF($B16="","",IF(ROUND($G16,0)>0,"بدهکار",IF(ROUND($G16,0)<0,"بستانکار","تسویه")))
A17: =IF($B17="","",8) | B17: =IF(Sync!$A13="","",Sync!$A13&" — "&Sync!$B13) | C17: =IF($B17="","",Sync!$A13) | D17: =IF($B17="","","b") | E17: =IF($B17="","",SUMIF(CalcDebit,Sync!$A13,CalcAmt)+IF(Sync!$D13="بله",IF(Sync!$C13="",0,Sync!$C13),0)) | F17: =IF($B17="","",SUMIF(CalcCredit,Sync!$A13,CalcAmt)) | G17: =IF($B17="","",ROUND($E17-$F17,0)) | H17: =IF($B17="","",IF(ROUND($G17,0)>0,"بدهکار",IF(ROUND($G17,0)<0,"بستانکار","تسویه")))
A18: =IF($B18="","",9) | B18: =IF(Sync!$A14="","",Sync!$A14&" — "&Sync!$B14) | C18: =IF($B18="","",Sync!$A14) | D18: =IF($B18="","","b") | E18: =IF($B18="","",SUMIF(CalcDebit,Sync!$A14,CalcAmt)+IF(Sync!$D14="بله",IF(Sync!$C14="",0,Sync!$C14),0)) | F18: =IF($B18="","",SUMIF(CalcCredit,Sync!$A14,CalcAmt)) | G18: =IF($B18="","",ROUND($E18-$F18,0)) | H18: =IF($B18="","",IF(ROUND($G18,0)>0,"بدهکار",IF(ROUND($G18,0)<0,"بستانکار","تسویه")))
A19: =IF($B19="","",10) | B19: =IF(Sync!$A15="","",Sync!$A15&" — "&Sync!$B15) | C19: =IF($B19="","",Sync!$A15) | D19: =IF($B19="","","b") | E19: =IF($B19="","",SUMIF(CalcDebit,Sync!$A15,CalcAmt)+IF(Sync!$D15="بله",IF(Sync!$C15="",0,Sync!$C15),0)) | F19: =IF($B19="","",SUMIF(CalcCredit,Sync!$A15,CalcAmt)) | G19: =IF($B19="","",ROUND($E19-$F19,0)) | H19: =IF($B19="","",IF(ROUND($G19,0)>0,"بدهکار",IF(ROUND($G19,0)<0,"بستانکار","تسویه")))
A20: =IF($B20="","",11) | B20: ="اسناد چک پرداختی" | C20: =IF($B20="","","چک پرداختی") | D20: =IF($B20="","","q") | E20: =IF($B20="","",SUMIF(CalcDebit,"چک پرداختی",CalcAmt)) | F20: =IF($B20="","",SUMIF(CalcCredit2,"چک پرداختی",CalcAmt2)) | G20: =IF($B20="","",ROUND($E20-$F20,0)) | H20: =IF($B20="","",IF(ROUND($G20,0)>0,"بدهکار",IF(ROUND($G20,0)<0,"بستانکار","تسویه")))
A21: =IF($B21="","",12) | B21: ="افتتاحیه (مانده اولیه بانک‌ها)" | C21: =IF($B21="","","افتتاحیه") | D21: =IF($B21="","","o") | E21: =IF($B21="","",0) | F21: =IF($B21="","",SUMIFS(SyncBankC,SyncBankD,"بله")) | G21: =IF($B21="","",ROUND($E21-$F21,0)) | H21: =IF($B21="","",IF(ROUND($G21,0)>0,"بدهکار",IF(ROUND($G21,0)<0,"بستانکار","تسویه")))
A22: =IF($B22="","",13) | B22: ="متفرقه / بدون طبقه" | C22: =IF($B22="","","متفرقه") | D22: =IF($B22="","","m") | E22: =IF($B22="","",SUMIF(CalcDebit,"متفرقه",CalcAmt)+SUMIF(CalcDebit2,"متفرقه",CalcAmt2)+SUMIF(CalcDebit3,"متفرقه",CalcAmt3)) | F22: =IF($B22="","",SUMIF(CalcCredit,"متفرقه",CalcAmt)+SUMIF(CalcCredit2,"متفرقه",CalcAmt2)+SUMIF(CalcCredit3,"متفرقه",CalcAmt3)) | G22: =IF($B22="","",ROUND($E22-$F22,0)) | H22: =IF($B22="","",IF(ROUND($G22,0)>0,"بدهکار",IF(ROUND($G22,0)<0,"بستانکار","تسویه")))
A23: =IF($B23="","",14) | B23: ="شخصی قاسم (خارج از حساب‌های شرکت)" | C23: =IF($B23="","","شخصی قاسم") | D23: =IF($B23="","","x") | E23: =IF($B23="","",SUMIF(CalcDebit,"شخصی قاسم",CalcAmt)) | F23: =IF($B23="","",SUMIF(CalcCredit,"شخصی قاسم",CalcAmt)) | G23: =IF($B23="","",ROUND($E23-$F23,0)) | H23: =IF($B23="","",IF(ROUND($G23,0)>0,"بدهکار",IF(ROUND($G23,0)<0,"بستانکار","تسویه")))
A24: =IF($B24="","",15) | B24: ="سبد و ظروف — از دفتر Baskets" | C24: =IF($B24="","","سبد و ظروف") | D24: =IF($B24="","","s") | E24: =IF($B24="","",SUMIF(CalcDebit3,"سبد و ظروف",CalcAmt3)) | F24: =IF($B24="","",0) | G24: =IF($B24="","",ROUND($E24-$F24,0)) | H24: =IF($B24="","",IF(ROUND($G24,0)>0,"بدهکار",IF(ROUND($G24,0)<0,"بستانکار","تسویه")))
A25: =IF($B25="","",16) | B25: =IF(1>NPartyA,"",IFERROR(IF(VLOOKUP(INDEX(PkPartyA,1),AcctTblA,4,0)="","(بدون نام)",VLOOKUP(INDEX(PkPartyA,1),AcctTblA,4,0)),"—")) | C25: =IF($B25="","",IF(1>NPartyA,"",INDEX(PkPartyA,1))) | D25: =IF($B25="","","p") | E25: =IF($B25="","",IF(1>NPartyA,0,SUMIF(CalcDebit,INDEX(PkPartyA,1),CalcAmt)+SUMIF(CalcDebit2,INDEX(PkPartyA,1),CalcAmt2)+SUMIF(CalcDebit3,INDEX(PkPartyA,1),CalcAmt3))) | F25: =IF($B25="","",IF(1>NPartyA,0,SUMIF(CalcCredit,INDEX(PkPartyA,1),CalcAmt)+SUMIF(CalcCredit2,INDEX(PkPartyA,1),CalcAmt2)+SUMIF(CalcCredit3,INDEX(PkPartyA,1),CalcAmt3))) | G25: =IF($B25="","",ROUND($E25-$F25,0)) | H25: =IF($B25="","",IF(ROUND($G25,0)>0,"بدهکار",IF(ROUND($G25,0)<0,"بستانکار","تسویه")))
A26: =IF($B26="","",17) | B26: =IF(2>NPartyA,"",IFERROR(IF(VLOOKUP(INDEX(PkPartyA,2),AcctTblA,4,0)="","(بدون نام)",VLOOKUP(INDEX(PkPartyA,2),AcctTblA,4,0)),"—")) | C26: =IF($B26="","",IF(2>NPartyA,"",INDEX(PkPartyA,2))) | D26: =IF($B26="","","p") | E26: =IF($B26="","",IF(2>NPartyA,0,SUMIF(CalcDebit,INDEX(PkPartyA,2),CalcAmt)+SUMIF(CalcDebit2,INDEX(PkPartyA,2),CalcAmt2)+SUMIF(CalcDebit3,INDEX(PkPartyA,2),CalcAmt3))) | F26: =IF($B26="","",IF(2>NPartyA,0,SUMIF(CalcCredit,INDEX(PkPartyA,2),CalcAmt)+SUMIF(CalcCredit2,INDEX(PkPartyA,2),CalcAmt2)+SUMIF(CalcCredit3,INDEX(PkPartyA,2),CalcAmt3))) | G26: =IF($B26="","",ROUND($E26-$F26,0)) | H26: =IF($B26="","",IF(ROUND($G26,0)>0,"بدهکار",IF(ROUND($G26,0)<0,"بستانکار","تسویه")))
A27: =IF($B27="","",18) | B27: =IF(3>NPartyA,"",IFERROR(IF(VLOOKUP(INDEX(PkPartyA,3),AcctTblA,4,0)="","(بدون نام)",VLOOKUP(INDEX(PkPartyA,3),AcctTblA,4,0)),"—")) | C27: =IF($B27="","",IF(3>NPartyA,"",INDEX(PkPartyA,3))) | D27: =IF($B27="","","p") | E27: =IF($B27="","",IF(3>NPartyA,0,SUMIF(CalcDebit,INDEX(PkPartyA,3),CalcAmt)+SUMIF(CalcDebit2,INDEX(PkPartyA,3),CalcAmt2)+SUMIF(CalcDebit3,INDEX(PkPartyA,3),CalcAmt3))) | F27: =IF($B27="","",IF(3>NPartyA,0,SUMIF(CalcCredit,INDEX(PkPartyA,3),CalcAmt)+SUMIF(CalcCredit2,INDEX(PkPartyA,3),CalcAmt2)+SUMIF(CalcCredit3,INDEX(PkPartyA,3),CalcAmt3))) | G27: =IF($B27="","",ROUND($E27-$F27,0)) | H27: =IF($B27="","",IF(ROUND($G27,0)>0,"بدهکار",IF(ROUND($G27,0)<0,"بستانکار","تسویه")))
A28: =IF($B28="","",19) | B28: =IF(4>NPartyA,"",IFERROR(IF(VLOOKUP(INDEX(PkPartyA,4),AcctTblA,4,0)="","(بدون نام)",VLOOKUP(INDEX(PkPartyA,4),AcctTblA,4,0)),"—")) | C28: =IF($B28="","",IF(4>NPartyA,"",INDEX(PkPartyA,4))) | D28: =IF($B28="","","p") | E28: =IF($B28="","",IF(4>NPartyA,0,SUMIF(CalcDebit,INDEX(PkPartyA,4),CalcAmt)+SUMIF(CalcDebit2,INDEX(PkPartyA,4),CalcAmt2)+SUMIF(CalcDebit3,INDEX(PkPartyA,4),CalcAmt3))) | F28: =IF($B28="","",IF(4>NPartyA,0,SUMIF(CalcCredit,INDEX(PkPartyA,4),CalcAmt)+SUMIF(CalcCredit2,INDEX(PkPartyA,4),CalcAmt2)+SUMIF(CalcCredit3,INDEX(PkPartyA,4),CalcAmt3))) | G28: =IF($B28="","",ROUND($E28-$F28,0)) | H28: =IF($B28="","",IF(ROUND($G28,0)>0,"بدهکار",IF(ROUND($G28,0)<0,"بستانکار","تسویه")))
A29: =IF($B29="","",20) | B29: =IF(5>NPartyA,"",IFERROR(IF(VLOOKUP(INDEX(PkPartyA,5),AcctTblA,4,0)="","(بدون نام)",VLOOKUP(INDEX(PkPartyA,5),AcctTblA,4,0)),"—")) | C29: =IF($B29="","",IF(5>NPartyA,"",INDEX(PkPartyA,5))) | D29: =IF($B29="","","p") | E29: =IF($B29="","",IF(5>NPartyA,0,SUMIF(CalcDebit,INDEX(PkPartyA,5),CalcAmt)+SUMIF(CalcDebit2,INDEX(PkPartyA,5),CalcAmt2)+SUMIF(CalcDebit3,INDEX(PkPartyA,5),CalcAmt3))) | F29: =IF($B29="","",IF(5>NPartyA,0,SUMIF(CalcCredit,INDEX(PkPartyA,5),CalcAmt)+SUMIF(CalcCredit2,INDEX(PkPartyA,5),CalcAmt2)+SUMIF(CalcCredit3,INDEX(PkPartyA,5),CalcAmt3))) | G29: =IF($B29="","",ROUND($E29-$F29,0)) | H29: =IF($B29="","",IF(ROUND($G29,0)>0,"بدهکار",IF(ROUND($G29,0)<0,"بستانکار","تسویه")))
A30: =IF($B30="","",21) | B30: =IF(6>NPartyA,"",IFERROR(IF(VLOOKUP(INDEX(PkPartyA,6),AcctTblA,4,0)="","(بدون نام)",VLOOKUP(INDEX(PkPartyA,6),AcctTblA,4,0)),"—")) | C30: =IF($B30="","",IF(6>NPartyA,"",INDEX(PkPartyA,6))) | D30: =IF($B30="","","p") | E30: =IF($B30="","",IF(6>NPartyA,0,SUMIF(CalcDebit,INDEX(PkPartyA,6),CalcAmt)+SUMIF(CalcDebit2,INDEX(PkPartyA,6),CalcAmt2)+SUMIF(CalcDebit3,INDEX(PkPartyA,6),CalcAmt3))) | F30: =IF($B30="","",IF(6>NPartyA,0,SUMIF(CalcCredit,INDEX(PkPartyA,6),CalcAmt)+SUMIF(CalcCredit2,INDEX(PkPartyA,6),CalcAmt2)+SUMIF(CalcCredit3,INDEX(PkPartyA,6),CalcAmt3))) | G30: =IF($B30="","",ROUND($E30-$F30,0)) | H30: =IF($B30="","",IF(ROUND($G30,0)>0,"بدهکار",IF(ROUND($G30,0)<0,"بستانکار","تسویه")))
A31: =IF($B31="","",22) | B31: =IF(7>NPartyA,"",IFERROR(IF(VLOOKUP(INDEX(PkPartyA,7),AcctTblA,4,0)="","(بدون نام)",VLOOKUP(INDEX(PkPartyA,7),AcctTblA,4,0)),"—")) | C31: =IF($B31="","",IF(7>NPartyA,"",INDEX(PkPartyA,7))) | D31: =IF($B31="","","p") | E31: =IF($B31="","",IF(7>NPartyA,0,SUMIF(CalcDebit,INDEX(PkPartyA,7),CalcAmt)+SUMIF(CalcDebit2,INDEX(PkPartyA,7),CalcAmt2)+SUMIF(CalcDebit3,INDEX(PkPartyA,7),CalcAmt3))) | F31: =IF($B31="","",IF(7>NPartyA,0,SUMIF(CalcCredit,INDEX(PkPartyA,7),CalcAmt)+SUMIF(CalcCredit2,INDEX(PkPartyA,7),CalcAmt2)+SUMIF(CalcCredit3,INDEX(PkPartyA,7),CalcAmt3))) | G31: =IF($B31="","",ROUND($E31-$F31,0)) | H31: =IF($B31="","",IF(ROUND($G31,0)>0,"بدهکار",IF(ROUND($G31,0)<0,"بستانکار","تسویه")))
A32: =IF($B32="","",23) | B32: =IF(8>NPartyA,"",IFERROR(IF(VLOOKUP(INDEX(PkPartyA,8),AcctTblA,4,0)="","(بدون نام)",VLOOKUP(INDEX(PkPartyA,8),AcctTblA,4,0)),"—")) | C32: =IF($B32="","",IF(8>NPartyA,"",INDEX(PkPartyA,8))) | D32: =IF($B32="","","p") | E32: =IF($B32="","",IF(8>NPartyA,0,SUMIF(CalcDebit,INDEX(PkPartyA,8),CalcAmt)+SUMIF(CalcDebit2,INDEX(PkPartyA,8),CalcAmt2)+SUMIF(CalcDebit3,INDEX(PkPartyA,8),CalcAmt3))) | F32: =IF($B32="","",IF(8>NPartyA,0,SUMIF(CalcCredit,INDEX(PkPartyA,8),CalcAmt)+SUMIF(CalcCredit2,INDEX(PkPartyA,8),CalcAmt2)+SUMIF(CalcCredit3,INDEX(PkPartyA,8),CalcAmt3))) | G32: =IF($B32="","",ROUND($E32-$F32,0)) | H32: =IF($B32="","",IF(ROUND($G32,0)>0,"بدهکار",IF(ROUND($G32,0)<0,"بستانکار","تسویه")))
A33: =IF($B33="","",24) | B33: =IF(9>NPartyA,"",IFERROR(IF(VLOOKUP(INDEX(PkPartyA,9),AcctTblA,4,0)="","(بدون نام)",VLOOKUP(INDEX(PkPartyA,9),AcctTblA,4,0)),"—")) | C33: =IF($B33="","",IF(9>NPartyA,"",INDEX(PkPartyA,9))) | D33: =IF($B33="","","p") | E33: =IF($B33="","",IF(9>NPartyA,0,SUMIF(CalcDebit,INDEX(PkPartyA,9),CalcAmt)+SUMIF(CalcDebit2,INDEX(PkPartyA,9),CalcAmt2)+SUMIF(CalcDebit3,INDEX(PkPartyA,9),CalcAmt3))) | F33: =IF($B33="","",IF(9>NPartyA,0,SUMIF(CalcCredit,INDEX(PkPartyA,9),CalcAmt)+SUMIF(CalcCredit2,INDEX(PkPartyA,9),CalcAmt2)+SUMIF(CalcCredit3,INDEX(PkPartyA,9),CalcAmt3))) | G33: =IF($B33="","",ROUND($E33-$F33,0)) | H33: =IF($B33="","",IF(ROUND($G33,0)>0,"بدهکار",IF(ROUND($G33,0)<0,"بستانکار","تسویه")))
A34: =IF($B34="","",25) | B34: =IF(10>NPartyA,"",IFERROR(IF(VLOOKUP(INDEX(PkPartyA,10),AcctTblA,4,0)="","(بدون نام)",VLOOKUP(INDEX(PkPartyA,10),AcctTblA,4,0)),"—")) | C34: =IF($B34="","",IF(10>NPartyA,"",INDEX(PkPartyA,10))) | D34: =IF($B34="","","p") | E34: =IF($B34="","",IF(10>NPartyA,0,SUMIF(CalcDebit,INDEX(PkPartyA,10),CalcAmt)+SUMIF(CalcDebit2,INDEX(PkPartyA,10),CalcAmt2)+SUMIF(CalcDebit3,INDEX(PkPartyA,10),CalcAmt3))) | F34: =IF($B34="","",IF(10>NPartyA,0,SUMIF(CalcCredit,INDEX(PkPartyA,10),CalcAmt)+SUMIF(CalcCredit2,INDEX(PkPartyA,10),CalcAmt2)+SUMIF(CalcCredit3,INDEX(PkPartyA,10),CalcAmt3))) | G34: =IF($B34="","",ROUND($E34-$F34,0)) | H34: =IF($B34="","",IF(ROUND($G34,0)>0,"بدهکار",IF(ROUND($G34,0)<0,"بستانکار","تسویه")))
A35: =IF($B35="","",26) | B35: =IF(11>NPartyA,"",IFERROR(IF(VLOOKUP(INDEX(PkPartyA,11),AcctTblA,4,0)="","(بدون نام)",VLOOKUP(INDEX(PkPartyA,11),AcctTblA,4,0)),"—")) | C35: =IF($B35="","",IF(11>NPartyA,"",INDEX(PkPartyA,11))) | D35: =IF($B35="","","p") | E35: =IF($B35="","",IF(11>NPartyA,0,SUMIF(CalcDebit,INDEX(PkPartyA,11),CalcAmt)+SUMIF(CalcDebit2,INDEX(PkPartyA,11),CalcAmt2)+SUMIF(CalcDebit3,INDEX(PkPartyA,11),CalcAmt3))) | F35: =IF($B35="","",IF(11>NPartyA,0,SUMIF(CalcCredit,INDEX(PkPartyA,11),CalcAmt)+SUMIF(CalcCredit2,INDEX(PkPartyA,11),CalcAmt2)+SUMIF(CalcCredit3,INDEX(PkPartyA,11),CalcAmt3))) | G35: =IF($B35="","",ROUND($E35-$F35,0)) | H35: =IF($B35="","",IF(ROUND($G35,0)>0,"بدهکار",IF(ROUND($G35,0)<0,"بستانکار","تسویه")))
A36: =IF($B36="","",27) | B36: =IF(12>NPartyA,"",IFERROR(IF(VLOOKUP(INDEX(PkPartyA,12),AcctTblA,4,0)="","(بدون نام)",VLOOKUP(INDEX(PkPartyA,12),AcctTblA,4,0)),"—")) | C36: =IF($B36="","",IF(12>NPartyA,"",INDEX(PkPartyA,12))) | D36: =IF($B36="","","p") | E36: =IF($B36="","",IF(12>NPartyA,0,SUMIF(CalcDebit,INDEX(PkPartyA,12),CalcAmt)+SUMIF(CalcDebit2,INDEX(PkPartyA,12),CalcAmt2)+SUMIF(CalcDebit3,INDEX(PkPartyA,12),CalcAmt3))) | F36: =IF($B36="","",IF(12>NPartyA,0,SUMIF(CalcCredit,INDEX(PkPartyA,12),CalcAmt)+SUMIF(CalcCredit2,INDEX(PkPartyA,12),CalcAmt2)+SUMIF(CalcCredit3,INDEX(PkPartyA,12),CalcAmt3))) | G36: =IF($B36="","",ROUND($E36-$F36,0)) | H36: =IF($B36="","",IF(ROUND($G36,0)>0,"بدهکار",IF(ROUND($G36,0)<0,"بستانکار","تسویه")))
A37: =IF($B37="","",28) | B37: =IF(13>NPartyA,"",IFERROR(IF(VLOOKUP(INDEX(PkPartyA,13),AcctTblA,4,0)="","(بدون نام)",VLOOKUP(INDEX(PkPartyA,13),AcctTblA,4,0)),"—")) | C37: =IF($B37="","",IF(13>NPartyA,"",INDEX(PkPartyA,13))) | D37: =IF($B37="","","p") | E37: =IF($B37="","",IF(13>NPartyA,0,SUMIF(CalcDebit,INDEX(PkPartyA,13),CalcAmt)+SUMIF(CalcDebit2,INDEX(PkPartyA,13),CalcAmt2)+SUMIF(CalcDebit3,INDEX(PkPartyA,13),CalcAmt3))) | F37: =IF($B37="","",IF(13>NPartyA,0,SUMIF(CalcCredit,INDEX(PkPartyA,13),CalcAmt)+SUMIF(CalcCredit2,INDEX(PkPartyA,13),CalcAmt2)+SUMIF(CalcCredit3,INDEX(PkPartyA,13),CalcAmt3))) | G37: =IF($B37="","",ROUND($E37-$F37,0)) | H37: =IF($B37="","",IF(ROUND($G37,0)>0,"بدهکار",IF(ROUND($G37,0)<0,"بستانکار","تسویه")))
A38: =IF($B38="","",29) | B38: =IF(14>NPartyA,"",IFERROR(IF(VLOOKUP(INDEX(PkPartyA,14),AcctTblA,4,0)="","(بدون نام)",VLOOKUP(INDEX(PkPartyA,14),AcctTblA,4,0)),"—")) | C38: =IF($B38="","",IF(14>NPartyA,"",INDEX(PkPartyA,14))) | D38: =IF($B38="","","p") | E38: =IF($B38="","",IF(14>NPartyA,0,SUMIF(CalcDebit,INDEX(PkPartyA,14),CalcAmt)+SUMIF(CalcDebit2,INDEX(PkPartyA,14),CalcAmt2)+SUMIF(CalcDebit3,INDEX(PkPartyA,14),CalcAmt3))) | F38: =IF($B38="","",IF(14>NPartyA,0,SUMIF(CalcCredit,INDEX(PkPartyA,14),CalcAmt)+SUMIF(CalcCredit2,INDEX(PkPartyA,14),CalcAmt2)+SUMIF(CalcCredit3,INDEX(PkPartyA,14),CalcAmt3))) | G38: =IF($B38="","",ROUND($E38-$F38,0)) | H38: =IF($B38="","",IF(ROUND($G38,0)>0,"بدهکار",IF(ROUND($G38,0)<0,"بستانکار","تسویه")))
A39: =IF($B39="","",30) | B39: =IF(15>NPartyA,"",IFERROR(IF(VLOOKUP(INDEX(PkPartyA,15),AcctTblA,4,0)="","(بدون نام)",VLOOKUP(INDEX(PkPartyA,15),AcctTblA,4,0)),"—")) | C39: =IF($B39="","",IF(15>NPartyA,"",INDEX(PkPartyA,15))) | D39: =IF($B39="","","p") | E39: =IF($B39="","",IF(15>NPartyA,0,SUMIF(CalcDebit,INDEX(PkPartyA,15),CalcAmt)+SUMIF(CalcDebit2,INDEX(PkPartyA,15),CalcAmt2)+SUMIF(CalcDebit3,INDEX(PkPartyA,15),CalcAmt3))) | F39: =IF($B39="","",IF(15>NPartyA,0,SUMIF(CalcCredit,INDEX(PkPartyA,15),CalcAmt)+SUMIF(CalcCredit2,INDEX(PkPartyA,15),CalcAmt2)+SUMIF(CalcCredit3,INDEX(PkPartyA,15),CalcAmt3))) | G39: =IF($B39="","",ROUND($E39-$F39,0)) | H39: =IF($B39="","",IF(ROUND($G39,0)>0,"بدهکار",IF(ROUND($G39,0)<0,"بستانکار","تسویه")))
A40: =IF($B40="","",31) | B40: =IF(16>NPartyA,"",IFERROR(IF(VLOOKUP(INDEX(PkPartyA,16),AcctTblA,4,0)="","(بدون نام)",VLOOKUP(INDEX(PkPartyA,16),AcctTblA,4,0)),"—")) | C40: =IF($B40="","",IF(16>NPartyA,"",INDEX(PkPartyA,16))) | D40: =IF($B40="","","p") | E40: =IF($B40="","",IF(16>NPartyA,0,SUMIF(CalcDebit,INDEX(PkPartyA,16),CalcAmt)+SUMIF(CalcDebit2,INDEX(PkPartyA,16),CalcAmt2)+SUMIF(CalcDebit3,INDEX(PkPartyA,16),CalcAmt3))) | F40: =IF($B40="","",IF(16>NPartyA,0,SUMIF(CalcCredit,INDEX(PkPartyA,16),CalcAmt)+SUMIF(CalcCredit2,INDEX(PkPartyA,16),CalcAmt2)+SUMIF(CalcCredit3,INDEX(PkPartyA,16),CalcAmt3))) | G40: =IF($B40="","",ROUND($E40-$F40,0)) | H40: =IF($B40="","",IF(ROUND($G40,0)>0,"بدهکار",IF(ROUND($G40,0)<0,"بستانکار","تسویه")))
A41: =IF($B41="","",32) | B41: =IF(17>NPartyA,"",IFERROR(IF(VLOOKUP(INDEX(PkPartyA,17),AcctTblA,4,0)="","(بدون نام)",VLOOKUP(INDEX(PkPartyA,17),AcctTblA,4,0)),"—")) | C41: =IF($B41="","",IF(17>NPartyA,"",INDEX(PkPartyA,17))) | D41: =IF($B41="","","p") | E41: =IF($B41="","",IF(17>NPartyA,0,SUMIF(CalcDebit,INDEX(PkPartyA,17),CalcAmt)+SUMIF(CalcDebit2,INDEX(PkPartyA,17),CalcAmt2)+SUMIF(CalcDebit3,INDEX(PkPartyA,17),CalcAmt3))) | F41: =IF($B41="","",IF(17>NPartyA,0,SUMIF(CalcCredit,INDEX(PkPartyA,17),CalcAmt)+SUMIF(CalcCredit2,INDEX(PkPartyA,17),CalcAmt2)+SUMIF(CalcCredit3,INDEX(PkPartyA,17),CalcAmt3))) | G41: =IF($B41="","",ROUND($E41-$F41,0)) | H41: =IF($B41="","",IF(ROUND($G41,0)>0,"بدهکار",IF(ROUND($G41,0)<0,"بستانکار","تسویه")))
...

Sheet Balance
A1: =IF(Sync!$P$6="","مازندشت",Sync!$P$6)&" — "&IF(Sync!$P$9="","سورتینگ و بسته‌بندی مرکبات",Sync!$P$9)
A2: =IF(Sync!$P$7="","باغدشت، بخش مرکزی، شهرستان قائم‌شهر، استان مازندران، ایران",Sync!$P$7)&" | MAZANDASHT · CITRUS SORTING & PACKING"
A3: ترازنامه گزارشی — از تراکنش‌ها و چک‌های پرداختی (خودکار)
A4: دارایی = نقد بانک‌ها + طلب اشخاص + سبد و ظروف + دارایی‌های ثابت (F…) · بدهی = دیون اشخاص + چک‌های پاس‌نشده + وام‌ها (L…) + متفرقه · حقوق صاحبان = افتتاحیه + سرمایه و آورده (CAP…) − هزینه‌های دوره − تراکنش‌های شخصی. ستون «درصد از جمع» سهم هر ردیف از جمع همان بخش است؛ ستون «دوره قبل» اختیاری و دستی است (برای ترازنامه تطبیقی، ارقام پایان دوره قبل را بنویسید) تا ستون «اختلاف» خودکار محاسبه شود. ارقام جاری از شیت Trial (تراز آزمایشی) جمع می‌شوند — پس از تغییر تراکنش‌ها: Data ← Edit Links ← Update Values.
A5: جمع دارایی‌ها (ریال) | C5: جمع بدهی‌ها (ریال) | E5: حقوق صاحبان (ریال) | G5: کنترل ترازنامه | I5: نسبت جاری (پوشش بدهی کوتاه‌مدت)
A6: =E15 | C6: =E21 | E6: =E27 | G6: =IF(ROUND(E15-(E21+E27),0)=0,"√ تراز است","▲ مغایرت") | I6: =IFERROR(ROUND((E11+E12)/(E17+E18+E20),2),"—")
A8: واریزهای فروش (ریال) | C8: برداشت‌های خرید (ریال) | E8: هزینه‌های دوره (ریال) | G8: چک‌های پاس‌نشده (ریال) | I8: سود نقدی دوره (تقریبی)
A9: =SUMIF(CalcGroup,"فروش",CalcDep) | C9: =SUMIF(CalcGroup,"خرید",CalcWit) | E9: =SUMIF(CalcGroup,"هزینه",CalcWit)-SUMIF(CalcGroup,"هزینه",CalcDep) | G9: =-SUMIFS(TrialBal,TrialType,"q") | I9: =SUMIF(CalcGroup,"فروش",CalcDep)-SUMIF(CalcGroup,"خرید",CalcWit)-(SUMIF(CalcGroup,"هزینه",CalcWit)-SUMIF(CalcGroup,"هزینه",CalcDep))
A10: بخش | B10: شرح | D10: کد طبقه | E10: مبلغ (ریال) | F10: ٪ از جمع | G10: دوره قبل (دستی) | H10: اختلاف با دوره قبل
A11: دارایی | B11: موجودی نقدی بانک‌ها | D11: b | E11: =SUMIFS(TrialBal,TrialType,"b") | F11: =IFERROR(E11/E$15,"") | H11: =IF($G11="","",E11-$G11)
A12: دارایی | B12: طلب از اشخاص (مانده بدهکار / پیش‌پرداخت) | D12: p+ | E12: =SUMIFS(TrialBal,TrialType,"p",TrialBal,">0") | F12: =IFERROR(E12/E$15,"") | H12: =IF($G12="","",E12-$G12)
A13: دارایی | B13: سبد و ظروف (دفتر Baskets) | D13: s | E13: =SUMIFS(TrialBal,TrialType,"s") | F13: =IFERROR(E13/E$15,"") | H13: =IF($G13="","",E13-$G13)
A14: دارایی | B14: دارایی‌های ثابت — زمین، خودرو، تجهیزات (F…) | D14: f | E14: =SUMIFS(TrialBal,TrialType,"f") | F14: =IFERROR(E14/E$15,"") | H14: =IF($G14="","",E14-$G14)
A15: جمع دارایی‌ها | E15: =SUM(E11:E14) | F15: =IFERROR(E15/E$15,"") | G15: =SUM(G11:G14) | H15: =IF(COUNT(G11:G14)=0,"",E15-G15)
A17: بدهی | B17: دیون اشخاص (مانده بستانکار) | D17: p- | E17: =-SUMIFS(TrialBal,TrialType,"p",TrialBal,"<0") | F17: =IFERROR(E17/E$21,"") | H17: =IF($G17="","",E17-$G17)
A18: بدهی | B18: اسناد چک پرداختی — پاس‌نشده | D18: q | E18: =-SUMIFS(TrialBal,TrialType,"q") | F18: =IFERROR(E18/E$21,"") | H18: =IF($G18="","",E18-$G18)
A19: بدهی | B19: وام‌ها و تسهیلات (L…) | D19: l | E19: =-SUMIFS(TrialBal,TrialType,"l") | F19: =IFERROR(E19/E$21,"") | H19: =IF($G19="","",E19-$G19)
A20: بدهی | B20: متفرقه / در انتظار تعریف (شیت Control) | D20: m | E20: =-SUMIFS(TrialBal,TrialType,"m") | F20: =IFERROR(E20/E$21,"") | H20: =IF($G20="","",E20-$G20)
A21: جمع بدهی‌ها | E21: =SUM(E17:E20) | F21: =IFERROR(E21/E$21,"") | G21: =SUM(G17:G20) | H21: =IF(COUNT(G17:G20)=0,"",E21-G21)
A23: حقوق صاحبان | B23: افتتاحیه (مانده اولیه بانک‌ها) | D23: o | E23: =SUMIFS(TrialBal,TrialType,"o")*-1 | F23: =IFERROR(E23/E$27,"") | H23: =IF($G23="","",E23-$G23)
A24: حقوق صاحبان | B24: سرمایه و آورده صاحبان (CAP…) | D24: c | E24: =SUMIFS(TrialBal,TrialType,"c")*-1 | F24: =IFERROR(E24/E$27,"") | H24: =IF($G24="","",E24-$G24)
A25: حقوق صاحبان | B25: هزینه‌های دوره (کسر — مبنای نقدی) | D25: e | E25: =SUMIFS(TrialBal,TrialType,"e")*-1 | F25: =IFERROR(E25/E$27,"") | H25: =IF($G25="","",E25-$G25)
A26: حقوق صاحبان | B26: تراکنش‌های شخصی قاسم (خارج از شرکت، کسر) | D26: x | E26: =SUMIFS(TrialBal,TrialType,"x")*-1 | F26: =IFERROR(E26/E$27,"") | H26: =IF($G26="","",E26-$G26)
A27: جمع حقوق صاحبان (مبنای نقدی) | E27: =SUM(E23:E26) | F27: =IFERROR(E27/E$27,"") | G27: =SUM(G23:G26) | H27: =IF(COUNT(G23:G26)=0,"",E27-G27)
A29: ⚠️ مبنای این ترازنامه نقدی است: درآمد فروش تا تطبیق با فاکتورها در «دیون اشخاص» (پیش‌دریافت) می‌نشیند و هنوز سود شناسایی‌شده نیست؛ سود واقعی دوره = درآمد فاکتورشده (فایل Sales) − بهای تمام‌شده (Purchases) − هزینه‌ها (Expenses). «متفرقه» حساب معلق است و تا تعریف شدن (شیت Control) در بدهی‌ها می‌ماند.

Sheet BalanceClassic
A1: =IF(Sync!$P$6="","مازندشت",Sync!$P$6)&" — "&IF(Sync!$P$9="","سورتینگ و بسته‌بندی مرکبات",Sync!$P$9)
A2: =IF(Sync!$P$7="","باغدشت، بخش مرکزی، شهرستان قائم‌شهر، استان مازندران، ایران",Sync!$P$7)&" | MAZANDASHT · CITRUS SORTING & PACKING"
A3: ترازنامه کلاسیک دوستونه — سبک سنتی (خودکار)
A4: چیدمان سنتی: دارایی‌ها یک سمت، بدهی‌ها و حقوق صاحبان سمت دیگر — ارقام هر دو سمت از شیت Trial جمع می‌شوند و باید برابر باشند (معادله حسابداری). «متفرقه» تا تعریف شدن در شیت Control، در بدهی‌های کوتاه‌مدت می‌ماند.
A10: دارایی‌ها | D10: مبلغ (ریال) | E10: بدهی‌ها و حقوق صاحبان | H10: مبلغ (ریال)
A11: موجودی نقدی بانک‌ها | D11: =SUMIFS(TrialBal,TrialType,"b") | E11: دیون اشخاص (بستانکار) | H11: =-SUMIFS(TrialBal,TrialType,"p",TrialBal,"<0")
A12: طلب از اشخاص (بدهکار) | D12: =SUMIFS(TrialBal,TrialType,"p",TrialBal,">0") | E12: اسناد چک پرداختی — پاس‌نشده | H12: =-SUMIFS(TrialBal,TrialType,"q")
A13: دارایی‌های ثابت (F…) | D13: =SUMIFS(TrialBal,TrialType,"f") | E13: وام‌ها و تسهیلات (L…) | H13: =-SUMIFS(TrialBal,TrialType,"l")
A14: سبد و ظروف (دفتر Baskets) | D14: =SUMIFS(TrialBal,TrialType,"s") | E14: متفرقه — در انتظار تعریف | H14: =-SUMIFS(TrialBal,TrialType,"m")
E15: جمع بدهی‌ها | H15: =SUM(H11:H14)
E17: سرمایه و آورده صاحبان (CAP…) | H17: =-SUMIFS(TrialBal,TrialType,"c")
E18: افتتاحیه (آورده اولیه) | H18: =-SUMIFS(TrialBal,TrialType,"o")
E19: تغییرات نقدی دوره (− هزینه‌ها − شخصی) | H19: =-SUMIFS(TrialBal,TrialType,"e")-SUMIFS(TrialBal,TrialType,"x")
A20: جمع دارایی‌ها | D20: =SUM(D11:D14) | E20: جمع حقوق صاحبان | H20: =SUM(H17:H19)
A21: جمع کل دارایی‌ها | D21: =D20 | E21: جمع کل بدهی‌ها + حقوق صاحبان | H21: =H15+H20
A23: =IF(ROUND(D21-H21,0)=0,"√ تراز است — دارایی‌ها = بدهی‌ها + حقوق صاحبان","▲ مغایرت: دارایی‌ها ≠ بدهی‌ها + حقوق صاحبان")
A25: مبنای نقدی: واریزهای فروش تا تطبیق با فاکتور در «دیون اشخاص» است و سود واقعی دوره از فاکتورهای فروش/خرید محاسبه می‌شود (فایل‌های Sales و Purchases و Expenses).

Sheet Control
A1: =IF(Sync!$P$6="","مازندشت",Sync!$P$6)&" — "&IF(Sync!$P$9="","سورتینگ و بسته‌بندی مرکبات",Sync!$P$9)
A2: =IF(Sync!$P$7="","باغدشت، بخش مرکزی، شهرستان قائم‌شهر، استان مازندران، ایران",Sync!$P$7)&" | MAZANDASHT · CITRUS SORTING & PACKING"
A3: کنترل و اعتبارسنجی — موارد تعریف‌نشده یا نیازمند تعریف
A4: این شیت خودکار است: هر تراکنش یا چکی که به حساب/زیرگروه/شماره‌ی تعریف‌نشده اشاره کند اینجا فهرست می‌شود تا در INFO (یا Transactions / Cheques) تعریف و اصلاحش کنید. موارد ناشناس تا تعریف نشوند، در «متفرقه» تراز می‌مانند. پس از اصلاح: Data ← Edit Links ← Update Values.
A5: موارد نیازمند اقدام | C5: جمع مبلغ تراکنش‌های مشکل‌دار (ریال) | E5: هزینه بدون زیرگروه (ریال) | G5: مانده متفرقه — در انتظار تعریف (ریال)
A6: =COUNTIF(CalcRank1,">0")+COUNTIF(CalcRank2,">0") | C6: =SUMIF(CalcRank1,">0",CalcAmt) | E6: =SUMIF(CalcProb1,"هزینه بدون زیرگروه",CalcAmt) | G6: =-SUMIFS(TrialBal,TrialType,"m")
A7: =IF(COUNTIF(CalcRank1,">0")+COUNTIF(CalcRank2,">0")=0,"✓ همه‌چیز تعریف‌شده — موردی برای اقدام نیست","▲ "&COUNTIF(CalcRank1,">0")+COUNTIF(CalcRank2,">0")&" مورد نیازمند تعریف — فهرست زیر را اصلاح کنید")
A9: الف) تراکنش‌های نیازمند تعریف — از Transactions ← Entry
A10: ردیف | B10: نوع مشکل | C10: تاریخ | D10: بانک | E10: طرف | F10: نوع تراکنش | G10: مبلغ (ریال)
A11: No. | B11: Issue | C11: Date | D11: Bank | E11: Party | F11: Txn Type | G11: Amount
A12: =IF(IFERROR(MATCH(1,CalcRank1,0),0)=0,"",1) | B12: =IF(IFERROR(MATCH(1,CalcRank1,0),0)=0,"",INDEX(CalcProb1,IFERROR(MATCH(1,CalcRank1,0),0))) | C12: =IF(IFERROR(MATCH(1,CalcRank1,0),0)=0,"",INDEX(Sync!$AK$6:$AK$2005,IFERROR(MATCH(1,CalcRank1,0),0))) | D12: =IF(IFERROR(MATCH(1,CalcRank1,0),0)=0,"",INDEX(Calc!$A$6:$A$2005,IFERROR(MATCH(1,CalcRank1,0),0))) | E12: =IF(IFERROR(MATCH(1,CalcRank1,0),0)=0,"",INDEX(Calc!$B$6:$B$2005,IFERROR(MATCH(1,CalcRank1,0),0))) | F12: =IF(IFERROR(MATCH(1,CalcRank1,0),0)=0,"",INDEX(Calc!$C$6:$C$2005,IFERROR(MATCH(1,CalcRank1,0),0))) | G12: =IF(IFERROR(MATCH(1,CalcRank1,0),0)=0,"",INDEX(Calc!$H$6:$H$2005,IFERROR(MATCH(1,CalcRank1,0),0)))
A13: =IF(IFERROR(MATCH(2,CalcRank1,0),0)=0,"",2) | B13: =IF(IFERROR(MATCH(2,CalcRank1,0),0)=0,"",INDEX(CalcProb1,IFERROR(MATCH(2,CalcRank1,0),0))) | C13: =IF(IFERROR(MATCH(2,CalcRank1,0),0)=0,"",INDEX(Sync!$AK$6:$AK$2005,IFERROR(MATCH(2,CalcRank1,0),0))) | D13: =IF(IFERROR(MATCH(2,CalcRank1,0),0)=0,"",INDEX(Calc!$A$6:$A$2005,IFERROR(MATCH(2,CalcRank1,0),0))) | E13: =IF(IFERROR(MATCH(2,CalcRank1,0),0)=0,"",INDEX(Calc!$B$6:$B$2005,IFERROR(MATCH(2,CalcRank1,0),0))) | F13: =IF(IFERROR(MATCH(2,CalcRank1,0),0)=0,"",INDEX(Calc!$C$6:$C$2005,IFERROR(MATCH(2,CalcRank1,0),0))) | G13: =IF(IFERROR(MATCH(2,CalcRank1,0),0)=0,"",INDEX(Calc!$H$6:$H$2005,IFERROR(MATCH(2,CalcRank1,0),0)))
A14: =IF(IFERROR(MATCH(3,CalcRank1,0),0)=0,"",3) | B14: =IF(IFERROR(MATCH(3,CalcRank1,0),0)=0,"",INDEX(CalcProb1,IFERROR(MATCH(3,CalcRank1,0),0))) | C14: =IF(IFERROR(MATCH(3,CalcRank1,0),0)=0,"",INDEX(Sync!$AK$6:$AK$2005,IFERROR(MATCH(3,CalcRank1,0),0))) | D14: =IF(IFERROR(MATCH(3,CalcRank1,0),0)=0,"",INDEX(Calc!$A$6:$A$2005,IFERROR(MATCH(3,CalcRank1,0),0))) | E14: =IF(IFERROR(MATCH(3,CalcRank1,0),0)=0,"",INDEX(Calc!$B$6:$B$2005,IFERROR(MATCH(3,CalcRank1,0),0))) | F14: =IF(IFERROR(MATCH(3,CalcRank1,0),0)=0,"",INDEX(Calc!$C$6:$C$2005,IFERROR(MATCH(3,CalcRank1,0),0))) | G14: =IF(IFERROR(MATCH(3,CalcRank1,0),0)=0,"",INDEX(Calc!$H$6:$H$2005,IFERROR(MATCH(3,CalcRank1,0),0)))
A15: =IF(IFERROR(MATCH(4,CalcRank1,0),0)=0,"",4) | B15: =IF(IFERROR(MATCH(4,CalcRank1,0),0)=0,"",INDEX(CalcProb1,IFERROR(MATCH(4,CalcRank1,0),0))) | C15: =IF(IFERROR(MATCH(4,CalcRank1,0),0)=0,"",INDEX(Sync!$AK$6:$AK$2005,IFERROR(MATCH(4,CalcRank1,0),0))) | D15: =IF(IFERROR(MATCH(4,CalcRank1,0),0)=0,"",INDEX(Calc!$A$6:$A$2005,IFERROR(MATCH(4,CalcRank1,0),0))) | E15: =IF(IFERROR(MATCH(4,CalcRank1,0),0)=0,"",INDEX(Calc!$B$6:$B$2005,IFERROR(MATCH(4,CalcRank1,0),0))) | F15: =IF(IFERROR(MATCH(4,CalcRank1,0),0)=0,"",INDEX(Calc!$C$6:$C$2005,IFERROR(MATCH(4,CalcRank1,0),0))) | G15: =IF(IFERROR(MATCH(4,CalcRank1,0),0)=0,"",INDEX(Calc!$H$6:$H$2005,IFERROR(MATCH(4,CalcRank1,0),0)))
A16: =IF(IFERROR(MATCH(5,CalcRank1,0),0)=0,"",5) | B16: =IF(IFERROR(MATCH(5,CalcRank1,0),0)=0,"",INDEX(CalcProb1,IFERROR(MATCH(5,CalcRank1,0),0))) | C16: =IF(IFERROR(MATCH(5,CalcRank1,0),0)=0,"",INDEX(Sync!$AK$6:$AK$2005,IFERROR(MATCH(5,CalcRank1,0),0))) | D16: =IF(IFERROR(MATCH(5,CalcRank1,0),0)=0,"",INDEX(Calc!$A$6:$A$2005,IFERROR(MATCH(5,CalcRank1,0),0))) | E16: =IF(IFERROR(MATCH(5,CalcRank1,0),0)=0,"",INDEX(Calc!$B$6:$B$2005,IFERROR(MATCH(5,CalcRank1,0),0))) | F16: =IF(IFERROR(MATCH(5,CalcRank1,0),0)=0,"",INDEX(Calc!$C$6:$C$2005,IFERROR(MATCH(5,CalcRank1,0),0))) | G16: =IF(IFERROR(MATCH(5,CalcRank1,0),0)=0,"",INDEX(Calc!$H$6:$H$2005,IFERROR(MATCH(5,CalcRank1,0),0)))
A17: =IF(IFERROR(MATCH(6,CalcRank1,0),0)=0,"",6) | B17: =IF(IFERROR(MATCH(6,CalcRank1,0),0)=0,"",INDEX(CalcProb1,IFERROR(MATCH(6,CalcRank1,0),0))) | C17: =IF(IFERROR(MATCH(6,CalcRank1,0),0)=0,"",INDEX(Sync!$AK$6:$AK$2005,IFERROR(MATCH(6,CalcRank1,0),0))) | D17: =IF(IFERROR(MATCH(6,CalcRank1,0),0)=0,"",INDEX(Calc!$A$6:$A$2005,IFERROR(MATCH(6,CalcRank1,0),0))) | E17: =IF(IFERROR(MATCH(6,CalcRank1,0),0)=0,"",INDEX(Calc!$B$6:$B$2005,IFERROR(MATCH(6,CalcRank1,0),0))) | F17: =IF(IFERROR(MATCH(6,CalcRank1,0),0)=0,"",INDEX(Calc!$C$6:$C$2005,IFERROR(MATCH(6,CalcRank1,0),0))) | G17: =IF(IFERROR(MATCH(6,CalcRank1,0),0)=0,"",INDEX(Calc!$H$6:$H$2005,IFERROR(MATCH(6,CalcRank1,0),0)))
A18: =IF(IFERROR(MATCH(7,CalcRank1,0),0)=0,"",7) | B18: =IF(IFERROR(MATCH(7,CalcRank1,0),0)=0,"",INDEX(CalcProb1,IFERROR(MATCH(7,CalcRank1,0),0))) | C18: =IF(IFERROR(MATCH(7,CalcRank1,0),0)=0,"",INDEX(Sync!$AK$6:$AK$2005,IFERROR(MATCH(7,CalcRank1,0),0))) | D18: =IF(IFERROR(MATCH(7,CalcRank1,0),0)=0,"",INDEX(Calc!$A$6:$A$2005,IFERROR(MATCH(7,CalcRank1,0),0))) | E18: =IF(IFERROR(MATCH(7,CalcRank1,0),0)=0,"",INDEX(Calc!$B$6:$B$2005,IFERROR(MATCH(7,CalcRank1,0),0))) | F18: =IF(IFERROR(MATCH(7,CalcRank1,0),0)=0,"",INDEX(Calc!$C$6:$C$2005,IFERROR(MATCH(7,CalcRank1,0),0))) | G18: =IF(IFERROR(MATCH(7,CalcRank1,0),0)=0,"",INDEX(Calc!$H$6:$H$2005,IFERROR(MATCH(7,CalcRank1,0),0)))
A19: =IF(IFERROR(MATCH(8,CalcRank1,0),0)=0,"",8) | B19: =IF(IFERROR(MATCH(8,CalcRank1,0),0)=0,"",INDEX(CalcProb1,IFERROR(MATCH(8,CalcRank1,0),0))) | C19: =IF(IFERROR(MATCH(8,CalcRank1,0),0)=0,"",INDEX(Sync!$AK$6:$AK$2005,IFERROR(MATCH(8,CalcRank1,0),0))) | D19: =IF(IFERROR(MATCH(8,CalcRank1,0),0)=0,"",INDEX(Calc!$A$6:$A$2005,IFERROR(MATCH(8,CalcRank1,0),0))) | E19: =IF(IFERROR(MATCH(8,CalcRank1,0),0)=0,"",INDEX(Calc!$B$6:$B$2005,IFERROR(MATCH(8,CalcRank1,0),0))) | F19: =IF(IFERROR(MATCH(8,CalcRank1,0),0)=0,"",INDEX(Calc!$C$6:$C$2005,IFERROR(MATCH(8,CalcRank1,0),0))) | G19: =IF(IFERROR(MATCH(8,CalcRank1,0),0)=0,"",INDEX(Calc!$H$6:$H$2005,IFERROR(MATCH(8,CalcRank1,0),0)))
A20: =IF(IFERROR(MATCH(9,CalcRank1,0),0)=0,"",9) | B20: =IF(IFERROR(MATCH(9,CalcRank1,0),0)=0,"",INDEX(CalcProb1,IFERROR(MATCH(9,CalcRank1,0),0))) | C20: =IF(IFERROR(MATCH(9,CalcRank1,0),0)=0,"",INDEX(Sync!$AK$6:$AK$2005,IFERROR(MATCH(9,CalcRank1,0),0))) | D20: =IF(IFERROR(MATCH(9,CalcRank1,0),0)=0,"",INDEX(Calc!$A$6:$A$2005,IFERROR(MATCH(9,CalcRank1,0),0))) | E20: =IF(IFERROR(MATCH(9,CalcRank1,0),0)=0,"",INDEX(Calc!$B$6:$B$2005,IFERROR(MATCH(9,CalcRank1,0),0))) | F20: =IF(IFERROR(MATCH(9,CalcRank1,0),0)=0,"",INDEX(Calc!$C$6:$C$2005,IFERROR(MATCH(9,CalcRank1,0),0))) | G20: =IF(IFERROR(MATCH(9,CalcRank1,0),0)=0,"",INDEX(Calc!$H$6:$H$2005,IFERROR(MATCH(9,CalcRank1,0),0)))
A21: =IF(IFERROR(MATCH(10,CalcRank1,0),0)=0,"",10) | B21: =IF(IFERROR(MATCH(10,CalcRank1,0),0)=0,"",INDEX(CalcProb1,IFERROR(MATCH(10,CalcRank1,0),0))) | C21: =IF(IFERROR(MATCH(10,CalcRank1,0),0)=0,"",INDEX(Sync!$AK$6:$AK$2005,IFERROR(MATCH(10,CalcRank1,0),0))) | D21: =IF(IFERROR(MATCH(10,CalcRank1,0),0)=0,"",INDEX(Calc!$A$6:$A$2005,IFERROR(MATCH(10,CalcRank1,0),0))) | E21: =IF(IFERROR(MATCH(10,CalcRank1,0),0)=0,"",INDEX(Calc!$B$6:$B$2005,IFERROR(MATCH(10,CalcRank1,0),0))) | F21: =IF(IFERROR(MATCH(10,CalcRank1,0),0)=0,"",INDEX(Calc!$C$6:$C$2005,IFERROR(MATCH(10,CalcRank1,0),0))) | G21: =IF(IFERROR(MATCH(10,CalcRank1,0),0)=0,"",INDEX(Calc!$H$6:$H$2005,IFERROR(MATCH(10,CalcRank1,0),0)))
A22: =IF(IFERROR(MATCH(11,CalcRank1,0),0)=0,"",11) | B22: =IF(IFERROR(MATCH(11,CalcRank1,0),0)=0,"",INDEX(CalcProb1,IFERROR(MATCH(11,CalcRank1,0),0))) | C22: =IF(IFERROR(MATCH(11,CalcRank1,0),0)=0,"",INDEX(Sync!$AK$6:$AK$2005,IFERROR(MATCH(11,CalcRank1,0),0))) | D22: =IF(IFERROR(MATCH(11,CalcRank1,0),0)=0,"",INDEX(Calc!$A$6:$A$2005,IFERROR(MATCH(11,CalcRank1,0),0))) | E22: =IF(IFERROR(MATCH(11,CalcRank1,0),0)=0,"",INDEX(Calc!$B$6:$B$2005,IFERROR(MATCH(11,CalcRank1,0),0))) | F22: =IF(IFERROR(MATCH(11,CalcRank1,0),0)=0,"",INDEX(Calc!$C$6:$C$2005,IFERROR(MATCH(11,CalcRank1,0),0))) | G22: =IF(IFERROR(MATCH(11,CalcRank1,0),0)=0,"",INDEX(Calc!$H$6:$H$2005,IFERROR(MATCH(11,CalcRank1,0),0)))
A23: =IF(IFERROR(MATCH(12,CalcRank1,0),0)=0,"",12) | B23: =IF(IFERROR(MATCH(12,CalcRank1,0),0)=0,"",INDEX(CalcProb1,IFERROR(MATCH(12,CalcRank1,0),0))) | C23: =IF(IFERROR(MATCH(12,CalcRank1,0),0)=0,"",INDEX(Sync!$AK$6:$AK$2005,IFERROR(MATCH(12,CalcRank1,0),0))) | D23: =IF(IFERROR(MATCH(12,CalcRank1,0),0)=0,"",INDEX(Calc!$A$6:$A$2005,IFERROR(MATCH(12,CalcRank1,0),0))) | E23: =IF(IFERROR(MATCH(12,CalcRank1,0),0)=0,"",INDEX(Calc!$B$6:$B$2005,IFERROR(MATCH(12,CalcRank1,0),0))) | F23: =IF(IFERROR(MATCH(12,CalcRank1,0),0)=0,"",INDEX(Calc!$C$6:$C$2005,IFERROR(MATCH(12,CalcRank1,0),0))) | G23: =IF(IFERROR(MATCH(12,CalcRank1,0),0)=0,"",INDEX(Calc!$H$6:$H$2005,IFERROR(MATCH(12,CalcRank1,0),0)))
A24: =IF(IFERROR(MATCH(13,CalcRank1,0),0)=0,"",13) | B24: =IF(IFERROR(MATCH(13,CalcRank1,0),0)=0,"",INDEX(CalcProb1,IFERROR(MATCH(13,CalcRank1,0),0))) | C24: =IF(IFERROR(MATCH(13,CalcRank1,0),0)=0,"",INDEX(Sync!$AK$6:$AK$2005,IFERROR(MATCH(13,CalcRank1,0),0))) | D24: =IF(IFERROR(MATCH(13,CalcRank1,0),0)=0,"",INDEX(Calc!$A$6:$A$2005,IFERROR(MATCH(13,CalcRank1,0),0))) | E24: =IF(IFERROR(MATCH(13,CalcRank1,0),0)=0,"",INDEX(Calc!$B$6:$B$2005,IFERROR(MATCH(13,CalcRank1,0),0))) | F24: =IF(IFERROR(MATCH(13,CalcRank1,0),0)=0,"",INDEX(Calc!$C$6:$C$2005,IFERROR(MATCH(13,CalcRank1,0),0))) | G24: =IF(IFERROR(MATCH(13,CalcRank1,0),0)=0,"",INDEX(Calc!$H$6:$H$2005,IFERROR(MATCH(13,CalcRank1,0),0)))
A25: =IF(IFERROR(MATCH(14,CalcRank1,0),0)=0,"",14) | B25: =IF(IFERROR(MATCH(14,CalcRank1,0),0)=0,"",INDEX(CalcProb1,IFERROR(MATCH(14,CalcRank1,0),0))) | C25: =IF(IFERROR(MATCH(14,CalcRank1,0),0)=0,"",INDEX(Sync!$AK$6:$AK$2005,IFERROR(MATCH(14,CalcRank1,0),0))) | D25: =IF(IFERROR(MATCH(14,CalcRank1,0),0)=0,"",INDEX(Calc!$A$6:$A$2005,IFERROR(MATCH(14,CalcRank1,0),0))) | E25: =IF(IFERROR(MATCH(14,CalcRank1,0),0)=0,"",INDEX(Calc!$B$6:$B$2005,IFERROR(MATCH(14,CalcRank1,0),0))) | F25: =IF(IFERROR(MATCH(14,CalcRank1,0),0)=0,"",INDEX(Calc!$C$6:$C$2005,IFERROR(MATCH(14,CalcRank1,0),0))) | G25: =IF(IFERROR(MATCH(14,CalcRank1,0),0)=0,"",INDEX(Calc!$H$6:$H$2005,IFERROR(MATCH(14,CalcRank1,0),0)))
A26: =IF(IFERROR(MATCH(15,CalcRank1,0),0)=0,"",15) | B26: =IF(IFERROR(MATCH(15,CalcRank1,0),0)=0,"",INDEX(CalcProb1,IFERROR(MATCH(15,CalcRank1,0),0))) | C26: =IF(IFERROR(MATCH(15,CalcRank1,0),0)=0,"",INDEX(Sync!$AK$6:$AK$2005,IFERROR(MATCH(15,CalcRank1,0),0))) | D26: =IF(IFERROR(MATCH(15,CalcRank1,0),0)=0,"",INDEX(Calc!$A$6:$A$2005,IFERROR(MATCH(15,CalcRank1,0),0))) | E26: =IF(IFERROR(MATCH(15,CalcRank1,0),0)=0,"",INDEX(Calc!$B$6:$B$2005,IFERROR(MATCH(15,CalcRank1,0),0))) | F26: =IF(IFERROR(MATCH(15,CalcRank1,0),0)=0,"",INDEX(Calc!$C$6:$C$2005,IFERROR(MATCH(15,CalcRank1,0),0))) | G26: =IF(IFERROR(MATCH(15,CalcRank1,0),0)=0,"",INDEX(Calc!$H$6:$H$2005,IFERROR(MATCH(15,CalcRank1,0),0)))
A28: ب) چک‌های صادره با ذی‌نفع تعریف‌نشده — از Cheques ← Issues
A29: ردیف | B29: شماره چک | C29: تاریخ چک | D29: مبلغ (ریال) | E29: ذی‌نفع | F29: نوع مشکل
A30: No. | B30: Cheque No. | C30: Date | D30: Amount | E30: Beneficiary | F30: Issue
A31: =IF(IFERROR(MATCH(1,CalcRank2,0),0)=0,"",1) | B31: =IF(IFERROR(MATCH(1,CalcRank2,0),0)=0,"",INDEX(Sync!$AG$6:$AG$505,IFERROR(MATCH(1,CalcRank2,0),0))) | C31: =IF(IFERROR(MATCH(1,CalcRank2,0),0)=0,"",INDEX(Sync!$AW$6:$AW$505,IFERROR(MATCH(1,CalcRank2,0),0))) | D31: =IF(IFERROR(MATCH(1,CalcRank2,0),0)=0,"",INDEX(Sync!$AH$6:$AH$505,IFERROR(MATCH(1,CalcRank2,0),0))) | E31: =IF(IFERROR(MATCH(1,CalcRank2,0),0)=0,"",INDEX(Sync!$AI$6:$AI$505,IFERROR(MATCH(1,CalcRank2,0),0))) | F31: =IF(IFERROR(MATCH(1,CalcRank2,0),0)=0,"",INDEX(CalcProb2,IFERROR(MATCH(1,CalcRank2,0),0)))
A32: =IF(IFERROR(MATCH(2,CalcRank2,0),0)=0,"",2) | B32: =IF(IFERROR(MATCH(2,CalcRank2,0),0)=0,"",INDEX(Sync!$AG$6:$AG$505,IFERROR(MATCH(2,CalcRank2,0),0))) | C32: =IF(IFERROR(MATCH(2,CalcRank2,0),0)=0,"",INDEX(Sync!$AW$6:$AW$505,IFERROR(MATCH(2,CalcRank2,0),0))) | D32: =IF(IFERROR(MATCH(2,CalcRank2,0),0)=0,"",INDEX(Sync!$AH$6:$AH$505,IFERROR(MATCH(2,CalcRank2,0),0))) | E32: =IF(IFERROR(MATCH(2,CalcRank2,0),0)=0,"",INDEX(Sync!$AI$6:$AI$505,IFERROR(MATCH(2,CalcRank2,0),0))) | F32: =IF(IFERROR(MATCH(2,CalcRank2,0),0)=0,"",INDEX(CalcProb2,IFERROR(MATCH(2,CalcRank2,0),0)))
A33: =IF(IFERROR(MATCH(3,CalcRank2,0),0)=0,"",3) | B33: =IF(IFERROR(MATCH(3,CalcRank2,0),0)=0,"",INDEX(Sync!$AG$6:$AG$505,IFERROR(MATCH(3,CalcRank2,0),0))) | C33: =IF(IFERROR(MATCH(3,CalcRank2,0),0)=0,"",INDEX(Sync!$AW$6:$AW$505,IFERROR(MATCH(3,CalcRank2,0),0))) | D33: =IF(IFERROR(MATCH(3,CalcRank2,0),0)=0,"",INDEX(Sync!$AH$6:$AH$505,IFERROR(MATCH(3,CalcRank2,0),0))) | E33: =IF(IFERROR(MATCH(3,CalcRank2,0),0)=0,"",INDEX(Sync!$AI$6:$AI$505,IFERROR(MATCH(3,CalcRank2,0),0))) | F33: =IF(IFERROR(MATCH(3,CalcRank2,0),0)=0,"",INDEX(CalcProb2,IFERROR(MATCH(3,CalcRank2,0),0)))
A34: =IF(IFERROR(MATCH(4,CalcRank2,0),0)=0,"",4) | B34: =IF(IFERROR(MATCH(4,CalcRank2,0),0)=0,"",INDEX(Sync!$AG$6:$AG$505,IFERROR(MATCH(4,CalcRank2,0),0))) | C34: =IF(IFERROR(MATCH(4,CalcRank2,0),0)=0,"",INDEX(Sync!$AW$6:$AW$505,IFERROR(MATCH(4,CalcRank2,0),0))) | D34: =IF(IFERROR(MATCH(4,CalcRank2,0),0)=0,"",INDEX(Sync!$AH$6:$AH$505,IFERROR(MATCH(4,CalcRank2,0),0))) | E34: =IF(IFERROR(MATCH(4,CalcRank2,0),0)=0,"",INDEX(Sync!$AI$6:$AI$505,IFERROR(MATCH(4,CalcRank2,0),0))) | F34: =IF(IFERROR(MATCH(4,CalcRank2,0),0)=0,"",INDEX(CalcProb2,IFERROR(MATCH(4,CalcRank2,0),0)))
A35: =IF(IFERROR(MATCH(5,CalcRank2,0),0)=0,"",5) | B35: =IF(IFERROR(MATCH(5,CalcRank2,0),0)=0,"",INDEX(Sync!$AG$6:$AG$505,IFERROR(MATCH(5,CalcRank2,0),0))) | C35: =IF(IFERROR(MATCH(5,CalcRank2,0),0)=0,"",INDEX(Sync!$AW$6:$AW$505,IFERROR(MATCH(5,CalcRank2,0),0))) | D35: =IF(IFERROR(MATCH(5,CalcRank2,0),0)=0,"",INDEX(Sync!$AH$6:$AH$505,IFERROR(MATCH(5,CalcRank2,0),0))) | E35: =IF(IFERROR(MATCH(5,CalcRank2,0),0)=0,"",INDEX(Sync!$AI$6:$AI$505,IFERROR(MATCH(5,CalcRank2,0),0))) | F35: =IF(IFERROR(MATCH(5,CalcRank2,0),0)=0,"",INDEX(CalcProb2,IFERROR(MATCH(5,CalcRank2,0),0)))
A36: =IF(IFERROR(MATCH(6,CalcRank2,0),0)=0,"",6) | B36: =IF(IFERROR(MATCH(6,CalcRank2,0),0)=0,"",INDEX(Sync!$AG$6:$AG$505,IFERROR(MATCH(6,CalcRank2,0),0))) | C36: =IF(IFERROR(MATCH(6,CalcRank2,0),0)=0,"",INDEX(Sync!$AW$6:$AW$505,IFERROR(MATCH(6,CalcRank2,0),0))) | D36: =IF(IFERROR(MATCH(6,CalcRank2,0),0)=0,"",INDEX(Sync!$AH$6:$AH$505,IFERROR(MATCH(6,CalcRank2,0),0))) | E36: =IF(IFERROR(MATCH(6,CalcRank2,0),0)=0,"",INDEX(Sync!$AI$6:$AI$505,IFERROR(MATCH(6,CalcRank2,0),0))) | F36: =IF(IFERROR(MATCH(6,CalcRank2,0),0)=0,"",INDEX(CalcProb2,IFERROR(MATCH(6,CalcRank2,0),0)))
A37: =IF(IFERROR(MATCH(7,CalcRank2,0),0)=0,"",7) | B37: =IF(IFERROR(MATCH(7,CalcRank2,0),0)=0,"",INDEX(Sync!$AG$6:$AG$505,IFERROR(MATCH(7,CalcRank2,0),0))) | C37: =IF(IFERROR(MATCH(7,CalcRank2,0),0)=0,"",INDEX(Sync!$AW$6:$AW$505,IFERROR(MATCH(7,CalcRank2,0),0))) | D37: =IF(IFERROR(MATCH(7,CalcRank2,0),0)=0,"",INDEX(Sync!$AH$6:$AH$505,IFERROR(MATCH(7,CalcRank2,0),0))) | E37: =IF(IFERROR(MATCH(7,CalcRank2,0),0)=0,"",INDEX(Sync!$AI$6:$AI$505,IFERROR(MATCH(7,CalcRank2,0),0))) | F37: =IF(IFERROR(MATCH(7,CalcRank2,0),0)=0,"",INDEX(CalcProb2,IFERROR(MATCH(7,CalcRank2,0),0)))
A38: =IF(IFERROR(MATCH(8,CalcRank2,0),0)=0,"",8) | B38: =IF(IFERROR(MATCH(8,CalcRank2,0),0)=0,"",INDEX(Sync!$AG$6:$AG$505,IFERROR(MATCH(8,CalcRank2,0),0))) | C38: =IF(IFERROR(MATCH(8,CalcRank2,0),0)=0,"",INDEX(Sync!$AW$6:$AW$505,IFERROR(MATCH(8,CalcRank2,0),0))) | D38: =IF(IFERROR(MATCH(8,CalcRank2,0),0)=0,"",INDEX(Sync!$AH$6:$AH$505,IFERROR(MATCH(8,CalcRank2,0),0))) | E38: =IF(IFERROR(MATCH(8,CalcRank2,0),0)=0,"",INDEX(Sync!$AI$6:$AI$505,IFERROR(MATCH(8,CalcRank2,0),0))) | F38: =IF(IFERROR(MATCH(8,CalcRank2,0),0)=0,"",INDEX(CalcProb2,IFERROR(MATCH(8,CalcRank2,0),0)))
A39: =IF(IFERROR(MATCH(9,CalcRank2,0),0)=0,"",9) | B39: =IF(IFERROR(MATCH(9,CalcRank2,0),0)=0,"",INDEX(Sync!$AG$6:$AG$505,IFERROR(MATCH(9,CalcRank2,0),0))) | C39: =IF(IFERROR(MATCH(9,CalcRank2,0),0)=0,"",INDEX(Sync!$AW$6:$AW$505,IFERROR(MATCH(9,CalcRank2,0),0))) | D39: =IF(IFERROR(MATCH(9,CalcRank2,0),0)=0,"",INDEX(Sync!$AH$6:$AH$505,IFERROR(MATCH(9,CalcRank2,0),0))) | E39: =IF(IFERROR(MATCH(9,CalcRank2,0),0)=0,"",INDEX(Sync!$AI$6:$AI$505,IFERROR(MATCH(9,CalcRank2,0),0))) | F39: =IF(IFERROR(MATCH(9,CalcRank2,0),0)=0,"",INDEX(CalcProb2,IFERROR(MATCH(9,CalcRank2,0),0)))
A40: =IF(IFERROR(MATCH(10,CalcRank2,0),0)=0,"",10) | B40: =IF(IFERROR(MATCH(10,CalcRank2,0),0)=0,"",INDEX(Sync!$AG$6:$AG$505,IFERROR(MATCH(10,CalcRank2,0),0))) | C40: =IF(IFERROR(MATCH(10,CalcRank2,0),0)=0,"",INDEX(Sync!$AW$6:$AW$505,IFERROR(MATCH(10,CalcRank2,0),0))) | D40: =IF(IFERROR(MATCH(10,CalcRank2,0),0)=0,"",INDEX(Sync!$AH$6:$AH$505,IFERROR(MATCH(10,CalcRank2,0),0))) | E40: =IF(IFERROR(MATCH(10,CalcRank2,0),0)=0,"",INDEX(Sync!$AI$6:$AI$505,IFERROR(MATCH(10,CalcRank2,0),0))) | F40: =IF(IFERROR(MATCH(10,CalcRank2,0),0)=0,"",INDEX(CalcProb2,IFERROR(MATCH(10,CalcRank2,0),0)))
A41: راه‌حل هر مورد: کد طرف/ذی‌نفع ناشناس ← در INFO ← شیت Accounts تعریف کنید (کد از پیش‌گذاشته) · هزینه بدون زیرگروه ← در Transactions ستون زیرگروه را انتخاب کنید · شماره چک نامعتبر ← شماره را اصلاح یا چک را در Cheques ← Issues صادر کنید.

Sheet Learn
A1: مازندشت — سورتینگ و بسته‌بندی مرکبات
A2: باغدشت، بخش مرکزی، شهرستان قائم‌شهر، استان مازندران، ایران | MAZANDASHT · CITRUS SORTING & PACKING
A3: آموزش حسابداری و کدگذاری — مفاهیم، سناریوهای ثبت و نقشه سامانه
A5: ۱) مفاهیم پایه (علم حسابداری)
A6: • معادله بنیادین حسابداری: دارایی = بدهی + حقوق صاحبان — ترازنامه همین معادله است و کنترل √ یعنی برقراری آن.
A7: • بدهکار (Dr) = سمت چپ ثبت؛ یعنی افزایش دارایی/هزینه یا کاهش بدهی/حقوق. بستانکار (Cr) = سمت راست ثبت؛ یعنی افزایش بدهی/حقوق/درآمد یا کاهش دارایی.
A8: • هر تراکنش دوطرفه ثبت می‌شود (مزدوج): یک حساب بدهکار و یک حساب بستانکار با مبلغ برابر — به همین دلیل جمع تراز آزمایشی همیشه برابر است.
A9: • دارایی جاری = نقد و طلب‌هایی که ظرف یک سال نقد می‌شوند (موجودی بانک، طلب اشخاص) · دارایی ثابت = زمین، خودرو، ماشین‌آلات (حساب‌های F…).
A10: • بدهی جاری = دیون کوتاه‌مدت (دیون اشخاص، چک‌های پاس‌نشده) · بدهی بلندمدت = وام‌ها و تسهیلات (L…) که قسط‌بندی می‌شوند.
A11: • حقوق صاحبان = آورده اولیه (افتتاحیه) + سرمایه و آورده (CAP…) + سود/زیان انباشته (− هزینه‌ها − تراکنش‌های شخصی).
A12: • حساب «متفرقه» (Suspense) محل موقت مبالغی است که طرفشان هنوز تعریف نشده — نباید مانده بماند؛ شیت Control آنها را فهرست می‌کند.
A14: ۲) سناریوهای ثبت — از رخداد تا ترازنامه
A15: رخداد | B15: ثبت کجا | C15: بدهکار (Dr) | D15: بستانکار (Cr) | E15: اثر در ترازنامه
A16: Event | B16: Where | C16: Debit | D16: Credit | E16: Effect
A17: فروش کالا (توزین فروش) | B17: Baskol | C17: — (فقط کالا) | D17: — (فقط کالا) | E17: تا تسویه، طلب مشتری از پرداخت‌ها ساخته می‌شود
A18: واریز پول مشتری | B18: Transactions ← واریز | C18: بانک | D18: مشتری (C…) | E18: دارایی نقد ↑ / طلب مشتری ↓
A19: خرید مرکبات (توزین خرید) | B19: Baskol | C19: — (فقط کالا) | D19: — (فقط کالا) | E19: تا تسویه، بدهی به تأمین‌کننده ساخته می‌شود
A20: پرداخت نقدی به تأمین‌کننده | B20: Transactions ← برداشت | C20: تأمین‌کننده (S…) | D20: بانک | E20: بدهی ↓ / نقد ↓
A21: ثبت هزینه عملیاتی | B21: Transactions ← برداشت + گروه هزینه | C21: هزینه: زیرگروه (SG…) | D21: بانک | E21: از حقوق (سود) کم می‌شود
A22: فروش دارایی شخصی و آورده به شرکت | B22: Transactions ← واریز + گروه سرمایه | C22: بانک | D22: سرمایه و آورده (CAP…) | E22: دارایی نقد ↑ / حقوق ↑
A23: برداشت سرمایه توسط صاحب | B23: Transactions ← برداشت + گروه سرمایه | C23: سرمایه و آورده (CAP…) | D23: بانک | E23: حقوق ↓ / نقد ↓
A24: دریافت وام بانکی | B24: Transactions ← واریز + گروه وام | C24: بانک | D24: وام (L…) | E24: نقد ↑ / بدهی بلندمدت ↑
A25: پرداخت قسط وام (اصل) | B25: Transactions ← برداشت + گروه وام | C25: وام (L…) | D25: بانک | E25: بدهی ↓ / نقد ↓
A26: پرداخت بهره/کارمزد وام | B26: Transactions ← برداشت + گروه هزینه + زیرگروه بهره | C26: هزینه: بهره و کارمزد وام | D26: بانک | E26: از حقوق کم می‌شود
... A30: پاس شدن چک صادره | B30: Transactions ← نوع پاس چک + شماره چک | C30: اسناد چک پرداختی | D30: بانک | E30: بدهی چک ↓ / نقد ↓
A32: ۳) کدگذاری سامانه (پیشوندها — هرگز تغییر ندهید)
A33: پیشوند | B33: چه چیزی | C33: تعریف در | D33: مثال
A34: Prefix | B34: What | C34: Defined in | D34: Example
A35: C… | B35: مشتری | C35: INFO ← Accounts | D35: C001
A36: SL… | B36: فروشنده | C36: INFO ← Accounts | D36: SL001
A37: S… | B37: تأمین‌کننده | C37: INFO ← Accounts | D37: S001
A38: E… | B38: کارمند | C38: INFO ← Accounts | D38: E002
A39: X… | B39: سایر حساب (اداری، مالیات، صندوق…) | C39: INFO ← Accounts | D39: X001
A40: F… | B40: دارایی ثابت (زمین، خودرو، تجهیزات) | C40: INFO ← Accounts | D40: F001
A41: L… | B41: وام و تسهیلات | C41: INFO ← Accounts | D41: L001
A42: CAP… | B42: سرمایه و آورده صاحبان | C42: INFO ← Accounts | D42: CAP001
A43: BANK… | B43: حساب بانکی | C43: INFO ← Banks | D43: BANK01
A44: G… | B44: گروه اصلی تراکنش (G01 خرید … G07 دارایی ثابت) | C44: INFO ← MainGroups | D44: G05
... A48: OP… / PB… / PS… / BK… / W… / P… | B48: عملیات باسکول / محصول خرید / محصول فروش / سبد / انبار / پارامتر | C48: INFO ← شیت مربوطه | D48: OP01 / PB01 / P01
A50: ۴) نقشه ارتباط فایل‌ها (لینک‌های خارجی — همیشه در یک پوشه)
...

Sheet Sync
A1: مازندشت — سورتینگ و بسته‌بندی مرکبات
A2: باغدشت، بخش مرکزی، شهرستان قائم‌شهر، استان مازندران، ایران | MAZANDASHT · CITRUS SORTING & PACKING
A3: برگه فنی — آینه‌ی فایل مادر (INFO)، تراکنش‌ها (Transactions)، چک‌ها (Cheques) و سبد (Baskets) برای تراز. فرمول‌ها را تغییر ندهید. اگر همه سلول‌ها خالی شدند یعنی لینک به‌روز نشده: Data ← Edit Links ← Update Values.
A5: Bank · Code | B5: · Title | C5: · Opening | D5: · Active | F5: Acct · Code | G5: · Nature | H5: · Sub | I5: · Name | K5: SG · Code | L5: · Group | M5: · Title | N5: · Desc | P5: Company | R5: flg | S5: cum·N | T5: packed·P | V5: flg | W5: cum·N | X5: packed·E | Z5: Entry · E | AA5: Entry · G | AB5: Entry · J | AC5: Entry · K | AD5: Entry · L | AE5: Entry · M | AF5: Entry · N | AG5: Issues · Cheque No. | AH5: Issues · Amount | AI5: Issues · Party | AJ5: Entry · S | AK5: Entry · C | AL5: Entry · D | AM5: flg | AN5: cum·N | AO5: packed·A | AP5: flg | AQ5: cum·N | AR5: packed·A | AS5: flg | AT5: cum·N | AU5: packed·A | AW5: Issues · Date | AX5: Bsk · Seller | AY5: Bsk · Qty | AZ5: Bsk · Price
A6: =IF([1]Banks!$B$7="","",[1]Banks!$A$7) | B6: =IF([1]Banks!$B$7="","",[1]Banks!$B$7) | C6: =IF([1]Banks!$B$7="","",[1]Banks!$C$7) | D6: =IF([1]Banks!$B$7="","",[1]Banks!$D$7) | F6: =IF([1]Accounts!$D$7="","",[1]Accounts!$A$7) | G6: =IF([1]Accounts!$D$7="","",[1]Accounts!$B$7) | H6: =IF([1]Accounts!$D$7="","",[1]Accounts!$C$7) | I6: =IF([1]Accounts!$D$7="","",[1]Accounts!$D$7) | K6: =IF([1]SubGroups!$C$7="","",[1]SubGroups!$A$7) | L6: =IF([1]SubGroups!$C$7="","",[1]SubGroups!$B$7) | M6: =IF([1]SubGroups!$C$7="","",[1]SubGroups!$C$7) | N6: =IF([1]SubGroups!$C$7="","",[1]SubGroups!$D$7) | P6: =IF([1]Company!$C$5="","",[1]Company!$C$5) | R6: =IF(AND($F6<>"",$I6<>""),IF(OR($G6="دارایی ثابت",$G6="وام و تسهیلات",$G6="سرمایه و آورده صاحبان"),0,1),0) | S6: =SUM($R$6:$R6) | T6: =IFERROR(INDEX($F$6:$F$565,MATCH(ROW()-5,$S$6:$S$565,0)),"") | V6: =IF(AND($K6<>"",$M6<>""),$L6="هزینه",0)*1 | W6: =SUM($V$6:$V6) | X6: =IFERROR(INDEX($M$6:$M$105,MATCH(ROW()-5,$W$6:$W$105,0)),"") | Z6: =IF([2]Entry!$E$9="","",[2]Entry!$E$9) | AA6: =IF([2]Entry!$G$9="","",[2]Entry!$G$9) | AB6: =IF([2]Entry!$J$9="","",[2]Entry!$J$9) | AC6: =IF([2]Entry!$K$9="","",[2]Entry!$K$9) | AD6: =IF([2]Entry!$L$9="","",[2]Entry!$L$9) | AE6: =IF([2]Entry!$M$9="","",[2]Entry!$M$9) | AF6: =IF([2]Entry!$N$9="","",[2]Entry!$N$9) | AG6: =IF([3]Issues!$B$9="","",[3]Issues!$B$9) | AH6: =IF([3]Issues!$D$9="","",[3]Issues!$D$9) | AI6: =IF([3]Issues!$E$9="","",[3]Issues!$E$9) | AJ6: =IF([2]Entry!$S$9="","",[2]Entry!$S$9) | AK6: =IF([2]Entry!$C$9="","",[2]Entry!$C$9) | AL6: =IF([2]Entry!$D$9="","",[2]Entry!$D$9) | AM6: =IF(AND($F6<>"",$I6<>""),IF($G6="دارایی ثابت",1,0),0) | AN6: =SUM($AM$6:$AM6) | AO6: =IFERROR(INDEX($F$6:$F$565,MATCH(ROW()-5,$AN$6:$AN$565,0)),"") | AP6: =IF(AND($F6<>"",$I6<>""),IF($G6="وام و تسهیلات",1,0),0) | AQ6: =SUM($AP$6:$AP6) | AR6: =IFERROR(INDEX($F$6:$F$565,MATCH(ROW()-5,$AQ$6:$AQ$565,0)),"") | AS6: =IF(AND($F6<>"",$I6<>""),IF($G6="سرمایه و آورده صاحبان",1,0),0) | AT6: =SUM($AS$6:$AS6) | AU6: =IFERROR(INDEX($F$6:$F$565,MATCH(ROW()-5,$AT$6:$AT$565,0)),"") | AW6: =IF([3]Issues!$C$9="","",[3]Issues!$C$9) | AX6: =IF([4]Entry!$E$9="","",[4]Entry!$E$9) | AY6: =IF([4]Entry!$H$9="","",[4]Entry!$H$9) | AZ6: =IF([4]Entry!$I$9="","",[4]Entry!$I$9)
A7: =IF([1]Banks!$B$8="","",[1]Banks!$A$8) | B7: =IF([1]Banks!$B$8="","",[1]Banks!$B$8) | C7: =IF([1]Banks!$B$8="","",[1]Banks!$C$8) | D7: =IF([1]Banks!$B$8="","",[1]Banks!$D$8) | F7: =IF([1]Accounts!$D$8="","",[1]Accounts!$A$8) | G7: =IF([1]Accounts!$D$8="","",[1]Accounts!$B$8) | H7: =IF([1]Accounts!$D$8="","",[1]Accounts!$C$8) | I7: =IF([1]Accounts!$D$8="","",[1]Accounts!$D$8) | K7: =IF([1]SubGroups!$C$8="","",[1]SubGroups!$A$8) | L7: =IF([1]SubGroups!$C$8="","",[1]SubGroups!$B$8) | M7: =IF([1]SubGroups!$C$8="","",[1]SubGroups!$C$8) | N7: =IF([1]SubGroups!$C$8="","",[1]SubGroups!$D$8) | P7: =IF([1]Company!$C$8="","",[1]Company!$C$8) | R7: =IF(AND($F7<>"",$I7<>""),IF(OR($G7="دارایی ثابت",$G7="وام و تسهیلات",$G7="سرمایه و آورده صاحبان"),0,1),0) | S7: =SUM($R$6:$R7) | T7: =IFERROR(INDEX($F$6:$F$565,MATCH(ROW()-5,$S$6:$S$565,0)),"") | V7: =IF(AND($K7<>"",$M7<>""),$L7="هزینه",0)*1 | W7: =SUM($V$6:$V7) | X7: =IFERROR(INDEX($M$6:$M$105,MATCH(ROW()-5,$W$6:$W$105,0)),"") | Z7: =IF([2]Entry!$E$10="","",[2]Entry!$E$10) | AA7: =IF([2]Entry!$G$10="","",[2]Entry!$G$10) | AB7: =IF([2]Entry!$J$10="","",[2]Entry!$J$10) | AC7: =IF([2]Entry!$K$10="","",[2]Entry!$K$10) | AD7: =IF([2]Entry!$L$10="","",[2]Entry!$L$10) | AE7: =IF([2]Entry!$M$10="","",[2]Entry!$M$10) | AF7: =IF([2]Entry!$N$10="","",[2]Entry!$N$10) | AG7: =IF([3]Issues!$B$10="","",[3]Issues!$B$10) | AH7: =IF([3]Issues!$D$10="","",[3]Issues!$D$10) | AI7: =IF([3]Issues!$E$10="","",[3]Issues!$E$10) | AJ7: =IF([2]Entry!$S$10="","",[2]Entry!$S$10) | AK7: =IF([2]Entry!$C$10="","",[2]Entry!$C$10) | AL7: =IF([2]Entry!$D$10="","",[2]Entry!$D$10) | AM7: =IF(AND($F7<>"",$I7<>""),IF($G7="دارایی ثابت",1,0),0) | AN7: =SUM($AM$6:$AM7) | AO7: =IFERROR(INDEX($F$6:$F$565,MATCH(ROW()-5,$AN$6:$AN$565,0)),"") | AP7: =IF(AND($F7<>"",$I7<>""),IF($G7="وام و تسهیلات",1,0),0) | AQ7: =SUM($AP$6:$AP7) | AR7: =IFERROR(INDEX($F$6:$F$565,MATCH(ROW()-5,$AQ$6:$AQ$565,0)),"") | AS7: =IF(AND($F7<>"",$I7<>""),IF($G7="سرمایه و آورده صاحبان",1,0),0) | AT7: =SUM($AS$6:$AS7) | AU7: =IFERROR(INDEX($F$6:$F$565,MATCH(ROW()-5,$AT$6:$AT$565,0)),"") | AW7: =IF([3]Issues!$C$10="","",[3]Issues!$C$10) | AX7: =IF([4]Entry!$E$10="","",[4]Entry!$E$10) | AY7: =IF([4]Entry!$H$10="","",[4]Entry!$H$10) | AZ7: =IF([4]Entry!$I$10="","",[4]Entry!$I$10)
A8: =IF([1]Banks!$B$9="","",[1]Banks!$A$9) | B8: =IF([1]Banks!$B$9="","",[1]Banks!$B$9) | C8: =IF([1]Banks!$B$9="","",[1]Banks!$C$9) | D8: =IF([1]Banks!$B$9="","",[1]Banks!$D$9) | F8: =IF([1]Accounts!$D$9="","",[1]Accounts!$A$9) | G8: =IF([1]Accounts!$D$9="","",[1]Accounts!$B$9) | H8: =IF([1]Accounts!$D$9="","",[1]Accounts!$C$9) | I8: =IF([1]Accounts!$D$9="","",[1]Accounts!$D$9) | K8: =IF([1]SubGroups!$C$9="","",[1]SubGroups!$A$9) | L8: =IF([1]SubGroups!$C$9="","",[1]SubGroups!$B$9) | M8: =IF([1]SubGroups!$C$9="","",[1]SubGroups!$C$9) | N8: =IF([1]SubGroups!$C$9="","",[1]SubGroups!$D$9) | P8: =IF([1]Company!$C$9="","",[1]Company!$C$9) | R8: =IF(AND($F8<>"",$I8<>""),IF(OR($G8="دارایی ثابت",$G8="وام و تسهیلات",$G8="سرمایه و آورده صاحبان"),0,1),0) | S8: =SUM($R$6:$R8) | T8: =IFERROR(INDEX($F$6:$F$565,MATCH(ROW()-5,$S$6:$S$565,0)),"") | V8: =IF(AND($K8<>"",$M8<>""),$L8="هزینه",0)*1 | W8: =SUM($V$6:$V8) | X8: =IFERROR(INDEX($M$6:$M$105,MATCH(ROW()-5,$W$6:$W$105,0)),"") | Z8: =IF([2]Entry!$E$11="","",[2]Entry!$E$11) | AA8: =IF([2]Entry!$G$11="","",[2]Entry!$G$11) | AB8: =IF([2]Entry!$J$11="","",[2]Entry!$J$11) | AC8: =IF([2]Entry!$K$11="","",[2]Entry!$K$11) | AD8: =IF([2]Entry!$L$11="","",[2]Entry!$L$11) | AE8: =IF([2]Entry!$M$11="","",[2]Entry!$M$11) | AF8: =IF([2]Entry!$N$11="","",[2]Entry!$N$11) | AG8: =IF([3]Issues!$B$11="","",[3]Issues!$B$11) | AH8: =IF([3]Issues!$D$11="","",[3]Issues!$D$11) | AI8: =IF([3]Issues!$E$11="","",[3]Issues!$E$11) | AJ8: =IF([2]Entry!$S$11="","",[2]Entry!$S$11) | AK8: =IF([2]Entry!$C$11="","",[2]Entry!$C$11) | AL8: =IF([2]Entry!$D$11="","",[2]Entry!$D$11) | AM8: =IF(AND($F8<>"",$I8<>""),IF($G8="دارایی ثابت",1,0),0) | AN8: =SUM($AM$6:$AM8) | AO8: =IFERROR(INDEX($F$6:$F$565,MATCH(ROW()-5,$AN$6:$AN$565,0)),"") | AP8: =IF(AND($F8<>"",$I8<>""),IF($G8="وام و تسهیلات",1,0),0) | AQ8: =SUM($AP$6:$AP8) | AR8: =IFERROR(INDEX($F$6:$F$565,MATCH(ROW()-5,$AQ$6:$AQ$565,0)),"") | AS8: =IF(AND($F8<>"",$I8<>""),IF($G8="سرمایه و آورده صاحبان",1,0),0) | AT8: =SUM($AS$6:$AS8) | AU8: =IFERROR(INDEX($F$6:$F$565,MATCH(ROW()-5,$AT$6:$AT$565,0)),"") | AW8: =IF([3]Issues!$C$11="","",[3]Issues!$C$11) | AX8: =IF([4]Entry!$E$11="","",[4]Entry!$E$11) | AY8: =IF([4]Entry!$H$11="","",[4]Entry!$H$11) | AZ8: =IF([4]Entry!$I$11="","",[4]Entry!$I$11)
A9: =IF([1]Banks!$B$10="","",[1]Banks!$A$10) | B9: =IF([1]Banks!$B$10="","",[1]Banks!$B$10) | C9: =IF([1]Banks!$B$10="","",[1]Banks!$C$10) | D9: =IF([1]Banks!$B$10="","",[1]Banks!$D$10) | F9: =IF([1]Accounts!$D$10="","",[1]Accounts!$A$10) | G9: =IF([1]Accounts!$D$10="","",[1]Accounts!$B$10) | H9: =IF([1]Accounts!$D$10="","",[1]Accounts!$C$10) | I9: =IF([1]Accounts!$D$10="","",[1]Accounts!$D$10) | K9: =IF([1]SubGroups!$C$10="","",[1]SubGroups!$A$10) | L9: =IF([1]SubGroups!$C$10="","",[1]SubGroups!$B$10) | M9: =IF([1]SubGroups!$C$10="","",[1]SubGroups!$C$10) | N9: =IF([1]SubGroups!$C$10="","",[1]SubGroups!$D$10) | P9: =IF([1]Company!$C$7="","",[1]Company!$C$7) | R9: =IF(AND($F9<>"",$I9<>""),IF(OR($G9="دارایی ثابت",$G9="وام و تسهیلات",$G9="سرمایه و آورده صاحبان"),0,1),0) | S9: =SUM($R$6:$R9) | T9: =IFERROR(INDEX($F$6:$F$565,MATCH(ROW()-5,$S$6:$S$565,0)),"") | V9: =IF(AND($K9<>"",$M9<>""),$L9="هزینه",0)*1 | W9: =SUM($V$6:$V9) | X9: =IFERROR(INDEX($M$6:$M$105,MATCH(ROW()-5,$W$6:$W$105,0)),"") | Z9: =IF([2]Entry!$E$12="","",[2]Entry!$E$12) | AA9: =IF([2]Entry!$G$12="","",[2]Entry!$G$12) | AB9: =IF([2]Entry!$J$12="","",[2]Entry!$J$12) | AC9: =IF([2]Entry!$K$12="","",[2]Entry!$K$12) | AD9: =IF([2]Entry!$L$12="","",[2]Entry!$L$12) | AE9: =IF([2]Entry!$M$12="","",[2]Entry!$M$12) | AF9: =IF([2]Entry!$N$12="","",[2]Entry!$N$12) | AG9: =IF([3]Issues!$B$12="","",[3]Issues!$B$12) | AH9: =IF([3]Issues!$D$12="","",[3]Issues!$D$12) | AI9: =IF([3]Issues!$E$12="","",[3]Issues!$E$12) | AJ9: =IF([2]Entry!$S$12="","",[2]Entry!$S$12) | AK9: =IF([2]Entry!$C$12="","",[2]Entry!$C$12) | AL9: =IF([2]Entry!$D$12="","",[2]Entry!$D$12) | AM9: =IF(AND($F9<>"",$I9<>""),IF($G9="دارایی ثابت",1,0),0) | AN9: =SUM($AM$6:$AM9) | AO9: =IFERROR(INDEX($F$6:$F$565,MATCH(ROW()-5,$AN$6:$AN$565,0)),"") | AP9: =IF(AND($F9<>"",$I9<>""),IF($G9="وام و تسهیلات",1,0),0) | AQ9: =SUM($AP$6:$AP9) | AR9: =IFERROR(INDEX($F$6:$F$565,MATCH(ROW()-5,$AQ$6:$AQ$565,0)),"") | AS9: =IF(AND($F9<>"",$I9<>""),IF($G9="سرمایه و آورده صاحبان",1,0),0) | AT9: =SUM($AS$6:$AS9) | AU9: =IFERROR(INDEX($F$6:$F$565,MATCH(ROW()-5,$AT$6:$AT$565,0)),"") | AW9: =IF([3]Issues!$C$12="","",[3]Issues!$C$12) | AX9: =IF([4]Entry!$E$12="","",[4]Entry!$E$12) | AY9: =IF([4]Entry!$H$12="","",[4]Entry!$H$12) | AZ9: =IF([4]Entry!$I$12="","",[4]Entry!$I$12)
