Workbook
Name AcctCodes: Sync!$A$6:$A$565
Name AcctTbl: Sync!$A$6:$F$565
Name CalcAmtA: Calc!$J$6:$J$1005
Name CalcBankB: Calc!$V$6:$V$2005
Name CalcDateA: Calc!$E$6:$E$1005
Name CalcDateB: Calc!$O$6:$O$2005
Name CalcDepB: Calc!$T$6:$T$2005
Name CalcDocA: Calc!$K$6:$K$1005
Name CalcKeyA: Calc!$B$6:$B$1005
Name CalcKeyB: Calc!$P$6:$P$2005
Name CalcNoteA: Calc!$L$6:$L$1005
Name CalcNoteB: Calc!$W$6:$W$2005
Name CalcPartyA: Calc!$A$6:$A$1005
Name CalcPartyB: Calc!$N$6:$N$2005
Name CalcPriceA: Calc!$I$6:$I$1005
Name CalcQtyA: Calc!$H$6:$H$1005
Name CalcRankKeyA: Calc!$D$6:$D$1005
Name CalcRankKeyB: Calc!$S$6:$S$2005
Name CalcTypeA: Calc!$G$6:$G$1005
Name CalcWitB: Calc!$U$6:$U$2005
Name NBskParty: Calc!$AB$1005
Name PkBskParty: Calc!$AC$6:$AC$1005

Sheet Entry
A1: =IF(Sync!$N$6="","مازندشت",Sync!$N$6)&" — "&IF(Sync!$N$9="","سورتینگ و بسته‌بندی مرکبات",Sync!$N$9) -> 250000000 — 90000000
A2: =IF(Sync!$N$7="","باغدشت، بخش مرکزی، شهرستان قائم‌شهر، استان مازندران، ایران",Sync!$N$7)&" | MAZANDASHT · CITRUS SORTING & PACKING" -> باغدشت، بخش مرکزی، شهرستان قائم‌شهر، استان مازندران، ایران | MAZANDASHT · CITRUS SORTING & PACKING
A3: دفتر سبد و ظروف — خرید سبد از فروشنده (هر ردیف = یک خرید)
A4: هر ردیف: تاریخ، کد فروشنده سبد (از INFO ← Accounts — مثل S004)، نوع سبد (کشویی از INFO ← Baskets)، تعداد و فی. مبلغ و نام فروشنده و «مانده حساب» خودکار است: مانده = جمع خرید سبد تا این سطر − پرداخت‌های بانکی تا همین لحظه (به همه ردیف‌های همان حساب اعمال می‌شود). پرداخت به فروشنده را در Transactions.xlsx (برداشت با همان کد) ثبت کنید — اینجا خودش کم می‌شود.
A7: ردیف | B7: تاریخ | C7: ساعت | D7: شماره سند | E7: کد فروشنده | F7: نام فروشنده | G7: نوع سبد | H7: تعداد | I7: فی (ریال) | J7: مبلغ (ریال) | K7: مانده حساب (ریال) | L7: توضیحات
A8: No. | B8: Date | C8: Time | D8: Doc | E8: Seller Code | F8: Seller Name | G8: Basket Type | H8: Qty | I8: Unit Price | J8: Amount | K8: Account Balance | L8: Notes
A9: =IF($B9="","",COUNTA($B$9:$B9)) -> 1 | B9: 1405/07/13 | E9: S001 | F9: =IF($E9="","",IFERROR(IF(VLOOKUP($E9,AcctTbl,4,0)="","",VLOOKUP($E9,AcctTbl,4,0)),"—")) -> حسن کوچکزاده | G9: سبد6ک مشکی | H9: 637 | I9: 25000 | J9: =IF(OR($H9="",$I9=""),"",ROUND($H9*$I9,0)) -> 15925000 | K9: =IF(OR($B9="",$E9="",Calc!$B6=""),"",SUMIFS(CalcAmtA,CalcPartyA,$E9,CalcKeyA,"<="&Calc!$B6)-SUMIFS(CalcWitB,CalcPartyB,$E9,CalcKeyB,"<="&Calc!$B6)+SUMIFS(CalcDepB,CalcPartyB,$E9,CalcKeyB,"<="&Calc!$B6)) -> #REF!
A10: =IF($B10="","",COUNTA($B$9:$B10)) -> 2 | B10: 1405/07/13 | E10: S001 | F10: =IF($E10="","",IFERROR(IF(VLOOKUP($E10,AcctTbl,4,0)="","",VLOOKUP($E10,AcctTbl,4,0)),"—")) -> حسن کوچکزاده | G10: درب6ک | H10: 650 | I10: 5000 | J10: =IF(OR($H10="",$I10=""),"",ROUND($H10*$I10,0)) -> 3250000 | K10: =IF(OR($B10="",$E10="",Calc!$B7=""),"",SUMIFS(CalcAmtA,CalcPartyA,$E10,CalcKeyA,"<="&Calc!$B7)-SUMIFS(CalcWitB,CalcPartyB,$E10,CalcKeyB,"<="&Calc!$B7)+SUMIFS(CalcDepB,CalcPartyB,$E10,CalcKeyB,"<="&Calc!$B7)) -> #REF!
A11: =IF($B11="","",COUNTA($B$9:$B11)) -> 3 | B11: 1405/07/13 | E11: S001 | F11: =IF($E11="","",IFERROR(IF(VLOOKUP($E11,AcctTbl,4,0)="","",VLOOKUP($E11,AcctTbl,4,0)),"—")) -> حسن کوچکزاده | G11: سبد6ک مشکی | H11: 637 | I11: 25000 | J11: =IF(OR($H11="",$I11=""),"",ROUND($H11*$I11,0)) -> 15925000 | K11: =IF(OR($B11="",$E11="",Calc!$B8=""),"",SUMIFS(CalcAmtA,CalcPartyA,$E11,CalcKeyA,"<="&Calc!$B8)-SUMIFS(CalcWitB,CalcPartyB,$E11,CalcKeyB,"<="&Calc!$B8)+SUMIFS(CalcDepB,CalcPartyB,$E11,CalcKeyB,"<="&Calc!$B8)) -> #REF!
A12: =IF($B12="","",COUNTA($B$9:$B12)) -> 4 | B12: 1405/07/13 | E12: S001 | F12: =IF($E12="","",IFERROR(IF(VLOOKUP($E12,AcctTbl,4,0)="","",VLOOKUP($E12,AcctTbl,4,0)),"—")) -> حسن کوچکزاده | G12: درب6ک | H12: 650 | I12: 5000 | J12: =IF(OR($H12="",$I12=""),"",ROUND($H12*$I12,0)) -> 3250000 | K12: =IF(OR($B12="",$E12="",Calc!$B9=""),"",SUMIFS(CalcAmtA,CalcPartyA,$E12,CalcKeyA,"<="&Calc!$B9)-SUMIFS(CalcWitB,CalcPartyB,$E12,CalcKeyB,"<="&Calc!$B9)+SUMIFS(CalcDepB,CalcPartyB,$E12,CalcKeyB,"<="&Calc!$B9)) -> #REF!
A13: =IF($B13="","",COUNTA($B$9:$B13)) -> 5 | B13: 1405/07/16 | E13: S001 | F13: =IF($E13="","",IFERROR(IF(VLOOKUP($E13,AcctTbl,4,0)="","",VLOOKUP($E13,AcctTbl,4,0)),"—")) -> حسن کوچکزاده | G13: سبد6ک مشکی | H13: 749 | I13: 25000 | J13: =IF(OR($H13="",$I13=""),"",ROUND($H13*$I13,0)) -> 18725000 | K13: =IF(OR($B13="",$E13="",Calc!$B10=""),"",SUMIFS(CalcAmtA,CalcPartyA,$E13,CalcKeyA,"<="&Calc!$B10)-SUMIFS(CalcWitB,CalcPartyB,$E13,CalcKeyB,"<="&Calc!$B10)+SUMIFS(CalcDepB,CalcPartyB,$E13,CalcKeyB,"<="&Calc!$B10)) -> #REF!
A14: =IF($B14="","",COUNTA($B$9:$B14)) -> 6 | B14: 1405/07/16 | E14: S001 | F14: =IF($E14="","",IFERROR(IF(VLOOKUP($E14,AcctTbl,4,0)="","",VLOOKUP($E14,AcctTbl,4,0)),"—")) -> حسن کوچکزاده | G14: درب6ک | H14: 800 | I14: 5000 | J14: =IF(OR($H14="",$I14=""),"",ROUND($H14*$I14,0)) -> 4000000 | K14: =IF(OR($B14="",$E14="",Calc!$B11=""),"",SUMIFS(CalcAmtA,CalcPartyA,$E14,CalcKeyA,"<="&Calc!$B11)-SUMIFS(CalcWitB,CalcPartyB,$E14,CalcKeyB,"<="&Calc!$B11)+SUMIFS(CalcDepB,CalcPartyB,$E14,CalcKeyB,"<="&Calc!$B11)) -> #REF!
A15: =IF($B15="","",COUNTA($B$9:$B15)) -> 7 | B15: 1405/07/17 | E15: S001 | F15: =IF($E15="","",IFERROR(IF(VLOOKUP($E15,AcctTbl,4,0)="","",VLOOKUP($E15,AcctTbl,4,0)),"—")) -> حسن کوچکزاده | G15: سبد6ک مشکی | H15: 749 | I15: 25000 | J15: =IF(OR($H15="",$I15=""),"",ROUND($H15*$I15,0)) -> 18725000 | K15: =IF(OR($B15="",$E15="",Calc!$B12=""),"",SUMIFS(CalcAmtA,CalcPartyA,$E15,CalcKeyA,"<="&Calc!$B12)-SUMIFS(CalcWitB,CalcPartyB,$E15,CalcKeyB,"<="&Calc!$B12)+SUMIFS(CalcDepB,CalcPartyB,$E15,CalcKeyB,"<="&Calc!$B12)) -> #REF!
A16: =IF($B16="","",COUNTA($B$9:$B16)) -> 8 | B16: 1405/07/17 | E16: S001 | F16: =IF($E16="","",IFERROR(IF(VLOOKUP($E16,AcctTbl,4,0)="","",VLOOKUP($E16,AcctTbl,4,0)),"—")) -> حسن کوچکزاده | G16: درب6ک | H16: 800 | I16: 5000 | J16: =IF(OR($H16="",$I16=""),"",ROUND($H16*$I16,0)) -> 4000000 | K16: =IF(OR($B16="",$E16="",Calc!$B13=""),"",SUMIFS(CalcAmtA,CalcPartyA,$E16,CalcKeyA,"<="&Calc!$B13)-SUMIFS(CalcWitB,CalcPartyB,$E16,CalcKeyB,"<="&Calc!$B13)+SUMIFS(CalcDepB,CalcPartyB,$E16,CalcKeyB,"<="&Calc!$B13)) -> #REF!
A17: =IF($B17="","",COUNTA($B$9:$B17)) -> 9 | B17: 1405/07/17 | E17: S001 | F17: =IF($E17="","",IFERROR(IF(VLOOKUP($E17,AcctTbl,4,0)="","",VLOOKUP($E17,AcctTbl,4,0)),"—")) -> حسن کوچکزاده | G17: سبد6ک مشکی | H17: 749 | I17: 25000 | J17: =IF(OR($H17="",$I17=""),"",ROUND($H17*$I17,0)) -> 18725000 | K17: =IF(OR($B17="",$E17="",Calc!$B14=""),"",SUMIFS(CalcAmtA,CalcPartyA,$E17,CalcKeyA,"<="&Calc!$B14)-SUMIFS(CalcWitB,CalcPartyB,$E17,CalcKeyB,"<="&Calc!$B14)+SUMIFS(CalcDepB,CalcPartyB,$E17,CalcKeyB,"<="&Calc!$B14)) -> #REF!
A18: =IF($B18="","",COUNTA($B$9:$B18)) -> 10 | B18: 1405/07/17 | E18: S001 | F18: =IF($E18="","",IFERROR(IF(VLOOKUP($E18,AcctTbl,4,0)="","",VLOOKUP($E18,AcctTbl,4,0)),"—")) -> حسن کوچکزاده | G18: درب6ک | H18: 800 | I18: 5000 | J18: =IF(OR($H18="",$I18=""),"",ROUND($H18*$I18,0)) -> 4000000 | K18: =IF(OR($B18="",$E18="",Calc!$B15=""),"",SUMIFS(CalcAmtA,CalcPartyA,$E18,CalcKeyA,"<="&Calc!$B15)-SUMIFS(CalcWitB,CalcPartyB,$E18,CalcKeyB,"<="&Calc!$B15)+SUMIFS(CalcDepB,CalcPartyB,$E18,CalcKeyB,"<="&Calc!$B15)) -> #REF!
A19: =IF($B19="","",COUNTA($B$9:$B19)) -> 11 | B19: 1405/07/17 | E19: S001 | F19: =IF($E19="","",IFERROR(IF(VLOOKUP($E19,AcctTbl,4,0)="","",VLOOKUP($E19,AcctTbl,4,0)),"—")) -> حسن کوچکزاده | G19: سبد6ک مشکی | H19: 749 | I19: 25000 | J19: =IF(OR($H19="",$I19=""),"",ROUND($H19*$I19,0)) -> 18725000 | K19: =IF(OR($B19="",$E19="",Calc!$B16=""),"",SUMIFS(CalcAmtA,CalcPartyA,$E19,CalcKeyA,"<="&Calc!$B16)-SUMIFS(CalcWitB,CalcPartyB,$E19,CalcKeyB,"<="&Calc!$B16)+SUMIFS(CalcDepB,CalcPartyB,$E19,CalcKeyB,"<="&Calc!$B16)) -> #REF!
A20: =IF($B20="","",COUNTA($B$9:$B20)) -> 12 | B20: 1405/07/17 | E20: S001 | F20: =IF($E20="","",IFERROR(IF(VLOOKUP($E20,AcctTbl,4,0)="","",VLOOKUP($E20,AcctTbl,4,0)),"—")) -> حسن کوچکزاده | G20: درب6ک | H20: 600 | I20: 5000 | J20: =IF(OR($H20="",$I20=""),"",ROUND($H20*$I20,0)) -> 3000000 | K20: =IF(OR($B20="",$E20="",Calc!$B17=""),"",SUMIFS(CalcAmtA,CalcPartyA,$E20,CalcKeyA,"<="&Calc!$B17)-SUMIFS(CalcWitB,CalcPartyB,$E20,CalcKeyB,"<="&Calc!$B17)+SUMIFS(CalcDepB,CalcPartyB,$E20,CalcKeyB,"<="&Calc!$B17)) -> #REF!
... A50: =IF($B50="","",COUNTA($B$9:$B50)) -> 42 | B50: 1405/08/03 | E50: S001 | F50: =IF($E50="","",IFERROR(IF(VLOOKUP($E50,AcctTbl,4,0)="","",VLOOKUP($E50,AcctTbl,4,0)),"—")) -> حسن کوچکزاده | G50: 9ک مشکی | H50: 2023 | I50: 47000 | J50: =IF(OR($H50="",$I50=""),"",ROUND($H50*$I50,0)) -> 95081000 | K50: =IF(OR($B50="",$E50="",Calc!$B47=""),"",SUMIFS(CalcAmtA,CalcPartyA,$E50,CalcKeyA,"<="&Calc!$B47)-SUMIFS(CalcWitB,CalcPartyB,$E50,CalcKeyB,"<="&Calc!$B47)+SUMIFS(CalcDepB,CalcPartyB,$E50,CalcKeyB,"<="&Calc!$B47)) -> #REF!
A51: =IF($B51="","",COUNTA($B$9:$B51)) | F51: =IF($E51="","",IFERROR(IF(VLOOKUP($E51,AcctTbl,4,0)="","",VLOOKUP($E51,AcctTbl,4,0)),"—")) | J51: =IF(OR($H51="",$I51=""),"",ROUND($H51*$I51,0)) | K51: =IF(OR($B51="",$E51="",Calc!$B48=""),"",SUMIFS(CalcAmtA,CalcPartyA,$E51,CalcKeyA,"<="&Calc!$B48)-SUMIFS(CalcWitB,CalcPartyB,$E51,CalcKeyB,"<="&Calc!$B48)+SUMIFS(CalcDepB,CalcPartyB,$E51,CalcKeyB,"<="&Calc!$B48))
A52: =IF($B52="","",COUNTA($B$9:$B52)) | F52: =IF($E52="","",IFERROR(IF(VLOOKUP($E52,AcctTbl,4,0)="","",VLOOKUP($E52,AcctTbl,4,0)),"—")) | J52: =IF(OR($H52="",$I52=""),"",ROUND($H52*$I52,0)) | K52: =IF(OR($B52="",$E52="",Calc!$B49=""),"",SUMIFS(CalcAmtA,CalcPartyA,$E52,CalcKeyA,"<="&Calc!$B49)-SUMIFS(CalcWitB,CalcPartyB,$E52,CalcKeyB,"<="&Calc!$B49)+SUMIFS(CalcDepB,CalcPartyB,$E52,CalcKeyB,"<="&Calc!$B49))
A53: =IF($B53="","",COUNTA($B$9:$B53)) | F53: =IF($E53="","",IFERROR(IF(VLOOKUP($E53,AcctTbl,4,0)="","",VLOOKUP($E53,AcctTbl,4,0)),"—")) | J53: =IF(OR($H53="",$I53=""),"",ROUND($H53*$I53,0)) | K53: =IF(OR($B53="",$E53="",Calc!$B50=""),"",SUMIFS(CalcAmtA,CalcPartyA,$E53,CalcKeyA,"<="&Calc!$B50)-SUMIFS(CalcWitB,CalcPartyB,$E53,CalcKeyB,"<="&Calc!$B50)+SUMIFS(CalcDepB,CalcPartyB,$E53,CalcKeyB,"<="&Calc!$B50))
A54: =IF($B54="","",COUNTA($B$9:$B54)) | F54: =IF($E54="","",IFERROR(IF(VLOOKUP($E54,AcctTbl,4,0)="","",VLOOKUP($E54,AcctTbl,4,0)),"—")) | J54: =IF(OR($H54="",$I54=""),"",ROUND($H54*$I54,0)) | K54: =IF(OR($B54="",$E54="",Calc!$B51=""),"",SUMIFS(CalcAmtA,CalcPartyA,$E54,CalcKeyA,"<="&Calc!$B51)-SUMIFS(CalcWitB,CalcPartyB,$E54,CalcKeyB,"<="&Calc!$B51)+SUMIFS(CalcDepB,CalcPartyB,$E54,CalcKeyB,"<="&Calc!$B51))
A55: =IF($B55="","",COUNTA($B$9:$B55)) | F55: =IF($E55="","",IFERROR(IF(VLOOKUP($E55,AcctTbl,4,0)="","",VLOOKUP($E55,AcctTbl,4,0)),"—")) | J55: =IF(OR($H55="",$I55=""),"",ROUND($H55*$I55,0)) | K55: =IF(OR($B55="",$E55="",Calc!$B52=""),"",SUMIFS(CalcAmtA,CalcPartyA,$E55,CalcKeyA,"<="&Calc!$B52)-SUMIFS(CalcWitB,CalcPartyB,$E55,CalcKeyB,"<="&Calc!$B52)+SUMIFS(CalcDepB,CalcPartyB,$E55,CalcKeyB,"<="&Calc!$B52))
A56: =IF($B56="","",COUNTA($B$9:$B56)) | F56: =IF($E56="","",IFERROR(IF(VLOOKUP($E56,AcctTbl,4,0)="","",VLOOKUP($E56,AcctTbl,4,0)),"—")) | J56: =IF(OR($H56="",$I56=""),"",ROUND($H56*$I56,0)) | K56: =IF(OR($B56="",$E56="",Calc!$B53=""),"",SUMIFS(CalcAmtA,CalcPartyA,$E56,CalcKeyA,"<="&Calc!$B53)-SUMIFS(CalcWitB,CalcPartyB,$E56,CalcKeyB,"<="&Calc!$B53)+SUMIFS(CalcDepB,CalcPartyB,$E56,CalcKeyB,"<="&Calc!$B53))
A57: =IF($B57="","",COUNTA($B$9:$B57)) | F57: =IF($E57="","",IFERROR(IF(VLOOKUP($E57,AcctTbl,4,0)="","",VLOOKUP($E57,AcctTbl,4,0)),"—")) | J57: =IF(OR($H57="",$I57=""),"",ROUND($H57*$I57,0)) | K57: =IF(OR($B57="",$E57="",Calc!$B54=""),"",SUMIFS(CalcAmtA,CalcPartyA,$E57,CalcKeyA,"<="&Calc!$B54)-SUMIFS(CalcWitB,CalcPartyB,$E57,CalcKeyB,"<="&Calc!$B54)+SUMIFS(CalcDepB,CalcPartyB,$E57,CalcKeyB,"<="&Calc!$B54))
A58: =IF($B58="","",COUNTA($B$9:$B58)) | F58: =IF($E58="","",IFERROR(IF(VLOOKUP($E58,AcctTbl,4,0)="","",VLOOKUP($E58,AcctTbl,4,0)),"—")) | J58: =IF(OR($H58="",$I58=""),"",ROUND($H58*$I58,0)) | K58: =IF(OR($B58="",$E58="",Calc!$B55=""),"",SUMIFS(CalcAmtA,CalcPartyA,$E58,CalcKeyA,"<="&Calc!$B55)-SUMIFS(CalcWitB,CalcPartyB,$E58,CalcKeyB,"<="&Calc!$B55)+SUMIFS(CalcDepB,CalcPartyB,$E58,CalcKeyB,"<="&Calc!$B55))
A59: =IF($B59="","",COUNTA($B$9:$B59)) | F59: =IF($E59="","",IFERROR(IF(VLOOKUP($E59,AcctTbl,4,0)="","",VLOOKUP($E59,AcctTbl,4,0)),"—")) | J59: =IF(OR($H59="",$I59=""),"",ROUND($H59*$I59,0)) | K59: =IF(OR($B59="",$E59="",Calc!$B56=""),"",SUMIFS(CalcAmtA,CalcPartyA,$E59,CalcKeyA,"<="&Calc!$B56)-SUMIFS(CalcWitB,CalcPartyB,$E59,CalcKeyB,"<="&Calc!$B56)+SUMIFS(CalcDepB,CalcPartyB,$E59,CalcKeyB,"<="&Calc!$B56))
A60: =IF($B60="","",COUNTA($B$9:$B60)) | F60: =IF($E60="","",IFERROR(IF(VLOOKUP($E60,AcctTbl,4,0)="","",VLOOKUP($E60,AcctTbl,4,0)),"—")) | J60: =IF(OR($H60="",$I60=""),"",ROUND($H60*$I60,0)) | K60: =IF(OR($B60="",$E60="",Calc!$B57=""),"",SUMIFS(CalcAmtA,CalcPartyA,$E60,CalcKeyA,"<="&Calc!$B57)-SUMIFS(CalcWitB,CalcPartyB,$E60,CalcKeyB,"<="&Calc!$B57)+SUMIFS(CalcDepB,CalcPartyB,$E60,CalcKeyB,"<="&Calc!$B57))
A61: =IF($B61="","",COUNTA($B$9:$B61)) | F61: =IF($E61="","",IFERROR(IF(VLOOKUP($E61,AcctTbl,4,0)="","",VLOOKUP($E61,AcctTbl,4,0)),"—")) | J61: =IF(OR($H61="",$I61=""),"",ROUND($H61*$I61,0)) | K61: =IF(OR($B61="",$E61="",Calc!$B58=""),"",SUMIFS(CalcAmtA,CalcPartyA,$E61,CalcKeyA,"<="&Calc!$B58)-SUMIFS(CalcWitB,CalcPartyB,$E61,CalcKeyB,"<="&Calc!$B58)+SUMIFS(CalcDepB,CalcPartyB,$E61,CalcKeyB,"<="&Calc!$B58))
A62: =IF($B62="","",COUNTA($B$9:$B62)) | F62: =IF($E62="","",IFERROR(IF(VLOOKUP($E62,AcctTbl,4,0)="","",VLOOKUP($E62,AcctTbl,4,0)),"—")) | J62: =IF(OR($H62="",$I62=""),"",ROUND($H62*$I62,0)) | K62: =IF(OR($B62="",$E62="",Calc!$B59=""),"",SUMIFS(CalcAmtA,CalcPartyA,$E62,CalcKeyA,"<="&Calc!$B59)-SUMIFS(CalcWitB,CalcPartyB,$E62,CalcKeyB,"<="&Calc!$B59)+SUMIFS(CalcDepB,CalcPartyB,$E62,CalcKeyB,"<="&Calc!$B59))
... A1005: =IF($B1005="","",COUNTA($B$9:$B1005)) | F1005: =IF($E1005="","",IFERROR(IF(VLOOKUP($E1005,AcctTbl,4,0)="","",VLOOKUP($E1005,AcctTbl,4,0)),"—")) | J1005: =IF(OR($H1005="",$I1005=""),"",ROUND($H1005*$I1005,0)) | K1005: =IF(OR($B1005="",$E1005="",Calc!$B1002=""),"",SUMIFS(CalcAmtA,CalcPartyA,$E1005,CalcKeyA,"<="&Calc!$B1002)-SUMIFS(CalcWitB,CalcPartyB,$E1005,CalcKeyB,"<="&Calc!$B1002)+SUMIFS(CalcDepB,CalcPartyB,$E1005,CalcKeyB,"<="&Calc!$B1002))
A1006: =IF($B1006="","",COUNTA($B$9:$B1006)) | F1006: =IF($E1006="","",IFERROR(IF(VLOOKUP($E1006,AcctTbl,4,0)="","",VLOOKUP($E1006,AcctTbl,4,0)),"—")) | K1006: =IF(OR($B1006="",$E1006="",Calc!$B1003=""),"",SUMIFS(CalcAmtA,CalcPartyA,$E1006,CalcKeyA,"<="&Calc!$B1003)-SUMIFS(CalcWitB,CalcPartyB,$E1006,CalcKeyB,"<="&Calc!$B1003)+SUMIFS(CalcDepB,CalcPartyB,$E1006,CalcKeyB,"<="&Calc!$B1003))
A1007: =IF($B1007="","",COUNTA($B$9:$B1007)) | F1007: =IF($E1007="","",IFERROR(IF(VLOOKUP($E1007,AcctTbl,4,0)="","",VLOOKUP($E1007,AcctTbl,4,0)),"—")) | K1007: =IF(OR($B1007="",$E1007="",Calc!$B1004=""),"",SUMIFS(CalcAmtA,CalcPartyA,$E1007,CalcKeyA,"<="&Calc!$B1004)-SUMIFS(CalcWitB,CalcPartyB,$E1007,CalcKeyB,"<="&Calc!$B1004)+SUMIFS(CalcDepB,CalcPartyB,$E1007,CalcKeyB,"<="&Calc!$B1004))
A1008: =IF($B1008="","",COUNTA($B$9:$B1008)) | F1008: =IF($E1008="","",IFERROR(IF(VLOOKUP($E1008,AcctTbl,4,0)="","",VLOOKUP($E1008,AcctTbl,4,0)),"—")) | K1008: =IF(OR($B1008="",$E1008="",Calc!$B1005=""),"",SUMIFS(CalcAmtA,CalcPartyA,$E1008,CalcKeyA,"<="&Calc!$B1005)-SUMIFS(CalcWitB,CalcPartyB,$E1008,CalcKeyB,"<="&Calc!$B1005)+SUMIFS(CalcDepB,CalcPartyB,$E1008,CalcKeyB,"<="&Calc!$B1005))

Sheet Report
A1: =IF(Sync!$N$6="","مازندشت",Sync!$N$6)&" — "&IF(Sync!$N$9="","سورتینگ و بسته‌بندی مرکبات",Sync!$N$9) -> 250000000 — 90000000
A2: =IF(Sync!$N$7="","باغدشت، بخش مرکزی، شهرستان قائم‌شهر، استان مازندران، ایران",Sync!$N$7)&" | MAZANDASHT · CITRUS SORTING & PACKING" -> باغدشت، بخش مرکزی، شهرستان قائم‌شهر، استان مازندران، ایران | MAZANDASHT · CITRUS SORTING & PACKING
A3: ="کارتکس فروشنده سبد — "&IFERROR(IF(VLOOKUP($C$5,AcctTbl,4,0)="","(بدون عنوان)",VLOOKUP($C$5,AcctTbl,4,0)),"کد را وارد کنید") -> کارتکس فروشنده سبد — حسن کوچکزاده
A5: کد فروشنده سبد (ورود دستی): | C5: S001 | E5: کد را از INFO (شیت Accounts) وارد کنید — کل گردش خودکار به‌روز می‌شود. برای فروشنده دیگر، همین شیت را کپی و کد را عوض کنید.
A6: نام صاحب حساب: | C6: =IFERROR(IF(VLOOKUP($C$5,AcctTbl,4,0)="","(بدون عنوان)",VLOOKUP($C$5,AcctTbl,4,0)),"—") -> حسن کوچکزاده
A7: نوع و زیرمجموعه: | C7: =IFERROR(IF(VLOOKUP($C$5,AcctTbl,3,0)="",VLOOKUP($C$5,AcctTbl,2,0),VLOOKUP($C$5,AcctTbl,2,0)&" — "&VLOOKUP($C$5,AcctTbl,3,0)),"—") -> تأمین‌کننده — فروشنده سبد
A8: مانده اولیه (دستی): | C8: 0 | E8: مثبت = بدهی قبلی ما به او. در مانده اولِ ردیف‌ها اثر می‌گذارد.
A10: جمع خرید سبد (ریال) | C10: جمع پرداخت به او (ریال) | E10: جمع دریافت از او (ریال) | G10: مانده نهایی (ریال) | I10: وضعیت
A11: =SUM($I$17:$I$2016) -> #REF! | C11: =SUM($H$17:$H$2016) -> 95000000 | E11: =SUM($E$17:$E$2016) -> 0 | G11: =IFERROR(LOOKUP(9.99E+307,$J$17:$J$2016),$C$8) -> -15000000 | I11: =IF($G$11>0,"● بستانکار — به او بدهکاریم",IF($G$11<0,"● بدهکار — به ما بدهکار است","= تسویه شده")) -> ● بدهکار — به ما بدهکار است
A13: تعداد کل سبد خریداری‌شده | C13: تعداد ردیف خرید سبد | E13: تعداد پرداخت/دریافت | G13: آخرین رویداد
A14: =SUM($F$17:$F$2016) -> #REF! | C14: =COUNTIF($C$17:$C$2016,"خرید سبد") -> 30 | E14: =COUNTIF($C$17:$C$2016,"پرداخت بانکی")+COUNTIF($C$17:$C$2016,"دریافت بانکی") -> 2 | G14: =IF(COUNT($J$17:$J$2016)=0,"—",INDEX($B$17:$B$2016,COUNT($J$17:$J$2016))) -> 1405/07/07
A15: ردیف | B15: تاریخ | C15: نوع رویداد | D15: سند / بانک | E15: دریافت (ریال) | F15: تعداد سبد | G15: فی (ریال) | H15: پرداخت (ریال) | I15: خرید سبد (ریال) | J15: مانده (ریال) | K15: توضیحات
A16: No. | B16: Date | C16: Type | D16: Doc / Bank | E16: Received | F16: Qty | G16: Unit Price | H16: Paid | I16: Purchase | J16: Balance | K16: Notes
A17: 1 | B17: =IF(AND($M17="",$N17=""),"",IF($M17<>"",INDEX(CalcDateA,$M17),INDEX(CalcDateB,$N17))) -> 1405/07/07 | C17: =IF($M17<>"","خرید سبد",IF($N17<>"",IF(N(INDEX(CalcDepB,$N17))>0,"دریافت بانکی","پرداخت بانکی"),"")) -> پرداخت بانکی | D17: =IF($M17<>"",IF(INDEX(CalcDocA,$M17)="","—",INDEX(CalcDocA,$M17)),IF($N17<>"",INDEX(CalcBankB,$N17),"")) -> BANK01 – ملت — جاری شرکت | E17: =IF($N17<>"",IF(INDEX(CalcDepB,$N17)=0,"",INDEX(CalcDepB,$N17)),"") | F17: =IF($M17<>"",IF(INDEX(CalcQtyA,$M17)=0,"",INDEX(CalcQtyA,$M17)),"") | G17: =IF($M17<>"",IF(INDEX(CalcPriceA,$M17)=0,"",INDEX(CalcPriceA,$M17)),"") | H17: =IF($N17<>"",IF(INDEX(CalcWitB,$N17)=0,"",INDEX(CalcWitB,$N17)),"") -> 15000000 | I17: =IF($M17<>"",INDEX(CalcAmtA,$M17),"") | J17: =IF($B17="","",$C$8+IF($I17="",0,$I17)+IF($E17="",0,$E17)-IF($H17="",0,$H17)) -> -15000000 | K17: =IF($M17<>"",IF(INDEX(CalcNoteA,$M17)="","—",INDEX(CalcNoteA,$M17)),IF($N17<>"",IF(INDEX(CalcNoteB,$N17)="","—",INDEX(CalcNoteB,$N17)),"")) -> پیش‌پرداخت باغ آقای رستمی (نمونه) | M17: =IFERROR(MATCH($C$5&"|"&RIGHT("000000"&1,6),CalcRankKeyA,0),"") | N17: =IFERROR(MATCH($C$5&"|"&RIGHT("000000"&1,6),CalcRankKeyB,0),"") -> 13
A18: 2 | B18: =IF(AND($M18="",$N18=""),"",IF($M18<>"",INDEX(CalcDateA,$M18),INDEX(CalcDateB,$N18))) -> 1405/07/13 | C18: =IF($M18<>"","خرید سبد",IF($N18<>"",IF(N(INDEX(CalcDepB,$N18))>0,"دریافت بانکی","پرداخت بانکی"),"")) -> خرید سبد | D18: =IF($M18<>"",IF(INDEX(CalcDocA,$M18)="","—",INDEX(CalcDocA,$M18)),IF($N18<>"",INDEX(CalcBankB,$N18),"")) -> 0 | E18: =IF($N18<>"",IF(INDEX(CalcDepB,$N18)=0,"",INDEX(CalcDepB,$N18)),"") | F18: =IF($M18<>"",IF(INDEX(CalcQtyA,$M18)=0,"",INDEX(CalcQtyA,$M18)),"") -> #REF! | G18: =IF($M18<>"",IF(INDEX(CalcPriceA,$M18)=0,"",INDEX(CalcPriceA,$M18)),"") -> #REF! | H18: =IF($N18<>"",IF(INDEX(CalcWitB,$N18)=0,"",INDEX(CalcWitB,$N18)),"") | I18: =IF($M18<>"",INDEX(CalcAmtA,$M18),"") -> #REF! | J18: =IF($B18="","",IF($J17="",$C$8,$J17)+IF($I18="",0,$I18)+IF($E18="",0,$E18)-IF($H18="",0,$H18)) -> #REF! | K18: =IF($M18<>"",IF(INDEX(CalcNoteA,$M18)="","—",INDEX(CalcNoteA,$M18)),IF($N18<>"",IF(INDEX(CalcNoteB,$N18)="","—",INDEX(CalcNoteB,$N18)),"")) -> 0 | M18: =IFERROR(MATCH($C$5&"|"&RIGHT("000000"&2,6),CalcRankKeyA,0),"") -> 1 | N18: =IFERROR(MATCH($C$5&"|"&RIGHT("000000"&2,6),CalcRankKeyB,0),"")
A19: 3 | B19: =IF(AND($M19="",$N19=""),"",IF($M19<>"",INDEX(CalcDateA,$M19),INDEX(CalcDateB,$N19))) -> 1405/07/13 | C19: =IF($M19<>"","خرید سبد",IF($N19<>"",IF(N(INDEX(CalcDepB,$N19))>0,"دریافت بانکی","پرداخت بانکی"),"")) -> خرید سبد | D19: =IF($M19<>"",IF(INDEX(CalcDocA,$M19)="","—",INDEX(CalcDocA,$M19)),IF($N19<>"",INDEX(CalcBankB,$N19),"")) -> 0 | E19: =IF($N19<>"",IF(INDEX(CalcDepB,$N19)=0,"",INDEX(CalcDepB,$N19)),"") | F19: =IF($M19<>"",IF(INDEX(CalcQtyA,$M19)=0,"",INDEX(CalcQtyA,$M19)),"") -> #REF! | G19: =IF($M19<>"",IF(INDEX(CalcPriceA,$M19)=0,"",INDEX(CalcPriceA,$M19)),"") -> #REF! | H19: =IF($N19<>"",IF(INDEX(CalcWitB,$N19)=0,"",INDEX(CalcWitB,$N19)),"") | I19: =IF($M19<>"",INDEX(CalcAmtA,$M19),"") -> #REF! | J19: =IF($B19="","",IF($J18="",$C$8,$J18)+IF($I19="",0,$I19)+IF($E19="",0,$E19)-IF($H19="",0,$H19)) -> #REF! | K19: =IF($M19<>"",IF(INDEX(CalcNoteA,$M19)="","—",INDEX(CalcNoteA,$M19)),IF($N19<>"",IF(INDEX(CalcNoteB,$N19)="","—",INDEX(CalcNoteB,$N19)),"")) -> 0 | M19: =IFERROR(MATCH($C$5&"|"&RIGHT("000000"&3,6),CalcRankKeyA,0),"") -> 2 | N19: =IFERROR(MATCH($C$5&"|"&RIGHT("000000"&3,6),CalcRankKeyB,0),"")
A20: 4 | B20: =IF(AND($M20="",$N20=""),"",IF($M20<>"",INDEX(CalcDateA,$M20),INDEX(CalcDateB,$N20))) -> 1405/07/13 | C20: =IF($M20<>"","خرید سبد",IF($N20<>"",IF(N(INDEX(CalcDepB,$N20))>0,"دریافت بانکی","پرداخت بانکی"),"")) -> خرید سبد | D20: =IF($M20<>"",IF(INDEX(CalcDocA,$M20)="","—",INDEX(CalcDocA,$M20)),IF($N20<>"",INDEX(CalcBankB,$N20),"")) -> 0 | E20: =IF($N20<>"",IF(INDEX(CalcDepB,$N20)=0,"",INDEX(CalcDepB,$N20)),"") | F20: =IF($M20<>"",IF(INDEX(CalcQtyA,$M20)=0,"",INDEX(CalcQtyA,$M20)),"") -> #REF! | G20: =IF($M20<>"",IF(INDEX(CalcPriceA,$M20)=0,"",INDEX(CalcPriceA,$M20)),"") -> #REF! | H20: =IF($N20<>"",IF(INDEX(CalcWitB,$N20)=0,"",INDEX(CalcWitB,$N20)),"") | I20: =IF($M20<>"",INDEX(CalcAmtA,$M20),"") -> #REF! | J20: =IF($B20="","",IF($J19="",$C$8,$J19)+IF($I20="",0,$I20)+IF($E20="",0,$E20)-IF($H20="",0,$H20)) -> #REF! | K20: =IF($M20<>"",IF(INDEX(CalcNoteA,$M20)="","—",INDEX(CalcNoteA,$M20)),IF($N20<>"",IF(INDEX(CalcNoteB,$N20)="","—",INDEX(CalcNoteB,$N20)),"")) -> 0 | M20: =IFERROR(MATCH($C$5&"|"&RIGHT("000000"&4,6),CalcRankKeyA,0),"") -> 3 | N20: =IFERROR(MATCH($C$5&"|"&RIGHT("000000"&4,6),CalcRankKeyB,0),"")
A21: 5 | B21: =IF(AND($M21="",$N21=""),"",IF($M21<>"",INDEX(CalcDateA,$M21),INDEX(CalcDateB,$N21))) -> 1405/07/13 | C21: =IF($M21<>"","خرید سبد",IF($N21<>"",IF(N(INDEX(CalcDepB,$N21))>0,"دریافت بانکی","پرداخت بانکی"),"")) -> خرید سبد | D21: =IF($M21<>"",IF(INDEX(CalcDocA,$M21)="","—",INDEX(CalcDocA,$M21)),IF($N21<>"",INDEX(CalcBankB,$N21),"")) -> 0 | E21: =IF($N21<>"",IF(INDEX(CalcDepB,$N21)=0,"",INDEX(CalcDepB,$N21)),"") | F21: =IF($M21<>"",IF(INDEX(CalcQtyA,$M21)=0,"",INDEX(CalcQtyA,$M21)),"") -> 637 | G21: =IF($M21<>"",IF(INDEX(CalcPriceA,$M21)=0,"",INDEX(CalcPriceA,$M21)),"") -> 25000 | H21: =IF($N21<>"",IF(INDEX(CalcWitB,$N21)=0,"",INDEX(CalcWitB,$N21)),"") | I21: =IF($M21<>"",INDEX(CalcAmtA,$M21),"") -> 15925000 | J21: =IF($B21="","",IF($J20="",$C$8,$J20)+IF($I21="",0,$I21)+IF($E21="",0,$E21)-IF($H21="",0,$H21)) -> #REF! | K21: =IF($M21<>"",IF(INDEX(CalcNoteA,$M21)="","—",INDEX(CalcNoteA,$M21)),IF($N21<>"",IF(INDEX(CalcNoteB,$N21)="","—",INDEX(CalcNoteB,$N21)),"")) -> 0 | M21: =IFERROR(MATCH($C$5&"|"&RIGHT("000000"&5,6),CalcRankKeyA,0),"") -> 4 | N21: =IFERROR(MATCH($C$5&"|"&RIGHT("000000"&5,6),CalcRankKeyB,0),"")
A22: 6 | B22: =IF(AND($M22="",$N22=""),"",IF($M22<>"",INDEX(CalcDateA,$M22),INDEX(CalcDateB,$N22))) -> 1405/07/15 | C22: =IF($M22<>"","خرید سبد",IF($N22<>"",IF(N(INDEX(CalcDepB,$N22))>0,"دریافت بانکی","پرداخت بانکی"),"")) -> پرداخت بانکی | D22: =IF($M22<>"",IF(INDEX(CalcDocA,$M22)="","—",INDEX(CalcDocA,$M22)),IF($N22<>"",INDEX(CalcBankB,$N22),"")) -> BANK01 – ملت — جاری شرکت | E22: =IF($N22<>"",IF(INDEX(CalcDepB,$N22)=0,"",INDEX(CalcDepB,$N22)),"") | F22: =IF($M22<>"",IF(INDEX(CalcQtyA,$M22)=0,"",INDEX(CalcQtyA,$M22)),"") | G22: =IF($M22<>"",IF(INDEX(CalcPriceA,$M22)=0,"",INDEX(CalcPriceA,$M22)),"") | H22: =IF($N22<>"",IF(INDEX(CalcWitB,$N22)=0,"",INDEX(CalcWitB,$N22)),"") -> 80000000 | I22: =IF($M22<>"",INDEX(CalcAmtA,$M22),"") | J22: =IF($B22="","",IF($J21="",$C$8,$J21)+IF($I22="",0,$I22)+IF($E22="",0,$E22)-IF($H22="",0,$H22)) -> #REF! | K22: =IF($M22<>"",IF(INDEX(CalcNoteA,$M22)="","—",INDEX(CalcNoteA,$M22)),IF($N22<>"",IF(INDEX(CalcNoteB,$N22)="","—",INDEX(CalcNoteB,$N22)),"")) -> پاس شدن چک ۲۴۰۱۲۳۴۵ — تسویه خرید باغ (نمونه) | M22: =IFERROR(MATCH($C$5&"|"&RIGHT("000000"&6,6),CalcRankKeyA,0),"") | N22: =IFERROR(MATCH($C$5&"|"&RIGHT("000000"&6,6),CalcRankKeyB,0),"") -> 14
A23: 7 | B23: =IF(AND($M23="",$N23=""),"",IF($M23<>"",INDEX(CalcDateA,$M23),INDEX(CalcDateB,$N23))) -> 1405/07/16 | C23: =IF($M23<>"","خرید سبد",IF($N23<>"",IF(N(INDEX(CalcDepB,$N23))>0,"دریافت بانکی","پرداخت بانکی"),"")) -> خرید سبد | D23: =IF($M23<>"",IF(INDEX(CalcDocA,$M23)="","—",INDEX(CalcDocA,$M23)),IF($N23<>"",INDEX(CalcBankB,$N23),"")) -> 0 | E23: =IF($N23<>"",IF(INDEX(CalcDepB,$N23)=0,"",INDEX(CalcDepB,$N23)),"") | F23: =IF($M23<>"",IF(INDEX(CalcQtyA,$M23)=0,"",INDEX(CalcQtyA,$M23)),"") -> 650 | G23: =IF($M23<>"",IF(INDEX(CalcPriceA,$M23)=0,"",INDEX(CalcPriceA,$M23)),"") -> 5000 | H23: =IF($N23<>"",IF(INDEX(CalcWitB,$N23)=0,"",INDEX(CalcWitB,$N23)),"") | I23: =IF($M23<>"",INDEX(CalcAmtA,$M23),"") -> 3250000 | J23: =IF($B23="","",IF($J22="",$C$8,$J22)+IF($I23="",0,$I23)+IF($E23="",0,$E23)-IF($H23="",0,$H23)) -> #REF! | K23: =IF($M23<>"",IF(INDEX(CalcNoteA,$M23)="","—",INDEX(CalcNoteA,$M23)),IF($N23<>"",IF(INDEX(CalcNoteB,$N23)="","—",INDEX(CalcNoteB,$N23)),"")) -> 0 | M23: =IFERROR(MATCH($C$5&"|"&RIGHT("000000"&7,6),CalcRankKeyA,0),"") -> 5 | N23: =IFERROR(MATCH($C$5&"|"&RIGHT("000000"&7,6),CalcRankKeyB,0),"")
A24: 8 | B24: =IF(AND($M24="",$N24=""),"",IF($M24<>"",INDEX(CalcDateA,$M24),INDEX(CalcDateB,$N24))) -> 1405/07/16 | C24: =IF($M24<>"","خرید سبد",IF($N24<>"",IF(N(INDEX(CalcDepB,$N24))>0,"دریافت بانکی","پرداخت بانکی"),"")) -> خرید سبد | D24: =IF($M24<>"",IF(INDEX(CalcDocA,$M24)="","—",INDEX(CalcDocA,$M24)),IF($N24<>"",INDEX(CalcBankB,$N24),"")) -> 0 | E24: =IF($N24<>"",IF(INDEX(CalcDepB,$N24)=0,"",INDEX(CalcDepB,$N24)),"") | F24: =IF($M24<>"",IF(INDEX(CalcQtyA,$M24)=0,"",INDEX(CalcQtyA,$M24)),"") -> 637 | G24: =IF($M24<>"",IF(INDEX(CalcPriceA,$M24)=0,"",INDEX(CalcPriceA,$M24)),"") -> 25000 | H24: =IF($N24<>"",IF(INDEX(CalcWitB,$N24)=0,"",INDEX(CalcWitB,$N24)),"") | I24: =IF($M24<>"",INDEX(CalcAmtA,$M24),"") -> 15925000 | J24: =IF($B24="","",IF($J23="",$C$8,$J23)+IF($I24="",0,$I24)+IF($E24="",0,$E24)-IF($H24="",0,$H24)) -> #REF! | K24: =IF($M24<>"",IF(INDEX(CalcNoteA,$M24)="","—",INDEX(CalcNoteA,$M24)),IF($N24<>"",IF(INDEX(CalcNoteB,$N24)="","—",INDEX(CalcNoteB,$N24)),"")) -> 0 | M24: =IFERROR(MATCH($C$5&"|"&RIGHT("000000"&8,6),CalcRankKeyA,0),"") -> 6 | N24: =IFERROR(MATCH($C$5&"|"&RIGHT("000000"&8,6),CalcRankKeyB,0),"")
A25: 9 | B25: =IF(AND($M25="",$N25=""),"",IF($M25<>"",INDEX(CalcDateA,$M25),INDEX(CalcDateB,$N25))) -> 1405/07/17 | C25: =IF($M25<>"","خرید سبد",IF($N25<>"",IF(N(INDEX(CalcDepB,$N25))>0,"دریافت بانکی","پرداخت بانکی"),"")) -> خرید سبد | D25: =IF($M25<>"",IF(INDEX(CalcDocA,$M25)="","—",INDEX(CalcDocA,$M25)),IF($N25<>"",INDEX(CalcBankB,$N25),"")) -> 0 | E25: =IF($N25<>"",IF(INDEX(CalcDepB,$N25)=0,"",INDEX(CalcDepB,$N25)),"") | F25: =IF($M25<>"",IF(INDEX(CalcQtyA,$M25)=0,"",INDEX(CalcQtyA,$M25)),"") -> 650 | G25: =IF($M25<>"",IF(INDEX(CalcPriceA,$M25)=0,"",INDEX(CalcPriceA,$M25)),"") -> 5000 | H25: =IF($N25<>"",IF(INDEX(CalcWitB,$N25)=0,"",INDEX(CalcWitB,$N25)),"") | I25: =IF($M25<>"",INDEX(CalcAmtA,$M25),"") -> 3250000 | J25: =IF($B25="","",IF($J24="",$C$8,$J24)+IF($I25="",0,$I25)+IF($E25="",0,$E25)-IF($H25="",0,$H25)) -> #REF! | K25: =IF($M25<>"",IF(INDEX(CalcNoteA,$M25)="","—",INDEX(CalcNoteA,$M25)),IF($N25<>"",IF(INDEX(CalcNoteB,$N25)="","—",INDEX(CalcNoteB,$N25)),"")) -> 0 | M25: =IFERROR(MATCH($C$5&"|"&RIGHT("000000"&9,6),CalcRankKeyA,0),"") -> 7 | N25: =IFERROR(MATCH($C$5&"|"&RIGHT("000000"&9,6),CalcRankKeyB,0),"")
A26: 10 | B26: =IF(AND($M26="",$N26=""),"",IF($M26<>"",INDEX(CalcDateA,$M26),INDEX(CalcDateB,$N26))) -> 1405/07/17 | C26: =IF($M26<>"","خرید سبد",IF($N26<>"",IF(N(INDEX(CalcDepB,$N26))>0,"دریافت بانکی","پرداخت بانکی"),"")) -> خرید سبد | D26: =IF($M26<>"",IF(INDEX(CalcDocA,$M26)="","—",INDEX(CalcDocA,$M26)),IF($N26<>"",INDEX(CalcBankB,$N26),"")) -> 0 | E26: =IF($N26<>"",IF(INDEX(CalcDepB,$N26)=0,"",INDEX(CalcDepB,$N26)),"") | F26: =IF($M26<>"",IF(INDEX(CalcQtyA,$M26)=0,"",INDEX(CalcQtyA,$M26)),"") -> 749 | G26: =IF($M26<>"",IF(INDEX(CalcPriceA,$M26)=0,"",INDEX(CalcPriceA,$M26)),"") -> 25000 | H26: =IF($N26<>"",IF(INDEX(CalcWitB,$N26)=0,"",INDEX(CalcWitB,$N26)),"") | I26: =IF($M26<>"",INDEX(CalcAmtA,$M26),"") -> 18725000 | J26: =IF($B26="","",IF($J25="",$C$8,$J25)+IF($I26="",0,$I26)+IF($E26="",0,$E26)-IF($H26="",0,$H26)) -> #REF! | K26: =IF($M26<>"",IF(INDEX(CalcNoteA,$M26)="","—",INDEX(CalcNoteA,$M26)),IF($N26<>"",IF(INDEX(CalcNoteB,$N26)="","—",INDEX(CalcNoteB,$N26)),"")) -> 0 | M26: =IFERROR(MATCH($C$5&"|"&RIGHT("000000"&10,6),CalcRankKeyA,0),"") -> 8 | N26: =IFERROR(MATCH($C$5&"|"&RIGHT("000000"&10,6),CalcRankKeyB,0),"")
A27: 11 | B27: =IF(AND($M27="",$N27=""),"",IF($M27<>"",INDEX(CalcDateA,$M27),INDEX(CalcDateB,$N27))) -> 1405/07/17 | C27: =IF($M27<>"","خرید سبد",IF($N27<>"",IF(N(INDEX(CalcDepB,$N27))>0,"دریافت بانکی","پرداخت بانکی"),"")) -> خرید سبد | D27: =IF($M27<>"",IF(INDEX(CalcDocA,$M27)="","—",INDEX(CalcDocA,$M27)),IF($N27<>"",INDEX(CalcBankB,$N27),"")) -> 0 | E27: =IF($N27<>"",IF(INDEX(CalcDepB,$N27)=0,"",INDEX(CalcDepB,$N27)),"") | F27: =IF($M27<>"",IF(INDEX(CalcQtyA,$M27)=0,"",INDEX(CalcQtyA,$M27)),"") -> 800 | G27: =IF($M27<>"",IF(INDEX(CalcPriceA,$M27)=0,"",INDEX(CalcPriceA,$M27)),"") -> 5000 | H27: =IF($N27<>"",IF(INDEX(CalcWitB,$N27)=0,"",INDEX(CalcWitB,$N27)),"") | I27: =IF($M27<>"",INDEX(CalcAmtA,$M27),"") -> 4000000 | J27: =IF($B27="","",IF($J26="",$C$8,$J26)+IF($I27="",0,$I27)+IF($E27="",0,$E27)-IF($H27="",0,$H27)) -> #REF! | K27: =IF($M27<>"",IF(INDEX(CalcNoteA,$M27)="","—",INDEX(CalcNoteA,$M27)),IF($N27<>"",IF(INDEX(CalcNoteB,$N27)="","—",INDEX(CalcNoteB,$N27)),"")) -> 0 | M27: =IFERROR(MATCH($C$5&"|"&RIGHT("000000"&11,6),CalcRankKeyA,0),"") -> 9 | N27: =IFERROR(MATCH($C$5&"|"&RIGHT("000000"&11,6),CalcRankKeyB,0),"")
A28: 12 | B28: =IF(AND($M28="",$N28=""),"",IF($M28<>"",INDEX(CalcDateA,$M28),INDEX(CalcDateB,$N28))) -> 1405/07/17 | C28: =IF($M28<>"","خرید سبد",IF($N28<>"",IF(N(INDEX(CalcDepB,$N28))>0,"دریافت بانکی","پرداخت بانکی"),"")) -> خرید سبد | D28: =IF($M28<>"",IF(INDEX(CalcDocA,$M28)="","—",INDEX(CalcDocA,$M28)),IF($N28<>"",INDEX(CalcBankB,$N28),"")) -> 0 | E28: =IF($N28<>"",IF(INDEX(CalcDepB,$N28)=0,"",INDEX(CalcDepB,$N28)),"") | F28: =IF($M28<>"",IF(INDEX(CalcQtyA,$M28)=0,"",INDEX(CalcQtyA,$M28)),"") -> 749 | G28: =IF($M28<>"",IF(INDEX(CalcPriceA,$M28)=0,"",INDEX(CalcPriceA,$M28)),"") -> 25000 | H28: =IF($N28<>"",IF(INDEX(CalcWitB,$N28)=0,"",INDEX(CalcWitB,$N28)),"") | I28: =IF($M28<>"",INDEX(CalcAmtA,$M28),"") -> 18725000 | J28: =IF($B28="","",IF($J27="",$C$8,$J27)+IF($I28="",0,$I28)+IF($E28="",0,$E28)-IF($H28="",0,$H28)) -> #REF! | K28: =IF($M28<>"",IF(INDEX(CalcNoteA,$M28)="","—",INDEX(CalcNoteA,$M28)),IF($N28<>"",IF(INDEX(CalcNoteB,$N28)="","—",INDEX(CalcNoteB,$N28)),"")) -> 0 | M28: =IFERROR(MATCH($C$5&"|"&RIGHT("000000"&12,6),CalcRankKeyA,0),"") -> 10 | N28: =IFERROR(MATCH($C$5&"|"&RIGHT("000000"&12,6),CalcRankKeyB,0),"")
A29: 13 | B29: =IF(AND($M29="",$N29=""),"",IF($M29<>"",INDEX(CalcDateA,$M29),INDEX(CalcDateB,$N29))) -> 1405/07/17 | C29: =IF($M29<>"","خرید سبد",IF($N29<>"",IF(N(INDEX(CalcDepB,$N29))>0,"دریافت بانکی","پرداخت بانکی"),"")) -> خرید سبد | D29: =IF($M29<>"",IF(INDEX(CalcDocA,$M29)="","—",INDEX(CalcDocA,$M29)),IF($N29<>"",INDEX(CalcBankB,$N29),"")) -> 0 | E29: =IF($N29<>"",IF(INDEX(CalcDepB,$N29)=0,"",INDEX(CalcDepB,$N29)),"") | F29: =IF($M29<>"",IF(INDEX(CalcQtyA,$M29)=0,"",INDEX(CalcQtyA,$M29)),"") -> 800 | G29: =IF($M29<>"",IF(INDEX(CalcPriceA,$M29)=0,"",INDEX(CalcPriceA,$M29)),"") -> 5000 | H29: =IF($N29<>"",IF(INDEX(CalcWitB,$N29)=0,"",INDEX(CalcWitB,$N29)),"") | I29: =IF($M29<>"",INDEX(CalcAmtA,$M29),"") -> 4000000 | J29: =IF($B29="","",IF($J28="",$C$8,$J28)+IF($I29="",0,$I29)+IF($E29="",0,$E29)-IF($H29="",0,$H29)) -> #REF! | K29: =IF($M29<>"",IF(INDEX(CalcNoteA,$M29)="","—",INDEX(CalcNoteA,$M29)),IF($N29<>"",IF(INDEX(CalcNoteB,$N29)="","—",INDEX(CalcNoteB,$N29)),"")) -> 0 | M29: =IFERROR(MATCH($C$5&"|"&RIGHT("000000"&13,6),CalcRankKeyA,0),"") -> 11 | N29: =IFERROR(MATCH($C$5&"|"&RIGHT("000000"&13,6),CalcRankKeyB,0),"")
A30: 14 | B30: =IF(AND($M30="",$N30=""),"",IF($M30<>"",INDEX(CalcDateA,$M30),INDEX(CalcDateB,$N30))) -> 1405/07/17 | C30: =IF($M30<>"","خرید سبد",IF($N30<>"",IF(N(INDEX(CalcDepB,$N30))>0,"دریافت بانکی","پرداخت بانکی"),"")) -> خرید سبد | D30: =IF($M30<>"",IF(INDEX(CalcDocA,$M30)="","—",INDEX(CalcDocA,$M30)),IF($N30<>"",INDEX(CalcBankB,$N30),"")) -> 0 | E30: =IF($N30<>"",IF(INDEX(CalcDepB,$N30)=0,"",INDEX(CalcDepB,$N30)),"") | F30: =IF($M30<>"",IF(INDEX(CalcQtyA,$M30)=0,"",INDEX(CalcQtyA,$M30)),"") -> 749 | G30: =IF($M30<>"",IF(INDEX(CalcPriceA,$M30)=0,"",INDEX(CalcPriceA,$M30)),"") -> 25000 | H30: =IF($N30<>"",IF(INDEX(CalcWitB,$N30)=0,"",INDEX(CalcWitB,$N30)),"") | I30: =IF($M30<>"",INDEX(CalcAmtA,$M30),"") -> 18725000 | J30: =IF($B30="","",IF($J29="",$C$8,$J29)+IF($I30="",0,$I30)+IF($E30="",0,$E30)-IF($H30="",0,$H30)) -> #REF! | K30: =IF($M30<>"",IF(INDEX(CalcNoteA,$M30)="","—",INDEX(CalcNoteA,$M30)),IF($N30<>"",IF(INDEX(CalcNoteB,$N30)="","—",INDEX(CalcNoteB,$N30)),"")) -> 0 | M30: =IFERROR(MATCH($C$5&"|"&RIGHT("000000"&14,6),CalcRankKeyA,0),"") -> 12 | N30: =IFERROR(MATCH($C$5&"|"&RIGHT("000000"&14,6),CalcRankKeyB,0),"")
A31: 15 | B31: =IF(AND($M31="",$N31=""),"",IF($M31<>"",INDEX(CalcDateA,$M31),INDEX(CalcDateB,$N31))) -> 1405/07/19 | C31: =IF($M31<>"","خرید سبد",IF($N31<>"",IF(N(INDEX(CalcDepB,$N31))>0,"دریافت بانکی","پرداخت بانکی"),"")) -> خرید سبد | D31: =IF($M31<>"",IF(INDEX(CalcDocA,$M31)="","—",INDEX(CalcDocA,$M31)),IF($N31<>"",INDEX(CalcBankB,$N31),"")) -> 0 | E31: =IF($N31<>"",IF(INDEX(CalcDepB,$N31)=0,"",INDEX(CalcDepB,$N31)),"") | F31: =IF($M31<>"",IF(INDEX(CalcQtyA,$M31)=0,"",INDEX(CalcQtyA,$M31)),"") -> 960 | G31: =IF($M31<>"",IF(INDEX(CalcPriceA,$M31)=0,"",INDEX(CalcPriceA,$M31)),"") -> 17500 | H31: =IF($N31<>"",IF(INDEX(CalcWitB,$N31)=0,"",INDEX(CalcWitB,$N31)),"") | I31: =IF($M31<>"",INDEX(CalcAmtA,$M31),"") -> 16800000 | J31: =IF($B31="","",IF($J30="",$C$8,$J30)+IF($I31="",0,$I31)+IF($E31="",0,$E31)-IF($H31="",0,$H31)) -> #REF! | K31: =IF($M31<>"",IF(INDEX(CalcNoteA,$M31)="","—",INDEX(CalcNoteA,$M31)),IF($N31<>"",IF(INDEX(CalcNoteB,$N31)="","—",INDEX(CalcNoteB,$N31)),"")) -> 0 | M31: =IFERROR(MATCH($C$5&"|"&RIGHT("000000"&15,6),CalcRankKeyA,0),"") -> 19 | N31: =IFERROR(MATCH($C$5&"|"&RIGHT("000000"&15,6),CalcRankKeyB,0),"")
A32: 16 | B32: =IF(AND($M32="",$N32=""),"",IF($M32<>"",INDEX(CalcDateA,$M32),INDEX(CalcDateB,$N32))) -> 1405/07/20 | C32: =IF($M32<>"","خرید سبد",IF($N32<>"",IF(N(INDEX(CalcDepB,$N32))>0,"دریافت بانکی","پرداخت بانکی"),"")) -> خرید سبد | D32: =IF($M32<>"",IF(INDEX(CalcDocA,$M32)="","—",INDEX(CalcDocA,$M32)),IF($N32<>"",INDEX(CalcBankB,$N32),"")) -> 0 | E32: =IF($N32<>"",IF(INDEX(CalcDepB,$N32)=0,"",INDEX(CalcDepB,$N32)),"") | F32: =IF($M32<>"",IF(INDEX(CalcQtyA,$M32)=0,"",INDEX(CalcQtyA,$M32)),"") -> 3840 | G32: =IF($M32<>"",IF(INDEX(CalcPriceA,$M32)=0,"",INDEX(CalcPriceA,$M32)),"") -> 15000 | H32: =IF($N32<>"",IF(INDEX(CalcWitB,$N32)=0,"",INDEX(CalcWitB,$N32)),"") | I32: =IF($M32<>"",INDEX(CalcAmtA,$M32),"") -> 57600000 | J32: =IF($B32="","",IF($J31="",$C$8,$J31)+IF($I32="",0,$I32)+IF($E32="",0,$E32)-IF($H32="",0,$H32)) -> #REF! | K32: =IF($M32<>"",IF(INDEX(CalcNoteA,$M32)="","—",INDEX(CalcNoteA,$M32)),IF($N32<>"",IF(INDEX(CalcNoteB,$N32)="","—",INDEX(CalcNoteB,$N32)),"")) -> 0 | M32: =IFERROR(MATCH($C$5&"|"&RIGHT("000000"&16,6),CalcRankKeyA,0),"") -> 20 | N32: =IFERROR(MATCH($C$5&"|"&RIGHT("000000"&16,6),CalcRankKeyB,0),"")
A33: 17 | B33: =IF(AND($M33="",$N33=""),"",IF($M33<>"",INDEX(CalcDateA,$M33),INDEX(CalcDateB,$N33))) -> 1405/07/20 | C33: =IF($M33<>"","خرید سبد",IF($N33<>"",IF(N(INDEX(CalcDepB,$N33))>0,"دریافت بانکی","پرداخت بانکی"),"")) -> خرید سبد | D33: =IF($M33<>"",IF(INDEX(CalcDocA,$M33)="","—",INDEX(CalcDocA,$M33)),IF($N33<>"",INDEX(CalcBankB,$N33),"")) -> 0 | E33: =IF($N33<>"",IF(INDEX(CalcDepB,$N33)=0,"",INDEX(CalcDepB,$N33)),"") | F33: =IF($M33<>"",IF(INDEX(CalcQtyA,$M33)=0,"",INDEX(CalcQtyA,$M33)),"") -> 1000 | G33: =IF($M33<>"",IF(INDEX(CalcPriceA,$M33)=0,"",INDEX(CalcPriceA,$M33)),"") -> 16000 | H33: =IF($N33<>"",IF(INDEX(CalcWitB,$N33)=0,"",INDEX(CalcWitB,$N33)),"") | I33: =IF($M33<>"",INDEX(CalcAmtA,$M33),"") -> 16000000 | J33: =IF($B33="","",IF($J32="",$C$8,$J32)+IF($I33="",0,$I33)+IF($E33="",0,$E33)-IF($H33="",0,$H33)) -> #REF! | K33: =IF($M33<>"",IF(INDEX(CalcNoteA,$M33)="","—",INDEX(CalcNoteA,$M33)),IF($N33<>"",IF(INDEX(CalcNoteB,$N33)="","—",INDEX(CalcNoteB,$N33)),"")) -> 0 | M33: =IFERROR(MATCH($C$5&"|"&RIGHT("000000"&17,6),CalcRankKeyA,0),"") -> 21 | N33: =IFERROR(MATCH($C$5&"|"&RIGHT("000000"&17,6),CalcRankKeyB,0),"")
A34: 18 | B34: =IF(AND($M34="",$N34=""),"",IF($M34<>"",INDEX(CalcDateA,$M34),INDEX(CalcDateB,$N34))) -> 1405/07/23 | C34: =IF($M34<>"","خرید سبد",IF($N34<>"",IF(N(INDEX(CalcDepB,$N34))>0,"دریافت بانکی","پرداخت بانکی"),"")) -> خرید سبد | D34: =IF($M34<>"",IF(INDEX(CalcDocA,$M34)="","—",INDEX(CalcDocA,$M34)),IF($N34<>"",INDEX(CalcBankB,$N34),"")) -> 0 | E34: =IF($N34<>"",IF(INDEX(CalcDepB,$N34)=0,"",INDEX(CalcDepB,$N34)),"") | F34: =IF($M34<>"",IF(INDEX(CalcQtyA,$M34)=0,"",INDEX(CalcQtyA,$M34)),"") -> 565 | G34: =IF($M34<>"",IF(INDEX(CalcPriceA,$M34)=0,"",INDEX(CalcPriceA,$M34)),"") -> 45000 | H34: =IF($N34<>"",IF(INDEX(CalcWitB,$N34)=0,"",INDEX(CalcWitB,$N34)),"") | I34: =IF($M34<>"",INDEX(CalcAmtA,$M34),"") -> 25425000 | J34: =IF($B34="","",IF($J33="",$C$8,$J33)+IF($I34="",0,$I34)+IF($E34="",0,$E34)-IF($H34="",0,$H34)) -> #REF! | K34: =IF($M34<>"",IF(INDEX(CalcNoteA,$M34)="","—",INDEX(CalcNoteA,$M34)),IF($N34<>"",IF(INDEX(CalcNoteB,$N34)="","—",INDEX(CalcNoteB,$N34)),"")) -> 0 | M34: =IFERROR(MATCH($C$5&"|"&RIGHT("000000"&18,6),CalcRankKeyA,0),"") -> 22 | N34: =IFERROR(MATCH($C$5&"|"&RIGHT("000000"&18,6),CalcRankKeyB,0),"")
A35: 19 | B35: =IF(AND($M35="",$N35=""),"",IF($M35<>"",INDEX(CalcDateA,$M35),INDEX(CalcDateB,$N35))) -> 1405/07/24 | C35: =IF($M35<>"","خرید سبد",IF($N35<>"",IF(N(INDEX(CalcDepB,$N35))>0,"دریافت بانکی","پرداخت بانکی"),"")) -> خرید سبد | D35: =IF($M35<>"",IF(INDEX(CalcDocA,$M35)="","—",INDEX(CalcDocA,$M35)),IF($N35<>"",INDEX(CalcBankB,$N35),"")) -> 0 | E35: =IF($N35<>"",IF(INDEX(CalcDepB,$N35)=0,"",INDEX(CalcDepB,$N35)),"") | F35: =IF($M35<>"",IF(INDEX(CalcQtyA,$M35)=0,"",INDEX(CalcQtyA,$M35)),"") -> 805 | G35: =IF($M35<>"",IF(INDEX(CalcPriceA,$M35)=0,"",INDEX(CalcPriceA,$M35)),"") -> 45000 | H35: =IF($N35<>"",IF(INDEX(CalcWitB,$N35)=0,"",INDEX(CalcWitB,$N35)),"") | I35: =IF($M35<>"",INDEX(CalcAmtA,$M35),"") -> 36225000 | J35: =IF($B35="","",IF($J34="",$C$8,$J34)+IF($I35="",0,$I35)+IF($E35="",0,$E35)-IF($H35="",0,$H35)) -> #REF! | K35: =IF($M35<>"",IF(INDEX(CalcNoteA,$M35)="","—",INDEX(CalcNoteA,$M35)),IF($N35<>"",IF(INDEX(CalcNoteB,$N35)="","—",INDEX(CalcNoteB,$N35)),"")) -> 0 | M35: =IFERROR(MATCH($C$5&"|"&RIGHT("000000"&19,6),CalcRankKeyA,0),"") -> 23 | N35: =IFERROR(MATCH($C$5&"|"&RIGHT("000000"&19,6),CalcRankKeyB,0),"")
A36: 20 | B36: =IF(AND($M36="",$N36=""),"",IF($M36<>"",INDEX(CalcDateA,$M36),INDEX(CalcDateB,$N36))) -> 1405/07/25 | C36: =IF($M36<>"","خرید سبد",IF($N36<>"",IF(N(INDEX(CalcDepB,$N36))>0,"دریافت بانکی","پرداخت بانکی"),"")) -> خرید سبد | D36: =IF($M36<>"",IF(INDEX(CalcDocA,$M36)="","—",INDEX(CalcDocA,$M36)),IF($N36<>"",INDEX(CalcBankB,$N36),"")) -> 0 | E36: =IF($N36<>"",IF(INDEX(CalcDepB,$N36)=0,"",INDEX(CalcDepB,$N36)),"") | F36: =IF($M36<>"",IF(INDEX(CalcQtyA,$M36)=0,"",INDEX(CalcQtyA,$M36)),"") -> 1420 | G36: =IF($M36<>"",IF(INDEX(CalcPriceA,$M36)=0,"",INDEX(CalcPriceA,$M36)),"") -> 16000 | H36: =IF($N36<>"",IF(INDEX(CalcWitB,$N36)=0,"",INDEX(CalcWitB,$N36)),"") | I36: =IF($M36<>"",INDEX(CalcAmtA,$M36),"") -> 22720000 | J36: =IF($B36="","",IF($J35="",$C$8,$J35)+IF($I36="",0,$I36)+IF($E36="",0,$E36)-IF($H36="",0,$H36)) -> #REF! | K36: =IF($M36<>"",IF(INDEX(CalcNoteA,$M36)="","—",INDEX(CalcNoteA,$M36)),IF($N36<>"",IF(INDEX(CalcNoteB,$N36)="","—",INDEX(CalcNoteB,$N36)),"")) -> 0 | M36: =IFERROR(MATCH($C$5&"|"&RIGHT("000000"&20,6),CalcRankKeyA,0),"") -> 30 | N36: =IFERROR(MATCH($C$5&"|"&RIGHT("000000"&20,6),CalcRankKeyB,0),"")
A37: 21 | B37: =IF(AND($M37="",$N37=""),"",IF($M37<>"",INDEX(CalcDateA,$M37),INDEX(CalcDateB,$N37))) -> 1405/07/25 | C37: =IF($M37<>"","خرید سبد",IF($N37<>"",IF(N(INDEX(CalcDepB,$N37))>0,"دریافت بانکی","پرداخت بانکی"),"")) -> خرید سبد | D37: =IF($M37<>"",IF(INDEX(CalcDocA,$M37)="","—",INDEX(CalcDocA,$M37)),IF($N37<>"",INDEX(CalcBankB,$N37),"")) -> 0 | E37: =IF($N37<>"",IF(INDEX(CalcDepB,$N37)=0,"",INDEX(CalcDepB,$N37)),"") | F37: =IF($M37<>"",IF(INDEX(CalcQtyA,$M37)=0,"",INDEX(CalcQtyA,$M37)),"") -> 704 | G37: =IF($M37<>"",IF(INDEX(CalcPriceA,$M37)=0,"",INDEX(CalcPriceA,$M37)),"") -> 15000 | H37: =IF($N37<>"",IF(INDEX(CalcWitB,$N37)=0,"",INDEX(CalcWitB,$N37)),"") | I37: =IF($M37<>"",INDEX(CalcAmtA,$M37),"") -> 10560000 | J37: =IF($B37="","",IF($J36="",$C$8,$J36)+IF($I37="",0,$I37)+IF($E37="",0,$E37)-IF($H37="",0,$H37)) -> #REF! | K37: =IF($M37<>"",IF(INDEX(CalcNoteA,$M37)="","—",INDEX(CalcNoteA,$M37)),IF($N37<>"",IF(INDEX(CalcNoteB,$N37)="","—",INDEX(CalcNoteB,$N37)),"")) -> 0 | M37: =IFERROR(MATCH($C$5&"|"&RIGHT("000000"&21,6),CalcRankKeyA,0),"") -> 31 | N37: =IFERROR(MATCH($C$5&"|"&RIGHT("000000"&21,6),CalcRankKeyB,0),"")
A38: 22 | B38: =IF(AND($M38="",$N38=""),"",IF($M38<>"",INDEX(CalcDateA,$M38),INDEX(CalcDateB,$N38))) -> 1405/07/26 | C38: =IF($M38<>"","خرید سبد",IF($N38<>"",IF(N(INDEX(CalcDepB,$N38))>0,"دریافت بانکی","پرداخت بانکی"),"")) -> خرید سبد | D38: =IF($M38<>"",IF(INDEX(CalcDocA,$M38)="","—",INDEX(CalcDocA,$M38)),IF($N38<>"",INDEX(CalcBankB,$N38),"")) -> 0 | E38: =IF($N38<>"",IF(INDEX(CalcDepB,$N38)=0,"",INDEX(CalcDepB,$N38)),"") | F38: =IF($M38<>"",IF(INDEX(CalcQtyA,$M38)=0,"",INDEX(CalcQtyA,$M38)),"") -> 2300 | G38: =IF($M38<>"",IF(INDEX(CalcPriceA,$M38)=0,"",INDEX(CalcPriceA,$M38)),"") -> 16000 | H38: =IF($N38<>"",IF(INDEX(CalcWitB,$N38)=0,"",INDEX(CalcWitB,$N38)),"") | I38: =IF($M38<>"",INDEX(CalcAmtA,$M38),"") -> 36800000 | J38: =IF($B38="","",IF($J37="",$C$8,$J37)+IF($I38="",0,$I38)+IF($E38="",0,$E38)-IF($H38="",0,$H38)) -> #REF! | K38: =IF($M38<>"",IF(INDEX(CalcNoteA,$M38)="","—",INDEX(CalcNoteA,$M38)),IF($N38<>"",IF(INDEX(CalcNoteB,$N38)="","—",INDEX(CalcNoteB,$N38)),"")) -> 0 | M38: =IFERROR(MATCH($C$5&"|"&RIGHT("000000"&22,6),CalcRankKeyA,0),"") -> 32 | N38: =IFERROR(MATCH($C$5&"|"&RIGHT("000000"&22,6),CalcRankKeyB,0),"")
A39: 23 | B39: =IF(AND($M39="",$N39=""),"",IF($M39<>"",INDEX(CalcDateA,$M39),INDEX(CalcDateB,$N39))) -> 1405/07/26 | C39: =IF($M39<>"","خرید سبد",IF($N39<>"",IF(N(INDEX(CalcDepB,$N39))>0,"دریافت بانکی","پرداخت بانکی"),"")) -> خرید سبد | D39: =IF($M39<>"",IF(INDEX(CalcDocA,$M39)="","—",INDEX(CalcDocA,$M39)),IF($N39<>"",INDEX(CalcBankB,$N39),"")) -> 0 | E39: =IF($N39<>"",IF(INDEX(CalcDepB,$N39)=0,"",INDEX(CalcDepB,$N39)),"") | F39: =IF($M39<>"",IF(INDEX(CalcQtyA,$M39)=0,"",INDEX(CalcQtyA,$M39)),"") -> 420 | G39: =IF($M39<>"",IF(INDEX(CalcPriceA,$M39)=0,"",INDEX(CalcPriceA,$M39)),"") -> 25000 | H39: =IF($N39<>"",IF(INDEX(CalcWitB,$N39)=0,"",INDEX(CalcWitB,$N39)),"") | I39: =IF($M39<>"",INDEX(CalcAmtA,$M39),"") -> 10500000 | J39: =IF($B39="","",IF($J38="",$C$8,$J38)+IF($I39="",0,$I39)+IF($E39="",0,$E39)-IF($H39="",0,$H39)) -> #REF! | K39: =IF($M39<>"",IF(INDEX(CalcNoteA,$M39)="","—",INDEX(CalcNoteA,$M39)),IF($N39<>"",IF(INDEX(CalcNoteB,$N39)="","—",INDEX(CalcNoteB,$N39)),"")) -> 0 | M39: =IFERROR(MATCH($C$5&"|"&RIGHT("000000"&23,6),CalcRankKeyA,0),"") -> 33 | N39: =IFERROR(MATCH($C$5&"|"&RIGHT("000000"&23,6),CalcRankKeyB,0),"")
A40: 24 | B40: =IF(AND($M40="",$N40=""),"",IF($M40<>"",INDEX(CalcDateA,$M40),INDEX(CalcDateB,$N40))) -> 1405/07/28 | C40: =IF($M40<>"","خرید سبد",IF($N40<>"",IF(N(INDEX(CalcDepB,$N40))>0,"دریافت بانکی","پرداخت بانکی"),"")) -> خرید سبد | D40: =IF($M40<>"",IF(INDEX(CalcDocA,$M40)="","—",INDEX(CalcDocA,$M40)),IF($N40<>"",INDEX(CalcBankB,$N40),"")) -> 0 | E40: =IF($N40<>"",IF(INDEX(CalcDepB,$N40)=0,"",INDEX(CalcDepB,$N40)),"") | F40: =IF($M40<>"",IF(INDEX(CalcQtyA,$M40)=0,"",INDEX(CalcQtyA,$M40)),"") -> 400 | G40: =IF($M40<>"",IF(INDEX(CalcPriceA,$M40)=0,"",INDEX(CalcPriceA,$M40)),"") -> 5000 | H40: =IF($N40<>"",IF(INDEX(CalcWitB,$N40)=0,"",INDEX(CalcWitB,$N40)),"") | I40: =IF($M40<>"",INDEX(CalcAmtA,$M40),"") -> 2000000 | J40: =IF($B40="","",IF($J39="",$C$8,$J39)+IF($I40="",0,$I40)+IF($E40="",0,$E40)-IF($H40="",0,$H40)) -> #REF! | K40: =IF($M40<>"",IF(INDEX(CalcNoteA,$M40)="","—",INDEX(CalcNoteA,$M40)),IF($N40<>"",IF(INDEX(CalcNoteB,$N40)="","—",INDEX(CalcNoteB,$N40)),"")) -> 0 | M40: =IFERROR(MATCH($C$5&"|"&RIGHT("000000"&24,6),CalcRankKeyA,0),"") -> 34 | N40: =IFERROR(MATCH($C$5&"|"&RIGHT("000000"&24,6),CalcRankKeyB,0),"")
A41: 25 | B41: =IF(AND($M41="",$N41=""),"",IF($M41<>"",INDEX(CalcDateA,$M41),INDEX(CalcDateB,$N41))) -> 1405/07/28 | C41: =IF($M41<>"","خرید سبد",IF($N41<>"",IF(N(INDEX(CalcDepB,$N41))>0,"دریافت بانکی","پرداخت بانکی"),"")) -> خرید سبد | D41: =IF($M41<>"",IF(INDEX(CalcDocA,$M41)="","—",INDEX(CalcDocA,$M41)),IF($N41<>"",INDEX(CalcBankB,$N41),"")) -> 0 | E41: =IF($N41<>"",IF(INDEX(CalcDepB,$N41)=0,"",INDEX(CalcDepB,$N41)),"") | F41: =IF($M41<>"",IF(INDEX(CalcQtyA,$M41)=0,"",INDEX(CalcQtyA,$M41)),"") -> 1200 | G41: =IF($M41<>"",IF(INDEX(CalcPriceA,$M41)=0,"",INDEX(CalcPriceA,$M41)),"") -> 5000 | H41: =IF($N41<>"",IF(INDEX(CalcWitB,$N41)=0,"",INDEX(CalcWitB,$N41)),"") | I41: =IF($M41<>"",INDEX(CalcAmtA,$M41),"") -> 6000000 | J41: =IF($B41="","",IF($J40="",$C$8,$J40)+IF($I41="",0,$I41)+IF($E41="",0,$E41)-IF($H41="",0,$H41)) -> #REF! | K41: =IF($M41<>"",IF(INDEX(CalcNoteA,$M41)="","—",INDEX(CalcNoteA,$M41)),IF($N41<>"",IF(INDEX(CalcNoteB,$N41)="","—",INDEX(CalcNoteB,$N41)),"")) -> 0 | M41: =IFERROR(MATCH($C$5&"|"&RIGHT("000000"&25,6),CalcRankKeyA,0),"") -> 36 | N41: =IFERROR(MATCH($C$5&"|"&RIGHT("000000"&25,6),CalcRankKeyB,0),"")
A42: 26 | B42: =IF(AND($M42="",$N42=""),"",IF($M42<>"",INDEX(CalcDateA,$M42),INDEX(CalcDateB,$N42))) -> 1405/07/28 | C42: =IF($M42<>"","خرید سبد",IF($N42<>"",IF(N(INDEX(CalcDepB,$N42))>0,"دریافت بانکی","پرداخت بانکی"),"")) -> خرید سبد | D42: =IF($M42<>"",IF(INDEX(CalcDocA,$M42)="","—",INDEX(CalcDocA,$M42)),IF($N42<>"",INDEX(CalcBankB,$N42),"")) -> 0 | E42: =IF($N42<>"",IF(INDEX(CalcDepB,$N42)=0,"",INDEX(CalcDepB,$N42)),"") | F42: =IF($M42<>"",IF(INDEX(CalcQtyA,$M42)=0,"",INDEX(CalcQtyA,$M42)),"") -> 847 | G42: =IF($M42<>"",IF(INDEX(CalcPriceA,$M42)=0,"",INDEX(CalcPriceA,$M42)),"") -> 47000 | H42: =IF($N42<>"",IF(INDEX(CalcWitB,$N42)=0,"",INDEX(CalcWitB,$N42)),"") | I42: =IF($M42<>"",INDEX(CalcAmtA,$M42),"") -> 39809000 | J42: =IF($B42="","",IF($J41="",$C$8,$J41)+IF($I42="",0,$I42)+IF($E42="",0,$E42)-IF($H42="",0,$H42)) -> #REF! | K42: =IF($M42<>"",IF(INDEX(CalcNoteA,$M42)="","—",INDEX(CalcNoteA,$M42)),IF($N42<>"",IF(INDEX(CalcNoteB,$N42)="","—",INDEX(CalcNoteB,$N42)),"")) -> 0 | M42: =IFERROR(MATCH($C$5&"|"&RIGHT("000000"&26,6),CalcRankKeyA,0),"") -> 37 | N42: =IFERROR(MATCH($C$5&"|"&RIGHT("000000"&26,6),CalcRankKeyB,0),"")
A43: 27 | B43: =IF(AND($M43="",$N43=""),"",IF($M43<>"",INDEX(CalcDateA,$M43),INDEX(CalcDateB,$N43))) -> 1405/07/29 | C43: =IF($M43<>"","خرید سبد",IF($N43<>"",IF(N(INDEX(CalcDepB,$N43))>0,"دریافت بانکی","پرداخت بانکی"),"")) -> خرید سبد | D43: =IF($M43<>"",IF(INDEX(CalcDocA,$M43)="","—",INDEX(CalcDocA,$M43)),IF($N43<>"",INDEX(CalcBankB,$N43),"")) -> 0 | E43: =IF($N43<>"",IF(INDEX(CalcDepB,$N43)=0,"",INDEX(CalcDepB,$N43)),"") | F43: =IF($M43<>"",IF(INDEX(CalcQtyA,$M43)=0,"",INDEX(CalcQtyA,$M43)),"") -> 1190 | G43: =IF($M43<>"",IF(INDEX(CalcPriceA,$M43)=0,"",INDEX(CalcPriceA,$M43)),"") -> 25000 | H43: =IF($N43<>"",IF(INDEX(CalcWitB,$N43)=0,"",INDEX(CalcWitB,$N43)),"") | I43: =IF($M43<>"",INDEX(CalcAmtA,$M43),"") -> 29750000 | J43: =IF($B43="","",IF($J42="",$C$8,$J42)+IF($I43="",0,$I43)+IF($E43="",0,$E43)-IF($H43="",0,$H43)) -> #REF! | K43: =IF($M43<>"",IF(INDEX(CalcNoteA,$M43)="","—",INDEX(CalcNoteA,$M43)),IF($N43<>"",IF(INDEX(CalcNoteB,$N43)="","—",INDEX(CalcNoteB,$N43)),"")) -> 0 | M43: =IFERROR(MATCH($C$5&"|"&RIGHT("000000"&27,6),CalcRankKeyA,0),"") -> 35 | N43: =IFERROR(MATCH($C$5&"|"&RIGHT("000000"&27,6),CalcRankKeyB,0),"")
...

Sheet Summary
A1: =IF(Sync!$N$6="","مازندشت",Sync!$N$6)&" — "&IF(Sync!$N$9="","سورتینگ و بسته‌بندی مرکبات",Sync!$N$9) -> 250000000 — 90000000
A2: =IF(Sync!$N$7="","باغدشت، بخش مرکزی، شهرستان قائم‌شهر، استان مازندران، ایران",Sync!$N$7)&" | MAZANDASHT · CITRUS SORTING & PACKING" -> باغدشت، بخش مرکزی، شهرستان قائم‌شهر، استان مازندران، ایران | MAZANDASHT · CITRUS SORTING & PACKING
A3: خلاصه دفتر سبد — همه فروشندگان و انواع سبد
A4: جدول بالا: گردش هر فروشنده سبد (از Entry و پرداخت‌های Transactions) — جدول پایین: جمع خرید به تفکیک نوع سبد. همه‌چیز خودکار.
A5: جمع کل خرید سبد (ریال) | C5: جمع پرداخت به فروشندگان (ریال) | E5: مانده کل (بدهی ما) | G5: تعداد فروشندگان سبد
A6: =SUM(CalcAmtA) -> #REF! | C6: =SUMPRODUCT(SUMIF(CalcPartyB,PkBskParty,CalcWitB)) -> 179500000 | E6: =SUM(CalcAmtA)-SUMPRODUCT(SUMIF(CalcPartyB,PkBskParty,CalcWitB))+SUMPRODUCT(SUMIF(CalcPartyB,PkBskParty,CalcDepB)) -> #REF! | G6: =NBskParty -> 3
A8: الف) گردش فروشندگان سبد
A9: ردیف | B9: کد | C9: نام فروشنده | D9: تعداد سبد | E9: جمع خرید (ریال) | F9: جمع پرداخت (ریال) | G9: جمع دریافت (ریال) | H9: مانده (ریال) | I9: وضعیت
A10: =IF($B10="","",1) -> 1 | B10: =IF(1>NBskParty,"",INDEX(PkBskParty,1)) -> S001 | C10: =IF($B10="","",IFERROR(IF(VLOOKUP($B10,AcctTbl,4,0)="","(بدون نام)",VLOOKUP($B10,AcctTbl,4,0)),"—")) -> حسن کوچکزاده | D10: =IF($B10="","",SUMIF(CalcPartyA,$B10,CalcQtyA)) -> #REF! | E10: =IF($B10="","",SUMIF(CalcPartyA,$B10,CalcAmtA)) -> #REF! | F10: =IF($B10="","",SUMIF(CalcPartyB,$B10,CalcWitB)) -> 95000000 | G10: =IF($B10="","",SUMIF(CalcPartyB,$B10,CalcDepB)) -> 0 | H10: =IF($B10="","",$E10-$F10+$G10) -> #REF! | I10: =IF($B10="","",IF(ROUND($H10,0)>0,"● بستانکار",IF(ROUND($H10,0)<0,"● بدهکار","تسویه"))) -> #REF!
A11: =IF($B11="","",2) -> 2 | B11: =IF(2>NBskParty,"",INDEX(PkBskParty,2)) -> S002 | C11: =IF($B11="","",IFERROR(IF(VLOOKUP($B11,AcctTbl,4,0)="","(بدون نام)",VLOOKUP($B11,AcctTbl,4,0)),"—")) -> سید محمد موسویان | D11: =IF($B11="","",SUMIF(CalcPartyA,$B11,CalcQtyA)) -> 7473 | E11: =IF($B11="","",SUMIF(CalcPartyA,$B11,CalcAmtA)) -> 202765000 | F11: =IF($B11="","",SUMIF(CalcPartyB,$B11,CalcWitB)) -> 84500000 | G11: =IF($B11="","",SUMIF(CalcPartyB,$B11,CalcDepB)) -> 0 | H11: =IF($B11="","",$E11-$F11+$G11) -> 118265000 | I11: =IF($B11="","",IF(ROUND($H11,0)>0,"● بستانکار",IF(ROUND($H11,0)<0,"● بدهکار","تسویه"))) -> ● بستانکار
A12: =IF($B12="","",3) -> 3 | B12: =IF(3>NBskParty,"",INDEX(PkBskParty,3)) -> S003 | C12: =IF($B12="","",IFERROR(IF(VLOOKUP($B12,AcctTbl,4,0)="","(بدون نام)",VLOOKUP($B12,AcctTbl,4,0)),"—")) -> سید ربیع موسویان | D12: =IF($B12="","",SUMIF(CalcPartyA,$B12,CalcQtyA)) -> 2891 | E12: =IF($B12="","",SUMIF(CalcPartyA,$B12,CalcAmtA)) -> 127197000 | F12: =IF($B12="","",SUMIF(CalcPartyB,$B12,CalcWitB)) -> 0 | G12: =IF($B12="","",SUMIF(CalcPartyB,$B12,CalcDepB)) -> 0 | H12: =IF($B12="","",$E12-$F12+$G12) -> 127197000 | I12: =IF($B12="","",IF(ROUND($H12,0)>0,"● بستانکار",IF(ROUND($H12,0)<0,"● بدهکار","تسویه"))) -> ● بستانکار
A13: =IF($B13="","",4) | B13: =IF(4>NBskParty,"",INDEX(PkBskParty,4)) | C13: =IF($B13="","",IFERROR(IF(VLOOKUP($B13,AcctTbl,4,0)="","(بدون نام)",VLOOKUP($B13,AcctTbl,4,0)),"—")) | D13: =IF($B13="","",SUMIF(CalcPartyA,$B13,CalcQtyA)) | E13: =IF($B13="","",SUMIF(CalcPartyA,$B13,CalcAmtA)) | F13: =IF($B13="","",SUMIF(CalcPartyB,$B13,CalcWitB)) | G13: =IF($B13="","",SUMIF(CalcPartyB,$B13,CalcDepB)) | H13: =IF($B13="","",$E13-$F13+$G13) | I13: =IF($B13="","",IF(ROUND($H13,0)>0,"● بستانکار",IF(ROUND($H13,0)<0,"● بدهکار","تسویه")))
A14: =IF($B14="","",5) | B14: =IF(5>NBskParty,"",INDEX(PkBskParty,5)) | C14: =IF($B14="","",IFERROR(IF(VLOOKUP($B14,AcctTbl,4,0)="","(بدون نام)",VLOOKUP($B14,AcctTbl,4,0)),"—")) | D14: =IF($B14="","",SUMIF(CalcPartyA,$B14,CalcQtyA)) | E14: =IF($B14="","",SUMIF(CalcPartyA,$B14,CalcAmtA)) | F14: =IF($B14="","",SUMIF(CalcPartyB,$B14,CalcWitB)) | G14: =IF($B14="","",SUMIF(CalcPartyB,$B14,CalcDepB)) | H14: =IF($B14="","",$E14-$F14+$G14) | I14: =IF($B14="","",IF(ROUND($H14,0)>0,"● بستانکار",IF(ROUND($H14,0)<0,"● بدهکار","تسویه")))
A15: =IF($B15="","",6) | B15: =IF(6>NBskParty,"",INDEX(PkBskParty,6)) | C15: =IF($B15="","",IFERROR(IF(VLOOKUP($B15,AcctTbl,4,0)="","(بدون نام)",VLOOKUP($B15,AcctTbl,4,0)),"—")) | D15: =IF($B15="","",SUMIF(CalcPartyA,$B15,CalcQtyA)) | E15: =IF($B15="","",SUMIF(CalcPartyA,$B15,CalcAmtA)) | F15: =IF($B15="","",SUMIF(CalcPartyB,$B15,CalcWitB)) | G15: =IF($B15="","",SUMIF(CalcPartyB,$B15,CalcDepB)) | H15: =IF($B15="","",$E15-$F15+$G15) | I15: =IF($B15="","",IF(ROUND($H15,0)>0,"● بستانکار",IF(ROUND($H15,0)<0,"● بدهکار","تسویه")))
A16: =IF($B16="","",7) | B16: =IF(7>NBskParty,"",INDEX(PkBskParty,7)) | C16: =IF($B16="","",IFERROR(IF(VLOOKUP($B16,AcctTbl,4,0)="","(بدون نام)",VLOOKUP($B16,AcctTbl,4,0)),"—")) | D16: =IF($B16="","",SUMIF(CalcPartyA,$B16,CalcQtyA)) | E16: =IF($B16="","",SUMIF(CalcPartyA,$B16,CalcAmtA)) | F16: =IF($B16="","",SUMIF(CalcPartyB,$B16,CalcWitB)) | G16: =IF($B16="","",SUMIF(CalcPartyB,$B16,CalcDepB)) | H16: =IF($B16="","",$E16-$F16+$G16) | I16: =IF($B16="","",IF(ROUND($H16,0)>0,"● بستانکار",IF(ROUND($H16,0)<0,"● بدهکار","تسویه")))
A17: =IF($B17="","",8) | B17: =IF(8>NBskParty,"",INDEX(PkBskParty,8)) | C17: =IF($B17="","",IFERROR(IF(VLOOKUP($B17,AcctTbl,4,0)="","(بدون نام)",VLOOKUP($B17,AcctTbl,4,0)),"—")) | D17: =IF($B17="","",SUMIF(CalcPartyA,$B17,CalcQtyA)) | E17: =IF($B17="","",SUMIF(CalcPartyA,$B17,CalcAmtA)) | F17: =IF($B17="","",SUMIF(CalcPartyB,$B17,CalcWitB)) | G17: =IF($B17="","",SUMIF(CalcPartyB,$B17,CalcDepB)) | H17: =IF($B17="","",$E17-$F17+$G17) | I17: =IF($B17="","",IF(ROUND($H17,0)>0,"● بستانکار",IF(ROUND($H17,0)<0,"● بدهکار","تسویه")))
A18: =IF($B18="","",9) | B18: =IF(9>NBskParty,"",INDEX(PkBskParty,9)) | C18: =IF($B18="","",IFERROR(IF(VLOOKUP($B18,AcctTbl,4,0)="","(بدون نام)",VLOOKUP($B18,AcctTbl,4,0)),"—")) | D18: =IF($B18="","",SUMIF(CalcPartyA,$B18,CalcQtyA)) | E18: =IF($B18="","",SUMIF(CalcPartyA,$B18,CalcAmtA)) | F18: =IF($B18="","",SUMIF(CalcPartyB,$B18,CalcWitB)) | G18: =IF($B18="","",SUMIF(CalcPartyB,$B18,CalcDepB)) | H18: =IF($B18="","",$E18-$F18+$G18) | I18: =IF($B18="","",IF(ROUND($H18,0)>0,"● بستانکار",IF(ROUND($H18,0)<0,"● بدهکار","تسویه")))
A19: =IF($B19="","",10) | B19: =IF(10>NBskParty,"",INDEX(PkBskParty,10)) | C19: =IF($B19="","",IFERROR(IF(VLOOKUP($B19,AcctTbl,4,0)="","(بدون نام)",VLOOKUP($B19,AcctTbl,4,0)),"—")) | D19: =IF($B19="","",SUMIF(CalcPartyA,$B19,CalcQtyA)) | E19: =IF($B19="","",SUMIF(CalcPartyA,$B19,CalcAmtA)) | F19: =IF($B19="","",SUMIF(CalcPartyB,$B19,CalcWitB)) | G19: =IF($B19="","",SUMIF(CalcPartyB,$B19,CalcDepB)) | H19: =IF($B19="","",$E19-$F19+$G19) | I19: =IF($B19="","",IF(ROUND($H19,0)>0,"● بستانکار",IF(ROUND($H19,0)<0,"● بدهکار","تسویه")))
A20: =IF($B20="","",11) | B20: =IF(11>NBskParty,"",INDEX(PkBskParty,11)) | C20: =IF($B20="","",IFERROR(IF(VLOOKUP($B20,AcctTbl,4,0)="","(بدون نام)",VLOOKUP($B20,AcctTbl,4,0)),"—")) | D20: =IF($B20="","",SUMIF(CalcPartyA,$B20,CalcQtyA)) | E20: =IF($B20="","",SUMIF(CalcPartyA,$B20,CalcAmtA)) | F20: =IF($B20="","",SUMIF(CalcPartyB,$B20,CalcWitB)) | G20: =IF($B20="","",SUMIF(CalcPartyB,$B20,CalcDepB)) | H20: =IF($B20="","",$E20-$F20+$G20) | I20: =IF($B20="","",IF(ROUND($H20,0)>0,"● بستانکار",IF(ROUND($H20,0)<0,"● بدهکار","تسویه")))
A21: =IF($B21="","",12) | B21: =IF(12>NBskParty,"",INDEX(PkBskParty,12)) | C21: =IF($B21="","",IFERROR(IF(VLOOKUP($B21,AcctTbl,4,0)="","(بدون نام)",VLOOKUP($B21,AcctTbl,4,0)),"—")) | D21: =IF($B21="","",SUMIF(CalcPartyA,$B21,CalcQtyA)) | E21: =IF($B21="","",SUMIF(CalcPartyA,$B21,CalcAmtA)) | F21: =IF($B21="","",SUMIF(CalcPartyB,$B21,CalcWitB)) | G21: =IF($B21="","",SUMIF(CalcPartyB,$B21,CalcDepB)) | H21: =IF($B21="","",$E21-$F21+$G21) | I21: =IF($B21="","",IF(ROUND($H21,0)>0,"● بستانکار",IF(ROUND($H21,0)<0,"● بدهکار","تسویه")))
A22: =IF($B22="","",13) | B22: =IF(13>NBskParty,"",INDEX(PkBskParty,13)) | C22: =IF($B22="","",IFERROR(IF(VLOOKUP($B22,AcctTbl,4,0)="","(بدون نام)",VLOOKUP($B22,AcctTbl,4,0)),"—")) | D22: =IF($B22="","",SUMIF(CalcPartyA,$B22,CalcQtyA)) | E22: =IF($B22="","",SUMIF(CalcPartyA,$B22,CalcAmtA)) | F22: =IF($B22="","",SUMIF(CalcPartyB,$B22,CalcWitB)) | G22: =IF($B22="","",SUMIF(CalcPartyB,$B22,CalcDepB)) | H22: =IF($B22="","",$E22-$F22+$G22) | I22: =IF($B22="","",IF(ROUND($H22,0)>0,"● بستانکار",IF(ROUND($H22,0)<0,"● بدهکار","تسویه")))
A23: =IF($B23="","",14) | B23: =IF(14>NBskParty,"",INDEX(PkBskParty,14)) | C23: =IF($B23="","",IFERROR(IF(VLOOKUP($B23,AcctTbl,4,0)="","(بدون نام)",VLOOKUP($B23,AcctTbl,4,0)),"—")) | D23: =IF($B23="","",SUMIF(CalcPartyA,$B23,CalcQtyA)) | E23: =IF($B23="","",SUMIF(CalcPartyA,$B23,CalcAmtA)) | F23: =IF($B23="","",SUMIF(CalcPartyB,$B23,CalcWitB)) | G23: =IF($B23="","",SUMIF(CalcPartyB,$B23,CalcDepB)) | H23: =IF($B23="","",$E23-$F23+$G23) | I23: =IF($B23="","",IF(ROUND($H23,0)>0,"● بستانکار",IF(ROUND($H23,0)<0,"● بدهکار","تسویه")))
A24: =IF($B24="","",15) | B24: =IF(15>NBskParty,"",INDEX(PkBskParty,15)) | C24: =IF($B24="","",IFERROR(IF(VLOOKUP($B24,AcctTbl,4,0)="","(بدون نام)",VLOOKUP($B24,AcctTbl,4,0)),"—")) | D24: =IF($B24="","",SUMIF(CalcPartyA,$B24,CalcQtyA)) | E24: =IF($B24="","",SUMIF(CalcPartyA,$B24,CalcAmtA)) | F24: =IF($B24="","",SUMIF(CalcPartyB,$B24,CalcWitB)) | G24: =IF($B24="","",SUMIF(CalcPartyB,$B24,CalcDepB)) | H24: =IF($B24="","",$E24-$F24+$G24) | I24: =IF($B24="","",IF(ROUND($H24,0)>0,"● بستانکار",IF(ROUND($H24,0)<0,"● بدهکار","تسویه")))
A25: =IF($B25="","",16) | B25: =IF(16>NBskParty,"",INDEX(PkBskParty,16)) | C25: =IF($B25="","",IFERROR(IF(VLOOKUP($B25,AcctTbl,4,0)="","(بدون نام)",VLOOKUP($B25,AcctTbl,4,0)),"—")) | D25: =IF($B25="","",SUMIF(CalcPartyA,$B25,CalcQtyA)) | E25: =IF($B25="","",SUMIF(CalcPartyA,$B25,CalcAmtA)) | F25: =IF($B25="","",SUMIF(CalcPartyB,$B25,CalcWitB)) | G25: =IF($B25="","",SUMIF(CalcPartyB,$B25,CalcDepB)) | H25: =IF($B25="","",$E25-$F25+$G25) | I25: =IF($B25="","",IF(ROUND($H25,0)>0,"● بستانکار",IF(ROUND($H25,0)<0,"● بدهکار","تسویه")))
A26: =IF($B26="","",17) | B26: =IF(17>NBskParty,"",INDEX(PkBskParty,17)) | C26: =IF($B26="","",IFERROR(IF(VLOOKUP($B26,AcctTbl,4,0)="","(بدون نام)",VLOOKUP($B26,AcctTbl,4,0)),"—")) | D26: =IF($B26="","",SUMIF(CalcPartyA,$B26,CalcQtyA)) | E26: =IF($B26="","",SUMIF(CalcPartyA,$B26,CalcAmtA)) | F26: =IF($B26="","",SUMIF(CalcPartyB,$B26,CalcWitB)) | G26: =IF($B26="","",SUMIF(CalcPartyB,$B26,CalcDepB)) | H26: =IF($B26="","",$E26-$F26+$G26) | I26: =IF($B26="","",IF(ROUND($H26,0)>0,"● بستانکار",IF(ROUND($H26,0)<0,"● بدهکار","تسویه")))
A27: =IF($B27="","",18) | B27: =IF(18>NBskParty,"",INDEX(PkBskParty,18)) | C27: =IF($B27="","",IFERROR(IF(VLOOKUP($B27,AcctTbl,4,0)="","(بدون نام)",VLOOKUP($B27,AcctTbl,4,0)),"—")) | D27: =IF($B27="","",SUMIF(CalcPartyA,$B27,CalcQtyA)) | E27: =IF($B27="","",SUMIF(CalcPartyA,$B27,CalcAmtA)) | F27: =IF($B27="","",SUMIF(CalcPartyB,$B27,CalcWitB)) | G27: =IF($B27="","",SUMIF(CalcPartyB,$B27,CalcDepB)) | H27: =IF($B27="","",$E27-$F27+$G27) | I27: =IF($B27="","",IF(ROUND($H27,0)>0,"● بستانکار",IF(ROUND($H27,0)<0,"● بدهکار","تسویه")))
A28: =IF($B28="","",19) | B28: =IF(19>NBskParty,"",INDEX(PkBskParty,19)) | C28: =IF($B28="","",IFERROR(IF(VLOOKUP($B28,AcctTbl,4,0)="","(بدون نام)",VLOOKUP($B28,AcctTbl,4,0)),"—")) | D28: =IF($B28="","",SUMIF(CalcPartyA,$B28,CalcQtyA)) | E28: =IF($B28="","",SUMIF(CalcPartyA,$B28,CalcAmtA)) | F28: =IF($B28="","",SUMIF(CalcPartyB,$B28,CalcWitB)) | G28: =IF($B28="","",SUMIF(CalcPartyB,$B28,CalcDepB)) | H28: =IF($B28="","",$E28-$F28+$G28) | I28: =IF($B28="","",IF(ROUND($H28,0)>0,"● بستانکار",IF(ROUND($H28,0)<0,"● بدهکار","تسویه")))
