Workbook
Name WGTbl: Sync!$A$6:$C$35
Name StaffTblE: Sync!$E$6:$I$55
Name StaffGrpE: Sync!$F$6:$F$55
Name AcctTblE: Sync!$K$6:$N$565
Name PkStaffE: Sync!$AC$6:$AC$55
Name NStaffE: Sync!$AB$55
Name ListStaffEmp: OFFSET(Sync!$AC$6,0,0,MAX(COUNTIF(Sync!$AC$6:$AC$55,"?*"),1),1)
Name ListWGEmp: OFFSET(Sync!$AG$6,0,0,MAX(COUNTIF(Sync!$AG$6:$AG$35,"?*"),1),1)
Name WageKind: Wages!$C$9:$C$2008
Name WageIds: Wages!$D$9:$D$2008
Name WageParty: Wages!$E$9:$E$2008
Name WageDates: Wages!$B$9:$B$2008
Name ShareLink: Shares!$B$9:$B$2008
Name ShareMember: Shares!$C$9:$C$2008
Name ShareAmt: Shares!$E$9:$E$2008
Name LdAParty: Ledger!$A$6:$A$2005
Name LdAType: Ledger!$B$6:$B$2005
Name LdADate: Ledger!$F$6:$F$2005
Name LdAKey: Ledger!$G$6:$G$2005
Name LdAKeyM: Ledger!$I$6:$I$2005
Name LdAKeyG: Ledger!$K$6:$K$2005
Name LdAAmt: Ledger!$L$6:$L$2005
Name LdANote: Ledger!$M$6:$M$2005
Name LdAId: Ledger!$N$6:$N$2005
Name LdBMember: Ledger!$P$6:$P$2005
Name LdBId: Ledger!$Q$6:$Q$2005
Name LdBGroup: Ledger!$R$6:$R$2005
Name LdBDate: Ledger!$S$6:$S$2005
Name LdBKey: Ledger!$T$6:$T$2005
Name LdBKeyM: Ledger!$V$6:$V$2005
Name LdBKeyG: Ledger!$X$6:$X$2005
Name LdBAmt: Ledger!$Y$6:$Y$2005
Name LdBNote: Ledger!$Z$6:$Z$2005
Name LdCParty: Ledger!$AE$6:$AE$2005
Name LdCDate: Ledger!$AI$6:$AI$2005
Name LdCBank: Ledger!$AP$6:$AP$2005
Name LdCDep: Ledger!$AN$6:$AN$2005
Name LdCWit: Ledger!$AO$6:$AO$2005
Name LdCNote: Ledger!$AQ$6:$AQ$2005
Name LdCKey: Ledger!$AK$6:$AK$2005
Name LdCKeyM: Ledger!$AM$6:$AM$2005

Sheet Wages
A1: =IF(Sync!$AI$6="","مازندشت",Sync!$AI$6)&" — "&IF(Sync!$AI$9="","سورتینگ و بسته‌بندی مرکبات",Sync!$AI$9)
A2: =IF(Sync!$AI$7="","باغدشت، بخش مرکزی، شهرستان قائم‌شهر، استان مازندران، ایران",Sync!$AI$7)&" | MAZANDASHT · CITRUS SORTING & PACKING"
A3: دفتر دستمزد — ثبت حقوق، مساعده و دستمزد گروهی (تنها محل ثبت دستمزد)
A4: ستون‌های زرد = ورود دستی. «نوع» را انتخاب کنید: دستمزد فردی ← کد کارمند (E…) | دستمزد گروهی ← کد گروه کاری (WG…)؛ سپس «شناسه» یکتا بنویسید (مثل W-201). برای ردیف گروهی، سهم هر عضو را در شیت Shares با همین شناسه وارد کنید — ستون «جمع ریز» و «وضعیت» کنترل می‌کنند که جمع سهم‌ها با مبلغ کل برابر شود (√). پرداخت واقعی پول در Transactions (برداشت با کد کارمند) ثبت می‌شود و در گزارش همین فایل می‌آید.
A5: تعداد رویداد دستمزد | C5: جمع مبالغ (ریال) | E5: جمع ریز گروه‌ها (ریال) | G5: ظرفیت باقی‌مانده | I5: رویدادهای مغایرت
A6: =COUNTA($B$9:$B$2008) | C6: =SUM($G$9:$G$2008) | E6: =SUM($H$9:$H$2008) | G6: =2000-COUNTA($B$9:$B$2008) | I6: =COUNTIF($I$9:$I$2008,"▲*")
A7: ردیف | B7: تاریخ | C7: نوع دستمزد | D7: شناسه | E7: کد طرف | F7: نام / گروه (خودکار) | G7: مبلغ کل (ریال) | H7: جمع ریز سهم‌ها (خودکار) | I7: وضعیت (خودکار) | J7: توضیحات
A8: No. | B8: Date | C8: Kind | D8: Doc ID | E8: Party Code | F8: Name (auto) | G8: Total Amount | H8: Shares Sum (auto) | I8: Status (auto) | J8: Notes
A9: =IF($B9="","",COUNTA($B$9:$B9)) | F9: =IF($E9="","",IF($C9="دستمزد گروهی",IFERROR(VLOOKUP($E9,WGTbl,2,0),"کد ناشناخته"),IFERROR(IF(VLOOKUP($E9,AcctTblE,4,0)="","(بدون نام)",VLOOKUP($E9,AcctTblE,4,0)),"کد ناشناخته"))) | H9: =IF(OR($C9<>"دستمزد گروهی",$D9=""),"",SUMIFS(ShareAmt,ShareLink,$D9)) | I9: =IF($C9<>"دستمزد گروهی","—",IF($H9="","",IF(ROUND($H9-IF($G9="",0,$G9),0)=0,"√","▲ مغایرت "&TEXT(IF($G9="",0,$G9)-$H9,"#,##0"))))
A10: =IF($B10="","",COUNTA($B$9:$B10)) | F10: =IF($E10="","",IF($C10="دستمزد گروهی",IFERROR(VLOOKUP($E10,WGTbl,2,0),"کد ناشناخته"),IFERROR(IF(VLOOKUP($E10,AcctTblE,4,0)="","(بدون نام)",VLOOKUP($E10,AcctTblE,4,0)),"کد ناشناخته"))) | H10: =IF(OR($C10<>"دستمزد گروهی",$D10=""),"",SUMIFS(ShareAmt,ShareLink,$D10)) | I10: =IF($C10<>"دستمزد گروهی","—",IF($H10="","",IF(ROUND($H10-IF($G10="",0,$G10),0)=0,"√","▲ مغایرت "&TEXT(IF($G10="",0,$G10)-$H10,"#,##0"))))
A11: =IF($B11="","",COUNTA($B$9:$B11)) | F11: =IF($E11="","",IF($C11="دستمزد گروهی",IFERROR(VLOOKUP($E11,WGTbl,2,0),"کد ناشناخته"),IFERROR(IF(VLOOKUP($E11,AcctTblE,4,0)="","(بدون نام)",VLOOKUP($E11,AcctTblE,4,0)),"کد ناشناخته"))) | H11: =IF(OR($C11<>"دستمزد گروهی",$D11=""),"",SUMIFS(ShareAmt,ShareLink,$D11)) | I11: =IF($C11<>"دستمزد گروهی","—",IF($H11="","",IF(ROUND($H11-IF($G11="",0,$G11),0)=0,"√","▲ مغایرت "&TEXT(IF($G11="",0,$G11)-$H11,"#,##0"))))
A12: =IF($B12="","",COUNTA($B$9:$B12)) | F12: =IF($E12="","",IF($C12="دستمزد گروهی",IFERROR(VLOOKUP($E12,WGTbl,2,0),"کد ناشناخته"),IFERROR(IF(VLOOKUP($E12,AcctTblE,4,0)="","(بدون نام)",VLOOKUP($E12,AcctTblE,4,0)),"کد ناشناخته"))) | H12: =IF(OR($C12<>"دستمزد گروهی",$D12=""),"",SUMIFS(ShareAmt,ShareLink,$D12)) | I12: =IF($C12<>"دستمزد گروهی","—",IF($H12="","",IF(ROUND($H12-IF($G12="",0,$G12),0)=0,"√","▲ مغایرت "&TEXT(IF($G12="",0,$G12)-$H12,"#,##0"))))
A13: =IF($B13="","",COUNTA($B$9:$B13)) | F13: =IF($E13="","",IF($C13="دستمزد گروهی",IFERROR(VLOOKUP($E13,WGTbl,2,0),"کد ناشناخته"),IFERROR(IF(VLOOKUP($E13,AcctTblE,4,0)="","(بدون نام)",VLOOKUP($E13,AcctTblE,4,0)),"کد ناشناخته"))) | H13: =IF(OR($C13<>"دستمزد گروهی",$D13=""),"",SUMIFS(ShareAmt,ShareLink,$D13)) | I13: =IF($C13<>"دستمزد گروهی","—",IF($H13="","",IF(ROUND($H13-IF($G13="",0,$G13),0)=0,"√","▲ مغایرت "&TEXT(IF($G13="",0,$G13)-$H13,"#,##0"))))
A14: =IF($B14="","",COUNTA($B$9:$B14)) | F14: =IF($E14="","",IF($C14="دستمزد گروهی",IFERROR(VLOOKUP($E14,WGTbl,2,0),"کد ناشناخته"),IFERROR(IF(VLOOKUP($E14,AcctTblE,4,0)="","(بدون نام)",VLOOKUP($E14,AcctTblE,4,0)),"کد ناشناخته"))) | H14: =IF(OR($C14<>"دستمزد گروهی",$D14=""),"",SUMIFS(ShareAmt,ShareLink,$D14)) | I14: =IF($C14<>"دستمزد گروهی","—",IF($H14="","",IF(ROUND($H14-IF($G14="",0,$G14),0)=0,"√","▲ مغایرت "&TEXT(IF($G14="",0,$G14)-$H14,"#,##0"))))
A15: =IF($B15="","",COUNTA($B$9:$B15)) | F15: =IF($E15="","",IF($C15="دستمزد گروهی",IFERROR(VLOOKUP($E15,WGTbl,2,0),"کد ناشناخته"),IFERROR(IF(VLOOKUP($E15,AcctTblE,4,0)="","(بدون نام)",VLOOKUP($E15,AcctTblE,4,0)),"کد ناشناخته"))) | H15: =IF(OR($C15<>"دستمزد گروهی",$D15=""),"",SUMIFS(ShareAmt,ShareLink,$D15)) | I15: =IF($C15<>"دستمزد گروهی","—",IF($H15="","",IF(ROUND($H15-IF($G15="",0,$G15),0)=0,"√","▲ مغایرت "&TEXT(IF($G15="",0,$G15)-$H15,"#,##0"))))
A16: =IF($B16="","",COUNTA($B$9:$B16)) | F16: =IF($E16="","",IF($C16="دستمزد گروهی",IFERROR(VLOOKUP($E16,WGTbl,2,0),"کد ناشناخته"),IFERROR(IF(VLOOKUP($E16,AcctTblE,4,0)="","(بدون نام)",VLOOKUP($E16,AcctTblE,4,0)),"کد ناشناخته"))) | H16: =IF(OR($C16<>"دستمزد گروهی",$D16=""),"",SUMIFS(ShareAmt,ShareLink,$D16)) | I16: =IF($C16<>"دستمزد گروهی","—",IF($H16="","",IF(ROUND($H16-IF($G16="",0,$G16),0)=0,"√","▲ مغایرت "&TEXT(IF($G16="",0,$G16)-$H16,"#,##0"))))
A17: =IF($B17="","",COUNTA($B$9:$B17)) | F17: =IF($E17="","",IF($C17="دستمزد گروهی",IFERROR(VLOOKUP($E17,WGTbl,2,0),"کد ناشناخته"),IFERROR(IF(VLOOKUP($E17,AcctTblE,4,0)="","(بدون نام)",VLOOKUP($E17,AcctTblE,4,0)),"کد ناشناخته"))) | H17: =IF(OR($C17<>"دستمزد گروهی",$D17=""),"",SUMIFS(ShareAmt,ShareLink,$D17)) | I17: =IF($C17<>"دستمزد گروهی","—",IF($H17="","",IF(ROUND($H17-IF($G17="",0,$G17),0)=0,"√","▲ مغایرت "&TEXT(IF($G17="",0,$G17)-$H17,"#,##0"))))
A18: =IF($B18="","",COUNTA($B$9:$B18)) | F18: =IF($E18="","",IF($C18="دستمزد گروهی",IFERROR(VLOOKUP($E18,WGTbl,2,0),"کد ناشناخته"),IFERROR(IF(VLOOKUP($E18,AcctTblE,4,0)="","(بدون نام)",VLOOKUP($E18,AcctTblE,4,0)),"کد ناشناخته"))) | H18: =IF(OR($C18<>"دستمزد گروهی",$D18=""),"",SUMIFS(ShareAmt,ShareLink,$D18)) | I18: =IF($C18<>"دستمزد گروهی","—",IF($H18="","",IF(ROUND($H18-IF($G18="",0,$G18),0)=0,"√","▲ مغایرت "&TEXT(IF($G18="",0,$G18)-$H18,"#,##0"))))
A19: =IF($B19="","",COUNTA($B$9:$B19)) | F19: =IF($E19="","",IF($C19="دستمزد گروهی",IFERROR(VLOOKUP($E19,WGTbl,2,0),"کد ناشناخته"),IFERROR(IF(VLOOKUP($E19,AcctTblE,4,0)="","(بدون نام)",VLOOKUP($E19,AcctTblE,4,0)),"کد ناشناخته"))) | H19: =IF(OR($C19<>"دستمزد گروهی",$D19=""),"",SUMIFS(ShareAmt,ShareLink,$D19)) | I19: =IF($C19<>"دستمزد گروهی","—",IF($H19="","",IF(ROUND($H19-IF($G19="",0,$G19),0)=0,"√","▲ مغایرت "&TEXT(IF($G19="",0,$G19)-$H19,"#,##0"))))
A20: =IF($B20="","",COUNTA($B$9:$B20)) | F20: =IF($E20="","",IF($C20="دستمزد گروهی",IFERROR(VLOOKUP($E20,WGTbl,2,0),"کد ناشناخته"),IFERROR(IF(VLOOKUP($E20,AcctTblE,4,0)="","(بدون نام)",VLOOKUP($E20,AcctTblE,4,0)),"کد ناشناخته"))) | H20: =IF(OR($C20<>"دستمزد گروهی",$D20=""),"",SUMIFS(ShareAmt,ShareLink,$D20)) | I20: =IF($C20<>"دستمزد گروهی","—",IF($H20="","",IF(ROUND($H20-IF($G20="",0,$G20),0)=0,"√","▲ مغایرت "&TEXT(IF($G20="",0,$G20)-$H20,"#,##0"))))
... A2008: =IF($B2008="","",COUNTA($B$9:$B2008)) | F2008: =IF($E2008="","",IF($C2008="دستمزد گروهی",IFERROR(VLOOKUP($E2008,WGTbl,2,0),"کد ناشناخته"),IFERROR(IF(VLOOKUP($E2008,AcctTblE,4,0)="","(بدون نام)",VLOOKUP($E2008,AcctTblE,4,0)),"کد ناشناخته"))) | H2008: =IF(OR($C2008<>"دستمزد گروهی",$D2008=""),"",SUMIFS(ShareAmt,ShareLink,$D2008)) | I2008: =IF($C2008<>"دستمزد گروهی","—",IF($H2008="","",IF(ROUND($H2008-IF($G2008="",0,$G2008),0)=0,"√","▲ مغایرت "&TEXT(IF($G2008="",0,$G2008)-$H2008,"#,##0"))))

Sheet Shares
A1: =IF(Sync!$AI$6="","مازندشت",Sync!$AI$6)&" — "&IF(Sync!$AI$9="","سورتینگ و بسته‌بندی مرکبات",Sync!$AI$9)
A2: =IF(Sync!$AI$7="","باغدشت، بخش مرکزی، شهرستان قائم‌شهر، استان مازندران، ایران",Sync!$AI$7)&" | MAZANDASHT · CITRUS SORTING & PACKING"
A3: ریز دستمزد گروهی — سهم هر عضو از هر رویداد گروهی
A4: برای هر رویداد «دستمزد گروهی» شیت Wages، اینجا به‌ازای هر عضو یک ردیف بنویسید: همان «شناسه» + کد کارمند + مبلغ سهم. تاریخ و گروه خودکار از رویداد می‌آیند. جمع سهم‌های هر شناسه باید با مبلغ کل رویداد برابر شود (وضعیت در شیت Wages).
A5: تعداد ردیف سهم | C5: جمع سهم‌ها (ریال) | E5: بزرگ‌ترین سهم (ریال) | G5: ظرفیت باقی‌مانده
A6: =COUNTA($B$9:$B$2008) | C6: =SUM($E$9:$E$2008) | E6: =IF(COUNT($E$9:$E$2008)=0,"—",MAX($E$9:$E$2008)) | G6: =2000-COUNTA($B$9:$B$2008)
A7: ردیف | B7: شناسه رویداد | C7: کد عضو | D7: نام عضو (خودکار) | E7: مبلغ سهم (ریال) | F7: توضیحات
A8: No. | B8: Event ID | C8: Member | D8: Member Name (auto) | E8: Share Amount | F8: Notes
A9: =IF($B9="","",COUNTA($B$9:$B9)) | B9: W-201 | C9: E005 | D9: =IF($C9="","",IFERROR(IF(VLOOKUP($C9,AcctTblE,4,0)="","(بدون نام)",VLOOKUP($C9,AcctTblE,4,0)),"کد ناشناخته")) | E9: 11000000 | F9: =IF($B9="","",IFERROR(INDEX(WageDates,MATCH($B9,WageIds,0)),"—")) | G9: =IF($B9="","",IFERROR(VLOOKUP(INDEX(WageParty,MATCH($B9,WageIds,0)),WGTbl,2,0),"—")) | H9: سهم سرپرست
A10: =IF($B10="","",COUNTA($B$9:$B10)) | B10: W-201 | C10: E006 | D10: =IF($C10="","",IFERROR(IF(VLOOKUP($C10,AcctTblE,4,0)="","(بدون نام)",VLOOKUP($C10,AcctTblE,4,0)),"کد ناشناخته")) | E10: 9000000 | F10: =IF($B10="","",IFERROR(INDEX(WageDates,MATCH($B10,WageIds,0)),"—")) | G10: =IF($B10="","",IFERROR(VLOOKUP(INDEX(WageParty,MATCH($B10,WageIds,0)),WGTbl,2,0),"—"))
A11: =IF($B11="","",COUNTA($B$9:$B11)) | B11: W-202 | C11: E005 | D11: =IF($C11="","",IFERROR(IF(VLOOKUP($C11,AcctTblE,4,0)="","(بدون نام)",VLOOKUP($C11,AcctTblE,4,0)),"کد ناشناخته")) | E11: 10000000 | F11: =IF($B11="","",IFERROR(INDEX(WageDates,MATCH($B11,WageIds,0)),"—")) | G11: =IF($B11="","",IFERROR(VLOOKUP(INDEX(WageParty,MATCH($B11,WageIds,0)),WGTbl,2,0),"—"))
A12: =IF($B12="","",COUNTA($B$9:$B12)) | B12: W-202 | C12: E006 | D12: =IF($C12="","",IFERROR(IF(VLOOKUP($C12,AcctTblE,4,0)="","(بدون نام)",VLOOKUP($C12,AcctTblE,4,0)),"کد ناشناخته")) | E12: 8000000 | F12: =IF($B12="","",IFERROR(INDEX(WageDates,MATCH($B12,WageIds,0)),"—")) | G12: =IF($B12="","",IFERROR(VLOOKUP(INDEX(WageParty,MATCH($B12,WageIds,0)),WGTbl,2,0),"—"))
A13: =IF($B13="","",COUNTA($B$9:$B13)) | D13: =IF($C13="","",IFERROR(IF(VLOOKUP($C13,AcctTblE,4,0)="","(بدون نام)",VLOOKUP($C13,AcctTblE,4,0)),"کد ناشناخته")) | F13: =IF($B13="","",IFERROR(INDEX(WageDates,MATCH($B13,WageIds,0)),"—")) | G13: =IF($B13="","",IFERROR(VLOOKUP(INDEX(WageParty,MATCH($B13,WageIds,0)),WGTbl,2,0),"—"))
A14: =IF($B14="","",COUNTA($B$9:$B14)) | D14: =IF($C14="","",IFERROR(IF(VLOOKUP($C14,AcctTblE,4,0)="","(بدون نام)",VLOOKUP($C14,AcctTblE,4,0)),"کد ناشناخته")) | F14: =IF($B14="","",IFERROR(INDEX(WageDates,MATCH($B14,WageIds,0)),"—")) | G14: =IF($B14="","",IFERROR(VLOOKUP(INDEX(WageParty,MATCH($B14,WageIds,0)),WGTbl,2,0),"—"))
A15: =IF($B15="","",COUNTA($B$9:$B15)) | D15: =IF($C15="","",IFERROR(IF(VLOOKUP($C15,AcctTblE,4,0)="","(بدون نام)",VLOOKUP($C15,AcctTblE,4,0)),"کد ناشناخته")) | F15: =IF($B15="","",IFERROR(INDEX(WageDates,MATCH($B15,WageIds,0)),"—")) | G15: =IF($B15="","",IFERROR(VLOOKUP(INDEX(WageParty,MATCH($B15,WageIds,0)),WGTbl,2,0),"—"))
A16: =IF($B16="","",COUNTA($B$9:$B16)) | D16: =IF($C16="","",IFERROR(IF(VLOOKUP($C16,AcctTblE,4,0)="","(بدون نام)",VLOOKUP($C16,AcctTblE,4,0)),"کد ناشناخته")) | F16: =IF($B16="","",IFERROR(INDEX(WageDates,MATCH($B16,WageIds,0)),"—")) | G16: =IF($B16="","",IFERROR(VLOOKUP(INDEX(WageParty,MATCH($B16,WageIds,0)),WGTbl,2,0),"—"))
A17: =IF($B17="","",COUNTA($B$9:$B17)) | D17: =IF($C17="","",IFERROR(IF(VLOOKUP($C17,AcctTblE,4,0)="","(بدون نام)",VLOOKUP($C17,AcctTblE,4,0)),"کد ناشناخته")) | F17: =IF($B17="","",IFERROR(INDEX(WageDates,MATCH($B17,WageIds,0)),"—")) | G17: =IF($B17="","",IFERROR(VLOOKUP(INDEX(WageParty,MATCH($B17,WageIds,0)),WGTbl,2,0),"—"))
A18: =IF($B18="","",COUNTA($B$9:$B18)) | D18: =IF($C18="","",IFERROR(IF(VLOOKUP($C18,AcctTblE,4,0)="","(بدون نام)",VLOOKUP($C18,AcctTblE,4,0)),"کد ناشناخته")) | F18: =IF($B18="","",IFERROR(INDEX(WageDates,MATCH($B18,WageIds,0)),"—")) | G18: =IF($B18="","",IFERROR(VLOOKUP(INDEX(WageParty,MATCH($B18,WageIds,0)),WGTbl,2,0),"—"))
A19: =IF($B19="","",COUNTA($B$9:$B19)) | D19: =IF($C19="","",IFERROR(IF(VLOOKUP($C19,AcctTblE,4,0)="","(بدون نام)",VLOOKUP($C19,AcctTblE,4,0)),"کد ناشناخته")) | F19: =IF($B19="","",IFERROR(INDEX(WageDates,MATCH($B19,WageIds,0)),"—")) | G19: =IF($B19="","",IFERROR(VLOOKUP(INDEX(WageParty,MATCH($B19,WageIds,0)),WGTbl,2,0),"—"))
A20: =IF($B20="","",COUNTA($B$9:$B20)) | D20: =IF($C20="","",IFERROR(IF(VLOOKUP($C20,AcctTblE,4,0)="","(بدون نام)",VLOOKUP($C20,AcctTblE,4,0)),"کد ناشناخته")) | F20: =IF($B20="","",IFERROR(INDEX(WageDates,MATCH($B20,WageIds,0)),"—")) | G20: =IF($B20="","",IFERROR(VLOOKUP(INDEX(WageParty,MATCH($B20,WageIds,0)),WGTbl,2,0),"—"))
A21: =IF($B21="","",COUNTA($B$9:$B21)) | D21: =IF($C21="","",IFERROR(IF(VLOOKUP($C21,AcctTblE,4,0)="","(بدون نام)",VLOOKUP($C21,AcctTblE,4,0)),"کد ناشناخته")) | F21: =IF($B21="","",IFERROR(INDEX(WageDates,MATCH($B21,WageIds,0)),"—")) | G21: =IF($B21="","",IFERROR(VLOOKUP(INDEX(WageParty,MATCH($B21,WageIds,0)),WGTbl,2,0),"—"))
A22: =IF($B22="","",COUNTA($B$9:$B22)) | D22: =IF($C22="","",IFERROR(IF(VLOOKUP($C22,AcctTblE,4,0)="","(بدون نام)",VLOOKUP($C22,AcctTblE,4,0)),"کد ناشناخته")) | F22: =IF($B22="","",IFERROR(INDEX(WageDates,MATCH($B22,WageIds,0)),"—")) | G22: =IF($B22="","",IFERROR(VLOOKUP(INDEX(WageParty,MATCH($B22,WageIds,0)),WGTbl,2,0),"—"))
A23: =IF($B23="","",COUNTA($B$9:$B23)) | D23: =IF($C23="","",IFERROR(IF(VLOOKUP($C23,AcctTblE,4,0)="","(بدون نام)",VLOOKUP($C23,AcctTblE,4,0)),"کد ناشناخته")) | F23: =IF($B23="","",IFERROR(INDEX(WageDates,MATCH($B23,WageIds,0)),"—")) | G23: =IF($B23="","",IFERROR(VLOOKUP(INDEX(WageParty,MATCH($B23,WageIds,0)),WGTbl,2,0),"—"))
A24: =IF($B24="","",COUNTA($B$9:$B24)) | D24: =IF($C24="","",IFERROR(IF(VLOOKUP($C24,AcctTblE,4,0)="","(بدون نام)",VLOOKUP($C24,AcctTblE,4,0)),"کد ناشناخته")) | F24: =IF($B24="","",IFERROR(INDEX(WageDates,MATCH($B24,WageIds,0)),"—")) | G24: =IF($B24="","",IFERROR(VLOOKUP(INDEX(WageParty,MATCH($B24,WageIds,0)),WGTbl,2,0),"—"))
... A2008: =IF($B2008="","",COUNTA($B$9:$B2008)) | D2008: =IF($C2008="","",IFERROR(IF(VLOOKUP($C2008,AcctTblE,4,0)="","(بدون نام)",VLOOKUP($C2008,AcctTblE,4,0)),"کد ناشناخته")) | F2008: =IF($B2008="","",IFERROR(INDEX(WageDates,MATCH($B2008,WageIds,0)),"—")) | G2008: =IF($B2008="","",IFERROR(VLOOKUP(INDEX(WageParty,MATCH($B2008,WageIds,0)),WGTbl,2,0),"—"))

Sheet Report
A1: =IF(Sync!$AI$6="","مازندشت",Sync!$AI$6)&" — "&IF(Sync!$AI$9="","سورتینگ و بسته‌بندی مرکبات",Sync!$AI$9)
A2: =IF(Sync!$AI$7="","باغدشت، بخش مرکزی، شهرستان قائم‌شهر، استان مازندران، ایران",Sync!$AI$7)&" | MAZANDASHT · CITRUS SORTING & PACKING"
A3: ="صورت دستمزد — "&IFERROR(IF(VLOOKUP($C$5,AcctTblE,4,0)="","(بدون نام)",VLOOKUP($C$5,AcctTblE,4,0)),"کد را وارد کنید")
A5: کد کارمند (ورود دستی): | C5: E002 | E5: کد را از INFO (شیت Accounts — حساب‌های E…) وارد کنید. برای نفر دیگر، همین شیت را کپی و کد را عوض کنید.
A6: نام: | C6: =IFERROR(IF(VLOOKUP($C$5,AcctTblE,4,0)="","(بدون نام)",VLOOKUP($C$5,AcctTblE,4,0)),"—")
A7: ماهیت / زیرمجموعه: | C7: =IFERROR(IF(VLOOKUP($C$5,AcctTblE,3,0)="",IF(VLOOKUP($C$5,AcctTblE,2,0)="","—",VLOOKUP($C$5,AcctTblE,2,0)),VLOOKUP($C$5,AcctTblE,3,0)),"—")
A8: گروه کاری: | C8: =IFERROR(IF(VLOOKUP(IFERROR(VLOOKUP($C$5,StaffTblE,2,0),""),WGTbl,2,0)="","—",VLOOKUP(IFERROR(VLOOKUP($C$5,StaffTblE,2,0),""),WGTbl,2,0)),"—")
A9: سمت: | C9: =IFERROR(IF(VLOOKUP($C$5,StaffTblE,3,0)="","—",VLOOKUP($C$5,StaffTblE,3,0)),"—")
A10: بدهکار = دستمزد تعلق‌گرفته (فردی + سهم از گروه‌ها) و بازگشت‌ها | بستانکار = پرداخت‌های بانکی. مانده مثبت = به او بدهکاریم.
A11: جمع دستمزد تعلق‌گرفته (ریال) | C11: جمع پرداخت‌های بانکی (ریال) | E11: مانده نهایی (ریال) | G11: وضعیت
A12: =SUM($E$17:$E$2016) | C12: =SUM($F$17:$F$2016) | E12: =IFERROR(LOOKUP(9.99E+307,$G$17:$G$2016),0) | G12: =IF($E$12>0,"● بدهکار — به او بدهکاریم",IF($E$12<0,"● بستانکار — اضافه پرداخت","= تسویه"))
A13: تعداد رویداد | C13: آخرین رویداد | E13: بزرگ‌ترین ردیف (ریال) | G13: گروه کاری
A14: =COUNT($G$17:$G$2016) | C14: =IF(COUNT($G$17:$G$2016)=0,"—",INDEX($B$17:$B$2016,COUNT($G$17:$G$2016))) | E14: =IF(COUNT($E$17:$E$2016)=0,"—",MAX($E$17:$E$2016)) | G14: =IFERROR(IF(VLOOKUP(IFERROR(VLOOKUP($C$5,StaffTblE,2,0),""),WGTbl,2,0)="","—",VLOOKUP(IFERROR(VLOOKUP($C$5,StaffTblE,2,0),""),WGTbl,2,0)),"—")
A15: ردیف | B15: تاریخ | C15: نوع رویداد | D15: مرجع | E15: بدهکار — تعلق (ریال) | F15: بستانکار — پرداخت (ریال) | G15: مانده (ریال) | H15: توضیحات
A16: No. | B16: Date | C16: Type | D16: Ref | E16: Debit | F16: Credit | G16: Balance | H16: Notes
A17: 1 | B17: =IF(AND($L17="",$M17="",$N17=""),"",IF($L17<>"",INDEX(LdADate,$L17),IF($M17<>"",INDEX(LdBDate,$M17),INDEX(LdCDate,$N17)))) | C17: =IF($L17<>"","دستمزد (فردی)",IF($M17<>"","سهم از گروه "&IFERROR(VLOOKUP(INDEX(LdBGroup,$M17),WGTbl,2,0),INDEX(LdBGroup,$M17)),IF($N17<>"",IF(N(INDEX(LdCDep,$N17))>0,"بازگشت بانکی","پرداخت بانکی"),""))) | D17: =IF($L17<>"",IF(INDEX(LdAId,$L17)="","—",INDEX(LdAId,$L17)),IF($M17<>"",IF(INDEX(LdBId,$M17)="","—",INDEX(LdBId,$M17)),IF($N17<>"",IF(INDEX(LdCBank,$N17)="","—",INDEX(LdCBank,$N17)),""))) | E17: =IF($L17<>"",IF(INDEX(LdAAmt,$L17)=0,"",INDEX(LdAAmt,$L17)),IF($M17<>"",IF(INDEX(LdBAmt,$M17)=0,"",INDEX(LdBAmt,$M17)),IF($N17<>"",IF(INDEX(LdCDep,$N17)=0,"",INDEX(LdCDep,$N17)),""))) | F17: =IF(AND($L17="",$M17="",$N17=""),"",IF($N17="","",IF(INDEX(LdCWit,$N17)=0,"",INDEX(LdCWit,$N17)))) | G17: =IF($B17="","",IF($E17="",0,$E17)-IF($F17="",0,$F17)) | H17: =IF(AND($L17="",$M17="",$N17=""),"",IF($L17<>"",IF(INDEX(LdANote,$L17)="","—",INDEX(LdANote,$L17)),IF($M17<>"",IF(INDEX(LdBNote,$M17)="","—",INDEX(LdBNote,$M17)),IF($N17<>"",IF(INDEX(LdCNote,$N17)="","—",INDEX(LdCNote,$N17)),"")))) | L17: =IFERROR(MATCH($C$5&"|"&RIGHT("000000"&1,6),LdAKeyM,0),"") | M17: =IFERROR(MATCH($C$5&"|"&RIGHT("000000"&1,6),LdBKeyM,0),"") | N17: =IFERROR(MATCH($C$5&"|"&RIGHT("000000"&1,6),LdCKeyM,0),"")
A18: 2 | B18: =IF(AND($L18="",$M18="",$N18=""),"",IF($L18<>"",INDEX(LdADate,$L18),IF($M18<>"",INDEX(LdBDate,$M18),INDEX(LdCDate,$N18)))) | C18: =IF($L18<>"","دستمزد (فردی)",IF($M18<>"","سهم از گروه "&IFERROR(VLOOKUP(INDEX(LdBGroup,$M18),WGTbl,2,0),INDEX(LdBGroup,$M18)),IF($N18<>"",IF(N(INDEX(LdCDep,$N18))>0,"بازگشت بانکی","پرداخت بانکی"),""))) | D18: =IF($L18<>"",IF(INDEX(LdAId,$L18)="","—",INDEX(LdAId,$L18)),IF($M18<>"",IF(INDEX(LdBId,$M18)="","—",INDEX(LdBId,$M18)),IF($N18<>"",IF(INDEX(LdCBank,$N18)="","—",INDEX(LdCBank,$N18)),""))) | E18: =IF($L18<>"",IF(INDEX(LdAAmt,$L18)=0,"",INDEX(LdAAmt,$L18)),IF($M18<>"",IF(INDEX(LdBAmt,$M18)=0,"",INDEX(LdBAmt,$M18)),IF($N18<>"",IF(INDEX(LdCDep,$N18)=0,"",INDEX(LdCDep,$N18)),""))) | F18: =IF(AND($L18="",$M18="",$N18=""),"",IF($N18="","",IF(INDEX(LdCWit,$N18)=0,"",INDEX(LdCWit,$N18)))) | G18: =IF($B18="","",IF($G17="",0,$G17)+IF($E18="",0,$E18)-IF($F18="",0,$F18)) | H18: =IF(AND($L18="",$M18="",$N18=""),"",IF($L18<>"",IF(INDEX(LdANote,$L18)="","—",INDEX(LdANote,$L18)),IF($M18<>"",IF(INDEX(LdBNote,$M18)="","—",INDEX(LdBNote,$M18)),IF($N18<>"",IF(INDEX(LdCNote,$N18)="","—",INDEX(LdCNote,$N18)),"")))) | L18: =IFERROR(MATCH($C$5&"|"&RIGHT("000000"&2,6),LdAKeyM,0),"") | M18: =IFERROR(MATCH($C$5&"|"&RIGHT("000000"&2,6),LdBKeyM,0),"") | N18: =IFERROR(MATCH($C$5&"|"&RIGHT("000000"&2,6),LdCKeyM,0),"")
A19: 3 | B19: =IF(AND($L19="",$M19="",$N19=""),"",IF($L19<>"",INDEX(LdADate,$L19),IF($M19<>"",INDEX(LdBDate,$M19),INDEX(LdCDate,$N19)))) | C19: =IF($L19<>"","دستمزد (فردی)",IF($M19<>"","سهم از گروه "&IFERROR(VLOOKUP(INDEX(LdBGroup,$M19),WGTbl,2,0),INDEX(LdBGroup,$M19)),IF($N19<>"",IF(N(INDEX(LdCDep,$N19))>0,"بازگشت بانکی","پرداخت بانکی"),""))) | D19: =IF($L19<>"",IF(INDEX(LdAId,$L19)="","—",INDEX(LdAId,$L19)),IF($M19<>"",IF(INDEX(LdBId,$M19)="","—",INDEX(LdBId,$M19)),IF($N19<>"",IF(INDEX(LdCBank,$N19)="","—",INDEX(LdCBank,$N19)),""))) | E19: =IF($L19<>"",IF(INDEX(LdAAmt,$L19)=0,"",INDEX(LdAAmt,$L19)),IF($M19<>"",IF(INDEX(LdBAmt,$M19)=0,"",INDEX(LdBAmt,$M19)),IF($N19<>"",IF(INDEX(LdCDep,$N19)=0,"",INDEX(LdCDep,$N19)),""))) | F19: =IF(AND($L19="",$M19="",$N19=""),"",IF($N19="","",IF(INDEX(LdCWit,$N19)=0,"",INDEX(LdCWit,$N19)))) | G19: =IF($B19="","",IF($G18="",0,$G18)+IF($E19="",0,$E19)-IF($F19="",0,$F19)) | H19: =IF(AND($L19="",$M19="",$N19=""),"",IF($L19<>"",IF(INDEX(LdANote,$L19)="","—",INDEX(LdANote,$L19)),IF($M19<>"",IF(INDEX(LdBNote,$M19)="","—",INDEX(LdBNote,$M19)),IF($N19<>"",IF(INDEX(LdCNote,$N19)="","—",INDEX(LdCNote,$N19)),"")))) | L19: =IFERROR(MATCH($C$5&"|"&RIGHT("000000"&3,6),LdAKeyM,0),"") | M19: =IFERROR(MATCH($C$5&"|"&RIGHT("000000"&3,6),LdBKeyM,0),"") | N19: =IFERROR(MATCH($C$5&"|"&RIGHT("000000"&3,6),LdCKeyM,0),"")
A20: 4 | B20: =IF(AND($L20="",$M20="",$N20=""),"",IF($L20<>"",INDEX(LdADate,$L20),IF($M20<>"",INDEX(LdBDate,$M20),INDEX(LdCDate,$N20)))) | C20: =IF($L20<>"","دستمزد (فردی)",IF($M20<>"","سهم از گروه "&IFERROR(VLOOKUP(INDEX(LdBGroup,$M20),WGTbl,2,0),INDEX(LdBGroup,$M20)),IF($N20<>"",IF(N(INDEX(LdCDep,$N20))>0,"بازگشت بانکی","پرداخت بانکی"),""))) | D20: =IF($L20<>"",IF(INDEX(LdAId,$L20)="","—",INDEX(LdAId,$L20)),IF($M20<>"",IF(INDEX(LdBId,$M20)="","—",INDEX(LdBId,$M20)),IF($N20<>"",IF(INDEX(LdCBank,$N20)="","—",INDEX(LdCBank,$N20)),""))) | E20: =IF($L20<>"",IF(INDEX(LdAAmt,$L20)=0,"",INDEX(LdAAmt,$L20)),IF($M20<>"",IF(INDEX(LdBAmt,$M20)=0,"",INDEX(LdBAmt,$M20)),IF($N20<>"",IF(INDEX(LdCDep,$N20)=0,"",INDEX(LdCDep,$N20)),""))) | F20: =IF(AND($L20="",$M20="",$N20=""),"",IF($N20="","",IF(INDEX(LdCWit,$N20)=0,"",INDEX(LdCWit,$N20)))) | G20: =IF($B20="","",IF($G19="",0,$G19)+IF($E20="",0,$E20)-IF($F20="",0,$F20)) | H20: =IF(AND($L20="",$M20="",$N20=""),"",IF($L20<>"",IF(INDEX(LdANote,$L20)="","—",INDEX(LdANote,$L20)),IF($M20<>"",IF(INDEX(LdBNote,$M20)="","—",INDEX(LdBNote,$M20)),IF($N20<>"",IF(INDEX(LdCNote,$N20)="","—",INDEX(LdCNote,$N20)),"")))) | L20: =IFERROR(MATCH($C$5&"|"&RIGHT("000000"&4,6),LdAKeyM,0),"") | M20: =IFERROR(MATCH($C$5&"|"&RIGHT("000000"&4,6),LdBKeyM,0),"") | N20: =IFERROR(MATCH($C$5&"|"&RIGHT("000000"&4,6),LdCKeyM,0),"")
A21: 5 | B21: =IF(AND($L21="",$M21="",$N21=""),"",IF($L21<>"",INDEX(LdADate,$L21),IF($M21<>"",INDEX(LdBDate,$M21),INDEX(LdCDate,$N21)))) | C21: =IF($L21<>"","دستمزد (فردی)",IF($M21<>"","سهم از گروه "&IFERROR(VLOOKUP(INDEX(LdBGroup,$M21),WGTbl,2,0),INDEX(LdBGroup,$M21)),IF($N21<>"",IF(N(INDEX(LdCDep,$N21))>0,"بازگشت بانکی","پرداخت بانکی"),""))) | D21: =IF($L21<>"",IF(INDEX(LdAId,$L21)="","—",INDEX(LdAId,$L21)),IF($M21<>"",IF(INDEX(LdBId,$M21)="","—",INDEX(LdBId,$M21)),IF($N21<>"",IF(INDEX(LdCBank,$N21)="","—",INDEX(LdCBank,$N21)),""))) | E21: =IF($L21<>"",IF(INDEX(LdAAmt,$L21)=0,"",INDEX(LdAAmt,$L21)),IF($M21<>"",IF(INDEX(LdBAmt,$M21)=0,"",INDEX(LdBAmt,$M21)),IF($N21<>"",IF(INDEX(LdCDep,$N21)=0,"",INDEX(LdCDep,$N21)),""))) | F21: =IF(AND($L21="",$M21="",$N21=""),"",IF($N21="","",IF(INDEX(LdCWit,$N21)=0,"",INDEX(LdCWit,$N21)))) | G21: =IF($B21="","",IF($G20="",0,$G20)+IF($E21="",0,$E21)-IF($F21="",0,$F21)) | H21: =IF(AND($L21="",$M21="",$N21=""),"",IF($L21<>"",IF(INDEX(LdANote,$L21)="","—",INDEX(LdANote,$L21)),IF($M21<>"",IF(INDEX(LdBNote,$M21)="","—",INDEX(LdBNote,$M21)),IF($N21<>"",IF(INDEX(LdCNote,$N21)="","—",INDEX(LdCNote,$N21)),"")))) | L21: =IFERROR(MATCH($C$5&"|"&RIGHT("000000"&5,6),LdAKeyM,0),"") | M21: =IFERROR(MATCH($C$5&"|"&RIGHT("000000"&5,6),LdBKeyM,0),"") | N21: =IFERROR(MATCH($C$5&"|"&RIGHT("000000"&5,6),LdCKeyM,0),"")
A22: 6 | B22: =IF(AND($L22="",$M22="",$N22=""),"",IF($L22<>"",INDEX(LdADate,$L22),IF($M22<>"",INDEX(LdBDate,$M22),INDEX(LdCDate,$N22)))) | C22: =IF($L22<>"","دستمزد (فردی)",IF($M22<>"","سهم از گروه "&IFERROR(VLOOKUP(INDEX(LdBGroup,$M22),WGTbl,2,0),INDEX(LdBGroup,$M22)),IF($N22<>"",IF(N(INDEX(LdCDep,$N22))>0,"بازگشت بانکی","پرداخت بانکی"),""))) | D22: =IF($L22<>"",IF(INDEX(LdAId,$L22)="","—",INDEX(LdAId,$L22)),IF($M22<>"",IF(INDEX(LdBId,$M22)="","—",INDEX(LdBId,$M22)),IF($N22<>"",IF(INDEX(LdCBank,$N22)="","—",INDEX(LdCBank,$N22)),""))) | E22: =IF($L22<>"",IF(INDEX(LdAAmt,$L22)=0,"",INDEX(LdAAmt,$L22)),IF($M22<>"",IF(INDEX(LdBAmt,$M22)=0,"",INDEX(LdBAmt,$M22)),IF($N22<>"",IF(INDEX(LdCDep,$N22)=0,"",INDEX(LdCDep,$N22)),""))) | F22: =IF(AND($L22="",$M22="",$N22=""),"",IF($N22="","",IF(INDEX(LdCWit,$N22)=0,"",INDEX(LdCWit,$N22)))) | G22: =IF($B22="","",IF($G21="",0,$G21)+IF($E22="",0,$E22)-IF($F22="",0,$F22)) | H22: =IF(AND($L22="",$M22="",$N22=""),"",IF($L22<>"",IF(INDEX(LdANote,$L22)="","—",INDEX(LdANote,$L22)),IF($M22<>"",IF(INDEX(LdBNote,$M22)="","—",INDEX(LdBNote,$M22)),IF($N22<>"",IF(INDEX(LdCNote,$N22)="","—",INDEX(LdCNote,$N22)),"")))) | L22: =IFERROR(MATCH($C$5&"|"&RIGHT("000000"&6,6),LdAKeyM,0),"") | M22: =IFERROR(MATCH($C$5&"|"&RIGHT("000000"&6,6),LdBKeyM,0),"") | N22: =IFERROR(MATCH($C$5&"|"&RIGHT("000000"&6,6),LdCKeyM,0),"")
A23: 7 | B23: =IF(AND($L23="",$M23="",$N23=""),"",IF($L23<>"",INDEX(LdADate,$L23),IF($M23<>"",INDEX(LdBDate,$M23),INDEX(LdCDate,$N23)))) | C23: =IF($L23<>"","دستمزد (فردی)",IF($M23<>"","سهم از گروه "&IFERROR(VLOOKUP(INDEX(LdBGroup,$M23),WGTbl,2,0),INDEX(LdBGroup,$M23)),IF($N23<>"",IF(N(INDEX(LdCDep,$N23))>0,"بازگشت بانکی","پرداخت بانکی"),""))) | D23: =IF($L23<>"",IF(INDEX(LdAId,$L23)="","—",INDEX(LdAId,$L23)),IF($M23<>"",IF(INDEX(LdBId,$M23)="","—",INDEX(LdBId,$M23)),IF($N23<>"",IF(INDEX(LdCBank,$N23)="","—",INDEX(LdCBank,$N23)),""))) | E23: =IF($L23<>"",IF(INDEX(LdAAmt,$L23)=0,"",INDEX(LdAAmt,$L23)),IF($M23<>"",IF(INDEX(LdBAmt,$M23)=0,"",INDEX(LdBAmt,$M23)),IF($N23<>"",IF(INDEX(LdCDep,$N23)=0,"",INDEX(LdCDep,$N23)),""))) | F23: =IF(AND($L23="",$M23="",$N23=""),"",IF($N23="","",IF(INDEX(LdCWit,$N23)=0,"",INDEX(LdCWit,$N23)))) | G23: =IF($B23="","",IF($G22="",0,$G22)+IF($E23="",0,$E23)-IF($F23="",0,$F23)) | H23: =IF(AND($L23="",$M23="",$N23=""),"",IF($L23<>"",IF(INDEX(LdANote,$L23)="","—",INDEX(LdANote,$L23)),IF($M23<>"",IF(INDEX(LdBNote,$M23)="","—",INDEX(LdBNote,$M23)),IF($N23<>"",IF(INDEX(LdCNote,$N23)="","—",INDEX(LdCNote,$N23)),"")))) | L23: =IFERROR(MATCH($C$5&"|"&RIGHT("000000"&7,6),LdAKeyM,0),"") | M23: =IFERROR(MATCH($C$5&"|"&RIGHT("000000"&7,6),LdBKeyM,0),"") | N23: =IFERROR(MATCH($C$5&"|"&RIGHT("000000"&7,6),LdCKeyM,0),"")
A24: 8 | B24: =IF(AND($L24="",$M24="",$N24=""),"",IF($L24<>"",INDEX(LdADate,$L24),IF($M24<>"",INDEX(LdBDate,$M24),INDEX(LdCDate,$N24)))) | C24: =IF($L24<>"","دستمزد (فردی)",IF($M24<>"","سهم از گروه "&IFERROR(VLOOKUP(INDEX(LdBGroup,$M24),WGTbl,2,0),INDEX(LdBGroup,$M24)),IF($N24<>"",IF(N(INDEX(LdCDep,$N24))>0,"بازگشت بانکی","پرداخت بانکی"),""))) | D24: =IF($L24<>"",IF(INDEX(LdAId,$L24)="","—",INDEX(LdAId,$L24)),IF($M24<>"",IF(INDEX(LdBId,$M24)="","—",INDEX(LdBId,$M24)),IF($N24<>"",IF(INDEX(LdCBank,$N24)="","—",INDEX(LdCBank,$N24)),""))) | E24: =IF($L24<>"",IF(INDEX(LdAAmt,$L24)=0,"",INDEX(LdAAmt,$L24)),IF($M24<>"",IF(INDEX(LdBAmt,$M24)=0,"",INDEX(LdBAmt,$M24)),IF($N24<>"",IF(INDEX(LdCDep,$N24)=0,"",INDEX(LdCDep,$N24)),""))) | F24: =IF(AND($L24="",$M24="",$N24=""),"",IF($N24="","",IF(INDEX(LdCWit,$N24)=0,"",INDEX(LdCWit,$N24)))) | G24: =IF($B24="","",IF($G23="",0,$G23)+IF($E24="",0,$E24)-IF($F24="",0,$F24)) | H24: =IF(AND($L24="",$M24="",$N24=""),"",IF($L24<>"",IF(INDEX(LdANote,$L24)="","—",INDEX(LdANote,$L24)),IF($M24<>"",IF(INDEX(LdBNote,$M24)="","—",INDEX(LdBNote,$M24)),IF($N24<>"",IF(INDEX(LdCNote,$N24)="","—",INDEX(LdCNote,$N24)),"")))) | L24: =IFERROR(MATCH($C$5&"|"&RIGHT("000000"&8,6),LdAKeyM,0),"") | M24: =IFERROR(MATCH($C$5&"|"&RIGHT("000000"&8,6),LdBKeyM,0),"") | N24: =IFERROR(MATCH($C$5&"|"&RIGHT("000000"&8,6),LdCKeyM,0),"")
A25: 9 | B25: =IF(AND($L25="",$M25="",$N25=""),"",IF($L25<>"",INDEX(LdADate,$L25),IF($M25<>"",INDEX(LdBDate,$M25),INDEX(LdCDate,$N25)))) | C25: =IF($L25<>"","دستمزد (فردی)",IF($M25<>"","سهم از گروه "&IFERROR(VLOOKUP(INDEX(LdBGroup,$M25),WGTbl,2,0),INDEX(LdBGroup,$M25)),IF($N25<>"",IF(N(INDEX(LdCDep,$N25))>0,"بازگشت بانکی","پرداخت بانکی"),""))) | D25: =IF($L25<>"",IF(INDEX(LdAId,$L25)="","—",INDEX(LdAId,$L25)),IF($M25<>"",IF(INDEX(LdBId,$M25)="","—",INDEX(LdBId,$M25)),IF($N25<>"",IF(INDEX(LdCBank,$N25)="","—",INDEX(LdCBank,$N25)),""))) | E25: =IF($L25<>"",IF(INDEX(LdAAmt,$L25)=0,"",INDEX(LdAAmt,$L25)),IF($M25<>"",IF(INDEX(LdBAmt,$M25)=0,"",INDEX(LdBAmt,$M25)),IF($N25<>"",IF(INDEX(LdCDep,$N25)=0,"",INDEX(LdCDep,$N25)),""))) | F25: =IF(AND($L25="",$M25="",$N25=""),"",IF($N25="","",IF(INDEX(LdCWit,$N25)=0,"",INDEX(LdCWit,$N25)))) | G25: =IF($B25="","",IF($G24="",0,$G24)+IF($E25="",0,$E25)-IF($F25="",0,$F25)) | H25: =IF(AND($L25="",$M25="",$N25=""),"",IF($L25<>"",IF(INDEX(LdANote,$L25)="","—",INDEX(LdANote,$L25)),IF($M25<>"",IF(INDEX(LdBNote,$M25)="","—",INDEX(LdBNote,$M25)),IF($N25<>"",IF(INDEX(LdCNote,$N25)="","—",INDEX(LdCNote,$N25)),"")))) | L25: =IFERROR(MATCH($C$5&"|"&RIGHT("000000"&9,6),LdAKeyM,0),"") | M25: =IFERROR(MATCH($C$5&"|"&RIGHT("000000"&9,6),LdBKeyM,0),"") | N25: =IFERROR(MATCH($C$5&"|"&RIGHT("000000"&9,6),LdCKeyM,0),"")
A26: 10 | B26: =IF(AND($L26="",$M26="",$N26=""),"",IF($L26<>"",INDEX(LdADate,$L26),IF($M26<>"",INDEX(LdBDate,$M26),INDEX(LdCDate,$N26)))) | C26: =IF($L26<>"","دستمزد (فردی)",IF($M26<>"","سهم از گروه "&IFERROR(VLOOKUP(INDEX(LdBGroup,$M26),WGTbl,2,0),INDEX(LdBGroup,$M26)),IF($N26<>"",IF(N(INDEX(LdCDep,$N26))>0,"بازگشت بانکی","پرداخت بانکی"),""))) | D26: =IF($L26<>"",IF(INDEX(LdAId,$L26)="","—",INDEX(LdAId,$L26)),IF($M26<>"",IF(INDEX(LdBId,$M26)="","—",INDEX(LdBId,$M26)),IF($N26<>"",IF(INDEX(LdCBank,$N26)="","—",INDEX(LdCBank,$N26)),""))) | E26: =IF($L26<>"",IF(INDEX(LdAAmt,$L26)=0,"",INDEX(LdAAmt,$L26)),IF($M26<>"",IF(INDEX(LdBAmt,$M26)=0,"",INDEX(LdBAmt,$M26)),IF($N26<>"",IF(INDEX(LdCDep,$N26)=0,"",INDEX(LdCDep,$N26)),""))) | F26: =IF(AND($L26="",$M26="",$N26=""),"",IF($N26="","",IF(INDEX(LdCWit,$N26)=0,"",INDEX(LdCWit,$N26)))) | G26: =IF($B26="","",IF($G25="",0,$G25)+IF($E26="",0,$E26)-IF($F26="",0,$F26)) | H26: =IF(AND($L26="",$M26="",$N26=""),"",IF($L26<>"",IF(INDEX(LdANote,$L26)="","—",INDEX(LdANote,$L26)),IF($M26<>"",IF(INDEX(LdBNote,$M26)="","—",INDEX(LdBNote,$M26)),IF($N26<>"",IF(INDEX(LdCNote,$N26)="","—",INDEX(LdCNote,$N26)),"")))) | L26: =IFERROR(MATCH($C$5&"|"&RIGHT("000000"&10,6),LdAKeyM,0),"") | M26: =IFERROR(MATCH($C$5&"|"&RIGHT("000000"&10,6),LdBKeyM,0),"") | N26: =IFERROR(MATCH($C$5&"|"&RIGHT("000000"&10,6),LdCKeyM,0),"")
A27: 11 | B27: =IF(AND($L27="",$M27="",$N27=""),"",IF($L27<>"",INDEX(LdADate,$L27),IF($M27<>"",INDEX(LdBDate,$M27),INDEX(LdCDate,$N27)))) | C27: =IF($L27<>"","دستمزد (فردی)",IF($M27<>"","سهم از گروه "&IFERROR(VLOOKUP(INDEX(LdBGroup,$M27),WGTbl,2,0),INDEX(LdBGroup,$M27)),IF($N27<>"",IF(N(INDEX(LdCDep,$N27))>0,"بازگشت بانکی","پرداخت بانکی"),""))) | D27: =IF($L27<>"",IF(INDEX(LdAId,$L27)="","—",INDEX(LdAId,$L27)),IF($M27<>"",IF(INDEX(LdBId,$M27)="","—",INDEX(LdBId,$M27)),IF($N27<>"",IF(INDEX(LdCBank,$N27)="","—",INDEX(LdCBank,$N27)),""))) | E27: =IF($L27<>"",IF(INDEX(LdAAmt,$L27)=0,"",INDEX(LdAAmt,$L27)),IF($M27<>"",IF(INDEX(LdBAmt,$M27)=0,"",INDEX(LdBAmt,$M27)),IF($N27<>"",IF(INDEX(LdCDep,$N27)=0,"",INDEX(LdCDep,$N27)),""))) | F27: =IF(AND($L27="",$M27="",$N27=""),"",IF($N27="","",IF(INDEX(LdCWit,$N27)=0,"",INDEX(LdCWit,$N27)))) | G27: =IF($B27="","",IF($G26="",0,$G26)+IF($E27="",0,$E27)-IF($F27="",0,$F27)) | H27: =IF(AND($L27="",$M27="",$N27=""),"",IF($L27<>"",IF(INDEX(LdANote,$L27)="","—",INDEX(LdANote,$L27)),IF($M27<>"",IF(INDEX(LdBNote,$M27)="","—",INDEX(LdBNote,$M27)),IF($N27<>"",IF(INDEX(LdCNote,$N27)="","—",INDEX(LdCNote,$N27)),"")))) | L27: =IFERROR(MATCH($C$5&"|"&RIGHT("000000"&11,6),LdAKeyM,0),"") | M27: =IFERROR(MATCH($C$5&"|"&RIGHT("000000"&11,6),LdBKeyM,0),"") | N27: =IFERROR(MATCH($C$5&"|"&RIGHT("000000"&11,6),LdCKeyM,0),"")
A28: 12 | B28: =IF(AND($L28="",$M28="",$N28=""),"",IF($L28<>"",INDEX(LdADate,$L28),IF($M28<>"",INDEX(LdBDate,$M28),INDEX(LdCDate,$N28)))) | C28: =IF($L28<>"","دستمزد (فردی)",IF($M28<>"","سهم از گروه "&IFERROR(VLOOKUP(INDEX(LdBGroup,$M28),WGTbl,2,0),INDEX(LdBGroup,$M28)),IF($N28<>"",IF(N(INDEX(LdCDep,$N28))>0,"بازگشت بانکی","پرداخت بانکی"),""))) | D28: =IF($L28<>"",IF(INDEX(LdAId,$L28)="","—",INDEX(LdAId,$L28)),IF($M28<>"",IF(INDEX(LdBId,$M28)="","—",INDEX(LdBId,$M28)),IF($N28<>"",IF(INDEX(LdCBank,$N28)="","—",INDEX(LdCBank,$N28)),""))) | E28: =IF($L28<>"",IF(INDEX(LdAAmt,$L28)=0,"",INDEX(LdAAmt,$L28)),IF($M28<>"",IF(INDEX(LdBAmt,$M28)=0,"",INDEX(LdBAmt,$M28)),IF($N28<>"",IF(INDEX(LdCDep,$N28)=0,"",INDEX(LdCDep,$N28)),""))) | F28: =IF(AND($L28="",$M28="",$N28=""),"",IF($N28="","",IF(INDEX(LdCWit,$N28)=0,"",INDEX(LdCWit,$N28)))) | G28: =IF($B28="","",IF($G27="",0,$G27)+IF($E28="",0,$E28)-IF($F28="",0,$F28)) | H28: =IF(AND($L28="",$M28="",$N28=""),"",IF($L28<>"",IF(INDEX(LdANote,$L28)="","—",INDEX(LdANote,$L28)),IF($M28<>"",IF(INDEX(LdBNote,$M28)="","—",INDEX(LdBNote,$M28)),IF($N28<>"",IF(INDEX(LdCNote,$N28)="","—",INDEX(LdCNote,$N28)),"")))) | L28: =IFERROR(MATCH($C$5&"|"&RIGHT("000000"&12,6),LdAKeyM,0),"") | M28: =IFERROR(MATCH($C$5&"|"&RIGHT("000000"&12,6),LdBKeyM,0),"") | N28: =IFERROR(MATCH($C$5&"|"&RIGHT("000000"&12,6),LdCKeyM,0),"")
A29: 13 | B29: =IF(AND($L29="",$M29="",$N29=""),"",IF($L29<>"",INDEX(LdADate,$L29),IF($M29<>"",INDEX(LdBDate,$M29),INDEX(LdCDate,$N29)))) | C29: =IF($L29<>"","دستمزد (فردی)",IF($M29<>"","سهم از گروه "&IFERROR(VLOOKUP(INDEX(LdBGroup,$M29),WGTbl,2,0),INDEX(LdBGroup,$M29)),IF($N29<>"",IF(N(INDEX(LdCDep,$N29))>0,"بازگشت بانکی","پرداخت بانکی"),""))) | D29: =IF($L29<>"",IF(INDEX(LdAId,$L29)="","—",INDEX(LdAId,$L29)),IF($M29<>"",IF(INDEX(LdBId,$M29)="","—",INDEX(LdBId,$M29)),IF($N29<>"",IF(INDEX(LdCBank,$N29)="","—",INDEX(LdCBank,$N29)),""))) | E29: =IF($L29<>"",IF(INDEX(LdAAmt,$L29)=0,"",INDEX(LdAAmt,$L29)),IF($M29<>"",IF(INDEX(LdBAmt,$M29)=0,"",INDEX(LdBAmt,$M29)),IF($N29<>"",IF(INDEX(LdCDep,$N29)=0,"",INDEX(LdCDep,$N29)),""))) | F29: =IF(AND($L29="",$M29="",$N29=""),"",IF($N29="","",IF(INDEX(LdCWit,$N29)=0,"",INDEX(LdCWit,$N29)))) | G29: =IF($B29="","",IF($G28="",0,$G28)+IF($E29="",0,$E29)-IF($F29="",0,$F29)) | H29: =IF(AND($L29="",$M29="",$N29=""),"",IF($L29<>"",IF(INDEX(LdANote,$L29)="","—",INDEX(LdANote,$L29)),IF($M29<>"",IF(INDEX(LdBNote,$M29)="","—",INDEX(LdBNote,$M29)),IF($N29<>"",IF(INDEX(LdCNote,$N29)="","—",INDEX(LdCNote,$N29)),"")))) | L29: =IFERROR(MATCH($C$5&"|"&RIGHT("000000"&13,6),LdAKeyM,0),"") | M29: =IFERROR(MATCH($C$5&"|"&RIGHT("000000"&13,6),LdBKeyM,0),"") | N29: =IFERROR(MATCH($C$5&"|"&RIGHT("000000"&13,6),LdCKeyM,0),"")
A30: 14 | B30: =IF(AND($L30="",$M30="",$N30=""),"",IF($L30<>"",INDEX(LdADate,$L30),IF($M30<>"",INDEX(LdBDate,$M30),INDEX(LdCDate,$N30)))) | C30: =IF($L30<>"","دستمزد (فردی)",IF($M30<>"","سهم از گروه "&IFERROR(VLOOKUP(INDEX(LdBGroup,$M30),WGTbl,2,0),INDEX(LdBGroup,$M30)),IF($N30<>"",IF(N(INDEX(LdCDep,$N30))>0,"بازگشت بانکی","پرداخت بانکی"),""))) | D30: =IF($L30<>"",IF(INDEX(LdAId,$L30)="","—",INDEX(LdAId,$L30)),IF($M30<>"",IF(INDEX(LdBId,$M30)="","—",INDEX(LdBId,$M30)),IF($N30<>"",IF(INDEX(LdCBank,$N30)="","—",INDEX(LdCBank,$N30)),""))) | E30: =IF($L30<>"",IF(INDEX(LdAAmt,$L30)=0,"",INDEX(LdAAmt,$L30)),IF($M30<>"",IF(INDEX(LdBAmt,$M30)=0,"",INDEX(LdBAmt,$M30)),IF($N30<>"",IF(INDEX(LdCDep,$N30)=0,"",INDEX(LdCDep,$N30)),""))) | F30: =IF(AND($L30="",$M30="",$N30=""),"",IF($N30="","",IF(INDEX(LdCWit,$N30)=0,"",INDEX(LdCWit,$N30)))) | G30: =IF($B30="","",IF($G29="",0,$G29)+IF($E30="",0,$E30)-IF($F30="",0,$F30)) | H30: =IF(AND($L30="",$M30="",$N30=""),"",IF($L30<>"",IF(INDEX(LdANote,$L30)="","—",INDEX(LdANote,$L30)),IF($M30<>"",IF(INDEX(LdBNote,$M30)="","—",INDEX(LdBNote,$M30)),IF($N30<>"",IF(INDEX(LdCNote,$N30)="","—",INDEX(LdCNote,$N30)),"")))) | L30: =IFERROR(MATCH($C$5&"|"&RIGHT("000000"&14,6),LdAKeyM,0),"") | M30: =IFERROR(MATCH($C$5&"|"&RIGHT("000000"&14,6),LdBKeyM,0),"") | N30: =IFERROR(MATCH($C$5&"|"&RIGHT("000000"&14,6),LdCKeyM,0),"")
A31: 15 | B31: =IF(AND($L31="",$M31="",$N31=""),"",IF($L31<>"",INDEX(LdADate,$L31),IF($M31<>"",INDEX(LdBDate,$M31),INDEX(LdCDate,$N31)))) | C31: =IF($L31<>"","دستمزد (فردی)",IF($M31<>"","سهم از گروه "&IFERROR(VLOOKUP(INDEX(LdBGroup,$M31),WGTbl,2,0),INDEX(LdBGroup,$M31)),IF($N31<>"",IF(N(INDEX(LdCDep,$N31))>0,"بازگشت بانکی","پرداخت بانکی"),""))) | D31: =IF($L31<>"",IF(INDEX(LdAId,$L31)="","—",INDEX(LdAId,$L31)),IF($M31<>"",IF(INDEX(LdBId,$M31)="","—",INDEX(LdBId,$M31)),IF($N31<>"",IF(INDEX(LdCBank,$N31)="","—",INDEX(LdCBank,$N31)),""))) | E31: =IF($L31<>"",IF(INDEX(LdAAmt,$L31)=0,"",INDEX(LdAAmt,$L31)),IF($M31<>"",IF(INDEX(LdBAmt,$M31)=0,"",INDEX(LdBAmt,$M31)),IF($N31<>"",IF(INDEX(LdCDep,$N31)=0,"",INDEX(LdCDep,$N31)),""))) | F31: =IF(AND($L31="",$M31="",$N31=""),"",IF($N31="","",IF(INDEX(LdCWit,$N31)=0,"",INDEX(LdCWit,$N31)))) | G31: =IF($B31="","",IF($G30="",0,$G30)+IF($E31="",0,$E31)-IF($F31="",0,$F31)) | H31: =IF(AND($L31="",$M31="",$N31=""),"",IF($L31<>"",IF(INDEX(LdANote,$L31)="","—",INDEX(LdANote,$L31)),IF($M31<>"",IF(INDEX(LdBNote,$M31)="","—",INDEX(LdBNote,$M31)),IF($N31<>"",IF(INDEX(LdCNote,$N31)="","—",INDEX(LdCNote,$N31)),"")))) | L31: =IFERROR(MATCH($C$5&"|"&RIGHT("000000"&15,6),LdAKeyM,0),"") | M31: =IFERROR(MATCH($C$5&"|"&RIGHT("000000"&15,6),LdBKeyM,0),"") | N31: =IFERROR(MATCH($C$5&"|"&RIGHT("000000"&15,6),LdCKeyM,0),"")
A32: 16 | B32: =IF(AND($L32="",$M32="",$N32=""),"",IF($L32<>"",INDEX(LdADate,$L32),IF($M32<>"",INDEX(LdBDate,$M32),INDEX(LdCDate,$N32)))) | C32: =IF($L32<>"","دستمزد (فردی)",IF($M32<>"","سهم از گروه "&IFERROR(VLOOKUP(INDEX(LdBGroup,$M32),WGTbl,2,0),INDEX(LdBGroup,$M32)),IF($N32<>"",IF(N(INDEX(LdCDep,$N32))>0,"بازگشت بانکی","پرداخت بانکی"),""))) | D32: =IF($L32<>"",IF(INDEX(LdAId,$L32)="","—",INDEX(LdAId,$L32)),IF($M32<>"",IF(INDEX(LdBId,$M32)="","—",INDEX(LdBId,$M32)),IF($N32<>"",IF(INDEX(LdCBank,$N32)="","—",INDEX(LdCBank,$N32)),""))) | E32: =IF($L32<>"",IF(INDEX(LdAAmt,$L32)=0,"",INDEX(LdAAmt,$L32)),IF($M32<>"",IF(INDEX(LdBAmt,$M32)=0,"",INDEX(LdBAmt,$M32)),IF($N32<>"",IF(INDEX(LdCDep,$N32)=0,"",INDEX(LdCDep,$N32)),""))) | F32: =IF(AND($L32="",$M32="",$N32=""),"",IF($N32="","",IF(INDEX(LdCWit,$N32)=0,"",INDEX(LdCWit,$N32)))) | G32: =IF($B32="","",IF($G31="",0,$G31)+IF($E32="",0,$E32)-IF($F32="",0,$F32)) | H32: =IF(AND($L32="",$M32="",$N32=""),"",IF($L32<>"",IF(INDEX(LdANote,$L32)="","—",INDEX(LdANote,$L32)),IF($M32<>"",IF(INDEX(LdBNote,$M32)="","—",INDEX(LdBNote,$M32)),IF($N32<>"",IF(INDEX(LdCNote,$N32)="","—",INDEX(LdCNote,$N32)),"")))) | L32: =IFERROR(MATCH($C$5&"|"&RIGHT("000000"&16,6),LdAKeyM,0),"") | M32: =IFERROR(MATCH($C$5&"|"&RIGHT("000000"&16,6),LdBKeyM,0),"") | N32: =IFERROR(MATCH($C$5&"|"&RIGHT("000000"&16,6),LdCKeyM,0),"")
A33: 17 | B33: =IF(AND($L33="",$M33="",$N33=""),"",IF($L33<>"",INDEX(LdADate,$L33),IF($M33<>"",INDEX(LdBDate,$M33),INDEX(LdCDate,$N33)))) | C33: =IF($L33<>"","دستمزد (فردی)",IF($M33<>"","سهم از گروه "&IFERROR(VLOOKUP(INDEX(LdBGroup,$M33),WGTbl,2,0),INDEX(LdBGroup,$M33)),IF($N33<>"",IF(N(INDEX(LdCDep,$N33))>0,"بازگشت بانکی","پرداخت بانکی"),""))) | D33: =IF($L33<>"",IF(INDEX(LdAId,$L33)="","—",INDEX(LdAId,$L33)),IF($M33<>"",IF(INDEX(LdBId,$M33)="","—",INDEX(LdBId,$M33)),IF($N33<>"",IF(INDEX(LdCBank,$N33)="","—",INDEX(LdCBank,$N33)),""))) | E33: =IF($L33<>"",IF(INDEX(LdAAmt,$L33)=0,"",INDEX(LdAAmt,$L33)),IF($M33<>"",IF(INDEX(LdBAmt,$M33)=0,"",INDEX(LdBAmt,$M33)),IF($N33<>"",IF(INDEX(LdCDep,$N33)=0,"",INDEX(LdCDep,$N33)),""))) | F33: =IF(AND($L33="",$M33="",$N33=""),"",IF($N33="","",IF(INDEX(LdCWit,$N33)=0,"",INDEX(LdCWit,$N33)))) | G33: =IF($B33="","",IF($G32="",0,$G32)+IF($E33="",0,$E33)-IF($F33="",0,$F33)) | H33: =IF(AND($L33="",$M33="",$N33=""),"",IF($L33<>"",IF(INDEX(LdANote,$L33)="","—",INDEX(LdANote,$L33)),IF($M33<>"",IF(INDEX(LdBNote,$M33)="","—",INDEX(LdBNote,$M33)),IF($N33<>"",IF(INDEX(LdCNote,$N33)="","—",INDEX(LdCNote,$N33)),"")))) | L33: =IFERROR(MATCH($C$5&"|"&RIGHT("000000"&17,6),LdAKeyM,0),"") | M33: =IFERROR(MATCH($C$5&"|"&RIGHT("000000"&17,6),LdBKeyM,0),"") | N33: =IFERROR(MATCH($C$5&"|"&RIGHT("000000"&17,6),LdCKeyM,0),"")
A34: 18 | B34: =IF(AND($L34="",$M34="",$N34=""),"",IF($L34<>"",INDEX(LdADate,$L34),IF($M34<>"",INDEX(LdBDate,$M34),INDEX(LdCDate,$N34)))) | C34: =IF($L34<>"","دستمزد (فردی)",IF($M34<>"","سهم از گروه "&IFERROR(VLOOKUP(INDEX(LdBGroup,$M34),WGTbl,2,0),INDEX(LdBGroup,$M34)),IF($N34<>"",IF(N(INDEX(LdCDep,$N34))>0,"بازگشت بانکی","پرداخت بانکی"),""))) | D34: =IF($L34<>"",IF(INDEX(LdAId,$L34)="","—",INDEX(LdAId,$L34)),IF($M34<>"",IF(INDEX(LdBId,$M34)="","—",INDEX(LdBId,$M34)),IF($N34<>"",IF(INDEX(LdCBank,$N34)="","—",INDEX(LdCBank,$N34)),""))) | E34: =IF($L34<>"",IF(INDEX(LdAAmt,$L34)=0,"",INDEX(LdAAmt,$L34)),IF($M34<>"",IF(INDEX(LdBAmt,$M34)=0,"",INDEX(LdBAmt,$M34)),IF($N34<>"",IF(INDEX(LdCDep,$N34)=0,"",INDEX(LdCDep,$N34)),""))) | F34: =IF(AND($L34="",$M34="",$N34=""),"",IF($N34="","",IF(INDEX(LdCWit,$N34)=0,"",INDEX(LdCWit,$N34)))) | G34: =IF($B34="","",IF($G33="",0,$G33)+IF($E34="",0,$E34)-IF($F34="",0,$F34)) | H34: =IF(AND($L34="",$M34="",$N34=""),"",IF($L34<>"",IF(INDEX(LdANote,$L34)="","—",INDEX(LdANote,$L34)),IF($M34<>"",IF(INDEX(LdBNote,$M34)="","—",INDEX(LdBNote,$M34)),IF($N34<>"",IF(INDEX(LdCNote,$N34)="","—",INDEX(LdCNote,$N34)),"")))) | L34: =IFERROR(MATCH($C$5&"|"&RIGHT("000000"&18,6),LdAKeyM,0),"") | M34: =IFERROR(MATCH($C$5&"|"&RIGHT("000000"&18,6),LdBKeyM,0),"") | N34: =IFERROR(MATCH($C$5&"|"&RIGHT("000000"&18,6),LdCKeyM,0),"")
A35: 19 | B35: =IF(AND($L35="",$M35="",$N35=""),"",IF($L35<>"",INDEX(LdADate,$L35),IF($M35<>"",INDEX(LdBDate,$M35),INDEX(LdCDate,$N35)))) | C35: =IF($L35<>"","دستمزد (فردی)",IF($M35<>"","سهم از گروه "&IFERROR(VLOOKUP(INDEX(LdBGroup,$M35),WGTbl,2,0),INDEX(LdBGroup,$M35)),IF($N35<>"",IF(N(INDEX(LdCDep,$N35))>0,"بازگشت بانکی","پرداخت بانکی"),""))) | D35: =IF($L35<>"",IF(INDEX(LdAId,$L35)="","—",INDEX(LdAId,$L35)),IF($M35<>"",IF(INDEX(LdBId,$M35)="","—",INDEX(LdBId,$M35)),IF($N35<>"",IF(INDEX(LdCBank,$N35)="","—",INDEX(LdCBank,$N35)),""))) | E35: =IF($L35<>"",IF(INDEX(LdAAmt,$L35)=0,"",INDEX(LdAAmt,$L35)),IF($M35<>"",IF(INDEX(LdBAmt,$M35)=0,"",INDEX(LdBAmt,$M35)),IF($N35<>"",IF(INDEX(LdCDep,$N35)=0,"",INDEX(LdCDep,$N35)),""))) | F35: =IF(AND($L35="",$M35="",$N35=""),"",IF($N35="","",IF(INDEX(LdCWit,$N35)=0,"",INDEX(LdCWit,$N35)))) | G35: =IF($B35="","",IF($G34="",0,$G34)+IF($E35="",0,$E35)-IF($F35="",0,$F35)) | H35: =IF(AND($L35="",$M35="",$N35=""),"",IF($L35<>"",IF(INDEX(LdANote,$L35)="","—",INDEX(LdANote,$L35)),IF($M35<>"",IF(INDEX(LdBNote,$M35)="","—",INDEX(LdBNote,$M35)),IF($N35<>"",IF(INDEX(LdCNote,$N35)="","—",INDEX(LdCNote,$N35)),"")))) | L35: =IFERROR(MATCH($C$5&"|"&RIGHT("000000"&19,6),LdAKeyM,0),"") | M35: =IFERROR(MATCH($C$5&"|"&RIGHT("000000"&19,6),LdBKeyM,0),"") | N35: =IFERROR(MATCH($C$5&"|"&RIGHT("000000"&19,6),LdCKeyM,0),"")
A36: 20 | B36: =IF(AND($L36="",$M36="",$N36=""),"",IF($L36<>"",INDEX(LdADate,$L36),IF($M36<>"",INDEX(LdBDate,$M36),INDEX(LdCDate,$N36)))) | C36: =IF($L36<>"","دستمزد (فردی)",IF($M36<>"","سهم از گروه "&IFERROR(VLOOKUP(INDEX(LdBGroup,$M36),WGTbl,2,0),INDEX(LdBGroup,$M36)),IF($N36<>"",IF(N(INDEX(LdCDep,$N36))>0,"بازگشت بانکی","پرداخت بانکی"),""))) | D36: =IF($L36<>"",IF(INDEX(LdAId,$L36)="","—",INDEX(LdAId,$L36)),IF($M36<>"",IF(INDEX(LdBId,$M36)="","—",INDEX(LdBId,$M36)),IF($N36<>"",IF(INDEX(LdCBank,$N36)="","—",INDEX(LdCBank,$N36)),""))) | E36: =IF($L36<>"",IF(INDEX(LdAAmt,$L36)=0,"",INDEX(LdAAmt,$L36)),IF($M36<>"",IF(INDEX(LdBAmt,$M36)=0,"",INDEX(LdBAmt,$M36)),IF($N36<>"",IF(INDEX(LdCDep,$N36)=0,"",INDEX(LdCDep,$N36)),""))) | F36: =IF(AND($L36="",$M36="",$N36=""),"",IF($N36="","",IF(INDEX(LdCWit,$N36)=0,"",INDEX(LdCWit,$N36)))) | G36: =IF($B36="","",IF($G35="",0,$G35)+IF($E36="",0,$E36)-IF($F36="",0,$F36)) | H36: =IF(AND($L36="",$M36="",$N36=""),"",IF($L36<>"",IF(INDEX(LdANote,$L36)="","—",INDEX(LdANote,$L36)),IF($M36<>"",IF(INDEX(LdBNote,$M36)="","—",INDEX(LdBNote,$M36)),IF($N36<>"",IF(INDEX(LdCNote,$N36)="","—",INDEX(LdCNote,$N36)),"")))) | L36: =IFERROR(MATCH($C$5&"|"&RIGHT("000000"&20,6),LdAKeyM,0),"") | M36: =IFERROR(MATCH($C$5&"|"&RIGHT("000000"&20,6),LdBKeyM,0),"") | N36: =IFERROR(MATCH($C$5&"|"&RIGHT("000000"&20,6),LdCKeyM,0),"")
A37: 21 | B37: =IF(AND($L37="",$M37="",$N37=""),"",IF($L37<>"",INDEX(LdADate,$L37),IF($M37<>"",INDEX(LdBDate,$M37),INDEX(LdCDate,$N37)))) | C37: =IF($L37<>"","دستمزد (فردی)",IF($M37<>"","سهم از گروه "&IFERROR(VLOOKUP(INDEX(LdBGroup,$M37),WGTbl,2,0),INDEX(LdBGroup,$M37)),IF($N37<>"",IF(N(INDEX(LdCDep,$N37))>0,"بازگشت بانکی","پرداخت بانکی"),""))) | D37: =IF($L37<>"",IF(INDEX(LdAId,$L37)="","—",INDEX(LdAId,$L37)),IF($M37<>"",IF(INDEX(LdBId,$M37)="","—",INDEX(LdBId,$M37)),IF($N37<>"",IF(INDEX(LdCBank,$N37)="","—",INDEX(LdCBank,$N37)),""))) | E37: =IF($L37<>"",IF(INDEX(LdAAmt,$L37)=0,"",INDEX(LdAAmt,$L37)),IF($M37<>"",IF(INDEX(LdBAmt,$M37)=0,"",INDEX(LdBAmt,$M37)),IF($N37<>"",IF(INDEX(LdCDep,$N37)=0,"",INDEX(LdCDep,$N37)),""))) | F37: =IF(AND($L37="",$M37="",$N37=""),"",IF($N37="","",IF(INDEX(LdCWit,$N37)=0,"",INDEX(LdCWit,$N37)))) | G37: =IF($B37="","",IF($G36="",0,$G36)+IF($E37="",0,$E37)-IF($F37="",0,$F37)) | H37: =IF(AND($L37="",$M37="",$N37=""),"",IF($L37<>"",IF(INDEX(LdANote,$L37)="","—",INDEX(LdANote,$L37)),IF($M37<>"",IF(INDEX(LdBNote,$M37)="","—",INDEX(LdBNote,$M37)),IF($N37<>"",IF(INDEX(LdCNote,$N37)="","—",INDEX(LdCNote,$N37)),"")))) | L37: =IFERROR(MATCH($C$5&"|"&RIGHT("000000"&21,6),LdAKeyM,0),"") | M37: =IFERROR(MATCH($C$5&"|"&RIGHT("000000"&21,6),LdBKeyM,0),"") | N37: =IFERROR(MATCH($C$5&"|"&RIGHT("000000"&21,6),LdCKeyM,0),"")
A38: 22 | B38: =IF(AND($L38="",$M38="",$N38=""),"",IF($L38<>"",INDEX(LdADate,$L38),IF($M38<>"",INDEX(LdBDate,$M38),INDEX(LdCDate,$N38)))) | C38: =IF($L38<>"","دستمزد (فردی)",IF($M38<>"","سهم از گروه "&IFERROR(VLOOKUP(INDEX(LdBGroup,$M38),WGTbl,2,0),INDEX(LdBGroup,$M38)),IF($N38<>"",IF(N(INDEX(LdCDep,$N38))>0,"بازگشت بانکی","پرداخت بانکی"),""))) | D38: =IF($L38<>"",IF(INDEX(LdAId,$L38)="","—",INDEX(LdAId,$L38)),IF($M38<>"",IF(INDEX(LdBId,$M38)="","—",INDEX(LdBId,$M38)),IF($N38<>"",IF(INDEX(LdCBank,$N38)="","—",INDEX(LdCBank,$N38)),""))) | E38: =IF($L38<>"",IF(INDEX(LdAAmt,$L38)=0,"",INDEX(LdAAmt,$L38)),IF($M38<>"",IF(INDEX(LdBAmt,$M38)=0,"",INDEX(LdBAmt,$M38)),IF($N38<>"",IF(INDEX(LdCDep,$N38)=0,"",INDEX(LdCDep,$N38)),""))) | F38: =IF(AND($L38="",$M38="",$N38=""),"",IF($N38="","",IF(INDEX(LdCWit,$N38)=0,"",INDEX(LdCWit,$N38)))) | G38: =IF($B38="","",IF($G37="",0,$G37)+IF($E38="",0,$E38)-IF($F38="",0,$F38)) | H38: =IF(AND($L38="",$M38="",$N38=""),"",IF($L38<>"",IF(INDEX(LdANote,$L38)="","—",INDEX(LdANote,$L38)),IF($M38<>"",IF(INDEX(LdBNote,$M38)="","—",INDEX(LdBNote,$M38)),IF($N38<>"",IF(INDEX(LdCNote,$N38)="","—",INDEX(LdCNote,$N38)),"")))) | L38: =IFERROR(MATCH($C$5&"|"&RIGHT("000000"&22,6),LdAKeyM,0),"") | M38: =IFERROR(MATCH($C$5&"|"&RIGHT("000000"&22,6),LdBKeyM,0),"") | N38: =IFERROR(MATCH($C$5&"|"&RIGHT("000000"&22,6),LdCKeyM,0),"")
A39: 23 | B39: =IF(AND($L39="",$M39="",$N39=""),"",IF($L39<>"",INDEX(LdADate,$L39),IF($M39<>"",INDEX(LdBDate,$M39),INDEX(LdCDate,$N39)))) | C39: =IF($L39<>"","دستمزد (فردی)",IF($M39<>"","سهم از گروه "&IFERROR(VLOOKUP(INDEX(LdBGroup,$M39),WGTbl,2,0),INDEX(LdBGroup,$M39)),IF($N39<>"",IF(N(INDEX(LdCDep,$N39))>0,"بازگشت بانکی","پرداخت بانکی"),""))) | D39: =IF($L39<>"",IF(INDEX(LdAId,$L39)="","—",INDEX(LdAId,$L39)),IF($M39<>"",IF(INDEX(LdBId,$M39)="","—",INDEX(LdBId,$M39)),IF($N39<>"",IF(INDEX(LdCBank,$N39)="","—",INDEX(LdCBank,$N39)),""))) | E39: =IF($L39<>"",IF(INDEX(LdAAmt,$L39)=0,"",INDEX(LdAAmt,$L39)),IF($M39<>"",IF(INDEX(LdBAmt,$M39)=0,"",INDEX(LdBAmt,$M39)),IF($N39<>"",IF(INDEX(LdCDep,$N39)=0,"",INDEX(LdCDep,$N39)),""))) | F39: =IF(AND($L39="",$M39="",$N39=""),"",IF($N39="","",IF(INDEX(LdCWit,$N39)=0,"",INDEX(LdCWit,$N39)))) | G39: =IF($B39="","",IF($G38="",0,$G38)+IF($E39="",0,$E39)-IF($F39="",0,$F39)) | H39: =IF(AND($L39="",$M39="",$N39=""),"",IF($L39<>"",IF(INDEX(LdANote,$L39)="","—",INDEX(LdANote,$L39)),IF($M39<>"",IF(INDEX(LdBNote,$M39)="","—",INDEX(LdBNote,$M39)),IF($N39<>"",IF(INDEX(LdCNote,$N39)="","—",INDEX(LdCNote,$N39)),"")))) | L39: =IFERROR(MATCH($C$5&"|"&RIGHT("000000"&23,6),LdAKeyM,0),"") | M39: =IFERROR(MATCH($C$5&"|"&RIGHT("000000"&23,6),LdBKeyM,0),"") | N39: =IFERROR(MATCH($C$5&"|"&RIGHT("000000"&23,6),LdCKeyM,0),"")
A40: 24 | B40: =IF(AND($L40="",$M40="",$N40=""),"",IF($L40<>"",INDEX(LdADate,$L40),IF($M40<>"",INDEX(LdBDate,$M40),INDEX(LdCDate,$N40)))) | C40: =IF($L40<>"","دستمزد (فردی)",IF($M40<>"","سهم از گروه "&IFERROR(VLOOKUP(INDEX(LdBGroup,$M40),WGTbl,2,0),INDEX(LdBGroup,$M40)),IF($N40<>"",IF(N(INDEX(LdCDep,$N40))>0,"بازگشت بانکی","پرداخت بانکی"),""))) | D40: =IF($L40<>"",IF(INDEX(LdAId,$L40)="","—",INDEX(LdAId,$L40)),IF($M40<>"",IF(INDEX(LdBId,$M40)="","—",INDEX(LdBId,$M40)),IF($N40<>"",IF(INDEX(LdCBank,$N40)="","—",INDEX(LdCBank,$N40)),""))) | E40: =IF($L40<>"",IF(INDEX(LdAAmt,$L40)=0,"",INDEX(LdAAmt,$L40)),IF($M40<>"",IF(INDEX(LdBAmt,$M40)=0,"",INDEX(LdBAmt,$M40)),IF($N40<>"",IF(INDEX(LdCDep,$N40)=0,"",INDEX(LdCDep,$N40)),""))) | F40: =IF(AND($L40="",$M40="",$N40=""),"",IF($N40="","",IF(INDEX(LdCWit,$N40)=0,"",INDEX(LdCWit,$N40)))) | G40: =IF($B40="","",IF($G39="",0,$G39)+IF($E40="",0,$E40)-IF($F40="",0,$F40)) | H40: =IF(AND($L40="",$M40="",$N40=""),"",IF($L40<>"",IF(INDEX(LdANote,$L40)="","—",INDEX(LdANote,$L40)),IF($M40<>"",IF(INDEX(LdBNote,$M40)="","—",INDEX(LdBNote,$M40)),IF($N40<>"",IF(INDEX(LdCNote,$N40)="","—",INDEX(LdCNote,$N40)),"")))) | L40: =IFERROR(MATCH($C$5&"|"&RIGHT("000000"&24,6),LdAKeyM,0),"") | M40: =IFERROR(MATCH($C$5&"|"&RIGHT("000000"&24,6),LdBKeyM,0),"") | N40: =IFERROR(MATCH($C$5&"|"&RIGHT("000000"&24,6),LdCKeyM,0),"")
A41: 25 | B41: =IF(AND($L41="",$M41="",$N41=""),"",IF($L41<>"",INDEX(LdADate,$L41),IF($M41<>"",INDEX(LdBDate,$M41),INDEX(LdCDate,$N41)))) | C41: =IF($L41<>"","دستمزد (فردی)",IF($M41<>"","سهم از گروه "&IFERROR(VLOOKUP(INDEX(LdBGroup,$M41),WGTbl,2,0),INDEX(LdBGroup,$M41)),IF($N41<>"",IF(N(INDEX(LdCDep,$N41))>0,"بازگشت بانکی","پرداخت بانکی"),""))) | D41: =IF($L41<>"",IF(INDEX(LdAId,$L41)="","—",INDEX(LdAId,$L41)),IF($M41<>"",IF(INDEX(LdBId,$M41)="","—",INDEX(LdBId,$M41)),IF($N41<>"",IF(INDEX(LdCBank,$N41)="","—",INDEX(LdCBank,$N41)),""))) | E41: =IF($L41<>"",IF(INDEX(LdAAmt,$L41)=0,"",INDEX(LdAAmt,$L41)),IF($M41<>"",IF(INDEX(LdBAmt,$M41)=0,"",INDEX(LdBAmt,$M41)),IF($N41<>"",IF(INDEX(LdCDep,$N41)=0,"",INDEX(LdCDep,$N41)),""))) | F41: =IF(AND($L41="",$M41="",$N41=""),"",IF($N41="","",IF(INDEX(LdCWit,$N41)=0,"",INDEX(LdCWit,$N41)))) | G41: =IF($B41="","",IF($G40="",0,$G40)+IF($E41="",0,$E41)-IF($F41="",0,$F41)) | H41: =IF(AND($L41="",$M41="",$N41=""),"",IF($L41<>"",IF(INDEX(LdANote,$L41)="","—",INDEX(LdANote,$L41)),IF($M41<>"",IF(INDEX(LdBNote,$M41)="","—",INDEX(LdBNote,$M41)),IF($N41<>"",IF(INDEX(LdCNote,$N41)="","—",INDEX(LdCNote,$N41)),"")))) | L41: =IFERROR(MATCH($C$5&"|"&RIGHT("000000"&25,6),LdAKeyM,0),"") | M41: =IFERROR(MATCH($C$5&"|"&RIGHT("000000"&25,6),LdBKeyM,0),"") | N41: =IFERROR(MATCH($C$5&"|"&RIGHT("000000"&25,6),LdCKeyM,0),"")
...

Sheet GroupReport
A1: =IF(Sync!$AI$6="","مازندشت",Sync!$AI$6)&" — "&IF(Sync!$AI$9="","سورتینگ و بسته‌بندی مرکبات",Sync!$AI$9)
A2: =IF(Sync!$AI$7="","باغدشت، بخش مرکزی، شهرستان قائم‌شهر، استان مازندران، ایران",Sync!$AI$7)&" | MAZANDASHT · CITRUS SORTING & PACKING"
A3: ="گزارش گروه کاری — "&IFERROR(IF(VLOOKUP($C$5,WGTbl,2,0)="","(بدون عنوان)",VLOOKUP($C$5,WGTbl,2,0)),"کد گروه را وارد کنید")
A5: کد گروه کاری (ورود دستی): | C5: WG01 | E5: کد را از INFO (شیت WorkGroups) وارد کنید. برای گروه دیگر، همین شیت را کپی و کد را عوض کنید.
A6: عنوان گروه: | C6: =IFERROR(IF(VLOOKUP($C$5,WGTbl,2,0)="","(بدون عنوان)",VLOOKUP($C$5,WGTbl,2,0)),"—")
A7: توضیح: | C7: =IFERROR(IF(VLOOKUP($C$5,WGTbl,3,0)="","—",VLOOKUP($C$5,WGTbl,3,0)),"—")
A8: اعضای گروه (INFO ← Staff): | C8: =IF($C$5="","—",COUNTIF(StaffGrpE,$C$5)&" نفر" &IF(COUNTIF(StaffGrpE,$C$5)=0," (هیچ عضوی تعیین نشده)"," (صرفاً اطلاعاتی — ریز سهم‌ها دستی وارد می‌شوند)"))
A9: بخش ۱: رویدادهای دستمزد گروهی این گروه با کنترل تطابق مبلغ کل با جمع ریز | بخش ۲: ریز سهم هر عضو به ترتیب تاریخ.
A11: جمع مبالغ رویدادها (ریال) | C11: جمع ریز توزیع‌شده (ریال) | E11: مغایرت (ریال) | G11: وضعیت
A12: =SUM($D$17:$D$2016) | C12: =SUM($F$2021:$F$4020) | E12: =$A$12-$C$12 | G12: =IF(ROUND($A$12-$C$12,0)=0,"√","▲")
A13: تعداد رویداد گروهی | C13: تعداد ردیف ریز | E13: آخرین رویداد | G13: اعضا
A14: =COUNT($D$17:$D$2016) | C14: =COUNT($F$2021:$F$4020) | E14: =IF(COUNT($D$17:$D$2016)=0,"—",INDEX($B$17:$B$2016,COUNT($D$17:$D$2016))) | G14: =IF($C$5="","—",COUNTIF(StaffGrpE,$C$5))
A15: ردیف | B15: تاریخ | C15: شناسه | D15: مبلغ کل (ریال) | E15: جمع ریز (ریال) | F15: تعداد سهم | G15: وضعیت
A16: No. | B16: Date | C16: Doc ID | D16: Total | E16: Shares Sum | F16: Shares | G16: Status
A17: 1 | B17: =IF($N17="","",INDEX(LdADate,$N17)) | C17: =IF($N17="","",IF(INDEX(LdAId,$N17)="","—",INDEX(LdAId,$N17))) | D17: =IF($N17="","",IF(INDEX(LdAAmt,$N17)=0,"",INDEX(LdAAmt,$N17))) | E17: =IF($N17="","",SUMIFS(ShareAmt,ShareLink,$C17)) | F17: =IF($N17="","",COUNTIF(ShareLink,$C17)) | G17: =IF($N17="","",IF(ROUND($E17-$D17,0)=0,"√","▲ "&TEXT($D17-$E17,"#,##0"))) | N17: =IFERROR(MATCH($C$5&"|"&RIGHT("000000"&1,6),LdAKeyG,0),"")
A18: 2 | B18: =IF($N18="","",INDEX(LdADate,$N18)) | C18: =IF($N18="","",IF(INDEX(LdAId,$N18)="","—",INDEX(LdAId,$N18))) | D18: =IF($N18="","",IF(INDEX(LdAAmt,$N18)=0,"",INDEX(LdAAmt,$N18))) | E18: =IF($N18="","",SUMIFS(ShareAmt,ShareLink,$C18)) | F18: =IF($N18="","",COUNTIF(ShareLink,$C18)) | G18: =IF($N18="","",IF(ROUND($E18-$D18,0)=0,"√","▲ "&TEXT($D18-$E18,"#,##0"))) | N18: =IFERROR(MATCH($C$5&"|"&RIGHT("000000"&2,6),LdAKeyG,0),"")
A19: 3 | B19: =IF($N19="","",INDEX(LdADate,$N19)) | C19: =IF($N19="","",IF(INDEX(LdAId,$N19)="","—",INDEX(LdAId,$N19))) | D19: =IF($N19="","",IF(INDEX(LdAAmt,$N19)=0,"",INDEX(LdAAmt,$N19))) | E19: =IF($N19="","",SUMIFS(ShareAmt,ShareLink,$C19)) | F19: =IF($N19="","",COUNTIF(ShareLink,$C19)) | G19: =IF($N19="","",IF(ROUND($E19-$D19,0)=0,"√","▲ "&TEXT($D19-$E19,"#,##0"))) | N19: =IFERROR(MATCH($C$5&"|"&RIGHT("000000"&3,6),LdAKeyG,0),"")
A20: 4 | B20: =IF($N20="","",INDEX(LdADate,$N20)) | C20: =IF($N20="","",IF(INDEX(LdAId,$N20)="","—",INDEX(LdAId,$N20))) | D20: =IF($N20="","",IF(INDEX(LdAAmt,$N20)=0,"",INDEX(LdAAmt,$N20))) | E20: =IF($N20="","",SUMIFS(ShareAmt,ShareLink,$C20)) | F20: =IF($N20="","",COUNTIF(ShareLink,$C20)) | G20: =IF($N20="","",IF(ROUND($E20-$D20,0)=0,"√","▲ "&TEXT($D20-$E20,"#,##0"))) | N20: =IFERROR(MATCH($C$5&"|"&RIGHT("000000"&4,6),LdAKeyG,0),"")
A21: 5 | B21: =IF($N21="","",INDEX(LdADate,$N21)) | C21: =IF($N21="","",IF(INDEX(LdAId,$N21)="","—",INDEX(LdAId,$N21))) | D21: =IF($N21="","",IF(INDEX(LdAAmt,$N21)=0,"",INDEX(LdAAmt,$N21))) | E21: =IF($N21="","",SUMIFS(ShareAmt,ShareLink,$C21)) | F21: =IF($N21="","",COUNTIF(ShareLink,$C21)) | G21: =IF($N21="","",IF(ROUND($E21-$D21,0)=0,"√","▲ "&TEXT($D21-$E21,"#,##0"))) | N21: =IFERROR(MATCH($C$5&"|"&RIGHT("000000"&5,6),LdAKeyG,0),"")
A22: 6 | B22: =IF($N22="","",INDEX(LdADate,$N22)) | C22: =IF($N22="","",IF(INDEX(LdAId,$N22)="","—",INDEX(LdAId,$N22))) | D22: =IF($N22="","",IF(INDEX(LdAAmt,$N22)=0,"",INDEX(LdAAmt,$N22))) | E22: =IF($N22="","",SUMIFS(ShareAmt,ShareLink,$C22)) | F22: =IF($N22="","",COUNTIF(ShareLink,$C22)) | G22: =IF($N22="","",IF(ROUND($E22-$D22,0)=0,"√","▲ "&TEXT($D22-$E22,"#,##0"))) | N22: =IFERROR(MATCH($C$5&"|"&RIGHT("000000"&6,6),LdAKeyG,0),"")
A23: 7 | B23: =IF($N23="","",INDEX(LdADate,$N23)) | C23: =IF($N23="","",IF(INDEX(LdAId,$N23)="","—",INDEX(LdAId,$N23))) | D23: =IF($N23="","",IF(INDEX(LdAAmt,$N23)=0,"",INDEX(LdAAmt,$N23))) | E23: =IF($N23="","",SUMIFS(ShareAmt,ShareLink,$C23)) | F23: =IF($N23="","",COUNTIF(ShareLink,$C23)) | G23: =IF($N23="","",IF(ROUND($E23-$D23,0)=0,"√","▲ "&TEXT($D23-$E23,"#,##0"))) | N23: =IFERROR(MATCH($C$5&"|"&RIGHT("000000"&7,6),LdAKeyG,0),"")
A24: 8 | B24: =IF($N24="","",INDEX(LdADate,$N24)) | C24: =IF($N24="","",IF(INDEX(LdAId,$N24)="","—",INDEX(LdAId,$N24))) | D24: =IF($N24="","",IF(INDEX(LdAAmt,$N24)=0,"",INDEX(LdAAmt,$N24))) | E24: =IF($N24="","",SUMIFS(ShareAmt,ShareLink,$C24)) | F24: =IF($N24="","",COUNTIF(ShareLink,$C24)) | G24: =IF($N24="","",IF(ROUND($E24-$D24,0)=0,"√","▲ "&TEXT($D24-$E24,"#,##0"))) | N24: =IFERROR(MATCH($C$5&"|"&RIGHT("000000"&8,6),LdAKeyG,0),"")
A25: 9 | B25: =IF($N25="","",INDEX(LdADate,$N25)) | C25: =IF($N25="","",IF(INDEX(LdAId,$N25)="","—",INDEX(LdAId,$N25))) | D25: =IF($N25="","",IF(INDEX(LdAAmt,$N25)=0,"",INDEX(LdAAmt,$N25))) | E25: =IF($N25="","",SUMIFS(ShareAmt,ShareLink,$C25)) | F25: =IF($N25="","",COUNTIF(ShareLink,$C25)) | G25: =IF($N25="","",IF(ROUND($E25-$D25,0)=0,"√","▲ "&TEXT($D25-$E25,"#,##0"))) | N25: =IFERROR(MATCH($C$5&"|"&RIGHT("000000"&9,6),LdAKeyG,0),"")
A26: 10 | B26: =IF($N26="","",INDEX(LdADate,$N26)) | C26: =IF($N26="","",IF(INDEX(LdAId,$N26)="","—",INDEX(LdAId,$N26))) | D26: =IF($N26="","",IF(INDEX(LdAAmt,$N26)=0,"",INDEX(LdAAmt,$N26))) | E26: =IF($N26="","",SUMIFS(ShareAmt,ShareLink,$C26)) | F26: =IF($N26="","",COUNTIF(ShareLink,$C26)) | G26: =IF($N26="","",IF(ROUND($E26-$D26,0)=0,"√","▲ "&TEXT($D26-$E26,"#,##0"))) | N26: =IFERROR(MATCH($C$5&"|"&RIGHT("000000"&10,6),LdAKeyG,0),"")
A27: 11 | B27: =IF($N27="","",INDEX(LdADate,$N27)) | C27: =IF($N27="","",IF(INDEX(LdAId,$N27)="","—",INDEX(LdAId,$N27))) | D27: =IF($N27="","",IF(INDEX(LdAAmt,$N27)=0,"",INDEX(LdAAmt,$N27))) | E27: =IF($N27="","",SUMIFS(ShareAmt,ShareLink,$C27)) | F27: =IF($N27="","",COUNTIF(ShareLink,$C27)) | G27: =IF($N27="","",IF(ROUND($E27-$D27,0)=0,"√","▲ "&TEXT($D27-$E27,"#,##0"))) | N27: =IFERROR(MATCH($C$5&"|"&RIGHT("000000"&11,6),LdAKeyG,0),"")
A28: 12 | B28: =IF($N28="","",INDEX(LdADate,$N28)) | C28: =IF($N28="","",IF(INDEX(LdAId,$N28)="","—",INDEX(LdAId,$N28))) | D28: =IF($N28="","",IF(INDEX(LdAAmt,$N28)=0,"",INDEX(LdAAmt,$N28))) | E28: =IF($N28="","",SUMIFS(ShareAmt,ShareLink,$C28)) | F28: =IF($N28="","",COUNTIF(ShareLink,$C28)) | G28: =IF($N28="","",IF(ROUND($E28-$D28,0)=0,"√","▲ "&TEXT($D28-$E28,"#,##0"))) | N28: =IFERROR(MATCH($C$5&"|"&RIGHT("000000"&12,6),LdAKeyG,0),"")
A29: 13 | B29: =IF($N29="","",INDEX(LdADate,$N29)) | C29: =IF($N29="","",IF(INDEX(LdAId,$N29)="","—",INDEX(LdAId,$N29))) | D29: =IF($N29="","",IF(INDEX(LdAAmt,$N29)=0,"",INDEX(LdAAmt,$N29))) | E29: =IF($N29="","",SUMIFS(ShareAmt,ShareLink,$C29)) | F29: =IF($N29="","",COUNTIF(ShareLink,$C29)) | G29: =IF($N29="","",IF(ROUND($E29-$D29,0)=0,"√","▲ "&TEXT($D29-$E29,"#,##0"))) | N29: =IFERROR(MATCH($C$5&"|"&RIGHT("000000"&13,6),LdAKeyG,0),"")
A30: 14 | B30: =IF($N30="","",INDEX(LdADate,$N30)) | C30: =IF($N30="","",IF(INDEX(LdAId,$N30)="","—",INDEX(LdAId,$N30))) | D30: =IF($N30="","",IF(INDEX(LdAAmt,$N30)=0,"",INDEX(LdAAmt,$N30))) | E30: =IF($N30="","",SUMIFS(ShareAmt,ShareLink,$C30)) | F30: =IF($N30="","",COUNTIF(ShareLink,$C30)) | G30: =IF($N30="","",IF(ROUND($E30-$D30,0)=0,"√","▲ "&TEXT($D30-$E30,"#,##0"))) | N30: =IFERROR(MATCH($C$5&"|"&RIGHT("000000"&14,6),LdAKeyG,0),"")
A31: 15 | B31: =IF($N31="","",INDEX(LdADate,$N31)) | C31: =IF($N31="","",IF(INDEX(LdAId,$N31)="","—",INDEX(LdAId,$N31))) | D31: =IF($N31="","",IF(INDEX(LdAAmt,$N31)=0,"",INDEX(LdAAmt,$N31))) | E31: =IF($N31="","",SUMIFS(ShareAmt,ShareLink,$C31)) | F31: =IF($N31="","",COUNTIF(ShareLink,$C31)) | G31: =IF($N31="","",IF(ROUND($E31-$D31,0)=0,"√","▲ "&TEXT($D31-$E31,"#,##0"))) | N31: =IFERROR(MATCH($C$5&"|"&RIGHT("000000"&15,6),LdAKeyG,0),"")
