Workbook
Name MainTbl: Sync!$A$6:$C$15
Name SubTbl: Sync!$E$6:$H$105
Name SubCodes: Sync!$E$6:$E$105
Name SubTitles: Sync!$G$6:$G$105
Name AcctTbl: Sync!$J$6:$M$565
Name PkSubExp: Sync!$AC$6:$AC$105
Name NSubExp: Sync!$AB$105
Name ExpNorm: Calc!$E$9:$E$2008
Name ExpTime: Calc!$F$9:$F$2008
Name ExpParty: Calc!$G$9:$G$2008
Name ExpBank: Calc!$H$9:$H$2008
Name ExpType: Calc!$I$9:$I$2008
Name ExpGroup: Calc!$J$9:$J$2008
Name ExpSub: Calc!$K$9:$K$2008
Name ExpDep: Calc!$L$9:$L$2008
Name ExpWit: Calc!$M$9:$M$2008
Name ExpKey: Calc!$O$9:$O$2008
Name ExpRankKey: Calc!$Q$9:$Q$2008
Name ExpNote: Sync!$Y$6:$Y$2005
Name ExpTotalNet: Summary!$G$111

Sheet Report
A1: =IF(Sync!$AE$6="","مازندشت",Sync!$AE$6)&" — "&IF(Sync!$AE$9="","سورتینگ و بسته‌بندی مرکبات",Sync!$AE$9)
A2: =IF(Sync!$AE$7="","باغدشت، بخش مرکزی، شهرستان قائم‌شهر، استان مازندران، ایران",Sync!$AE$7)&" | MAZANDASHT · CITRUS SORTING & PACKING"
A3: ="گزارش هزینه زیرگروه — "&IFERROR(IF(VLOOKUP($C$5,SubTbl,2,0)="","(بدون عنوان)",VLOOKUP($C$5,SubTbl,2,0)),"کد زیرگروه را وارد کنید")
A5: کد زیرگروه (ورود دستی): | C5: SG001 | E5: کد را از فایل INFO (شیت SubGroups) وارد کنید — سربرگ، کارت‌ها و کل فهرست خودکار به‌روز می‌شوند.
A6: عنوان زیرگروه: | C6: =IFERROR(IF(VLOOKUP($C$5,SubTbl,3,0)="","(بدون عنوان)",VLOOKUP($C$5,SubTbl,3,0)),"—")
A7: گروه اصلی: | C7: =IFERROR(IF(VLOOKUP($C$5,SubTbl,2,0)="","—",VLOOKUP($C$5,SubTbl,2,0)),"—")
A8: توضیح: | C8: =IFERROR(IF(VLOOKUP($C$5,SubTbl,4,0)="","—",VLOOKUP($C$5,SubTbl,4,0)),"—")
A9: فهرست زیر، همه تراکنش‌های گروه «هزینه» با این زیرگروه را به ترتیب تاریخ نشان می‌دهد. این شیت فقط نمایش/چاپ است؛ برای زیرگروه دیگر، شیت را کپی کنید و کد را عوض کنید.
A11: جمع برداشت (ریال) | C11: جمع واریز/بازگشت (ریال) | E11: خالص هزینه (ریال) | G11: تعداد تراکنش | I11: بزرگ‌ترین ردیف (ریال)
A12: =SUM($H$17:$H$2016) | C12: =SUM($G$17:$G$2016) | E12: =SUM($H$17:$H$2016)-SUM($G$17:$G$2016) | G12: =COUNT($I$17:$I$2016) | I12: =IF(COUNT($H$17:$H$2016)=0,"—",MAX($H$17:$H$2016))
A13: میانگین هر ردیف (ریال) | C13: سهم از کل هزینه | E13: اولین تاریخ | G13: آخرین تاریخ | I13: جمع خالص تا آخرین ردیف
A14: =IF($G$12=0,"—",ROUND($E$12/$G$12,0)) | C14: =IFERROR(IF(ExpTotalNet=0,"—",$E$12/ExpTotalNet),"—") | E14: =IF($G$12=0,"—",INDEX($B$17:$B$2016,1)) | G14: =IF($G$12=0,"—",INDEX($B$17:$B$2016,$G$12)) | I14: =IF($G$12=0,"—",LOOKUP(9.99E+307,$I$17:$I$2016))
A15: ردیف | B15: تاریخ | C15: ساعت | D15: بانک | E15: طرف حساب | F15: نوع تراکنش | G15: واریز (ریال) | H15: برداشت (ریال) | I15: جمع تجمعی خالص (ریال) | J15: توضیحات
A16: No. | B16: Date | C16: Time | D16: Bank | E16: Party | F16: Txn Type | G16: Deposit | H16: Withdrawal | I16: Cum. Net | J16: Notes
A17: 1 | B17: =IF($L17="","",INDEX(ExpNorm,$L17)) | C17: =IF($L17="","",IF(INDEX(ExpTime,$L17)="","—",LEFT(INDEX(ExpTime,$L17),2)&":"&RIGHT(INDEX(ExpTime,$L17),2))) | D17: =IF($L17="","",IF(INDEX(ExpBank,$L17)="","—",INDEX(ExpBank,$L17))) | E17: =IF($L17="","",IF(INDEX(ExpParty,$L17)="","—",IFERROR(VLOOKUP(INDEX(ExpParty,$L17),AcctTbl,4,0),INDEX(ExpParty,$L17)))) | F17: =IF($L17="","",IF(INDEX(ExpType,$L17)="","—",INDEX(ExpType,$L17))) | G17: =IF($L17="","",IF(INDEX(ExpDep,$L17)=0,"",INDEX(ExpDep,$L17))) | H17: =IF($L17="","",IF(INDEX(ExpWit,$L17)=0,"",INDEX(ExpWit,$L17))) | I17: =IF($B17="","",IF($H17="",0,$H17)-IF($G17="",0,$G17)) | J17: =IF($L17="","",IF(INDEX(ExpNote,$L17)="","—",INDEX(ExpNote,$L17))) | L17: =IFERROR(MATCH($C$5&"|"&RIGHT("000000"&1,6),ExpRankKey,0),"")
A18: 2 | B18: =IF($L18="","",INDEX(ExpNorm,$L18)) | C18: =IF($L18="","",IF(INDEX(ExpTime,$L18)="","—",LEFT(INDEX(ExpTime,$L18),2)&":"&RIGHT(INDEX(ExpTime,$L18),2))) | D18: =IF($L18="","",IF(INDEX(ExpBank,$L18)="","—",INDEX(ExpBank,$L18))) | E18: =IF($L18="","",IF(INDEX(ExpParty,$L18)="","—",IFERROR(VLOOKUP(INDEX(ExpParty,$L18),AcctTbl,4,0),INDEX(ExpParty,$L18)))) | F18: =IF($L18="","",IF(INDEX(ExpType,$L18)="","—",INDEX(ExpType,$L18))) | G18: =IF($L18="","",IF(INDEX(ExpDep,$L18)=0,"",INDEX(ExpDep,$L18))) | H18: =IF($L18="","",IF(INDEX(ExpWit,$L18)=0,"",INDEX(ExpWit,$L18))) | I18: =IF($B18="","",IF($I17="",0,$I17)+IF($H18="",0,$H18)-IF($G18="",0,$G18)) | J18: =IF($L18="","",IF(INDEX(ExpNote,$L18)="","—",INDEX(ExpNote,$L18))) | L18: =IFERROR(MATCH($C$5&"|"&RIGHT("000000"&2,6),ExpRankKey,0),"")
A19: 3 | B19: =IF($L19="","",INDEX(ExpNorm,$L19)) | C19: =IF($L19="","",IF(INDEX(ExpTime,$L19)="","—",LEFT(INDEX(ExpTime,$L19),2)&":"&RIGHT(INDEX(ExpTime,$L19),2))) | D19: =IF($L19="","",IF(INDEX(ExpBank,$L19)="","—",INDEX(ExpBank,$L19))) | E19: =IF($L19="","",IF(INDEX(ExpParty,$L19)="","—",IFERROR(VLOOKUP(INDEX(ExpParty,$L19),AcctTbl,4,0),INDEX(ExpParty,$L19)))) | F19: =IF($L19="","",IF(INDEX(ExpType,$L19)="","—",INDEX(ExpType,$L19))) | G19: =IF($L19="","",IF(INDEX(ExpDep,$L19)=0,"",INDEX(ExpDep,$L19))) | H19: =IF($L19="","",IF(INDEX(ExpWit,$L19)=0,"",INDEX(ExpWit,$L19))) | I19: =IF($B19="","",IF($I18="",0,$I18)+IF($H19="",0,$H19)-IF($G19="",0,$G19)) | J19: =IF($L19="","",IF(INDEX(ExpNote,$L19)="","—",INDEX(ExpNote,$L19))) | L19: =IFERROR(MATCH($C$5&"|"&RIGHT("000000"&3,6),ExpRankKey,0),"")
A20: 4 | B20: =IF($L20="","",INDEX(ExpNorm,$L20)) | C20: =IF($L20="","",IF(INDEX(ExpTime,$L20)="","—",LEFT(INDEX(ExpTime,$L20),2)&":"&RIGHT(INDEX(ExpTime,$L20),2))) | D20: =IF($L20="","",IF(INDEX(ExpBank,$L20)="","—",INDEX(ExpBank,$L20))) | E20: =IF($L20="","",IF(INDEX(ExpParty,$L20)="","—",IFERROR(VLOOKUP(INDEX(ExpParty,$L20),AcctTbl,4,0),INDEX(ExpParty,$L20)))) | F20: =IF($L20="","",IF(INDEX(ExpType,$L20)="","—",INDEX(ExpType,$L20))) | G20: =IF($L20="","",IF(INDEX(ExpDep,$L20)=0,"",INDEX(ExpDep,$L20))) | H20: =IF($L20="","",IF(INDEX(ExpWit,$L20)=0,"",INDEX(ExpWit,$L20))) | I20: =IF($B20="","",IF($I19="",0,$I19)+IF($H20="",0,$H20)-IF($G20="",0,$G20)) | J20: =IF($L20="","",IF(INDEX(ExpNote,$L20)="","—",INDEX(ExpNote,$L20))) | L20: =IFERROR(MATCH($C$5&"|"&RIGHT("000000"&4,6),ExpRankKey,0),"")
A21: 5 | B21: =IF($L21="","",INDEX(ExpNorm,$L21)) | C21: =IF($L21="","",IF(INDEX(ExpTime,$L21)="","—",LEFT(INDEX(ExpTime,$L21),2)&":"&RIGHT(INDEX(ExpTime,$L21),2))) | D21: =IF($L21="","",IF(INDEX(ExpBank,$L21)="","—",INDEX(ExpBank,$L21))) | E21: =IF($L21="","",IF(INDEX(ExpParty,$L21)="","—",IFERROR(VLOOKUP(INDEX(ExpParty,$L21),AcctTbl,4,0),INDEX(ExpParty,$L21)))) | F21: =IF($L21="","",IF(INDEX(ExpType,$L21)="","—",INDEX(ExpType,$L21))) | G21: =IF($L21="","",IF(INDEX(ExpDep,$L21)=0,"",INDEX(ExpDep,$L21))) | H21: =IF($L21="","",IF(INDEX(ExpWit,$L21)=0,"",INDEX(ExpWit,$L21))) | I21: =IF($B21="","",IF($I20="",0,$I20)+IF($H21="",0,$H21)-IF($G21="",0,$G21)) | J21: =IF($L21="","",IF(INDEX(ExpNote,$L21)="","—",INDEX(ExpNote,$L21))) | L21: =IFERROR(MATCH($C$5&"|"&RIGHT("000000"&5,6),ExpRankKey,0),"")
A22: 6 | B22: =IF($L22="","",INDEX(ExpNorm,$L22)) | C22: =IF($L22="","",IF(INDEX(ExpTime,$L22)="","—",LEFT(INDEX(ExpTime,$L22),2)&":"&RIGHT(INDEX(ExpTime,$L22),2))) | D22: =IF($L22="","",IF(INDEX(ExpBank,$L22)="","—",INDEX(ExpBank,$L22))) | E22: =IF($L22="","",IF(INDEX(ExpParty,$L22)="","—",IFERROR(VLOOKUP(INDEX(ExpParty,$L22),AcctTbl,4,0),INDEX(ExpParty,$L22)))) | F22: =IF($L22="","",IF(INDEX(ExpType,$L22)="","—",INDEX(ExpType,$L22))) | G22: =IF($L22="","",IF(INDEX(ExpDep,$L22)=0,"",INDEX(ExpDep,$L22))) | H22: =IF($L22="","",IF(INDEX(ExpWit,$L22)=0,"",INDEX(ExpWit,$L22))) | I22: =IF($B22="","",IF($I21="",0,$I21)+IF($H22="",0,$H22)-IF($G22="",0,$G22)) | J22: =IF($L22="","",IF(INDEX(ExpNote,$L22)="","—",INDEX(ExpNote,$L22))) | L22: =IFERROR(MATCH($C$5&"|"&RIGHT("000000"&6,6),ExpRankKey,0),"")
A23: 7 | B23: =IF($L23="","",INDEX(ExpNorm,$L23)) | C23: =IF($L23="","",IF(INDEX(ExpTime,$L23)="","—",LEFT(INDEX(ExpTime,$L23),2)&":"&RIGHT(INDEX(ExpTime,$L23),2))) | D23: =IF($L23="","",IF(INDEX(ExpBank,$L23)="","—",INDEX(ExpBank,$L23))) | E23: =IF($L23="","",IF(INDEX(ExpParty,$L23)="","—",IFERROR(VLOOKUP(INDEX(ExpParty,$L23),AcctTbl,4,0),INDEX(ExpParty,$L23)))) | F23: =IF($L23="","",IF(INDEX(ExpType,$L23)="","—",INDEX(ExpType,$L23))) | G23: =IF($L23="","",IF(INDEX(ExpDep,$L23)=0,"",INDEX(ExpDep,$L23))) | H23: =IF($L23="","",IF(INDEX(ExpWit,$L23)=0,"",INDEX(ExpWit,$L23))) | I23: =IF($B23="","",IF($I22="",0,$I22)+IF($H23="",0,$H23)-IF($G23="",0,$G23)) | J23: =IF($L23="","",IF(INDEX(ExpNote,$L23)="","—",INDEX(ExpNote,$L23))) | L23: =IFERROR(MATCH($C$5&"|"&RIGHT("000000"&7,6),ExpRankKey,0),"")
A24: 8 | B24: =IF($L24="","",INDEX(ExpNorm,$L24)) | C24: =IF($L24="","",IF(INDEX(ExpTime,$L24)="","—",LEFT(INDEX(ExpTime,$L24),2)&":"&RIGHT(INDEX(ExpTime,$L24),2))) | D24: =IF($L24="","",IF(INDEX(ExpBank,$L24)="","—",INDEX(ExpBank,$L24))) | E24: =IF($L24="","",IF(INDEX(ExpParty,$L24)="","—",IFERROR(VLOOKUP(INDEX(ExpParty,$L24),AcctTbl,4,0),INDEX(ExpParty,$L24)))) | F24: =IF($L24="","",IF(INDEX(ExpType,$L24)="","—",INDEX(ExpType,$L24))) | G24: =IF($L24="","",IF(INDEX(ExpDep,$L24)=0,"",INDEX(ExpDep,$L24))) | H24: =IF($L24="","",IF(INDEX(ExpWit,$L24)=0,"",INDEX(ExpWit,$L24))) | I24: =IF($B24="","",IF($I23="",0,$I23)+IF($H24="",0,$H24)-IF($G24="",0,$G24)) | J24: =IF($L24="","",IF(INDEX(ExpNote,$L24)="","—",INDEX(ExpNote,$L24))) | L24: =IFERROR(MATCH($C$5&"|"&RIGHT("000000"&8,6),ExpRankKey,0),"")
A25: 9 | B25: =IF($L25="","",INDEX(ExpNorm,$L25)) | C25: =IF($L25="","",IF(INDEX(ExpTime,$L25)="","—",LEFT(INDEX(ExpTime,$L25),2)&":"&RIGHT(INDEX(ExpTime,$L25),2))) | D25: =IF($L25="","",IF(INDEX(ExpBank,$L25)="","—",INDEX(ExpBank,$L25))) | E25: =IF($L25="","",IF(INDEX(ExpParty,$L25)="","—",IFERROR(VLOOKUP(INDEX(ExpParty,$L25),AcctTbl,4,0),INDEX(ExpParty,$L25)))) | F25: =IF($L25="","",IF(INDEX(ExpType,$L25)="","—",INDEX(ExpType,$L25))) | G25: =IF($L25="","",IF(INDEX(ExpDep,$L25)=0,"",INDEX(ExpDep,$L25))) | H25: =IF($L25="","",IF(INDEX(ExpWit,$L25)=0,"",INDEX(ExpWit,$L25))) | I25: =IF($B25="","",IF($I24="",0,$I24)+IF($H25="",0,$H25)-IF($G25="",0,$G25)) | J25: =IF($L25="","",IF(INDEX(ExpNote,$L25)="","—",INDEX(ExpNote,$L25))) | L25: =IFERROR(MATCH($C$5&"|"&RIGHT("000000"&9,6),ExpRankKey,0),"")
A26: 10 | B26: =IF($L26="","",INDEX(ExpNorm,$L26)) | C26: =IF($L26="","",IF(INDEX(ExpTime,$L26)="","—",LEFT(INDEX(ExpTime,$L26),2)&":"&RIGHT(INDEX(ExpTime,$L26),2))) | D26: =IF($L26="","",IF(INDEX(ExpBank,$L26)="","—",INDEX(ExpBank,$L26))) | E26: =IF($L26="","",IF(INDEX(ExpParty,$L26)="","—",IFERROR(VLOOKUP(INDEX(ExpParty,$L26),AcctTbl,4,0),INDEX(ExpParty,$L26)))) | F26: =IF($L26="","",IF(INDEX(ExpType,$L26)="","—",INDEX(ExpType,$L26))) | G26: =IF($L26="","",IF(INDEX(ExpDep,$L26)=0,"",INDEX(ExpDep,$L26))) | H26: =IF($L26="","",IF(INDEX(ExpWit,$L26)=0,"",INDEX(ExpWit,$L26))) | I26: =IF($B26="","",IF($I25="",0,$I25)+IF($H26="",0,$H26)-IF($G26="",0,$G26)) | J26: =IF($L26="","",IF(INDEX(ExpNote,$L26)="","—",INDEX(ExpNote,$L26))) | L26: =IFERROR(MATCH($C$5&"|"&RIGHT("000000"&10,6),ExpRankKey,0),"")
A27: 11 | B27: =IF($L27="","",INDEX(ExpNorm,$L27)) | C27: =IF($L27="","",IF(INDEX(ExpTime,$L27)="","—",LEFT(INDEX(ExpTime,$L27),2)&":"&RIGHT(INDEX(ExpTime,$L27),2))) | D27: =IF($L27="","",IF(INDEX(ExpBank,$L27)="","—",INDEX(ExpBank,$L27))) | E27: =IF($L27="","",IF(INDEX(ExpParty,$L27)="","—",IFERROR(VLOOKUP(INDEX(ExpParty,$L27),AcctTbl,4,0),INDEX(ExpParty,$L27)))) | F27: =IF($L27="","",IF(INDEX(ExpType,$L27)="","—",INDEX(ExpType,$L27))) | G27: =IF($L27="","",IF(INDEX(ExpDep,$L27)=0,"",INDEX(ExpDep,$L27))) | H27: =IF($L27="","",IF(INDEX(ExpWit,$L27)=0,"",INDEX(ExpWit,$L27))) | I27: =IF($B27="","",IF($I26="",0,$I26)+IF($H27="",0,$H27)-IF($G27="",0,$G27)) | J27: =IF($L27="","",IF(INDEX(ExpNote,$L27)="","—",INDEX(ExpNote,$L27))) | L27: =IFERROR(MATCH($C$5&"|"&RIGHT("000000"&11,6),ExpRankKey,0),"")
A28: 12 | B28: =IF($L28="","",INDEX(ExpNorm,$L28)) | C28: =IF($L28="","",IF(INDEX(ExpTime,$L28)="","—",LEFT(INDEX(ExpTime,$L28),2)&":"&RIGHT(INDEX(ExpTime,$L28),2))) | D28: =IF($L28="","",IF(INDEX(ExpBank,$L28)="","—",INDEX(ExpBank,$L28))) | E28: =IF($L28="","",IF(INDEX(ExpParty,$L28)="","—",IFERROR(VLOOKUP(INDEX(ExpParty,$L28),AcctTbl,4,0),INDEX(ExpParty,$L28)))) | F28: =IF($L28="","",IF(INDEX(ExpType,$L28)="","—",INDEX(ExpType,$L28))) | G28: =IF($L28="","",IF(INDEX(ExpDep,$L28)=0,"",INDEX(ExpDep,$L28))) | H28: =IF($L28="","",IF(INDEX(ExpWit,$L28)=0,"",INDEX(ExpWit,$L28))) | I28: =IF($B28="","",IF($I27="",0,$I27)+IF($H28="",0,$H28)-IF($G28="",0,$G28)) | J28: =IF($L28="","",IF(INDEX(ExpNote,$L28)="","—",INDEX(ExpNote,$L28))) | L28: =IFERROR(MATCH($C$5&"|"&RIGHT("000000"&12,6),ExpRankKey,0),"")
A29: 13 | B29: =IF($L29="","",INDEX(ExpNorm,$L29)) | C29: =IF($L29="","",IF(INDEX(ExpTime,$L29)="","—",LEFT(INDEX(ExpTime,$L29),2)&":"&RIGHT(INDEX(ExpTime,$L29),2))) | D29: =IF($L29="","",IF(INDEX(ExpBank,$L29)="","—",INDEX(ExpBank,$L29))) | E29: =IF($L29="","",IF(INDEX(ExpParty,$L29)="","—",IFERROR(VLOOKUP(INDEX(ExpParty,$L29),AcctTbl,4,0),INDEX(ExpParty,$L29)))) | F29: =IF($L29="","",IF(INDEX(ExpType,$L29)="","—",INDEX(ExpType,$L29))) | G29: =IF($L29="","",IF(INDEX(ExpDep,$L29)=0,"",INDEX(ExpDep,$L29))) | H29: =IF($L29="","",IF(INDEX(ExpWit,$L29)=0,"",INDEX(ExpWit,$L29))) | I29: =IF($B29="","",IF($I28="",0,$I28)+IF($H29="",0,$H29)-IF($G29="",0,$G29)) | J29: =IF($L29="","",IF(INDEX(ExpNote,$L29)="","—",INDEX(ExpNote,$L29))) | L29: =IFERROR(MATCH($C$5&"|"&RIGHT("000000"&13,6),ExpRankKey,0),"")
A30: 14 | B30: =IF($L30="","",INDEX(ExpNorm,$L30)) | C30: =IF($L30="","",IF(INDEX(ExpTime,$L30)="","—",LEFT(INDEX(ExpTime,$L30),2)&":"&RIGHT(INDEX(ExpTime,$L30),2))) | D30: =IF($L30="","",IF(INDEX(ExpBank,$L30)="","—",INDEX(ExpBank,$L30))) | E30: =IF($L30="","",IF(INDEX(ExpParty,$L30)="","—",IFERROR(VLOOKUP(INDEX(ExpParty,$L30),AcctTbl,4,0),INDEX(ExpParty,$L30)))) | F30: =IF($L30="","",IF(INDEX(ExpType,$L30)="","—",INDEX(ExpType,$L30))) | G30: =IF($L30="","",IF(INDEX(ExpDep,$L30)=0,"",INDEX(ExpDep,$L30))) | H30: =IF($L30="","",IF(INDEX(ExpWit,$L30)=0,"",INDEX(ExpWit,$L30))) | I30: =IF($B30="","",IF($I29="",0,$I29)+IF($H30="",0,$H30)-IF($G30="",0,$G30)) | J30: =IF($L30="","",IF(INDEX(ExpNote,$L30)="","—",INDEX(ExpNote,$L30))) | L30: =IFERROR(MATCH($C$5&"|"&RIGHT("000000"&14,6),ExpRankKey,0),"")
A31: 15 | B31: =IF($L31="","",INDEX(ExpNorm,$L31)) | C31: =IF($L31="","",IF(INDEX(ExpTime,$L31)="","—",LEFT(INDEX(ExpTime,$L31),2)&":"&RIGHT(INDEX(ExpTime,$L31),2))) | D31: =IF($L31="","",IF(INDEX(ExpBank,$L31)="","—",INDEX(ExpBank,$L31))) | E31: =IF($L31="","",IF(INDEX(ExpParty,$L31)="","—",IFERROR(VLOOKUP(INDEX(ExpParty,$L31),AcctTbl,4,0),INDEX(ExpParty,$L31)))) | F31: =IF($L31="","",IF(INDEX(ExpType,$L31)="","—",INDEX(ExpType,$L31))) | G31: =IF($L31="","",IF(INDEX(ExpDep,$L31)=0,"",INDEX(ExpDep,$L31))) | H31: =IF($L31="","",IF(INDEX(ExpWit,$L31)=0,"",INDEX(ExpWit,$L31))) | I31: =IF($B31="","",IF($I30="",0,$I30)+IF($H31="",0,$H31)-IF($G31="",0,$G31)) | J31: =IF($L31="","",IF(INDEX(ExpNote,$L31)="","—",INDEX(ExpNote,$L31))) | L31: =IFERROR(MATCH($C$5&"|"&RIGHT("000000"&15,6),ExpRankKey,0),"")
A32: 16 | B32: =IF($L32="","",INDEX(ExpNorm,$L32)) | C32: =IF($L32="","",IF(INDEX(ExpTime,$L32)="","—",LEFT(INDEX(ExpTime,$L32),2)&":"&RIGHT(INDEX(ExpTime,$L32),2))) | D32: =IF($L32="","",IF(INDEX(ExpBank,$L32)="","—",INDEX(ExpBank,$L32))) | E32: =IF($L32="","",IF(INDEX(ExpParty,$L32)="","—",IFERROR(VLOOKUP(INDEX(ExpParty,$L32),AcctTbl,4,0),INDEX(ExpParty,$L32)))) | F32: =IF($L32="","",IF(INDEX(ExpType,$L32)="","—",INDEX(ExpType,$L32))) | G32: =IF($L32="","",IF(INDEX(ExpDep,$L32)=0,"",INDEX(ExpDep,$L32))) | H32: =IF($L32="","",IF(INDEX(ExpWit,$L32)=0,"",INDEX(ExpWit,$L32))) | I32: =IF($B32="","",IF($I31="",0,$I31)+IF($H32="",0,$H32)-IF($G32="",0,$G32)) | J32: =IF($L32="","",IF(INDEX(ExpNote,$L32)="","—",INDEX(ExpNote,$L32))) | L32: =IFERROR(MATCH($C$5&"|"&RIGHT("000000"&16,6),ExpRankKey,0),"")
A33: 17 | B33: =IF($L33="","",INDEX(ExpNorm,$L33)) | C33: =IF($L33="","",IF(INDEX(ExpTime,$L33)="","—",LEFT(INDEX(ExpTime,$L33),2)&":"&RIGHT(INDEX(ExpTime,$L33),2))) | D33: =IF($L33="","",IF(INDEX(ExpBank,$L33)="","—",INDEX(ExpBank,$L33))) | E33: =IF($L33="","",IF(INDEX(ExpParty,$L33)="","—",IFERROR(VLOOKUP(INDEX(ExpParty,$L33),AcctTbl,4,0),INDEX(ExpParty,$L33)))) | F33: =IF($L33="","",IF(INDEX(ExpType,$L33)="","—",INDEX(ExpType,$L33))) | G33: =IF($L33="","",IF(INDEX(ExpDep,$L33)=0,"",INDEX(ExpDep,$L33))) | H33: =IF($L33="","",IF(INDEX(ExpWit,$L33)=0,"",INDEX(ExpWit,$L33))) | I33: =IF($B33="","",IF($I32="",0,$I32)+IF($H33="",0,$H33)-IF($G33="",0,$G33)) | J33: =IF($L33="","",IF(INDEX(ExpNote,$L33)="","—",INDEX(ExpNote,$L33))) | L33: =IFERROR(MATCH($C$5&"|"&RIGHT("000000"&17,6),ExpRankKey,0),"")
A34: 18 | B34: =IF($L34="","",INDEX(ExpNorm,$L34)) | C34: =IF($L34="","",IF(INDEX(ExpTime,$L34)="","—",LEFT(INDEX(ExpTime,$L34),2)&":"&RIGHT(INDEX(ExpTime,$L34),2))) | D34: =IF($L34="","",IF(INDEX(ExpBank,$L34)="","—",INDEX(ExpBank,$L34))) | E34: =IF($L34="","",IF(INDEX(ExpParty,$L34)="","—",IFERROR(VLOOKUP(INDEX(ExpParty,$L34),AcctTbl,4,0),INDEX(ExpParty,$L34)))) | F34: =IF($L34="","",IF(INDEX(ExpType,$L34)="","—",INDEX(ExpType,$L34))) | G34: =IF($L34="","",IF(INDEX(ExpDep,$L34)=0,"",INDEX(ExpDep,$L34))) | H34: =IF($L34="","",IF(INDEX(ExpWit,$L34)=0,"",INDEX(ExpWit,$L34))) | I34: =IF($B34="","",IF($I33="",0,$I33)+IF($H34="",0,$H34)-IF($G34="",0,$G34)) | J34: =IF($L34="","",IF(INDEX(ExpNote,$L34)="","—",INDEX(ExpNote,$L34))) | L34: =IFERROR(MATCH($C$5&"|"&RIGHT("000000"&18,6),ExpRankKey,0),"")
A35: 19 | B35: =IF($L35="","",INDEX(ExpNorm,$L35)) | C35: =IF($L35="","",IF(INDEX(ExpTime,$L35)="","—",LEFT(INDEX(ExpTime,$L35),2)&":"&RIGHT(INDEX(ExpTime,$L35),2))) | D35: =IF($L35="","",IF(INDEX(ExpBank,$L35)="","—",INDEX(ExpBank,$L35))) | E35: =IF($L35="","",IF(INDEX(ExpParty,$L35)="","—",IFERROR(VLOOKUP(INDEX(ExpParty,$L35),AcctTbl,4,0),INDEX(ExpParty,$L35)))) | F35: =IF($L35="","",IF(INDEX(ExpType,$L35)="","—",INDEX(ExpType,$L35))) | G35: =IF($L35="","",IF(INDEX(ExpDep,$L35)=0,"",INDEX(ExpDep,$L35))) | H35: =IF($L35="","",IF(INDEX(ExpWit,$L35)=0,"",INDEX(ExpWit,$L35))) | I35: =IF($B35="","",IF($I34="",0,$I34)+IF($H35="",0,$H35)-IF($G35="",0,$G35)) | J35: =IF($L35="","",IF(INDEX(ExpNote,$L35)="","—",INDEX(ExpNote,$L35))) | L35: =IFERROR(MATCH($C$5&"|"&RIGHT("000000"&19,6),ExpRankKey,0),"")
A36: 20 | B36: =IF($L36="","",INDEX(ExpNorm,$L36)) | C36: =IF($L36="","",IF(INDEX(ExpTime,$L36)="","—",LEFT(INDEX(ExpTime,$L36),2)&":"&RIGHT(INDEX(ExpTime,$L36),2))) | D36: =IF($L36="","",IF(INDEX(ExpBank,$L36)="","—",INDEX(ExpBank,$L36))) | E36: =IF($L36="","",IF(INDEX(ExpParty,$L36)="","—",IFERROR(VLOOKUP(INDEX(ExpParty,$L36),AcctTbl,4,0),INDEX(ExpParty,$L36)))) | F36: =IF($L36="","",IF(INDEX(ExpType,$L36)="","—",INDEX(ExpType,$L36))) | G36: =IF($L36="","",IF(INDEX(ExpDep,$L36)=0,"",INDEX(ExpDep,$L36))) | H36: =IF($L36="","",IF(INDEX(ExpWit,$L36)=0,"",INDEX(ExpWit,$L36))) | I36: =IF($B36="","",IF($I35="",0,$I35)+IF($H36="",0,$H36)-IF($G36="",0,$G36)) | J36: =IF($L36="","",IF(INDEX(ExpNote,$L36)="","—",INDEX(ExpNote,$L36))) | L36: =IFERROR(MATCH($C$5&"|"&RIGHT("000000"&20,6),ExpRankKey,0),"")
A37: 21 | B37: =IF($L37="","",INDEX(ExpNorm,$L37)) | C37: =IF($L37="","",IF(INDEX(ExpTime,$L37)="","—",LEFT(INDEX(ExpTime,$L37),2)&":"&RIGHT(INDEX(ExpTime,$L37),2))) | D37: =IF($L37="","",IF(INDEX(ExpBank,$L37)="","—",INDEX(ExpBank,$L37))) | E37: =IF($L37="","",IF(INDEX(ExpParty,$L37)="","—",IFERROR(VLOOKUP(INDEX(ExpParty,$L37),AcctTbl,4,0),INDEX(ExpParty,$L37)))) | F37: =IF($L37="","",IF(INDEX(ExpType,$L37)="","—",INDEX(ExpType,$L37))) | G37: =IF($L37="","",IF(INDEX(ExpDep,$L37)=0,"",INDEX(ExpDep,$L37))) | H37: =IF($L37="","",IF(INDEX(ExpWit,$L37)=0,"",INDEX(ExpWit,$L37))) | I37: =IF($B37="","",IF($I36="",0,$I36)+IF($H37="",0,$H37)-IF($G37="",0,$G37)) | J37: =IF($L37="","",IF(INDEX(ExpNote,$L37)="","—",INDEX(ExpNote,$L37))) | L37: =IFERROR(MATCH($C$5&"|"&RIGHT("000000"&21,6),ExpRankKey,0),"")
A38: 22 | B38: =IF($L38="","",INDEX(ExpNorm,$L38)) | C38: =IF($L38="","",IF(INDEX(ExpTime,$L38)="","—",LEFT(INDEX(ExpTime,$L38),2)&":"&RIGHT(INDEX(ExpTime,$L38),2))) | D38: =IF($L38="","",IF(INDEX(ExpBank,$L38)="","—",INDEX(ExpBank,$L38))) | E38: =IF($L38="","",IF(INDEX(ExpParty,$L38)="","—",IFERROR(VLOOKUP(INDEX(ExpParty,$L38),AcctTbl,4,0),INDEX(ExpParty,$L38)))) | F38: =IF($L38="","",IF(INDEX(ExpType,$L38)="","—",INDEX(ExpType,$L38))) | G38: =IF($L38="","",IF(INDEX(ExpDep,$L38)=0,"",INDEX(ExpDep,$L38))) | H38: =IF($L38="","",IF(INDEX(ExpWit,$L38)=0,"",INDEX(ExpWit,$L38))) | I38: =IF($B38="","",IF($I37="",0,$I37)+IF($H38="",0,$H38)-IF($G38="",0,$G38)) | J38: =IF($L38="","",IF(INDEX(ExpNote,$L38)="","—",INDEX(ExpNote,$L38))) | L38: =IFERROR(MATCH($C$5&"|"&RIGHT("000000"&22,6),ExpRankKey,0),"")
A39: 23 | B39: =IF($L39="","",INDEX(ExpNorm,$L39)) | C39: =IF($L39="","",IF(INDEX(ExpTime,$L39)="","—",LEFT(INDEX(ExpTime,$L39),2)&":"&RIGHT(INDEX(ExpTime,$L39),2))) | D39: =IF($L39="","",IF(INDEX(ExpBank,$L39)="","—",INDEX(ExpBank,$L39))) | E39: =IF($L39="","",IF(INDEX(ExpParty,$L39)="","—",IFERROR(VLOOKUP(INDEX(ExpParty,$L39),AcctTbl,4,0),INDEX(ExpParty,$L39)))) | F39: =IF($L39="","",IF(INDEX(ExpType,$L39)="","—",INDEX(ExpType,$L39))) | G39: =IF($L39="","",IF(INDEX(ExpDep,$L39)=0,"",INDEX(ExpDep,$L39))) | H39: =IF($L39="","",IF(INDEX(ExpWit,$L39)=0,"",INDEX(ExpWit,$L39))) | I39: =IF($B39="","",IF($I38="",0,$I38)+IF($H39="",0,$H39)-IF($G39="",0,$G39)) | J39: =IF($L39="","",IF(INDEX(ExpNote,$L39)="","—",INDEX(ExpNote,$L39))) | L39: =IFERROR(MATCH($C$5&"|"&RIGHT("000000"&23,6),ExpRankKey,0),"")
A40: 24 | B40: =IF($L40="","",INDEX(ExpNorm,$L40)) | C40: =IF($L40="","",IF(INDEX(ExpTime,$L40)="","—",LEFT(INDEX(ExpTime,$L40),2)&":"&RIGHT(INDEX(ExpTime,$L40),2))) | D40: =IF($L40="","",IF(INDEX(ExpBank,$L40)="","—",INDEX(ExpBank,$L40))) | E40: =IF($L40="","",IF(INDEX(ExpParty,$L40)="","—",IFERROR(VLOOKUP(INDEX(ExpParty,$L40),AcctTbl,4,0),INDEX(ExpParty,$L40)))) | F40: =IF($L40="","",IF(INDEX(ExpType,$L40)="","—",INDEX(ExpType,$L40))) | G40: =IF($L40="","",IF(INDEX(ExpDep,$L40)=0,"",INDEX(ExpDep,$L40))) | H40: =IF($L40="","",IF(INDEX(ExpWit,$L40)=0,"",INDEX(ExpWit,$L40))) | I40: =IF($B40="","",IF($I39="",0,$I39)+IF($H40="",0,$H40)-IF($G40="",0,$G40)) | J40: =IF($L40="","",IF(INDEX(ExpNote,$L40)="","—",INDEX(ExpNote,$L40))) | L40: =IFERROR(MATCH($C$5&"|"&RIGHT("000000"&24,6),ExpRankKey,0),"")
A41: 25 | B41: =IF($L41="","",INDEX(ExpNorm,$L41)) | C41: =IF($L41="","",IF(INDEX(ExpTime,$L41)="","—",LEFT(INDEX(ExpTime,$L41),2)&":"&RIGHT(INDEX(ExpTime,$L41),2))) | D41: =IF($L41="","",IF(INDEX(ExpBank,$L41)="","—",INDEX(ExpBank,$L41))) | E41: =IF($L41="","",IF(INDEX(ExpParty,$L41)="","—",IFERROR(VLOOKUP(INDEX(ExpParty,$L41),AcctTbl,4,0),INDEX(ExpParty,$L41)))) | F41: =IF($L41="","",IF(INDEX(ExpType,$L41)="","—",INDEX(ExpType,$L41))) | G41: =IF($L41="","",IF(INDEX(ExpDep,$L41)=0,"",INDEX(ExpDep,$L41))) | H41: =IF($L41="","",IF(INDEX(ExpWit,$L41)=0,"",INDEX(ExpWit,$L41))) | I41: =IF($B41="","",IF($I40="",0,$I40)+IF($H41="",0,$H41)-IF($G41="",0,$G41)) | J41: =IF($L41="","",IF(INDEX(ExpNote,$L41)="","—",INDEX(ExpNote,$L41))) | L41: =IFERROR(MATCH($C$5&"|"&RIGHT("000000"&25,6),ExpRankKey,0),"")
A42: 26 | B42: =IF($L42="","",INDEX(ExpNorm,$L42)) | C42: =IF($L42="","",IF(INDEX(ExpTime,$L42)="","—",LEFT(INDEX(ExpTime,$L42),2)&":"&RIGHT(INDEX(ExpTime,$L42),2))) | D42: =IF($L42="","",IF(INDEX(ExpBank,$L42)="","—",INDEX(ExpBank,$L42))) | E42: =IF($L42="","",IF(INDEX(ExpParty,$L42)="","—",IFERROR(VLOOKUP(INDEX(ExpParty,$L42),AcctTbl,4,0),INDEX(ExpParty,$L42)))) | F42: =IF($L42="","",IF(INDEX(ExpType,$L42)="","—",INDEX(ExpType,$L42))) | G42: =IF($L42="","",IF(INDEX(ExpDep,$L42)=0,"",INDEX(ExpDep,$L42))) | H42: =IF($L42="","",IF(INDEX(ExpWit,$L42)=0,"",INDEX(ExpWit,$L42))) | I42: =IF($B42="","",IF($I41="",0,$I41)+IF($H42="",0,$H42)-IF($G42="",0,$G42)) | J42: =IF($L42="","",IF(INDEX(ExpNote,$L42)="","—",INDEX(ExpNote,$L42))) | L42: =IFERROR(MATCH($C$5&"|"&RIGHT("000000"&26,6),ExpRankKey,0),"")
...

Sheet Summary
A1: =IF(Sync!$AE$6="","مازندشت",Sync!$AE$6)&" — "&IF(Sync!$AE$9="","سورتینگ و بسته‌بندی مرکبات",Sync!$AE$9)
A2: =IF(Sync!$AE$7="","باغدشت، بخش مرکزی، شهرستان قائم‌شهر، استان مازندران، ایران",Sync!$AE$7)&" | MAZANDASHT · CITRUS SORTING & PACKING"
A3: خلاصه و تحلیل هزینه‌ها به تفکیک زیرگروه — گروه اصلی: هزینه
A4: منبع: تراکنش‌های ثبت‌شده در فایل واریز/برداشت (Transactions.xlsx ← شیت Entry) با گروه «هزینه». زیرگروه‌ها در فایل مادر (INFO ← شیت SubGroups) تعریف می‌شوند.
A5: جمع خالص هزینه (ریال) | C5: جمع برداشت (ریال) | E5: جمع واریز/بازگشت (ریال) | G5: تعداد ردیف هزینه
A6: =G111 | C6: =F111 | E6: =E111 | G6: =D111
A8: ردیف | B8: کد زیرگروه | C8: عنوان زیرگروه | D8: تعداد ردیف | E8: جمع واریز (ریال) | F8: جمع برداشت (ریال) | G8: خالص هزینه (ریال) | H8: سهم از کل
A9: No. | B9: Code | C9: Subgroup | D9: Entries | E9: Deposits | F9: Withdrawals | G9: Net | H9: Share
A10: =IF(ROW()-9>NSubExp,"",ROW()-9) | B10: =IF($A10="","",IF($A10<=NSubExp,INDEX(PkSubExp,$A10),"")) | C10: =IF($B10="","",IFERROR(VLOOKUP($B10,SubTbl,3,0),"—")) | D10: =IF($B10="","",COUNTIFS(ExpSub,$B10,ExpGroup,"هزینه")) | E10: =IF($B10="","",SUMIFS(ExpDep,ExpSub,$B10,ExpGroup,"هزینه")) | F10: =IF($B10="","",SUMIFS(ExpWit,ExpSub,$B10,ExpGroup,"هزینه")) | G10: =IF($B10="","",$F10-$E10) | H10: =IF(OR($B10="",$G$111=0),"",$G10/$G$111)
A11: =IF(ROW()-9>NSubExp,"",ROW()-9) | B11: =IF($A11="","",IF($A11<=NSubExp,INDEX(PkSubExp,$A11),"")) | C11: =IF($B11="","",IFERROR(VLOOKUP($B11,SubTbl,3,0),"—")) | D11: =IF($B11="","",COUNTIFS(ExpSub,$B11,ExpGroup,"هزینه")) | E11: =IF($B11="","",SUMIFS(ExpDep,ExpSub,$B11,ExpGroup,"هزینه")) | F11: =IF($B11="","",SUMIFS(ExpWit,ExpSub,$B11,ExpGroup,"هزینه")) | G11: =IF($B11="","",$F11-$E11) | H11: =IF(OR($B11="",$G$111=0),"",$G11/$G$111)
A12: =IF(ROW()-9>NSubExp,"",ROW()-9) | B12: =IF($A12="","",IF($A12<=NSubExp,INDEX(PkSubExp,$A12),"")) | C12: =IF($B12="","",IFERROR(VLOOKUP($B12,SubTbl,3,0),"—")) | D12: =IF($B12="","",COUNTIFS(ExpSub,$B12,ExpGroup,"هزینه")) | E12: =IF($B12="","",SUMIFS(ExpDep,ExpSub,$B12,ExpGroup,"هزینه")) | F12: =IF($B12="","",SUMIFS(ExpWit,ExpSub,$B12,ExpGroup,"هزینه")) | G12: =IF($B12="","",$F12-$E12) | H12: =IF(OR($B12="",$G$111=0),"",$G12/$G$111)
A13: =IF(ROW()-9>NSubExp,"",ROW()-9) | B13: =IF($A13="","",IF($A13<=NSubExp,INDEX(PkSubExp,$A13),"")) | C13: =IF($B13="","",IFERROR(VLOOKUP($B13,SubTbl,3,0),"—")) | D13: =IF($B13="","",COUNTIFS(ExpSub,$B13,ExpGroup,"هزینه")) | E13: =IF($B13="","",SUMIFS(ExpDep,ExpSub,$B13,ExpGroup,"هزینه")) | F13: =IF($B13="","",SUMIFS(ExpWit,ExpSub,$B13,ExpGroup,"هزینه")) | G13: =IF($B13="","",$F13-$E13) | H13: =IF(OR($B13="",$G$111=0),"",$G13/$G$111)
A14: =IF(ROW()-9>NSubExp,"",ROW()-9) | B14: =IF($A14="","",IF($A14<=NSubExp,INDEX(PkSubExp,$A14),"")) | C14: =IF($B14="","",IFERROR(VLOOKUP($B14,SubTbl,3,0),"—")) | D14: =IF($B14="","",COUNTIFS(ExpSub,$B14,ExpGroup,"هزینه")) | E14: =IF($B14="","",SUMIFS(ExpDep,ExpSub,$B14,ExpGroup,"هزینه")) | F14: =IF($B14="","",SUMIFS(ExpWit,ExpSub,$B14,ExpGroup,"هزینه")) | G14: =IF($B14="","",$F14-$E14) | H14: =IF(OR($B14="",$G$111=0),"",$G14/$G$111)
A15: =IF(ROW()-9>NSubExp,"",ROW()-9) | B15: =IF($A15="","",IF($A15<=NSubExp,INDEX(PkSubExp,$A15),"")) | C15: =IF($B15="","",IFERROR(VLOOKUP($B15,SubTbl,3,0),"—")) | D15: =IF($B15="","",COUNTIFS(ExpSub,$B15,ExpGroup,"هزینه")) | E15: =IF($B15="","",SUMIFS(ExpDep,ExpSub,$B15,ExpGroup,"هزینه")) | F15: =IF($B15="","",SUMIFS(ExpWit,ExpSub,$B15,ExpGroup,"هزینه")) | G15: =IF($B15="","",$F15-$E15) | H15: =IF(OR($B15="",$G$111=0),"",$G15/$G$111)
A16: =IF(ROW()-9>NSubExp,"",ROW()-9) | B16: =IF($A16="","",IF($A16<=NSubExp,INDEX(PkSubExp,$A16),"")) | C16: =IF($B16="","",IFERROR(VLOOKUP($B16,SubTbl,3,0),"—")) | D16: =IF($B16="","",COUNTIFS(ExpSub,$B16,ExpGroup,"هزینه")) | E16: =IF($B16="","",SUMIFS(ExpDep,ExpSub,$B16,ExpGroup,"هزینه")) | F16: =IF($B16="","",SUMIFS(ExpWit,ExpSub,$B16,ExpGroup,"هزینه")) | G16: =IF($B16="","",$F16-$E16) | H16: =IF(OR($B16="",$G$111=0),"",$G16/$G$111)
A17: =IF(ROW()-9>NSubExp,"",ROW()-9) | B17: =IF($A17="","",IF($A17<=NSubExp,INDEX(PkSubExp,$A17),"")) | C17: =IF($B17="","",IFERROR(VLOOKUP($B17,SubTbl,3,0),"—")) | D17: =IF($B17="","",COUNTIFS(ExpSub,$B17,ExpGroup,"هزینه")) | E17: =IF($B17="","",SUMIFS(ExpDep,ExpSub,$B17,ExpGroup,"هزینه")) | F17: =IF($B17="","",SUMIFS(ExpWit,ExpSub,$B17,ExpGroup,"هزینه")) | G17: =IF($B17="","",$F17-$E17) | H17: =IF(OR($B17="",$G$111=0),"",$G17/$G$111)
A18: =IF(ROW()-9>NSubExp,"",ROW()-9) | B18: =IF($A18="","",IF($A18<=NSubExp,INDEX(PkSubExp,$A18),"")) | C18: =IF($B18="","",IFERROR(VLOOKUP($B18,SubTbl,3,0),"—")) | D18: =IF($B18="","",COUNTIFS(ExpSub,$B18,ExpGroup,"هزینه")) | E18: =IF($B18="","",SUMIFS(ExpDep,ExpSub,$B18,ExpGroup,"هزینه")) | F18: =IF($B18="","",SUMIFS(ExpWit,ExpSub,$B18,ExpGroup,"هزینه")) | G18: =IF($B18="","",$F18-$E18) | H18: =IF(OR($B18="",$G$111=0),"",$G18/$G$111)
A19: =IF(ROW()-9>NSubExp,"",ROW()-9) | B19: =IF($A19="","",IF($A19<=NSubExp,INDEX(PkSubExp,$A19),"")) | C19: =IF($B19="","",IFERROR(VLOOKUP($B19,SubTbl,3,0),"—")) | D19: =IF($B19="","",COUNTIFS(ExpSub,$B19,ExpGroup,"هزینه")) | E19: =IF($B19="","",SUMIFS(ExpDep,ExpSub,$B19,ExpGroup,"هزینه")) | F19: =IF($B19="","",SUMIFS(ExpWit,ExpSub,$B19,ExpGroup,"هزینه")) | G19: =IF($B19="","",$F19-$E19) | H19: =IF(OR($B19="",$G$111=0),"",$G19/$G$111)
A20: =IF(ROW()-9>NSubExp,"",ROW()-9) | B20: =IF($A20="","",IF($A20<=NSubExp,INDEX(PkSubExp,$A20),"")) | C20: =IF($B20="","",IFERROR(VLOOKUP($B20,SubTbl,3,0),"—")) | D20: =IF($B20="","",COUNTIFS(ExpSub,$B20,ExpGroup,"هزینه")) | E20: =IF($B20="","",SUMIFS(ExpDep,ExpSub,$B20,ExpGroup,"هزینه")) | F20: =IF($B20="","",SUMIFS(ExpWit,ExpSub,$B20,ExpGroup,"هزینه")) | G20: =IF($B20="","",$F20-$E20) | H20: =IF(OR($B20="",$G$111=0),"",$G20/$G$111)
A21: =IF(ROW()-9>NSubExp,"",ROW()-9) | B21: =IF($A21="","",IF($A21<=NSubExp,INDEX(PkSubExp,$A21),"")) | C21: =IF($B21="","",IFERROR(VLOOKUP($B21,SubTbl,3,0),"—")) | D21: =IF($B21="","",COUNTIFS(ExpSub,$B21,ExpGroup,"هزینه")) | E21: =IF($B21="","",SUMIFS(ExpDep,ExpSub,$B21,ExpGroup,"هزینه")) | F21: =IF($B21="","",SUMIFS(ExpWit,ExpSub,$B21,ExpGroup,"هزینه")) | G21: =IF($B21="","",$F21-$E21) | H21: =IF(OR($B21="",$G$111=0),"",$G21/$G$111)
... A109: =IF(ROW()-9>NSubExp,"",ROW()-9) | B109: =IF($A109="","",IF($A109<=NSubExp,INDEX(PkSubExp,$A109),"")) | C109: =IF($B109="","",IFERROR(VLOOKUP($B109,SubTbl,3,0),"—")) | D109: =IF($B109="","",COUNTIFS(ExpSub,$B109,ExpGroup,"هزینه")) | E109: =IF($B109="","",SUMIFS(ExpDep,ExpSub,$B109,ExpGroup,"هزینه")) | F109: =IF($B109="","",SUMIFS(ExpWit,ExpSub,$B109,ExpGroup,"هزینه")) | G109: =IF($B109="","",$F109-$E109) | H109: =IF(OR($B109="",$G$111=0),"",$G109/$G$111)
A110: — | C110: (بدون زیرگروه) | D110: =COUNTIF(ExpGroup,"هزینه")-SUM(D10:D109) | E110: =SUMIF(ExpGroup,"هزینه",ExpDep)-SUM(E10:E109) | F110: =SUMIF(ExpGroup,"هزینه",ExpWit)-SUM(F10:F109) | G110: =F110-E110 | H110: =IF($G$111=0,"",$G110/$G$111)
A111: جمع کل | D111: =SUM(D10:D110) | E111: =SUM(E10:E110) | F111: =SUM(F10:F110) | G111: =SUM(G10:G110)

Sheet Sync
A1: مازندشت — سورتینگ و بسته‌بندی مرکبات
A2: باغدشت، بخش مرکزی، شهرستان قائم‌شهر، استان مازندران، ایران | MAZANDASHT · CITRUS SORTING & PACKING
A3: برگه فنی — آینه‌ی فایل مادر (INFO) و فایل واریز/برداشت (Transactions) برای گزارش هزینه‌ها. فرمول‌ها را تغییر ندهید. اگر همه سلول‌ها خالی شدند یعنی لینک به‌روز نشده: Data ← Edit Links ← Update Values.
A5: MG · Code | B5: · Title | C5: · Desc | E5: SG · Code | F5: · Group | G5: · Title | H5: · Desc | J5: Acct · Code | K5: · Nature | L5: · Sub | M5: · Name | P5: Entry · C | Q5: Entry · D | R5: Entry · E | S5: Entry · G | T5: Entry · J | U5: Entry · K | V5: Entry · L | W5: Entry · M | X5: Entry · N | Y5: Entry · R | AA5: flg | AB5: cum·N | AC5: packed·SG | AE5: Company
A6: =IF([1]MainGroups!$B$7="","",[1]MainGroups!$A$7) | B6: =IF([1]MainGroups!$B$7="","",[1]MainGroups!$B$7) | C6: =IF([1]MainGroups!$B$7="","",[1]MainGroups!$C$7) | E6: =IF([1]SubGroups!$B$7="","",[1]SubGroups!$A$7) | F6: =IF([1]SubGroups!$B$7="","",[1]SubGroups!$B$7) | G6: =IF([1]SubGroups!$B$7="","",[1]SubGroups!$C$7) | H6: =IF([1]SubGroups!$B$7="","",[1]SubGroups!$D$7) | J6: =IF([1]Accounts!$D$7="","",[1]Accounts!$A$7) | K6: =IF([1]Accounts!$D$7="","",[1]Accounts!$B$7) | L6: =IF([1]Accounts!$D$7="","",[1]Accounts!$C$7) | M6: =IF([1]Accounts!$D$7="","",[1]Accounts!$D$7) | P6: =IF([2]Entry!$C$9="","",[2]Entry!$C$9) | Q6: =IF([2]Entry!$D$9="","",[2]Entry!$D$9) | R6: =IF([2]Entry!$E$9="","",[2]Entry!$E$9) | S6: =IF([2]Entry!$G$9="","",[2]Entry!$G$9) | T6: =IF([2]Entry!$J$9="","",[2]Entry!$J$9) | U6: =IF([2]Entry!$K$9="","",[2]Entry!$K$9) | V6: =IF([2]Entry!$L$9="","",[2]Entry!$L$9) | W6: =IF([2]Entry!$M$9="","",[2]Entry!$M$9) | X6: =IF([2]Entry!$N$9="","",[2]Entry!$N$9) | Y6: =IF([2]Entry!$R$9="","",[2]Entry!$R$9) | AA6: =IF(AND($E6<>"",$G6<>"",$F6="هزینه"),1,0) | AB6: =SUM($AA$6:$AA6) | AC6: =IFERROR(INDEX($E$6:$E$105,MATCH(ROW()-5,$AB$6:$AB$105,0)),"") | AE6: =IF([1]Company!$C$5="","",[1]Company!$C$5)
A7: =IF([1]MainGroups!$B$8="","",[1]MainGroups!$A$8) | B7: =IF([1]MainGroups!$B$8="","",[1]MainGroups!$B$8) | C7: =IF([1]MainGroups!$B$8="","",[1]MainGroups!$C$8) | E7: =IF([1]SubGroups!$B$8="","",[1]SubGroups!$A$8) | F7: =IF([1]SubGroups!$B$8="","",[1]SubGroups!$B$8) | G7: =IF([1]SubGroups!$B$8="","",[1]SubGroups!$C$8) | H7: =IF([1]SubGroups!$B$8="","",[1]SubGroups!$D$8) | J7: =IF([1]Accounts!$D$8="","",[1]Accounts!$A$8) | K7: =IF([1]Accounts!$D$8="","",[1]Accounts!$B$8) | L7: =IF([1]Accounts!$D$8="","",[1]Accounts!$C$8) | M7: =IF([1]Accounts!$D$8="","",[1]Accounts!$D$8) | P7: =IF([2]Entry!$C$10="","",[2]Entry!$C$10) | Q7: =IF([2]Entry!$D$10="","",[2]Entry!$D$10) | R7: =IF([2]Entry!$E$10="","",[2]Entry!$E$10) | S7: =IF([2]Entry!$G$10="","",[2]Entry!$G$10) | T7: =IF([2]Entry!$J$10="","",[2]Entry!$J$10) | U7: =IF([2]Entry!$K$10="","",[2]Entry!$K$10) | V7: =IF([2]Entry!$L$10="","",[2]Entry!$L$10) | W7: =IF([2]Entry!$M$10="","",[2]Entry!$M$10) | X7: =IF([2]Entry!$N$10="","",[2]Entry!$N$10) | Y7: =IF([2]Entry!$R$10="","",[2]Entry!$R$10) | AA7: =IF(AND($E7<>"",$G7<>"",$F7="هزینه"),1,0) | AB7: =SUM($AA$6:$AA7) | AC7: =IFERROR(INDEX($E$6:$E$105,MATCH(ROW()-5,$AB$6:$AB$105,0)),"") | AE7: =IF([1]Company!$C$8="","",[1]Company!$C$8)
A8: =IF([1]MainGroups!$B$9="","",[1]MainGroups!$A$9) | B8: =IF([1]MainGroups!$B$9="","",[1]MainGroups!$B$9) | C8: =IF([1]MainGroups!$B$9="","",[1]MainGroups!$C$9) | E8: =IF([1]SubGroups!$B$9="","",[1]SubGroups!$A$9) | F8: =IF([1]SubGroups!$B$9="","",[1]SubGroups!$B$9) | G8: =IF([1]SubGroups!$B$9="","",[1]SubGroups!$C$9) | H8: =IF([1]SubGroups!$B$9="","",[1]SubGroups!$D$9) | J8: =IF([1]Accounts!$D$9="","",[1]Accounts!$A$9) | K8: =IF([1]Accounts!$D$9="","",[1]Accounts!$B$9) | L8: =IF([1]Accounts!$D$9="","",[1]Accounts!$C$9) | M8: =IF([1]Accounts!$D$9="","",[1]Accounts!$D$9) | P8: =IF([2]Entry!$C$11="","",[2]Entry!$C$11) | Q8: =IF([2]Entry!$D$11="","",[2]Entry!$D$11) | R8: =IF([2]Entry!$E$11="","",[2]Entry!$E$11) | S8: =IF([2]Entry!$G$11="","",[2]Entry!$G$11) | T8: =IF([2]Entry!$J$11="","",[2]Entry!$J$11) | U8: =IF([2]Entry!$K$11="","",[2]Entry!$K$11) | V8: =IF([2]Entry!$L$11="","",[2]Entry!$L$11) | W8: =IF([2]Entry!$M$11="","",[2]Entry!$M$11) | X8: =IF([2]Entry!$N$11="","",[2]Entry!$N$11) | Y8: =IF([2]Entry!$R$11="","",[2]Entry!$R$11) | AA8: =IF(AND($E8<>"",$G8<>"",$F8="هزینه"),1,0) | AB8: =SUM($AA$6:$AA8) | AC8: =IFERROR(INDEX($E$6:$E$105,MATCH(ROW()-5,$AB$6:$AB$105,0)),"") | AE8: =IF([1]Company!$C$9="","",[1]Company!$C$9)
A9: =IF([1]MainGroups!$B$10="","",[1]MainGroups!$A$10) | B9: =IF([1]MainGroups!$B$10="","",[1]MainGroups!$B$10) | C9: =IF([1]MainGroups!$B$10="","",[1]MainGroups!$C$10) | E9: =IF([1]SubGroups!$B$10="","",[1]SubGroups!$A$10) | F9: =IF([1]SubGroups!$B$10="","",[1]SubGroups!$B$10) | G9: =IF([1]SubGroups!$B$10="","",[1]SubGroups!$C$10) | H9: =IF([1]SubGroups!$B$10="","",[1]SubGroups!$D$10) | J9: =IF([1]Accounts!$D$10="","",[1]Accounts!$A$10) | K9: =IF([1]Accounts!$D$10="","",[1]Accounts!$B$10) | L9: =IF([1]Accounts!$D$10="","",[1]Accounts!$C$10) | M9: =IF([1]Accounts!$D$10="","",[1]Accounts!$D$10) | P9: =IF([2]Entry!$C$12="","",[2]Entry!$C$12) | Q9: =IF([2]Entry!$D$12="","",[2]Entry!$D$12) | R9: =IF([2]Entry!$E$12="","",[2]Entry!$E$12) | S9: =IF([2]Entry!$G$12="","",[2]Entry!$G$12) | T9: =IF([2]Entry!$J$12="","",[2]Entry!$J$12) | U9: =IF([2]Entry!$K$12="","",[2]Entry!$K$12) | V9: =IF([2]Entry!$L$12="","",[2]Entry!$L$12) | W9: =IF([2]Entry!$M$12="","",[2]Entry!$M$12) | X9: =IF([2]Entry!$N$12="","",[2]Entry!$N$12) | Y9: =IF([2]Entry!$R$12="","",[2]Entry!$R$12) | AA9: =IF(AND($E9<>"",$G9<>"",$F9="هزینه"),1,0) | AB9: =SUM($AA$6:$AA9) | AC9: =IFERROR(INDEX($E$6:$E$105,MATCH(ROW()-5,$AB$6:$AB$105,0)),"") | AE9: =IF([1]Company!$C$7="","",[1]Company!$C$7)
A10: =IF([1]MainGroups!$B$11="","",[1]MainGroups!$A$11) | B10: =IF([1]MainGroups!$B$11="","",[1]MainGroups!$B$11) | C10: =IF([1]MainGroups!$B$11="","",[1]MainGroups!$C$11) | E10: =IF([1]SubGroups!$B$11="","",[1]SubGroups!$A$11) | F10: =IF([1]SubGroups!$B$11="","",[1]SubGroups!$B$11) | G10: =IF([1]SubGroups!$B$11="","",[1]SubGroups!$C$11) | H10: =IF([1]SubGroups!$B$11="","",[1]SubGroups!$D$11) | J10: =IF([1]Accounts!$D$11="","",[1]Accounts!$A$11) | K10: =IF([1]Accounts!$D$11="","",[1]Accounts!$B$11) | L10: =IF([1]Accounts!$D$11="","",[1]Accounts!$C$11) | M10: =IF([1]Accounts!$D$11="","",[1]Accounts!$D$11) | P10: =IF([2]Entry!$C$13="","",[2]Entry!$C$13) | Q10: =IF([2]Entry!$D$13="","",[2]Entry!$D$13) | R10: =IF([2]Entry!$E$13="","",[2]Entry!$E$13) | S10: =IF([2]Entry!$G$13="","",[2]Entry!$G$13) | T10: =IF([2]Entry!$J$13="","",[2]Entry!$J$13) | U10: =IF([2]Entry!$K$13="","",[2]Entry!$K$13) | V10: =IF([2]Entry!$L$13="","",[2]Entry!$L$13) | W10: =IF([2]Entry!$M$13="","",[2]Entry!$M$13) | X10: =IF([2]Entry!$N$13="","",[2]Entry!$N$13) | Y10: =IF([2]Entry!$R$13="","",[2]Entry!$R$13) | AA10: =IF(AND($E10<>"",$G10<>"",$F10="هزینه"),1,0) | AB10: =SUM($AA$6:$AA10) | AC10: =IFERROR(INDEX($E$6:$E$105,MATCH(ROW()-5,$AB$6:$AB$105,0)),"")
A11: =IF([1]MainGroups!$B$12="","",[1]MainGroups!$A$12) | B11: =IF([1]MainGroups!$B$12="","",[1]MainGroups!$B$12) | C11: =IF([1]MainGroups!$B$12="","",[1]MainGroups!$C$12) | E11: =IF([1]SubGroups!$B$12="","",[1]SubGroups!$A$12) | F11: =IF([1]SubGroups!$B$12="","",[1]SubGroups!$B$12) | G11: =IF([1]SubGroups!$B$12="","",[1]SubGroups!$C$12) | H11: =IF([1]SubGroups!$B$12="","",[1]SubGroups!$D$12) | J11: =IF([1]Accounts!$D$12="","",[1]Accounts!$A$12) | K11: =IF([1]Accounts!$D$12="","",[1]Accounts!$B$12) | L11: =IF([1]Accounts!$D$12="","",[1]Accounts!$C$12) | M11: =IF([1]Accounts!$D$12="","",[1]Accounts!$D$12) | P11: =IF([2]Entry!$C$14="","",[2]Entry!$C$14) | Q11: =IF([2]Entry!$D$14="","",[2]Entry!$D$14) | R11: =IF([2]Entry!$E$14="","",[2]Entry!$E$14) | S11: =IF([2]Entry!$G$14="","",[2]Entry!$G$14) | T11: =IF([2]Entry!$J$14="","",[2]Entry!$J$14) | U11: =IF([2]Entry!$K$14="","",[2]Entry!$K$14) | V11: =IF([2]Entry!$L$14="","",[2]Entry!$L$14) | W11: =IF([2]Entry!$M$14="","",[2]Entry!$M$14) | X11: =IF([2]Entry!$N$14="","",[2]Entry!$N$14) | Y11: =IF([2]Entry!$R$14="","",[2]Entry!$R$14) | AA11: =IF(AND($E11<>"",$G11<>"",$F11="هزینه"),1,0) | AB11: =SUM($AA$6:$AA11) | AC11: =IFERROR(INDEX($E$6:$E$105,MATCH(ROW()-5,$AB$6:$AB$105,0)),"")
A12: =IF([1]MainGroups!$B$13="","",[1]MainGroups!$A$13) | B12: =IF([1]MainGroups!$B$13="","",[1]MainGroups!$B$13) | C12: =IF([1]MainGroups!$B$13="","",[1]MainGroups!$C$13) | E12: =IF([1]SubGroups!$B$13="","",[1]SubGroups!$A$13) | F12: =IF([1]SubGroups!$B$13="","",[1]SubGroups!$B$13) | G12: =IF([1]SubGroups!$B$13="","",[1]SubGroups!$C$13) | H12: =IF([1]SubGroups!$B$13="","",[1]SubGroups!$D$13) | J12: =IF([1]Accounts!$D$13="","",[1]Accounts!$A$13) | K12: =IF([1]Accounts!$D$13="","",[1]Accounts!$B$13) | L12: =IF([1]Accounts!$D$13="","",[1]Accounts!$C$13) | M12: =IF([1]Accounts!$D$13="","",[1]Accounts!$D$13) | P12: =IF([2]Entry!$C$15="","",[2]Entry!$C$15) | Q12: =IF([2]Entry!$D$15="","",[2]Entry!$D$15) | R12: =IF([2]Entry!$E$15="","",[2]Entry!$E$15) | S12: =IF([2]Entry!$G$15="","",[2]Entry!$G$15) | T12: =IF([2]Entry!$J$15="","",[2]Entry!$J$15) | U12: =IF([2]Entry!$K$15="","",[2]Entry!$K$15) | V12: =IF([2]Entry!$L$15="","",[2]Entry!$L$15) | W12: =IF([2]Entry!$M$15="","",[2]Entry!$M$15) | X12: =IF([2]Entry!$N$15="","",[2]Entry!$N$15) | Y12: =IF([2]Entry!$R$15="","",[2]Entry!$R$15) | AA12: =IF(AND($E12<>"",$G12<>"",$F12="هزینه"),1,0) | AB12: =SUM($AA$6:$AA12) | AC12: =IFERROR(INDEX($E$6:$E$105,MATCH(ROW()-5,$AB$6:$AB$105,0)),"")
A13: =IF([1]MainGroups!$B$14="","",[1]MainGroups!$A$14) | B13: =IF([1]MainGroups!$B$14="","",[1]MainGroups!$B$14) | C13: =IF([1]MainGroups!$B$14="","",[1]MainGroups!$C$14) | E13: =IF([1]SubGroups!$B$14="","",[1]SubGroups!$A$14) | F13: =IF([1]SubGroups!$B$14="","",[1]SubGroups!$B$14) | G13: =IF([1]SubGroups!$B$14="","",[1]SubGroups!$C$14) | H13: =IF([1]SubGroups!$B$14="","",[1]SubGroups!$D$14) | J13: =IF([1]Accounts!$D$14="","",[1]Accounts!$A$14) | K13: =IF([1]Accounts!$D$14="","",[1]Accounts!$B$14) | L13: =IF([1]Accounts!$D$14="","",[1]Accounts!$C$14) | M13: =IF([1]Accounts!$D$14="","",[1]Accounts!$D$14) | P13: =IF([2]Entry!$C$16="","",[2]Entry!$C$16) | Q13: =IF([2]Entry!$D$16="","",[2]Entry!$D$16) | R13: =IF([2]Entry!$E$16="","",[2]Entry!$E$16) | S13: =IF([2]Entry!$G$16="","",[2]Entry!$G$16) | T13: =IF([2]Entry!$J$16="","",[2]Entry!$J$16) | U13: =IF([2]Entry!$K$16="","",[2]Entry!$K$16) | V13: =IF([2]Entry!$L$16="","",[2]Entry!$L$16) | W13: =IF([2]Entry!$M$16="","",[2]Entry!$M$16) | X13: =IF([2]Entry!$N$16="","",[2]Entry!$N$16) | Y13: =IF([2]Entry!$R$16="","",[2]Entry!$R$16) | AA13: =IF(AND($E13<>"",$G13<>"",$F13="هزینه"),1,0) | AB13: =SUM($AA$6:$AA13) | AC13: =IFERROR(INDEX($E$6:$E$105,MATCH(ROW()-5,$AB$6:$AB$105,0)),"")
A14: =IF([1]MainGroups!$B$15="","",[1]MainGroups!$A$15) | B14: =IF([1]MainGroups!$B$15="","",[1]MainGroups!$B$15) | C14: =IF([1]MainGroups!$B$15="","",[1]MainGroups!$C$15) | E14: =IF([1]SubGroups!$B$15="","",[1]SubGroups!$A$15) | F14: =IF([1]SubGroups!$B$15="","",[1]SubGroups!$B$15) | G14: =IF([1]SubGroups!$B$15="","",[1]SubGroups!$C$15) | H14: =IF([1]SubGroups!$B$15="","",[1]SubGroups!$D$15) | J14: =IF([1]Accounts!$D$15="","",[1]Accounts!$A$15) | K14: =IF([1]Accounts!$D$15="","",[1]Accounts!$B$15) | L14: =IF([1]Accounts!$D$15="","",[1]Accounts!$C$15) | M14: =IF([1]Accounts!$D$15="","",[1]Accounts!$D$15) | P14: =IF([2]Entry!$C$17="","",[2]Entry!$C$17) | Q14: =IF([2]Entry!$D$17="","",[2]Entry!$D$17) | R14: =IF([2]Entry!$E$17="","",[2]Entry!$E$17) | S14: =IF([2]Entry!$G$17="","",[2]Entry!$G$17) | T14: =IF([2]Entry!$J$17="","",[2]Entry!$J$17) | U14: =IF([2]Entry!$K$17="","",[2]Entry!$K$17) | V14: =IF([2]Entry!$L$17="","",[2]Entry!$L$17) | W14: =IF([2]Entry!$M$17="","",[2]Entry!$M$17) | X14: =IF([2]Entry!$N$17="","",[2]Entry!$N$17) | Y14: =IF([2]Entry!$R$17="","",[2]Entry!$R$17) | AA14: =IF(AND($E14<>"",$G14<>"",$F14="هزینه"),1,0) | AB14: =SUM($AA$6:$AA14) | AC14: =IFERROR(INDEX($E$6:$E$105,MATCH(ROW()-5,$AB$6:$AB$105,0)),"")
A15: =IF([1]MainGroups!$B$16="","",[1]MainGroups!$A$16) | B15: =IF([1]MainGroups!$B$16="","",[1]MainGroups!$B$16) | C15: =IF([1]MainGroups!$B$16="","",[1]MainGroups!$C$16) | E15: =IF([1]SubGroups!$B$16="","",[1]SubGroups!$A$16) | F15: =IF([1]SubGroups!$B$16="","",[1]SubGroups!$B$16) | G15: =IF([1]SubGroups!$B$16="","",[1]SubGroups!$C$16) | H15: =IF([1]SubGroups!$B$16="","",[1]SubGroups!$D$16) | J15: =IF([1]Accounts!$D$16="","",[1]Accounts!$A$16) | K15: =IF([1]Accounts!$D$16="","",[1]Accounts!$B$16) | L15: =IF([1]Accounts!$D$16="","",[1]Accounts!$C$16) | M15: =IF([1]Accounts!$D$16="","",[1]Accounts!$D$16) | P15: =IF([2]Entry!$C$18="","",[2]Entry!$C$18) | Q15: =IF([2]Entry!$D$18="","",[2]Entry!$D$18) | R15: =IF([2]Entry!$E$18="","",[2]Entry!$E$18) | S15: =IF([2]Entry!$G$18="","",[2]Entry!$G$18) | T15: =IF([2]Entry!$J$18="","",[2]Entry!$J$18) | U15: =IF([2]Entry!$K$18="","",[2]Entry!$K$18) | V15: =IF([2]Entry!$L$18="","",[2]Entry!$L$18) | W15: =IF([2]Entry!$M$18="","",[2]Entry!$M$18) | X15: =IF([2]Entry!$N$18="","",[2]Entry!$N$18) | Y15: =IF([2]Entry!$R$18="","",[2]Entry!$R$18) | AA15: =IF(AND($E15<>"",$G15<>"",$F15="هزینه"),1,0) | AB15: =SUM($AA$6:$AA15) | AC15: =IFERROR(INDEX($E$6:$E$105,MATCH(ROW()-5,$AB$6:$AB$105,0)),"")
E16: =IF([1]SubGroups!$B$17="","",[1]SubGroups!$A$17) | F16: =IF([1]SubGroups!$B$17="","",[1]SubGroups!$B$17) | G16: =IF([1]SubGroups!$B$17="","",[1]SubGroups!$C$17) | H16: =IF([1]SubGroups!$B$17="","",[1]SubGroups!$D$17) | J16: =IF([1]Accounts!$D$17="","",[1]Accounts!$A$17) | K16: =IF([1]Accounts!$D$17="","",[1]Accounts!$B$17) | L16: =IF([1]Accounts!$D$17="","",[1]Accounts!$C$17) | M16: =IF([1]Accounts!$D$17="","",[1]Accounts!$D$17) | P16: =IF([2]Entry!$C$19="","",[2]Entry!$C$19) | Q16: =IF([2]Entry!$D$19="","",[2]Entry!$D$19) | R16: =IF([2]Entry!$E$19="","",[2]Entry!$E$19) | S16: =IF([2]Entry!$G$19="","",[2]Entry!$G$19) | T16: =IF([2]Entry!$J$19="","",[2]Entry!$J$19) | U16: =IF([2]Entry!$K$19="","",[2]Entry!$K$19) | V16: =IF([2]Entry!$L$19="","",[2]Entry!$L$19) | W16: =IF([2]Entry!$M$19="","",[2]Entry!$M$19) | X16: =IF([2]Entry!$N$19="","",[2]Entry!$N$19) | Y16: =IF([2]Entry!$R$19="","",[2]Entry!$R$19) | AA16: =IF(AND($E16<>"",$G16<>"",$F16="هزینه"),1,0) | AB16: =SUM($AA$6:$AA16) | AC16: =IFERROR(INDEX($E$6:$E$105,MATCH(ROW()-5,$AB$6:$AB$105,0)),"")
E17: =IF([1]SubGroups!$B$18="","",[1]SubGroups!$A$18) | F17: =IF([1]SubGroups!$B$18="","",[1]SubGroups!$B$18) | G17: =IF([1]SubGroups!$B$18="","",[1]SubGroups!$C$18) | H17: =IF([1]SubGroups!$B$18="","",[1]SubGroups!$D$18) | J17: =IF([1]Accounts!$D$18="","",[1]Accounts!$A$18) | K17: =IF([1]Accounts!$D$18="","",[1]Accounts!$B$18) | L17: =IF([1]Accounts!$D$18="","",[1]Accounts!$C$18) | M17: =IF([1]Accounts!$D$18="","",[1]Accounts!$D$18) | P17: =IF([2]Entry!$C$20="","",[2]Entry!$C$20) | Q17: =IF([2]Entry!$D$20="","",[2]Entry!$D$20) | R17: =IF([2]Entry!$E$20="","",[2]Entry!$E$20) | S17: =IF([2]Entry!$G$20="","",[2]Entry!$G$20) | T17: =IF([2]Entry!$J$20="","",[2]Entry!$J$20) | U17: =IF([2]Entry!$K$20="","",[2]Entry!$K$20) | V17: =IF([2]Entry!$L$20="","",[2]Entry!$L$20) | W17: =IF([2]Entry!$M$20="","",[2]Entry!$M$20) | X17: =IF([2]Entry!$N$20="","",[2]Entry!$N$20) | Y17: =IF([2]Entry!$R$20="","",[2]Entry!$R$20) | AA17: =IF(AND($E17<>"",$G17<>"",$F17="هزینه"),1,0) | AB17: =SUM($AA$6:$AA17) | AC17: =IFERROR(INDEX($E$6:$E$105,MATCH(ROW()-5,$AB$6:$AB$105,0)),"")
E18: =IF([1]SubGroups!$B$19="","",[1]SubGroups!$A$19) | F18: =IF([1]SubGroups!$B$19="","",[1]SubGroups!$B$19) | G18: =IF([1]SubGroups!$B$19="","",[1]SubGroups!$C$19) | H18: =IF([1]SubGroups!$B$19="","",[1]SubGroups!$D$19) | J18: =IF([1]Accounts!$D$19="","",[1]Accounts!$A$19) | K18: =IF([1]Accounts!$D$19="","",[1]Accounts!$B$19) | L18: =IF([1]Accounts!$D$19="","",[1]Accounts!$C$19) | M18: =IF([1]Accounts!$D$19="","",[1]Accounts!$D$19) | P18: =IF([2]Entry!$C$21="","",[2]Entry!$C$21) | Q18: =IF([2]Entry!$D$21="","",[2]Entry!$D$21) | R18: =IF([2]Entry!$E$21="","",[2]Entry!$E$21) | S18: =IF([2]Entry!$G$21="","",[2]Entry!$G$21) | T18: =IF([2]Entry!$J$21="","",[2]Entry!$J$21) | U18: =IF([2]Entry!$K$21="","",[2]Entry!$K$21) | V18: =IF([2]Entry!$L$21="","",[2]Entry!$L$21) | W18: =IF([2]Entry!$M$21="","",[2]Entry!$M$21) | X18: =IF([2]Entry!$N$21="","",[2]Entry!$N$21) | Y18: =IF([2]Entry!$R$21="","",[2]Entry!$R$21) | AA18: =IF(AND($E18<>"",$G18<>"",$F18="هزینه"),1,0) | AB18: =SUM($AA$6:$AA18) | AC18: =IFERROR(INDEX($E$6:$E$105,MATCH(ROW()-5,$AB$6:$AB$105,0)),"")
E19: =IF([1]SubGroups!$B$20="","",[1]SubGroups!$A$20) | F19: =IF([1]SubGroups!$B$20="","",[1]SubGroups!$B$20) | G19: =IF([1]SubGroups!$B$20="","",[1]SubGroups!$C$20) | H19: =IF([1]SubGroups!$B$20="","",[1]SubGroups!$D$20) | J19: =IF([1]Accounts!$D$20="","",[1]Accounts!$A$20) | K19: =IF([1]Accounts!$D$20="","",[1]Accounts!$B$20) | L19: =IF([1]Accounts!$D$20="","",[1]Accounts!$C$20) | M19: =IF([1]Accounts!$D$20="","",[1]Accounts!$D$20) | P19: =IF([2]Entry!$C$22="","",[2]Entry!$C$22) | Q19: =IF([2]Entry!$D$22="","",[2]Entry!$D$22) | R19: =IF([2]Entry!$E$22="","",[2]Entry!$E$22) | S19: =IF([2]Entry!$G$22="","",[2]Entry!$G$22) | T19: =IF([2]Entry!$J$22="","",[2]Entry!$J$22) | U19: =IF([2]Entry!$K$22="","",[2]Entry!$K$22) | V19: =IF([2]Entry!$L$22="","",[2]Entry!$L$22) | W19: =IF([2]Entry!$M$22="","",[2]Entry!$M$22) | X19: =IF([2]Entry!$N$22="","",[2]Entry!$N$22) | Y19: =IF([2]Entry!$R$22="","",[2]Entry!$R$22) | AA19: =IF(AND($E19<>"",$G19<>"",$F19="هزینه"),1,0) | AB19: =SUM($AA$6:$AA19) | AC19: =IFERROR(INDEX($E$6:$E$105,MATCH(ROW()-5,$AB$6:$AB$105,0)),"")
E20: =IF([1]SubGroups!$B$21="","",[1]SubGroups!$A$21) | F20: =IF([1]SubGroups!$B$21="","",[1]SubGroups!$B$21) | G20: =IF([1]SubGroups!$B$21="","",[1]SubGroups!$C$21) | H20: =IF([1]SubGroups!$B$21="","",[1]SubGroups!$D$21) | J20: =IF([1]Accounts!$D$21="","",[1]Accounts!$A$21) | K20: =IF([1]Accounts!$D$21="","",[1]Accounts!$B$21) | L20: =IF([1]Accounts!$D$21="","",[1]Accounts!$C$21) | M20: =IF([1]Accounts!$D$21="","",[1]Accounts!$D$21) | P20: =IF([2]Entry!$C$23="","",[2]Entry!$C$23) | Q20: =IF([2]Entry!$D$23="","",[2]Entry!$D$23) | R20: =IF([2]Entry!$E$23="","",[2]Entry!$E$23) | S20: =IF([2]Entry!$G$23="","",[2]Entry!$G$23) | T20: =IF([2]Entry!$J$23="","",[2]Entry!$J$23) | U20: =IF([2]Entry!$K$23="","",[2]Entry!$K$23) | V20: =IF([2]Entry!$L$23="","",[2]Entry!$L$23) | W20: =IF([2]Entry!$M$23="","",[2]Entry!$M$23) | X20: =IF([2]Entry!$N$23="","",[2]Entry!$N$23) | Y20: =IF([2]Entry!$R$23="","",[2]Entry!$R$23) | AA20: =IF(AND($E20<>"",$G20<>"",$F20="هزینه"),1,0) | AB20: =SUM($AA$6:$AA20) | AC20: =IFERROR(INDEX($E$6:$E$105,MATCH(ROW()-5,$AB$6:$AB$105,0)),"")
E21: =IF([1]SubGroups!$B$22="","",[1]SubGroups!$A$22) | F21: =IF([1]SubGroups!$B$22="","",[1]SubGroups!$B$22) | G21: =IF([1]SubGroups!$B$22="","",[1]SubGroups!$C$22) | H21: =IF([1]SubGroups!$B$22="","",[1]SubGroups!$D$22) | J21: =IF([1]Accounts!$D$22="","",[1]Accounts!$A$22) | K21: =IF([1]Accounts!$D$22="","",[1]Accounts!$B$22) | L21: =IF([1]Accounts!$D$22="","",[1]Accounts!$C$22) | M21: =IF([1]Accounts!$D$22="","",[1]Accounts!$D$22) | P21: =IF([2]Entry!$C$24="","",[2]Entry!$C$24) | Q21: =IF([2]Entry!$D$24="","",[2]Entry!$D$24) | R21: =IF([2]Entry!$E$24="","",[2]Entry!$E$24) | S21: =IF([2]Entry!$G$24="","",[2]Entry!$G$24) | T21: =IF([2]Entry!$J$24="","",[2]Entry!$J$24) | U21: =IF([2]Entry!$K$24="","",[2]Entry!$K$24) | V21: =IF([2]Entry!$L$24="","",[2]Entry!$L$24) | W21: =IF([2]Entry!$M$24="","",[2]Entry!$M$24) | X21: =IF([2]Entry!$N$24="","",[2]Entry!$N$24) | Y21: =IF([2]Entry!$R$24="","",[2]Entry!$R$24) | AA21: =IF(AND($E21<>"",$G21<>"",$F21="هزینه"),1,0) | AB21: =SUM($AA$6:$AA21) | AC21: =IFERROR(INDEX($E$6:$E$105,MATCH(ROW()-5,$AB$6:$AB$105,0)),"")
E22: =IF([1]SubGroups!$B$23="","",[1]SubGroups!$A$23) | F22: =IF([1]SubGroups!$B$23="","",[1]SubGroups!$B$23) | G22: =IF([1]SubGroups!$B$23="","",[1]SubGroups!$C$23) | H22: =IF([1]SubGroups!$B$23="","",[1]SubGroups!$D$23) | J22: =IF([1]Accounts!$D$23="","",[1]Accounts!$A$23) | K22: =IF([1]Accounts!$D$23="","",[1]Accounts!$B$23) | L22: =IF([1]Accounts!$D$23="","",[1]Accounts!$C$23) | M22: =IF([1]Accounts!$D$23="","",[1]Accounts!$D$23) | P22: =IF([2]Entry!$C$25="","",[2]Entry!$C$25) | Q22: =IF([2]Entry!$D$25="","",[2]Entry!$D$25) | R22: =IF([2]Entry!$E$25="","",[2]Entry!$E$25) | S22: =IF([2]Entry!$G$25="","",[2]Entry!$G$25) | T22: =IF([2]Entry!$J$25="","",[2]Entry!$J$25) | U22: =IF([2]Entry!$K$25="","",[2]Entry!$K$25) | V22: =IF([2]Entry!$L$25="","",[2]Entry!$L$25) | W22: =IF([2]Entry!$M$25="","",[2]Entry!$M$25) | X22: =IF([2]Entry!$N$25="","",[2]Entry!$N$25) | Y22: =IF([2]Entry!$R$25="","",[2]Entry!$R$25) | AA22: =IF(AND($E22<>"",$G22<>"",$F22="هزینه"),1,0) | AB22: =SUM($AA$6:$AA22) | AC22: =IFERROR(INDEX($E$6:$E$105,MATCH(ROW()-5,$AB$6:$AB$105,0)),"")
E23: =IF([1]SubGroups!$B$24="","",[1]SubGroups!$A$24) | F23: =IF([1]SubGroups!$B$24="","",[1]SubGroups!$B$24) | G23: =IF([1]SubGroups!$B$24="","",[1]SubGroups!$C$24) | H23: =IF([1]SubGroups!$B$24="","",[1]SubGroups!$D$24) | J23: =IF([1]Accounts!$D$24="","",[1]Accounts!$A$24) | K23: =IF([1]Accounts!$D$24="","",[1]Accounts!$B$24) | L23: =IF([1]Accounts!$D$24="","",[1]Accounts!$C$24) | M23: =IF([1]Accounts!$D$24="","",[1]Accounts!$D$24) | P23: =IF([2]Entry!$C$26="","",[2]Entry!$C$26) | Q23: =IF([2]Entry!$D$26="","",[2]Entry!$D$26) | R23: =IF([2]Entry!$E$26="","",[2]Entry!$E$26) | S23: =IF([2]Entry!$G$26="","",[2]Entry!$G$26) | T23: =IF([2]Entry!$J$26="","",[2]Entry!$J$26) | U23: =IF([2]Entry!$K$26="","",[2]Entry!$K$26) | V23: =IF([2]Entry!$L$26="","",[2]Entry!$L$26) | W23: =IF([2]Entry!$M$26="","",[2]Entry!$M$26) | X23: =IF([2]Entry!$N$26="","",[2]Entry!$N$26) | Y23: =IF([2]Entry!$R$26="","",[2]Entry!$R$26) | AA23: =IF(AND($E23<>"",$G23<>"",$F23="هزینه"),1,0) | AB23: =SUM($AA$6:$AA23) | AC23: =IFERROR(INDEX($E$6:$E$105,MATCH(ROW()-5,$AB$6:$AB$105,0)),"")
E24: =IF([1]SubGroups!$B$25="","",[1]SubGroups!$A$25) | F24: =IF([1]SubGroups!$B$25="","",[1]SubGroups!$B$25) | G24: =IF([1]SubGroups!$B$25="","",[1]SubGroups!$C$25) | H24: =IF([1]SubGroups!$B$25="","",[1]SubGroups!$D$25) | J24: =IF([1]Accounts!$D$25="","",[1]Accounts!$A$25) | K24: =IF([1]Accounts!$D$25="","",[1]Accounts!$B$25) | L24: =IF([1]Accounts!$D$25="","",[1]Accounts!$C$25) | M24: =IF([1]Accounts!$D$25="","",[1]Accounts!$D$25) | P24: =IF([2]Entry!$C$27="","",[2]Entry!$C$27) | Q24: =IF([2]Entry!$D$27="","",[2]Entry!$D$27) | R24: =IF([2]Entry!$E$27="","",[2]Entry!$E$27) | S24: =IF([2]Entry!$G$27="","",[2]Entry!$G$27) | T24: =IF([2]Entry!$J$27="","",[2]Entry!$J$27) | U24: =IF([2]Entry!$K$27="","",[2]Entry!$K$27) | V24: =IF([2]Entry!$L$27="","",[2]Entry!$L$27) | W24: =IF([2]Entry!$M$27="","",[2]Entry!$M$27) | X24: =IF([2]Entry!$N$27="","",[2]Entry!$N$27) | Y24: =IF([2]Entry!$R$27="","",[2]Entry!$R$27) | AA24: =IF(AND($E24<>"",$G24<>"",$F24="هزینه"),1,0) | AB24: =SUM($AA$6:$AA24) | AC24: =IFERROR(INDEX($E$6:$E$105,MATCH(ROW()-5,$AB$6:$AB$105,0)),"")
E25: =IF([1]SubGroups!$B$26="","",[1]SubGroups!$A$26) | F25: =IF([1]SubGroups!$B$26="","",[1]SubGroups!$B$26) | G25: =IF([1]SubGroups!$B$26="","",[1]SubGroups!$C$26) | H25: =IF([1]SubGroups!$B$26="","",[1]SubGroups!$D$26) | J25: =IF([1]Accounts!$D$26="","",[1]Accounts!$A$26) | K25: =IF([1]Accounts!$D$26="","",[1]Accounts!$B$26) | L25: =IF([1]Accounts!$D$26="","",[1]Accounts!$C$26) | M25: =IF([1]Accounts!$D$26="","",[1]Accounts!$D$26) | P25: =IF([2]Entry!$C$28="","",[2]Entry!$C$28) | Q25: =IF([2]Entry!$D$28="","",[2]Entry!$D$28) | R25: =IF([2]Entry!$E$28="","",[2]Entry!$E$28) | S25: =IF([2]Entry!$G$28="","",[2]Entry!$G$28) | T25: =IF([2]Entry!$J$28="","",[2]Entry!$J$28) | U25: =IF([2]Entry!$K$28="","",[2]Entry!$K$28) | V25: =IF([2]Entry!$L$28="","",[2]Entry!$L$28) | W25: =IF([2]Entry!$M$28="","",[2]Entry!$M$28) | X25: =IF([2]Entry!$N$28="","",[2]Entry!$N$28) | Y25: =IF([2]Entry!$R$28="","",[2]Entry!$R$28) | AA25: =IF(AND($E25<>"",$G25<>"",$F25="هزینه"),1,0) | AB25: =SUM($AA$6:$AA25) | AC25: =IFERROR(INDEX($E$6:$E$105,MATCH(ROW()-5,$AB$6:$AB$105,0)),"")
E26: =IF([1]SubGroups!$B$27="","",[1]SubGroups!$A$27) | F26: =IF([1]SubGroups!$B$27="","",[1]SubGroups!$B$27) | G26: =IF([1]SubGroups!$B$27="","",[1]SubGroups!$C$27) | H26: =IF([1]SubGroups!$B$27="","",[1]SubGroups!$D$27) | J26: =IF([1]Accounts!$D$27="","",[1]Accounts!$A$27) | K26: =IF([1]Accounts!$D$27="","",[1]Accounts!$B$27) | L26: =IF([1]Accounts!$D$27="","",[1]Accounts!$C$27) | M26: =IF([1]Accounts!$D$27="","",[1]Accounts!$D$27) | P26: =IF([2]Entry!$C$29="","",[2]Entry!$C$29) | Q26: =IF([2]Entry!$D$29="","",[2]Entry!$D$29) | R26: =IF([2]Entry!$E$29="","",[2]Entry!$E$29) | S26: =IF([2]Entry!$G$29="","",[2]Entry!$G$29) | T26: =IF([2]Entry!$J$29="","",[2]Entry!$J$29) | U26: =IF([2]Entry!$K$29="","",[2]Entry!$K$29) | V26: =IF([2]Entry!$L$29="","",[2]Entry!$L$29) | W26: =IF([2]Entry!$M$29="","",[2]Entry!$M$29) | X26: =IF([2]Entry!$N$29="","",[2]Entry!$N$29) | Y26: =IF([2]Entry!$R$29="","",[2]Entry!$R$29) | AA26: =IF(AND($E26<>"",$G26<>"",$F26="هزینه"),1,0) | AB26: =SUM($AA$6:$AA26) | AC26: =IFERROR(INDEX($E$6:$E$105,MATCH(ROW()-5,$AB$6:$AB$105,0)),"")
E27: =IF([1]SubGroups!$B$28="","",[1]SubGroups!$A$28) | F27: =IF([1]SubGroups!$B$28="","",[1]SubGroups!$B$28) | G27: =IF([1]SubGroups!$B$28="","",[1]SubGroups!$C$28) | H27: =IF([1]SubGroups!$B$28="","",[1]SubGroups!$D$28) | J27: =IF([1]Accounts!$D$28="","",[1]Accounts!$A$28) | K27: =IF([1]Accounts!$D$28="","",[1]Accounts!$B$28) | L27: =IF([1]Accounts!$D$28="","",[1]Accounts!$C$28) | M27: =IF([1]Accounts!$D$28="","",[1]Accounts!$D$28) | P27: =IF([2]Entry!$C$30="","",[2]Entry!$C$30) | Q27: =IF([2]Entry!$D$30="","",[2]Entry!$D$30) | R27: =IF([2]Entry!$E$30="","",[2]Entry!$E$30) | S27: =IF([2]Entry!$G$30="","",[2]Entry!$G$30) | T27: =IF([2]Entry!$J$30="","",[2]Entry!$J$30) | U27: =IF([2]Entry!$K$30="","",[2]Entry!$K$30) | V27: =IF([2]Entry!$L$30="","",[2]Entry!$L$30) | W27: =IF([2]Entry!$M$30="","",[2]Entry!$M$30) | X27: =IF([2]Entry!$N$30="","",[2]Entry!$N$30) | Y27: =IF([2]Entry!$R$30="","",[2]Entry!$R$30) | AA27: =IF(AND($E27<>"",$G27<>"",$F27="هزینه"),1,0) | AB27: =SUM($AA$6:$AA27) | AC27: =IFERROR(INDEX($E$6:$E$105,MATCH(ROW()-5,$AB$6:$AB$105,0)),"")
E28: =IF([1]SubGroups!$B$29="","",[1]SubGroups!$A$29) | F28: =IF([1]SubGroups!$B$29="","",[1]SubGroups!$B$29) | G28: =IF([1]SubGroups!$B$29="","",[1]SubGroups!$C$29) | H28: =IF([1]SubGroups!$B$29="","",[1]SubGroups!$D$29) | J28: =IF([1]Accounts!$D$29="","",[1]Accounts!$A$29) | K28: =IF([1]Accounts!$D$29="","",[1]Accounts!$B$29) | L28: =IF([1]Accounts!$D$29="","",[1]Accounts!$C$29) | M28: =IF([1]Accounts!$D$29="","",[1]Accounts!$D$29) | P28: =IF([2]Entry!$C$31="","",[2]Entry!$C$31) | Q28: =IF([2]Entry!$D$31="","",[2]Entry!$D$31) | R28: =IF([2]Entry!$E$31="","",[2]Entry!$E$31) | S28: =IF([2]Entry!$G$31="","",[2]Entry!$G$31) | T28: =IF([2]Entry!$J$31="","",[2]Entry!$J$31) | U28: =IF([2]Entry!$K$31="","",[2]Entry!$K$31) | V28: =IF([2]Entry!$L$31="","",[2]Entry!$L$31) | W28: =IF([2]Entry!$M$31="","",[2]Entry!$M$31) | X28: =IF([2]Entry!$N$31="","",[2]Entry!$N$31) | Y28: =IF([2]Entry!$R$31="","",[2]Entry!$R$31) | AA28: =IF(AND($E28<>"",$G28<>"",$F28="هزینه"),1,0) | AB28: =SUM($AA$6:$AA28) | AC28: =IFERROR(INDEX($E$6:$E$105,MATCH(ROW()-5,$AB$6:$AB$105,0)),"")
E29: =IF([1]SubGroups!$B$30="","",[1]SubGroups!$A$30) | F29: =IF([1]SubGroups!$B$30="","",[1]SubGroups!$B$30) | G29: =IF([1]SubGroups!$B$30="","",[1]SubGroups!$C$30) | H29: =IF([1]SubGroups!$B$30="","",[1]SubGroups!$D$30) | J29: =IF([1]Accounts!$D$30="","",[1]Accounts!$A$30) | K29: =IF([1]Accounts!$D$30="","",[1]Accounts!$B$30) | L29: =IF([1]Accounts!$D$30="","",[1]Accounts!$C$30) | M29: =IF([1]Accounts!$D$30="","",[1]Accounts!$D$30) | P29: =IF([2]Entry!$C$32="","",[2]Entry!$C$32) | Q29: =IF([2]Entry!$D$32="","",[2]Entry!$D$32) | R29: =IF([2]Entry!$E$32="","",[2]Entry!$E$32) | S29: =IF([2]Entry!$G$32="","",[2]Entry!$G$32) | T29: =IF([2]Entry!$J$32="","",[2]Entry!$J$32) | U29: =IF([2]Entry!$K$32="","",[2]Entry!$K$32) | V29: =IF([2]Entry!$L$32="","",[2]Entry!$L$32) | W29: =IF([2]Entry!$M$32="","",[2]Entry!$M$32) | X29: =IF([2]Entry!$N$32="","",[2]Entry!$N$32) | Y29: =IF([2]Entry!$R$32="","",[2]Entry!$R$32) | AA29: =IF(AND($E29<>"",$G29<>"",$F29="هزینه"),1,0) | AB29: =SUM($AA$6:$AA29) | AC29: =IFERROR(INDEX($E$6:$E$105,MATCH(ROW()-5,$AB$6:$AB$105,0)),"")
E30: =IF([1]SubGroups!$B$31="","",[1]SubGroups!$A$31) | F30: =IF([1]SubGroups!$B$31="","",[1]SubGroups!$B$31) | G30: =IF([1]SubGroups!$B$31="","",[1]SubGroups!$C$31) | H30: =IF([1]SubGroups!$B$31="","",[1]SubGroups!$D$31) | J30: =IF([1]Accounts!$D$31="","",[1]Accounts!$A$31) | K30: =IF([1]Accounts!$D$31="","",[1]Accounts!$B$31) | L30: =IF([1]Accounts!$D$31="","",[1]Accounts!$C$31) | M30: =IF([1]Accounts!$D$31="","",[1]Accounts!$D$31) | P30: =IF([2]Entry!$C$33="","",[2]Entry!$C$33) | Q30: =IF([2]Entry!$D$33="","",[2]Entry!$D$33) | R30: =IF([2]Entry!$E$33="","",[2]Entry!$E$33) | S30: =IF([2]Entry!$G$33="","",[2]Entry!$G$33) | T30: =IF([2]Entry!$J$33="","",[2]Entry!$J$33) | U30: =IF([2]Entry!$K$33="","",[2]Entry!$K$33) | V30: =IF([2]Entry!$L$33="","",[2]Entry!$L$33) | W30: =IF([2]Entry!$M$33="","",[2]Entry!$M$33) | X30: =IF([2]Entry!$N$33="","",[2]Entry!$N$33) | Y30: =IF([2]Entry!$R$33="","",[2]Entry!$R$33) | AA30: =IF(AND($E30<>"",$G30<>"",$F30="هزینه"),1,0) | AB30: =SUM($AA$6:$AA30) | AC30: =IFERROR(INDEX($E$6:$E$105,MATCH(ROW()-5,$AB$6:$AB$105,0)),"")
